Workbook

Sheet Summary
B1: D
D2: =TEXT(D4, "mmm-yy") -> Apr-26 | E2: =TEXT(E4, "mmm-yy") -> May-26 | F2: =TEXT(F4, "mmm-yy") -> Jun-26 | G2: =TEXT(G4, "mmm-yy") -> Jul-26 | H2: =TEXT(H4, "mmm-yy") -> Aug-26 | I2: =TEXT(I4, "mmm-yy") -> Sep-26 | J2: =TEXT(J4, "mmm-yy") -> Oct-26 | K2: =TEXT(K4, "mmm-yy") -> Nov-26 | ... O2: =TEXT(O4, "mmm-yy") -> Mar-27
D3: 30 | E3: 31 | F3: 30 | G3: 0 | H3: 0 | I3: 0 | J3: 0 | K3: 0 | L3: 0 | M3: 0 | N3: 0 | O3: 0 | P3: =SUM(D3:O3) -> 91
C4: Marketplace (ITAD) | D4: 46113 | E4: 46143 | F4: 46174 | G4: 46204 | H4: 46235 | I4: 46266 | J4: 46296 | K4: 46327 | L4: 46357 | M4: 46388 | N4: 46419 | O4: 46447 | P4: FY 2026-27
C5: Quantity (units) | D5: 6453.55 | E5: 1326 | F5: 3549.26 | G5: =SUMIFS(Details!$BB$4:$BB$160,Details!$C$4:$C$160,Summary!G$4) -> 0 | H5: =SUMIFS(Details!$BB$4:$BB$160,Details!$C$4:$C$160,Summary!H$4) -> 0 | I5: =SUMIFS(Details!$BB$4:$BB$160,Details!$C$4:$C$160,Summary!I$4) -> 0 | J5: =SUMIFS(Details!$BB$4:$BB$160,Details!$C$4:$C$160,Summary!J$4) -> 0 | K5: =SUMIFS(Details!$BB$4:$BB$160,Details!$C$4:$C$160,Summary!K$4) -> 0 | L5: =SUMIFS(Details!$BB$4:$BB$160,Details!$C$4:$C$160,Summary!L$4) -> 0 | M5: =SUMIFS(Details!$BB$4:$BB$160,Details!$C$4:$C$160,Summary!M$4) -> 0 | N5: =SUMIFS(Details!$BB$4:$BB$160,Details!$C$4:$C$160,Summary!N$4) -> 0 | O5: =SUMIFS(Details!$BB$4:$BB$160,Details!$C$4:$C$160,Summary!O$4) -> 0 | P5: =SUM(D5:O5) -> 11328.81 | Q5: =Details!BB161 -> 11328.81 | R5: =P5-Q5 -> 0
C6: Sales | D6: 2227828.8 | E6: 1333242.9 | F6: 3099918.1 | G6: =SUMIFS(Details!$BO$4:$BO$160,Details!$C$4:$C$160,Summary!G$4) -> 0 | H6: =SUMIFS(Details!$BO$4:$BO$160,Details!$C$4:$C$160,Summary!H$4) -> 0 | I6: =SUMIFS(Details!$BO$4:$BO$160,Details!$C$4:$C$160,Summary!I$4) -> 0 | J6: =SUMIFS(Details!$BO$4:$BO$160,Details!$C$4:$C$160,Summary!J$4) -> 0 | K6: =SUMIFS(Details!$BO$4:$BO$160,Details!$C$4:$C$160,Summary!K$4) -> 0 | L6: =SUMIFS(Details!$BO$4:$BO$160,Details!$C$4:$C$160,Summary!L$4) -> 0 | M6: =SUMIFS(Details!$BO$4:$BO$160,Details!$C$4:$C$160,Summary!M$4) -> 0 | N6: =SUMIFS(Details!$BO$4:$BO$160,Details!$C$4:$C$160,Summary!N$4) -> 0 | O6: =SUMIFS(Details!$BO$4:$BO$160,Details!$C$4:$C$160,Summary!O$4) -> 0 | P6: =SUM(D6:O6) -> 6660989.7 | Q6: =Details!BO161 -> 6660989.7 | R6: =P6-Q6+P74 -> 0
C7: Purchases | D7: 1570805.1 | E7: 1206184 | F7: 2827776.9 | G7: =SUMIFS(Details!$AM$4:$AM$160,Details!$C$4:$C$160,Summary!G$4)-SUMIFS(Details!$AB$4:$AB$160,Details!$C$4:$C$160,Summary!G$4) -> 0 | H7: =SUMIFS(Details!$AM$4:$AM$160,Details!$C$4:$C$160,Summary!H$4)-SUMIFS(Details!$AB$4:$AB$160,Details!$C$4:$C$160,Summary!H$4) -> 0 | I7: =SUMIFS(Details!$AM$4:$AM$160,Details!$C$4:$C$160,Summary!I$4)-SUMIFS(Details!$AB$4:$AB$160,Details!$C$4:$C$160,Summary!I$4) -> 0 | J7: =SUMIFS(Details!$AM$4:$AM$160,Details!$C$4:$C$160,Summary!J$4)-SUMIFS(Details!$AB$4:$AB$160,Details!$C$4:$C$160,Summary!J$4) -> 0 | K7: =SUMIFS(Details!$AM$4:$AM$160,Details!$C$4:$C$160,Summary!K$4)-SUMIFS(Details!$AB$4:$AB$160,Details!$C$4:$C$160,Summary!K$4) -> 0 | L7: =SUMIFS(Details!$AM$4:$AM$160,Details!$C$4:$C$160,Summary!L$4)-SUMIFS(Details!$AB$4:$AB$160,Details!$C$4:$C$160,Summary!L$4) -> 0 | M7: =SUMIFS(Details!$AM$4:$AM$160,Details!$C$4:$C$160,Summary!M$4)-SUMIFS(Details!$AB$4:$AB$160,Details!$C$4:$C$160,Summary!M$4) -> 0 | N7: =SUMIFS(Details!$AM$4:$AM$160,Details!$C$4:$C$160,Summary!N$4)-SUMIFS(Details!$AB$4:$AB$160,Details!$C$4:$C$160,Summary!N$4) -> 0 | O7: =SUMIFS(Details!$AM$4:$AM$160,Details!$C$4:$C$160,Summary!O$4)-SUMIFS(Details!$AB$4:$AB$160,Details!$C$4:$C$160,Summary!O$4) -> 0 | P7: =SUM(D7:O7) -> 5604766 | Q7: =Details!P162 -> 5604766 | R7: =P7-Q7 -> 0
C8: Gross Margin | D8: =D6-D7 -> 657023.68 | E8: =E6-E7 -> 127058.89 | F8: =F6-F7 -> 272141.13 | G8: =G6-G7 -> 0 | H8: =H6-H7 -> 0 | I8: =I6-I7 -> 0 | J8: =J6-J7 -> 0 | K8: =K6-K7 -> 0 | ... O8: =O6-O7 -> 0 | P8: =SUM(D8:O8) -> 1056223.7
C9: Gross Margin (%) | D9: =IFERROR((D8/D6),0) -> 0.2949166 | E9: =IFERROR((E8/E6),0) -> 0.095300631 | F9: =IFERROR((F8/F6),0) -> 0.087789782 | G9: =IFERROR((G8/G6),0) -> 0 | H9: =IFERROR((H8/H6),0) -> 0 | I9: =IFERROR((I8/I6),0) -> 0 | J9: =IFERROR((J8/J6),0) -> 0 | K9: =IFERROR((K8/K6),0) -> 0 | ... P9: =IFERROR((P8/P6),0) -> 0.15856858
C10: Transportation Charges | D10: =SUMIFS(Details!$AB$4:$AB$160,Details!$C$4:$C$160,Summary!D$4) -> 0 | E10: =SUMIFS(Details!$AB$4:$AB$160,Details!$C$4:$C$160,Summary!E$4) -> 0 | F10: =SUMIFS(Details!$AB$4:$AB$160,Details!$C$4:$C$160,Summary!F$4) -> 0 | G10: =SUMIFS(Details!$AB$4:$AB$160,Details!$C$4:$C$160,Summary!G$4) -> 0 | H10: =SUMIFS(Details!$AB$4:$AB$160,Details!$C$4:$C$160,Summary!H$4) -> 0 | I10: =SUMIFS(Details!$AB$4:$AB$160,Details!$C$4:$C$160,Summary!I$4) -> 0 | J10: =SUMIFS(Details!$AB$4:$AB$160,Details!$C$4:$C$160,Summary!J$4) -> 0 | K10: =SUMIFS(Details!$AB$4:$AB$160,Details!$C$4:$C$160,Summary!K$4) -> 0 | ... O10: =SUMIFS(Details!$AB$4:$AB$160,Details!$C$4:$C$160,Summary!O$4) -> 0 | P10: =SUM(D10:O10) -> 0 | Q10: =Details!AB161 -> 0 | R10: =P10-Q10 -> 0
C11: Operational Cost | D11: =SUMIFS(Details!$AC$4:$AC$160,Details!$C$4:$C$160,Summary!D$4) -> 0 | E11: =SUMIFS(Details!$AC$4:$AC$160,Details!$C$4:$C$160,Summary!E$4) -> 0 | F11: =SUMIFS(Details!$AC$4:$AC$160,Details!$C$4:$C$160,Summary!F$4) -> 0 | G11: =SUMIFS(Details!$AC$4:$AC$160,Details!$C$4:$C$160,Summary!G$4) -> 0 | H11: =SUMIFS(Details!$AC$4:$AC$160,Details!$C$4:$C$160,Summary!H$4) -> 0 | I11: =SUMIFS(Details!$AC$4:$AC$160,Details!$C$4:$C$160,Summary!I$4) -> 0 | J11: =SUMIFS(Details!$AC$4:$AC$160,Details!$C$4:$C$160,Summary!J$4) -> 0 | K11: =SUMIFS(Details!$AC$4:$AC$160,Details!$C$4:$C$160,Summary!K$4) -> 0 | ... O11: =SUMIFS(Details!$AC$4:$AC$160,Details!$C$4:$C$160,Summary!O$4) -> 0 | P11: =SUM(D11:O11) -> 0
C12: Net Margin | D12: =D6-D7-D10-D11 -> 657023.68 | E12: =E6-E7-E10-E11 -> 127058.89 | F12: =F6-F7-F10-F11 -> 272141.13 | G12: =G6-G7-G10-G11 -> 0 | H12: =H6-H7-H10-H11 -> 0 | I12: =I6-I7-I10-I11 -> 0 | J12: =J6-J7-J10-J11 -> 0 | K12: =K6-K7-K10-K11 -> 0 | ... O12: =O6-O7-O10-O11 -> 0 | P12: =SUM(D12:O12) -> 1056223.7
C13: Net Margin (%) | D13: =IFERROR((D12/D6),0) -> 0.2949166 | E13: =IFERROR((E12/E6),0) -> 0.095300631 | F13: =IFERROR((F12/F6),0) -> 0.087789782 | G13: =IFERROR((G12/G6),0) -> 0 | H13: =IFERROR((H12/H6),0) -> 0 | I13: =IFERROR((I12/I6),0) -> 0 | J13: =IFERROR((J12/J6),0) -> 0 | K13: =IFERROR((K12/K6),0) -> 0 | ... P13: =IFERROR((P12/P6),0) -> 0.15856858
C14: Other Income | D14: 0 | E14: 0 | F14: 0 | G14: 0 | H14: 0 | I14: 0 | J14: 0 | K14: 0 | L14: 0 | M14: 0 | N14: 0 | O14: 0 | P14: =SUM(D14:O14) -> 0
C15: Transport Charges (%) | D15: =IFERROR((D10/D6),0) -> 0 | E15: =IFERROR((E10/E6),0) -> 0 | F15: =IFERROR((F10/F6),0) -> 0 | G15: =IFERROR((G10/G6),0) -> 0 | H15: =IFERROR((H10/H6),0) -> 0 | I15: =IFERROR((I10/I6),0) -> 0 | J15: =IFERROR((J10/J6),0) -> 0 | K15: =IFERROR((K10/K6),0) -> 0 | ... P15: =IFERROR((P10/P6),0) -> 0
C16: Revenue Per unit | D16: =IFERROR(D6/(D5*1000),0) -> 0.34520981 | E16: =IFERROR(E6/(E5*1000),0) -> 1.0054622 | F16: =IFERROR(F6/(F5*1000),0) -> 0.87339842 | G16: =IFERROR(G6/(G5*1000),0) -> 0 | H16: =IFERROR(H6/(H5*1000),0) -> 0 | I16: =IFERROR(I6/(I5*1000),0) -> 0 | J16: =IFERROR(J6/(J5*1000),0) -> 0 | K16: =IFERROR(K6/(K5*1000),0) -> 0 | ... O16: =IFERROR(O6/(O5*1000),0) -> 0 | P16: =+P6/(P5*1000) -> 0.58796906
C17: Purchase Cost Per unit | D17: =IFERROR(D7/(D5*1000),0) -> 0.24340171 | E17: =IFERROR(E7/(E5*1000),0) -> 0.90964104 | F17: =IFERROR(F7/(F5*1000),0) -> 0.79672296 | G17: =IFERROR(G7/(G5*1000),0) -> 0 | H17: =IFERROR(H7/(H5*1000),0) -> 0 | I17: =IFERROR(I7/(I5*1000),0) -> 0 | J17: =IFERROR(J7/(J5*1000),0) -> 0 | K17: =IFERROR(K7/(K5*1000),0) -> 0 | ... O17: =IFERROR(O7/(O5*1000),0) -> 0 | P17: =+P7/(P5*1000) -> 0.49473564
C18: Transportation Charges Per unit | D18: =IFERROR(D10/(D5*1000),0) -> 0 | E18: =IFERROR(E10/(E5*1000),0) -> 0 | F18: =IFERROR(F10/(F5*1000),0) -> 0 | G18: =IFERROR(G10/(G5*1000),0) -> 0 | H18: =IFERROR(H10/(H5*1000),0) -> 0 | I18: =IFERROR(I10/(I5*1000),0) -> 0 | J18: =IFERROR(J10/(J5*1000),0) -> 0 | K18: =IFERROR(K10/(K5*1000),0) -> 0 | ... O18: =IFERROR(O10/(O5*1000),0) -> 0 | P18: =P10/(P5*1000) -> 0
C19: No. of Transactions | D19: {=IFERROR(ROWS(_xlfn.UNIQUE(_xlfn._xlws.FILTER(Details!$AO$5:$AO$160, (Details!$C$5:$C$160)=Summary!D$2))),0)} -> 17 | E19: {=IFERROR(ROWS(_xlfn.UNIQUE(_xlfn._xlws.FILTER(Details!$AO$5:$AO$160, (Details!$C$5:$C$160)=Summary!E$2))),0)} -> 9 | F19: {=IFERROR(ROWS(_xlfn.UNIQUE(_xlfn._xlws.FILTER(Details!$AO$5:$AO$160, (Details!$C$5:$C$160)=Summary!F$2))),0)} -> 14 | G19: {=IFERROR(ROWS(_xlfn.UNIQUE(_xlfn._xlws.FILTER(Details!$AO$5:$AO$160, (Details!$C$5:$C$160)=Summary!G$2))),0)} -> 0 | H19: {=IFERROR(ROWS(_xlfn.UNIQUE(_xlfn._xlws.FILTER(Details!$AO$5:$AO$160, (Details!$C$5:$C$160)=Summary!H$2))),0)} -> 0 | I19: {=IFERROR(ROWS(_xlfn.UNIQUE(_xlfn._xlws.FILTER(Details!$AO$5:$AO$160, (Details!$C$5:$C$160)=Summary!I$2))),0)} -> 0 | J19: {=IFERROR(ROWS(_xlfn.UNIQUE(_xlfn._xlws.FILTER(Details!$AO$5:$AO$160, (Details!$C$5:$C$160)=Summary!J$2))),0)} -> 0 | K19: {=IFERROR(ROWS(_xlfn.UNIQUE(_xlfn._xlws.FILTER(Details!$AO$5:$AO$160, (Details!$C$5:$C$160)=Summary!K$2))),0)} -> 0 | ... O19: {=IFERROR(ROWS(_xlfn.UNIQUE(_xlfn._xlws.FILTER(Details!$AO$5:$AO$160, (Details!$C$5:$C$160)=Summary!O$2))),0)} -> 0 | P19: =SUM(D19:O19) -> 40
C20: No. of Sellers (Aggregators) | D20: {=IFERROR(ROWS(_xlfn.UNIQUE(_xlfn._xlws.FILTER(MID(Details!$G$5:$G$160,3,10), (Details!$C$5:$C$160)=Summary!D$2))),0)} -> 10 | E20: {=IFERROR(ROWS(_xlfn.UNIQUE(_xlfn._xlws.FILTER(MID(Details!$G$5:$G$160,3,10), (Details!$C$5:$C$160)=Summary!E$2))),0)-1} -> 5 | F20: {=IFERROR(ROWS(_xlfn.UNIQUE(_xlfn._xlws.FILTER(MID(Details!$G$5:$G$160,3,10), (Details!$C$5:$C$160)=Summary!F$2))),0)-1} -> 9 | G20: {=IFERROR(ROWS(_xlfn.UNIQUE(_xlfn._xlws.FILTER(MID(Details!$G$5:$G$160,3,10), (Details!$C$5:$C$160)=Summary!G$2))),0)} -> 0 | H20: {=IFERROR(ROWS(_xlfn.UNIQUE(_xlfn._xlws.FILTER(MID(Details!$G$5:$G$160,3,10), (Details!$C$5:$C$160)=Summary!H$2))),0)} -> 0 | I20: {=IFERROR(ROWS(_xlfn.UNIQUE(_xlfn._xlws.FILTER(MID(Details!$G$5:$G$160,3,10), (Details!$C$5:$C$160)=Summary!I$2))),0)} -> 0 | J20: {=IFERROR(ROWS(_xlfn.UNIQUE(_xlfn._xlws.FILTER(MID(Details!$G$5:$G$160,3,10), (Details!$C$5:$C$160)=Summary!J$2))),0)} -> 0 | K20: {=IFERROR(ROWS(_xlfn.UNIQUE(_xlfn._xlws.FILTER(MID(Details!$G$5:$G$160,3,10), (Details!$C$5:$C$160)=Summary!K$2))),0)} -> 0 | L20: {=IFERROR(ROWS(_xlfn.UNIQUE(_xlfn._xlws.FILTER(MID(Details!$G$5:$G$160,3,10), (Details!$C$5:$C$160)=Summary!L$2))),0)} -> 0 | M20: {=IFERROR(ROWS(_xlfn.UNIQUE(_xlfn._xlws.FILTER(MID(Details!$G$5:$G$160,3,10), (Details!$C$5:$C$160)=Summary!M$2))),0)} -> 0 | N20: {=IFERROR(ROWS(_xlfn.UNIQUE(_xlfn._xlws.FILTER(MID(Details!$G$5:$G$160,3,10), (Details!$C$5:$C$160)=Summary!N$2))),0)} -> 0 | O20: {=IFERROR(ROWS(_xlfn.UNIQUE(_xlfn._xlws.FILTER(MID(Details!$G$5:$G$160,3,10), (Details!$C$5:$C$160)=Summary!O$2))),0)} -> 0 | P20: ='Supplier Metrics'!E2 -> 22
C21: No. of Buyers (Recyclers) | D21: {=IFERROR(ROWS(_xlfn.UNIQUE(_xlfn._xlws.FILTER(MID(Details!$AR$5:$AR$160,3,10), (Details!$C$5:$C$160)=Summary!D$2))),0)} -> 7 | E21: {=IFERROR(ROWS(_xlfn.UNIQUE(_xlfn._xlws.FILTER(MID(Details!$AR$5:$AR$160,3,10), (Details!$C$5:$C$160)=Summary!E$2))),0)} -> 4 | F21: {=IFERROR(ROWS(_xlfn.UNIQUE(_xlfn._xlws.FILTER(MID(Details!$AR$5:$AR$160,3,10), (Details!$C$5:$C$160)=Summary!F$2))),0)} -> 9 | G21: {=IFERROR(ROWS(_xlfn.UNIQUE(_xlfn._xlws.FILTER(MID(Details!$AR$5:$AR$160,3,10), (Details!$C$5:$C$160)=Summary!G$2))),0)} -> 0 | H21: {=IFERROR(ROWS(_xlfn.UNIQUE(_xlfn._xlws.FILTER(MID(Details!$AR$5:$AR$160,3,10), (Details!$C$5:$C$160)=Summary!H$2))),0)} -> 0 | I21: {=IFERROR(ROWS(_xlfn.UNIQUE(_xlfn._xlws.FILTER(MID(Details!$AR$5:$AR$160,3,10), (Details!$C$5:$C$160)=Summary!I$2))),0)} -> 0 | J21: {=IFERROR(ROWS(_xlfn.UNIQUE(_xlfn._xlws.FILTER(MID(Details!$AR$5:$AR$160,3,10), (Details!$C$5:$C$160)=Summary!J$2))),0)} -> 0 | K21: {=IFERROR(ROWS(_xlfn.UNIQUE(_xlfn._xlws.FILTER(MID(Details!$AR$5:$AR$160,3,10), (Details!$C$5:$C$160)=Summary!K$2))),0)} -> 0 | ... O21: {=IFERROR(ROWS(_xlfn.UNIQUE(_xlfn._xlws.FILTER(MID(Details!$AR$5:$AR$160,3,10), (Details!$C$5:$C$160)=Summary!O$2))),0)} -> 0 | P21: ='Buyer Metrics'!C3 -> 14
C22: Full Rejection | D22: {=IFERROR(ROWS(_xlfn.UNIQUE(_xlfn._xlws.FILTER(Details!$E$5:$E$160,(Details!$C$5:$C$160=Summary!D$2)*(Details!$BR$5:$BR$160=Summary!$C$22)))),0)} -> 0 | E22: {=IFERROR(ROWS(_xlfn.UNIQUE(_xlfn._xlws.FILTER(Details!$E$5:$E$160,(Details!$C$5:$C$160=Summary!E$2)*(Details!$BR$5:$BR$160=Summary!$C$22)))),0)} -> 0 | F22: {=IFERROR(ROWS(_xlfn.UNIQUE(_xlfn._xlws.FILTER(Details!$E$5:$E$160,(Details!$C$5:$C$160=Summary!F$2)*(Details!$BR$5:$BR$160=Summary!$C$22)))),0)} -> 0 | G22: {=IFERROR(ROWS(_xlfn.UNIQUE(_xlfn._xlws.FILTER(Details!$E$5:$E$160,(Details!$C$5:$C$160=Summary!G$2)*(Details!$BR$5:$BR$160=Summary!$C$22)))),0)} -> 0 | H22: {=IFERROR(ROWS(_xlfn.UNIQUE(_xlfn._xlws.FILTER(Details!$E$5:$E$160,(Details!$C$5:$C$160=Summary!H$2)*(Details!$BR$5:$BR$160=Summary!$C$22)))),0)} -> 0 | I22: {=IFERROR(ROWS(_xlfn.UNIQUE(_xlfn._xlws.FILTER(Details!$E$5:$E$160,(Details!$C$5:$C$160=Summary!I$2)*(Details!$BR$5:$BR$160=Summary!$C$22)))),0)} -> 0 | J22: {=IFERROR(ROWS(_xlfn.UNIQUE(_xlfn._xlws.FILTER(Details!$E$5:$E$160,(Details!$C$5:$C$160=Summary!J$2)*(Details!$BR$5:$BR$160=Summary!$C$22)))),0)} -> 0 | K22: {=IFERROR(ROWS(_xlfn.UNIQUE(_xlfn._xlws.FILTER(Details!$E$5:$E$160,(Details!$C$5:$C$160=Summary!K$2)*(Details!$BR$5:$BR$160=Summary!$C$22)))),0)} -> 0 | ... O22: {=IFERROR(ROWS(_xlfn.UNIQUE(_xlfn._xlws.FILTER(Details!$E$5:$E$160,(Details!$C$5:$C$160=Summary!O$2)*(Details!$BR$5:$BR$160=Summary!$C$22)))),0)} -> 0 | P22: =SUM(D22:O22) -> 0
C23: Receivable | D23: 1423815.6 | E23: 1121048.3 | F23: 1389959.4 | G23: 0 | H23: 0 | I23: 0 | J23: 0 | K23: 0 | L23: 0 | M23: 0 | N23: 0 | O23: 0 | P23: =F23 -> 1389959.4
C24: DSO (Days) | D24: =IFERROR(((D23/(D6*1.18))*D3),0) -> 16.248422 | E24: =IFERROR(((E23/(E6*1.18))*E3),0) -> 22.089949 | F24: =IFERROR(((F23/(F6*1.18))*F3),0) -> 11.399641 | G24: =IFERROR(((G23/(G6*1.18))*G3),0) -> 0 | H24: =IFERROR(((H23/(H6*1.18))*H3),0) -> 0 | I24: =IFERROR(((I23/(I6*1.18))*I3),0) -> 0 | J24: =IFERROR(((J23/(J6*1.18))*J3),0) -> 0 | K24: =IFERROR(((K23/(K6*1.18))*K3),0) -> 0 | ... O24: =IFERROR(((O23/(O6*1.18))*O3),0) -> 0 | P24: =IFERROR(((P23)/(P6*1.18)*P3),0) -> 16.092471
C25: Payable | D25: 665050.13 | E25: 1299425.5 | F25: 1730327.6 | G25: 0 | H25: 0 | I25: 0 | J25: 0 | K25: 0 | L25: 0 | M25: 0 | N25: 0 | O25: 0 | P25: =F25 -> 1730327.6
C26: DPO (Days) | D26: =IFERROR(((D25/(D7*1.18))*D3),0) -> 10.763942 | E26: =IFERROR(((E25/(E7*1.18))*E3),0) -> 28.302025 | F26: =IFERROR(((F25/(F7*1.18))*F3),0) -> 15.556878 | G26: =IFERROR(((G25/(G7*1.18))*G3),0) -> 0 | H26: =IFERROR(((H25/(H7*1.18))*H3),0) -> 0 | I26: =IFERROR(((I25/(I7*1.18))*I3),0) -> 0 | J26: =IFERROR(((J25/(J7*1.18))*J3),0) -> 0 | K26: =IFERROR(((K25/(K7*1.18))*K3),0) -> 0 | ... P26: =IFERROR(((P25/(P7*1.18))*P3),0) -> 23.808402
C27: Working Capital Days | D27: =D24-D26 -> 5.4844803 | E27: =E24-E26 -> -6.2120757 | F27: =F24-F26 -> -4.1572375 | G27: =G24-G26 -> 0 | H27: =H24-H26 -> 0 | I27: =I24-I26 -> 0 | J27: =J24-J26 -> 0 | K27: =K24-K26 -> 0 | ... P27: =P24-P26 -> -7.7159305
C28: Credit Notes (Value - Incl. Prov) | D28: 0 | E28: =-SUMIFS(Details!$BW$4:$BW$160,Details!$C$4:$C$160,Summary!E4) -> 0 | F28: =-SUMIFS(Details!$BW$4:$BW$160,Details!$C$4:$C$160,Summary!F4) -> 0 | G28: =-SUMIFS(Details!$BW$4:$BW$160,Details!$C$4:$C$160,Summary!G4) -> 0 | H28: =-SUMIFS(Details!$BW$4:$BW$160,Details!$C$4:$C$160,Summary!H4) -> 0 | I28: =-SUMIFS(Details!$BW$4:$BW$160,Details!$C$4:$C$160,Summary!I4) -> 0 | J28: =-SUMIFS(Details!$BW$4:$BW$160,Details!$C$4:$C$160,Summary!J4) -> 0 | K28: =-SUMIFS(Details!$BW$4:$BW$160,Details!$C$4:$C$160,Summary!K4) -> 0 | L28: =-SUMIFS(Details!$BW$4:$BW$160,Details!$C$4:$C$160,Summary!L4) -> 0 | ... O28: =-SUMIFS(Details!$BW$4:$BW$160,Details!$C$4:$C$160,Summary!O4) -> 0 | P28: =SUM(D28:O28) -> 0 | Q28: =(-Details!BM161-Details!BN161) -> 0 | R28: =P28-Q28 -> 0
C29: Credit Notes (% to Revenue) | D29: =IFERROR((D28/D6),0) -> 0 | E29: =IFERROR((E28/E6),0) -> 0 | F29: =IFERROR((F28/F6),0) -> 0 | G29: =IFERROR((G28/G6),0) -> 0 | H29: =IFERROR((H28/H6),0) -> 0 | I29: =IFERROR((I28/I6),0) -> 0 | J29: =IFERROR((J28/J6),0) -> 0 | K29: =IFERROR((K28/K6),0) -> 0 | ... O29: =IFERROR((O28/O6),0) -> 0 | P29: =+P28/P6 -> 0
C30: Debit Notes (Value - Incl. Prov) | D30: 0 | E30: =-SUMIFS(Details!$BX$4:$BX$160,Details!$C$4:$C$160,Summary!E4) -> 0 | F30: =-SUMIFS(Details!$BX$4:$BX$160,Details!$C$4:$C$160,Summary!F4) -> 0 | G30: =-SUMIFS(Details!$BX$4:$BX$160,Details!$C$4:$C$160,Summary!G4) -> 0 | H30: =-SUMIFS(Details!$BX$4:$BX$160,Details!$C$4:$C$160,Summary!H4) -> 0 | I30: =-SUMIFS(Details!$BX$4:$BX$160,Details!$C$4:$C$160,Summary!I4) -> 0 | J30: =-SUMIFS(Details!$BX$4:$BX$160,Details!$C$4:$C$160,Summary!J4) -> 0 | K30: =-SUMIFS(Details!$BX$4:$BX$160,Details!$C$4:$C$160,Summary!K4) -> 0 | L30: =-SUMIFS(Details!$BX$4:$BX$160,Details!$C$4:$C$160,Summary!L4) -> 0 | ... O30: =-SUMIFS(Details!$BX$4:$BX$160,Details!$C$4:$C$160,Summary!O4) -> 0 | P30: =SUM(D30:O30) -> 0 | Q30: =(-Details!AK161-Details!AL161) -> 0 | R30: =P30-Q30 -> 0
C31: Debit Notes (% to Purchase) | D31: =IFERROR((D30/D7),0) -> 0 | E31: =IFERROR((E30/E7),0) -> 0 | F31: =IFERROR((F30/F7),0) -> 0 | G31: =IFERROR((G30/G7),0) -> 0 | H31: =IFERROR((H30/H7),0) -> 0 | I31: =IFERROR((I30/I7),0) -> 0 | J31: =IFERROR((J30/J7),0) -> 0 | K31: =IFERROR((K30/K7),0) -> 0 | ... O31: =IFERROR((O30/O7),0) -> 0 | P31: =(P30/(P7+P10)) -> 0
C33: KPI's without Provisions | D33: =D4 -> 46113 | E33: =E4 -> 46143 | F33: =F4 -> 46174 | G33: =G4 -> 46204 | H33: =H4 -> 46235 | I33: =I4 -> 46266 | J33: =J4 -> 46296 | K33: =K4 -> 46327 | ... P33: =P4 -> FY 2026-27
C34: Sales without Provision | D34: =D6-D53 -> 2227828.8 | E34: =E6+E53 -> 1333242.9 | F34: =F6+F53 -> 3099918.1 | G34: =G6+G53 -> 0 | H34: =H6+H53 -> 0 | I34: =I6+I53 -> 0 | J34: =J6+J53 -> 0 | K34: =K6+K53 -> 0 | L34: =L6+L53 -> 0 | ... O34: =O6+O53 -> 0 | P34: =SUM(D34:O34) -> 6660989.7
C35: Purchases without Provision | D35: =D7+D10-D52 -> 1570805.1 | E35: =E7+E10+E52 -> 1206184 | F35: =F7+F10+F52 -> 2827776.9 | G35: =G7+G10+G52 -> 0 | H35: =H7+H10+H52 -> 0 | I35: =I7+I10+I52 -> 0 | J35: =J7+J10+J52 -> 0 | K35: =K7+K10+K52 -> 0 | L35: =L7+L10+L52 -> 0 | ... O35: =O7+O10+O52 -> 0 | P35: =SUM(D35:O35) -> 5604766
C36: Contribution without Provision | D36: =D34-D35 -> 657023.68 | E36: =E34-E35 -> 127058.89 | F36: =F34-F35 -> 272141.13 | G36: =G34-G35 -> 0 | H36: =H34-H35 -> 0 | I36: =I34-I35 -> 0 | J36: =J34-J35 -> 0 | K36: =K34-K35 -> 0 | ... P36: =P34-P35 -> 1056223.7
C37: Contribution (%) | D37: =D36/D34 -> 0.2949166 | E37: =E36/E34 -> 0.095300631 | F37: =F36/F34 -> 0.087789782 | G37: =G36/G34 -> #DIV/0! | H37: =H36/H34 -> #DIV/0! | I37: =I36/I34 -> #DIV/0! | J37: =J36/J34 -> #DIV/0! | K37: =K36/K34 -> #DIV/0! | ... P37: =P36/P34 -> 0.15856858
C39: Business Trends | D39: =D4 -> 46113 | E39: =E4 -> 46143 | F39: =F4 -> 46174 | G39: =G4 -> 46204 | H39: =H4 -> 46235 | I39: =I4 -> 46266 | J39: =J4 -> 46296 | K39: =K4 -> 46327 | ... P39: =P4 -> FY 2026-27
C40: Sales-Revenue (MoM) | D40: =IFERROR(((D6/C6)-1),0) -> 0 | E40: =IFERROR(((E6/D6)-1),0) -> -0.40155055 | F40: =IFERROR(((F6/E6)-1),0) -> 1.3250962 | G40: =IFERROR(((G6/F6)-1),0) -> -1 | H40: =IFERROR(((H6/G6)-1),0) -> 0 | I40: =IFERROR(((I6/H6)-1),0) -> 0 | J40: =IFERROR(((J6/I6)-1),0) -> 0 | K40: =IFERROR(((K6/J6)-1),0) -> 0 | ... O40: =IFERROR(((O6/N6)-1),0) -> 0 | P40: 0
C41: Sales-Volume (MoM) | D41: =IFERROR(((D5/C5)-1),0) -> 0 | E41: =IFERROR(((E5/D5)-1),0) -> -0.79453169 | F41: =IFERROR(((F5/E5)-1),0) -> 1.6766667 | G41: =IFERROR(((G5/F5)-1),0) -> -1 | H41: =IFERROR(((H5/G5)-1),0) -> 0 | I41: =IFERROR(((I5/H5)-1),0) -> 0 | J41: =IFERROR(((J5/I5)-1),0) -> 0 | K41: =IFERROR(((K5/J5)-1),0) -> 0 | ... O41: =IFERROR(((O5/N5)-1),0) -> 0 | P41: 0
C42: Sales-Transactions (MoM) | D42: =IFERROR(((D19/C19)-1),0) -> 0 | E42: =IFERROR(((E19/D19)-1),0) -> -0.47058824 | F42: =IFERROR(((F19/E19)-1),0) -> 0.55555556 | G42: =IFERROR(((G19/F19)-1),0) -> -1 | H42: =IFERROR(((#REF!/G19)-1),0) -> 0 | I42: =IFERROR(((I19/#REF!)-1),0) -> 0 | J42: =IFERROR(((J19/I19)-1),0) -> 0 | K42: =IFERROR(((K19/J19)-1),0) -> 0 | L42: =IFERROR(((L19/K19)-1),0) -> 0 | M42: =IFERROR(((M19/L19)-1),0) -> 0 | N42: =IFERROR(((N19/M19)-1),0) -> 0 | O42: =IFERROR(((O19/N19)-1),0) -> 0 | P42: 0
...

Sheet Details
B3: Raw Data -ITAD | F3: Purchase Details | U3: Logistic Details of the transaction | AF3: Debit Notes to Suppliers | AM3: Sales Details | BD3: DN to Customer | BH3: Credit Notes from Customers | BM3: 0 | BV3: CN & DN Checks | CE3: Without Provisions | CJ3: Margin Buckets | CM3: Financials with GST
B4: Quarter | C4: Month | D4: Date | E4: Shipment ID | F4: Supplier Name | G4: GST Reg No. | H4: Vendor Invoice No. | I4: Vendor Invoice Date | J4: P V No. | K4: P V Date | L4: State (Origin) | M4: Vehicle No. | N4: Material | O4: Qty (Kg) | P4: Price/unit | Q4: Purchase Price | R4: Return Qty | S4: Net Qty | T4: Basic Customs Duty/Discount | U4: Transporter Name | V4: LR NO/BILL NO | W4: J V No. | X4: JV Date | Y4: Logistics cost | Z4: Debit note on logistic cost | AA4: Logistics Provision | AB4: Total Logistics Cost | AC4: Operational Cost | AD4: Cost/Kg. | AE4: Divertion/Internal | AF4: Debit Note No. | AG4: Debit Note Date. | AH4: Debit Note No. 2 | AI4: Debit Note Date. 2 | AJ4: Full Debit Note | AK4: Actual Debit Note | AL4: Provision for DN | AM4: Total Cost | AN4: Inv. Date | AO4: Inv. No. | AP4: Customer ID | AQ4: Buyer Name | AR4: Buyer GST Number | AS4: Location (Origin) | AT4: Location (Destination) | AU4: State (Destination) | AV4: E-WayBill Number | AW4: Qty(Kg) | AX4: Price/unit | AY4: Amount | AZ4: Qty Check | BA4: Return Qty | BB4: Net Qty | BC4: Divertion/Internal | BD4: Return Type | BE4: Date : DN to Buyer | BF4: DN to Buyer | BG4: Amount | BH4: Credit Note No:1 | BI4: CN Date. No:1 | BJ4: Credit Note No:2 | BK4: CN Date. No:2 | BL4: Full Credit Notes | BM4: Actual Credit Note | BN4: Provision for CN | BO4: Net Revenue | BP4: Margin | BQ4: Reamrks - Margin | BR4: Remarks | BS4: LMI @ Inception | BT4: Remarks @ Inception | BU4: Margin (%) | BV4: Margin Bucket | BW4: Total CN(Inc.Provisions) | BX4: Total DN(Inc.Provisions) | BY4: Check | BZ4: Actaul CN | CA4: Actual DN | CB4: Check | CC4: Material-Short Form | CD4: Supplier Type | CE4: Cost | CF4: Revenue | CG4: Week No: | CH4: Category (Material) | CI4: Broad Category | CJ4: POC Name | CK4: Gross Margin | CL4: Recykal Margin | CM4: Net Margin | CN4: Sales | CO4: Purchases | CP4: Credit Note | CQ4: Debit Note | CR4: Margin | CS4: Bill Branch | CT4: Inv Branch | CU4: Vendor PAN No | CV4: Customer PAN No
B5: ="Q" & IF(ROUNDUP(MONTH(D5)/3,0)-1=0,4,ROUNDUP(MONTH(D5)/3,0)-1) -> Q1 | C5: =TEXT(AN5,"mmm-yy") -> Apr-26 | D5: 46115 | E5: SH04260204 | F5: CHAITANYA INDIA FIN CREDIT PRIVATE LIMITED | G5: 33AADCC6184H1ZP | H5: 2026290000000088 | I5: 46094 | J5: 25-26/PUR/027030 | K5: 46115 | L5: TN | N5: ITAD Mixed E Waste | O5: 26 | P5: 1576 | Q5: =O5*P5 -> 40976 | R5: 0 | S5: =O5-R5 -> 26 | T5: 0 | U5: 0 | V5: 0 | W5: 0 | X5: 0 | Y5: 0 | Z5: 0 | AA5: 0 | AB5: =Y5+AA5+Z5 -> 0 | AC5: 0 | AD5: 0 | AE5: 0 | AF5: 0 | AG5: 0 | AH5: 0 | AI5: 0 | AJ5: 0 | AK5: 0 | AL5: =(BN5*P5/AX5)+AB5/O5*(BN5/AX5) -> 0 | AM5: =Q5+AB5+AL5+AK5+AJ5+T5+AE5 -> 40976 | AN5: 46115 | AO5: 29/IAD/27IN00002 | AP5: 832139000046796207 | AQ5: TRADEWIND BUSINESS SOLUTIONS LLP | AR5: 07AARFT3586D1ZR | AS5: Alamelupuram Tamil Nadu 636905 | AT5: New Delhi | AU5: Delhi | AW5: 26 | AX5: 1733.9 | AY5: =AW5*AX5 -> 45081.4 | AZ5: =AW5=O5 -> TRUE | BA5: 0 | BB5: =AW5-BA5 -> 26 | BC5: 0 | BD5: Regular | BE5: 0 | BF5: 0 | BG5: 0 | BH5: 0 | BI5: 0 | BJ5: 0 | BK5: 0 | BL5: 0 | BM5: 0 | BN5: =AY5*$BM$3 -> 0 | BO5: =AY5+BL5+BM5+BN5+BC5+BG5 -> 45081.4 | BP5: =BO5-AM5 -> 4105.4 | BQ5: =IF(BP5>=0,"Positive Margin","Negative Margin") -> Positive Margin | BR5: No Provision | BS5: =AY5-Y5-Q5-AA5-T5+BC5 -> 4105.4 | BT5: =IF(BS5<0, "Negative Margin at Inception", "Positive Margin at Inception") -> Positive Margin at Inception | BU5: =IFERROR(BP5/BO5,"0") -> 0.091066382 | BV5: =IF(BU5<1%,"Less Than 1%",IF(BU5>2%,"More than 2%",IF(BU5>=1%,"1% - 2%"))) -> More than 2% | BW5: =BM5+BN5 -> 0 | BX5: =AL5+AK5 -> 0 | BY5: =BW5-BX5 -> 0 | BZ5: =BM5 -> 0 | CA5: =AK5 -> 0 | CB5: =BZ5-CA5 -> 0 | CC5: Marketplace (IT Assets Disposition) | CD5: 0 | CE5: =AM5-AL5-AA5 -> 40976 | CF5: =BO5-BN5 -> 45081.4 | CG5: =INT((D5- IF(MONTH(D5) >= 4, DATE(YEAR(D5), 4, 1), DATE(YEAR(D5)-1, 4, 1))) / 7) + 1 -> 1 | CH5: 0 | CI5: 0 | CJ5: =_xlfn.XLOOKUP(AP5,POC!B:B,POC!D:D) -> #N/A | CK5: =AY5-Q5 -> 4105.4 | CL5: =CK5-Y5+Z5 -> 4105.4 | CM5: =BO5-AM5 -> 4105.4 | CN5: =AY5*118% -> 53196.052 | CO5: =-Q5*118% -> -48351.68 | CP5: =-BZ5*118% -> 0 | CQ5: =-CA5*118% -> 0 | CR5: =SUM(CN5:CQ5) -> 4844.372 | CS5: Telangana - HO | CT5: Telangana - HO | CU5: =MID(G5,3,10) -> AADCC6184H | CV5: =MID(AR5,3,10) -> AARFT3586D | CW5: =H5&F5 -> 2026290000000088CHAITANYA INDIA FIN CREDIT PRIVATE LIMITED
B6: ="Q" & IF(ROUNDUP(MONTH(D6)/3,0)-1=0,4,ROUNDUP(MONTH(D6)/3,0)-1) -> Q1 | C6: =TEXT(AN6,"mmm-yy") -> Apr-26 | D6: 46115 | E6: SH04260204 | F6: CHAITANYA INDIA FIN CREDIT PRIVATE LIMITED | G6: 33AADCC6184H1ZP | H6: 2026290000000088 | I6: 46094 | J6: 25-26/PUR/027030 | K6: 46115 | L6: TN | N6: ITAD Mixed E Waste | O6: 1 | P6: 85 | Q6: =O6*P6 -> 85 | R6: 0 | S6: =O6-R6 -> 1 | T6: 0 | U6: 0 | V6: 0 | W6: 0 | X6: 0 | Y6: 0 | Z6: 0 | AA6: 0 | AB6: =Y6+AA6+Z6 -> 0 | AC6: 0 | AD6: 0 | AE6: 0 | AF6: 0 | AG6: 0 | AH6: 0 | AI6: 0 | AJ6: 0 | AK6: 0 | AL6: =(BN6*P6/AX6)+AB6/O6*(BN6/AX6) -> 0 | AM6: =Q6+AB6+AL6+AK6+AJ6+T6+AE6 -> 85 | AN6: 46115 | AO6: 29/IAD/27IN00002 | AP6: 832139000046796207 | AQ6: TRADEWIND BUSINESS SOLUTIONS LLP | AR6: 07AARFT3586D1ZR | AS6: Alamelupuram Tamil Nadu 636905 | AT6: New Delhi | AU6: Delhi | AW6: 1 | AX6: 93.22 | AY6: =AW6*AX6 -> 93.22 | AZ6: =AW6=O6 -> TRUE | BA6: 0 | BB6: =AW6-BA6 -> 1 | BC6: 0 | BD6: Regular | BE6: 0 | BF6: 0 | BG6: 0 | BH6: 0 | BI6: 0 | BJ6: 0 | BK6: 0 | BL6: 0 | BM6: 0 | BN6: =AY6*$BM$3 -> 0 | BO6: =AY6+BL6+BM6+BN6+BC6+BG6 -> 93.22 | BP6: =BO6-AM6 -> 8.22 | BQ6: =IF(BP6>=0,"Positive Margin","Negative Margin") -> Positive Margin | BR6: No Provision | BS6: =AY6-Y6-Q6-AA6-T6+BC6 -> 8.22 | BT6: =IF(BS6<0, "Negative Margin at Inception", "Positive Margin at Inception") -> Positive Margin at Inception | BU6: =IFERROR(BP6/BO6,"0") -> 0.088178502 | BV6: =IF(BU6<1%,"Less Than 1%",IF(BU6>2%,"More than 2%",IF(BU6>=1%,"1% - 2%"))) -> More than 2% | BW6: =BM6+BN6 -> 0 | BX6: =AL6+AK6 -> 0 | BY6: =BW6-BX6 -> 0 | BZ6: =BM6 -> 0 | CA6: =AK6 -> 0 | CB6: =BZ6-CA6 -> 0 | CC6: Marketplace (IT Assets Disposition) | CD6: 0 | CE6: =AM6-AL6-AA6 -> 85 | CF6: =BO6-BN6 -> 93.22 | CG6: =INT((D6- IF(MONTH(D6) >= 4, DATE(YEAR(D6), 4, 1), DATE(YEAR(D6)-1, 4, 1))) / 7) + 1 -> 1 | CH6: 0 | CI6: 0 | CJ6: =_xlfn.XLOOKUP(AP6,POC!B:B,POC!D:D) -> #N/A | CK6: =AY6-Q6 -> 8.22 | CL6: =CK6-Y6+Z6 -> 8.22 | CM6: =BO6-AM6 -> 8.22 | CN6: =AY6*118% -> 109.9996 | CO6: =-Q6*118% -> -100.3 | CP6: =-BZ6*118% -> 0 | CQ6: =-CA6*118% -> 0 | CR6: =SUM(CN6:CQ6) -> 9.6996 | CS6: Telangana - HO | CT6: Telangana - HO | CU6: =MID(G6,3,10) -> AADCC6184H | CV6: =MID(AR6,3,10) -> AARFT3586D | CW6: =H6&F6 -> 2026290000000088CHAITANYA INDIA FIN CREDIT PRIVATE LIMITED
B7: ="Q" & IF(ROUNDUP(MONTH(D7)/3,0)-1=0,4,ROUNDUP(MONTH(D7)/3,0)-1) -> Q1 | C7: =TEXT(AN7,"mmm-yy") -> Apr-26 | D7: 46115 | E7: SH04260204 | F7: CHAITANYA INDIA FIN CREDIT PRIVATE LIMITED | G7: 33AADCC6184H1ZP | H7: 2026290000000088 | I7: 46094 | J7: 25-26/PUR/027030 | K7: 46115 | L7: TN | N7: ITAD Mixed E Waste | O7: 1 | P7: 85 | Q7: =O7*P7 -> 85 | R7: 0 | S7: =O7-R7 -> 1 | T7: 0 | U7: 0 | V7: 0 | W7: 0 | X7: 0 | Y7: 0 | Z7: 0 | AA7: 0 | AB7: =Y7+AA7+Z7 -> 0 | AC7: 0 | AD7: 0 | AE7: 0 | AF7: 0 | AG7: 0 | AH7: 0 | AI7: 0 | AJ7: 0 | AK7: 0 | AL7: =(BN7*P7/AX7)+AB7/O7*(BN7/AX7) -> 0 | AM7: =Q7+AB7+AL7+AK7+AJ7+T7+AE7 -> 85 | AN7: 46115 | AO7: 29/IAD/27IN00002 | AP7: 832139000046796207 | AQ7: TRADEWIND BUSINESS SOLUTIONS LLP | AR7: 07AARFT3586D1ZR | AS7: Alamelupuram Tamil Nadu 636905 | AT7: New Delhi | AU7: Delhi | AW7: 1 | AX7: 93.22 | AY7: =AW7*AX7 -> 93.22 | AZ7: =AW7=O7 -> TRUE | BA7: 0 | BB7: =AW7-BA7 -> 1 | BC7: 0 | BD7: Regular | BE7: 0 | BF7: 0 | BG7: 0 | BH7: 0 | BI7: 0 | BJ7: 0 | BK7: 0 | BL7: 0 | BM7: 0 | BN7: =AY7*$BM$3 -> 0 | BO7: =AY7+BL7+BM7+BN7+BC7+BG7 -> 93.22 | BP7: =BO7-AM7 -> 8.22 | BQ7: =IF(BP7>=0,"Positive Margin","Negative Margin") -> Positive Margin | BR7: No Provision | BS7: =AY7-Y7-Q7-AA7-T7+BC7 -> 8.22 | BT7: =IF(BS7<0, "Negative Margin at Inception", "Positive Margin at Inception") -> Positive Margin at Inception | BU7: =IFERROR(BP7/BO7,"0") -> 0.088178502 | BV7: =IF(BU7<1%,"Less Than 1%",IF(BU7>2%,"More than 2%",IF(BU7>=1%,"1% - 2%"))) -> More than 2% | BW7: =BM7+BN7 -> 0 | BX7: =AL7+AK7 -> 0 | BY7: =BW7-BX7 -> 0 | BZ7: =BM7 -> 0 | CA7: =AK7 -> 0 | CB7: =BZ7-CA7 -> 0 | CC7: Marketplace (IT Assets Disposition) | CD7: 0 | CE7: =AM7-AL7-AA7 -> 85 | CF7: =BO7-BN7 -> 93.22 | CG7: =INT((D7- IF(MONTH(D7) >= 4, DATE(YEAR(D7), 4, 1), DATE(YEAR(D7)-1, 4, 1))) / 7) + 1 -> 1 | CH7: 0 | CI7: 0 | CJ7: =_xlfn.XLOOKUP(AP7,POC!B:B,POC!D:D) -> #N/A | CK7: =AY7-Q7 -> 8.22 | CL7: =CK7-Y7+Z7 -> 8.22 | CM7: =BO7-AM7 -> 8.22 | CN7: =AY7*118% -> 109.9996 | CO7: =-Q7*118% -> -100.3 | CP7: =-BZ7*118% -> 0 | CQ7: =-CA7*118% -> 0 | CR7: =SUM(CN7:CQ7) -> 9.6996 | CS7: Telangana - HO | CT7: Telangana - HO | CU7: =MID(G7,3,10) -> AADCC6184H | CV7: =MID(AR7,3,10) -> AARFT3586D | CW7: =H7&F7 -> 2026290000000088CHAITANYA INDIA FIN CREDIT PRIVATE LIMITED
B8: ="Q" & IF(ROUNDUP(MONTH(D8)/3,0)-1=0,4,ROUNDUP(MONTH(D8)/3,0)-1) -> Q1 | C8: =TEXT(AN8,"mmm-yy") -> Apr-26 | D8: 46115 | E8: SH04260203 | F8: CHAITANYA INDIA FIN CREDIT PRIVATE LIMITED | G8: 08AADCC6184H1ZI | H8: 2026290000000087 | I8: 46094 | J8: 25-26/PUR/027028 | K8: 46115 | L8: RJ | N8: ITAD Mixed E Waste | O8: 15 | P8: 1576 | Q8: =O8*P8 -> 23640 | R8: 0 | S8: =O8-R8 -> 15 | T8: 0 | U8: 0 | V8: 0 | W8: 0 | X8: 0 | Y8: 0 | Z8: 0 | AA8: 0 | AB8: =Y8+AA8+Z8 -> 0 | AC8: 0 | AD8: 0 | AE8: 0 | AF8: 0 | AG8: 0 | AH8: 0 | AI8: 0 | AJ8: 0 | AK8: 0 | AL8: =(BN8*P8/AX8)+AB8/O8*(BN8/AX8) -> 0 | AM8: =Q8+AB8+AL8+AK8+AJ8+T8+AE8 -> 23640 | AN8: 46115 | AO8: 29/IAD/27IN00001 | AP8: 832139000046796207 | AQ8: TRADEWIND BUSINESS SOLUTIONS LLP | AR8: 07AARFT3586D1ZR | AS8: Jaipur Rajasthan 302020 | AT8: New Delhi | AU8: Delhi | AW8: 15 | AX8: 1733.9 | AY8: =AW8*AX8 -> 26008.5 | AZ8: =AW8=O8 -> TRUE | BA8: 0 | BB8: =AW8-BA8 -> 15 | BC8: 0 | BD8: Regular | BE8: 0 | BF8: 0 | BG8: 0 | BH8: 0 | BI8: 0 | BJ8: 0 | BK8: 0 | BL8: 0 | BM8: 0 | BN8: =AY8*$BM$3 -> 0 | BO8: =AY8+BL8+BM8+BN8+BC8+BG8 -> 26008.5 | BP8: =BO8-AM8 -> 2368.5 | BQ8: =IF(BP8>=0,"Positive Margin","Negative Margin") -> Positive Margin | BR8: No Provision | BS8: =AY8-Y8-Q8-AA8-T8+BC8 -> 2368.5 | BT8: =IF(BS8<0, "Negative Margin at Inception", "Positive Margin at Inception") -> Positive Margin at Inception | BU8: =IFERROR(BP8/BO8,"0") -> 0.091066382 | BV8: =IF(BU8<1%,"Less Than 1%",IF(BU8>2%,"More than 2%",IF(BU8>=1%,"1% - 2%"))) -> More than 2% | BW8: =BM8+BN8 -> 0 | BX8: =AL8+AK8 -> 0 | BY8: =BW8-BX8 -> 0 | BZ8: =BM8 -> 0 | CA8: =AK8 -> 0 | CB8: =BZ8-CA8 -> 0 | CC8: Marketplace (IT Assets Disposition) | CD8: 0 | CE8: =AM8-AL8-AA8 -> 23640 | CF8: =BO8-BN8 -> 26008.5 | CG8: =INT((D8- IF(MONTH(D8) >= 4, DATE(YEAR(D8), 4, 1), DATE(YEAR(D8)-1, 4, 1))) / 7) + 1 -> 1 | CH8: 0 | CI8: 0 | CJ8: =_xlfn.XLOOKUP(AP8,POC!B:B,POC!D:D) -> #N/A | CK8: =AY8-Q8 -> 2368.5 | CL8: =CK8-Y8+Z8 -> 2368.5 | CM8: =BO8-AM8 -> 2368.5 | CN8: =AY8*118% -> 30690.03 | CO8: =-Q8*118% -> -27895.2 | CP8: =-BZ8*118% -> 0 | CQ8: =-CA8*118% -> 0 | CR8: =SUM(CN8:CQ8) -> 2794.83 | CS8: Telangana - HO | CT8: Telangana - HO | CU8: =MID(G8,3,10) -> AADCC6184H | CV8: =MID(AR8,3,10) -> AARFT3586D | CW8: =H8&F8 -> 2026290000000087CHAITANYA INDIA FIN CREDIT PRIVATE LIMITED
B9: ="Q" & IF(ROUNDUP(MONTH(D9)/3,0)-1=0,4,ROUNDUP(MONTH(D9)/3,0)-1) -> Q1 | C9: =TEXT(AN9,"mmm-yy") -> Apr-26 | D9: 46115 | E9: SH04260203 | F9: CHAITANYA INDIA FIN CREDIT PRIVATE LIMITED | G9: 08AADCC6184H1ZI | H9: 2026290000000087 | I9: 46094 | J9: 25-26/PUR/027028 | K9: 46115 | L9: RJ | N9: ITAD Mixed E Waste | O9: 1 | P9: 85 | Q9: =O9*P9 -> 85 | R9: 0 | S9: =O9-R9 -> 1 | T9: 0 | U9: 0 | V9: 0 | W9: 0 | X9: 0 | Y9: 0 | Z9: 0 | AA9: 0 | AB9: =Y9+AA9+Z9 -> 0 | AC9: 0 | AD9: 0 | AE9: 0 | AF9: 0 | AG9: 0 | AH9: 0 | AI9: 0 | AJ9: 0 | AK9: 0 | AL9: =(BN9*P9/AX9)+AB9/O9*(BN9/AX9) -> 0 | AM9: =Q9+AB9+AL9+AK9+AJ9+T9+AE9 -> 85 | AN9: 46115 | AO9: 29/IAD/27IN00001 | AP9: 832139000046796207 | AQ9: TRADEWIND BUSINESS SOLUTIONS LLP | AR9: 07AARFT3586D1ZR | AS9: Jaipur Rajasthan 302020 | AT9: New Delhi | AU9: Delhi | AW9: 1 | AX9: 93.22 | AY9: =AW9*AX9 -> 93.22 | AZ9: =AW9=O9 -> TRUE | BA9: 0 | BB9: =AW9-BA9 -> 1 | BC9: 0 | BD9: Regular | BE9: 0 | BF9: 0 | BG9: 0 | BH9: 0 | BI9: 0 | BJ9: 0 | BK9: 0 | BL9: 0 | BM9: 0 | BN9: =AY9*$BM$3 -> 0 | BO9: =AY9+BL9+BM9+BN9+BC9+BG9 -> 93.22 | BP9: =BO9-AM9 -> 8.22 | BQ9: =IF(BP9>=0,"Positive Margin","Negative Margin") -> Positive Margin | BR9: No Provision | BS9: =AY9-Y9-Q9-AA9-T9+BC9 -> 8.22 | BT9: =IF(BS9<0, "Negative Margin at Inception", "Positive Margin at Inception") -> Positive Margin at Inception | BU9: =IFERROR(BP9/BO9,"0") -> 0.088178502 | BV9: =IF(BU9<1%,"Less Than 1%",IF(BU9>2%,"More than 2%",IF(BU9>=1%,"1% - 2%"))) -> More than 2% | BW9: =BM9+BN9 -> 0 | BX9: =AL9+AK9 -> 0 | BY9: =BW9-BX9 -> 0 | BZ9: =BM9 -> 0 | CA9: =AK9 -> 0 | CB9: =BZ9-CA9 -> 0 | CC9: Marketplace (IT Assets Disposition) | CD9: 0 | CE9: =AM9-AL9-AA9 -> 85 | CF9: =BO9-BN9 -> 93.22 | CG9: =INT((D9- IF(MONTH(D9) >= 4, DATE(YEAR(D9), 4, 1), DATE(YEAR(D9)-1, 4, 1))) / 7) + 1 -> 1 | CH9: 0 | CI9: 0 | CJ9: =_xlfn.XLOOKUP(AP9,POC!B:B,POC!D:D) -> #N/A | CK9: =AY9-Q9 -> 8.22 | CL9: =CK9-Y9+Z9 -> 8.22 | CM9: =BO9-AM9 -> 8.22 | CN9: =AY9*118% -> 109.9996 | CO9: =-Q9*118% -> -100.3 | CP9: =-BZ9*118% -> 0 | CQ9: =-CA9*118% -> 0 | CR9: =SUM(CN9:CQ9) -> 9.6996 | CS9: Telangana - HO | CT9: Telangana - HO | CU9: =MID(G9,3,10) -> AADCC6184H | CV9: =MID(AR9,3,10) -> AARFT3586D | CW9: =H9&F9 -> 2026290000000087CHAITANYA INDIA FIN CREDIT PRIVATE LIMITED
B10: ="Q" & IF(ROUNDUP(MONTH(D10)/3,0)-1=0,4,ROUNDUP(MONTH(D10)/3,0)-1) -> Q1 | C10: =TEXT(AN10,"mmm-yy") -> Apr-26 | D10: 46115 | E10: SH04260203 | F10: CHAITANYA INDIA FIN CREDIT PRIVATE LIMITED | G10: 08AADCC6184H1ZI | H10: 2026290000000087 | I10: 46094 | J10: 25-26/PUR/027028 | K10: 46115 | L10: RJ | N10: ITAD Mixed E Waste | O10: 1 | P10: 1576 | Q10: =O10*P10 -> 1576 | R10: 0 | S10: =O10-R10 -> 1 | T10: 0 | U10: 0 | V10: 0 | W10: 0 | X10: 0 | Y10: 0 | Z10: 0 | AA10: 0 | AB10: =Y10+AA10+Z10 -> 0 | AC10: 0 | AD10: 0 | AE10: 0 | AF10: 0 | AG10: 0 | AH10: 0 | AI10: 0 | AJ10: 0 | AK10: 0 | AL10: =(BN10*P10/AX10)+AB10/O10*(BN10/AX10) -> 0 | AM10: =Q10+AB10+AL10+AK10+AJ10+T10+AE10 -> 1576 | AN10: 46115 | AO10: 29/IAD/27IN00001 | AP10: 832139000046796207 | AQ10: TRADEWIND BUSINESS SOLUTIONS LLP | AR10: 07AARFT3586D1ZR | AS10: Jaipur Rajasthan 302020 | AT10: New Delhi | AU10: Delhi | AW10: 1 | AX10: 1733.9 | AY10: =AW10*AX10 -> 1733.9 | AZ10: =AW10=O10 -> TRUE | BA10: 0 | BB10: =AW10-BA10 -> 1 | BC10: 0 | BD10: Regular | BE10: 0 | BF10: 0 | BG10: 0 | BH10: 0 | BI10: 0 | BJ10: 0 | BK10: 0 | BL10: 0 | BM10: 0 | BN10: =AY10*$BM$3 -> 0 | BO10: =AY10+BL10+BM10+BN10+BC10+BG10 -> 1733.9 | BP10: =BO10-AM10 -> 157.9 | BQ10: =IF(BP10>=0,"Positive Margin","Negative Margin") -> Positive Margin | BR10: No Provision | BS10: =AY10-Y10-Q10-AA10-T10+BC10 -> 157.9 | BT10: =IF(BS10<0, "Negative Margin at Inception", "Positive Margin at Inception") -> Positive Margin at Inception | BU10: =IFERROR(BP10/BO10,"0") -> 0.091066382 | BV10: =IF(BU10<1%,"Less Than 1%",IF(BU10>2%,"More than 2%",IF(BU10>=1%,"1% - 2%"))) -> More than 2% | BW10: =BM10+BN10 -> 0 | BX10: =AL10+AK10 -> 0 | BY10: =BW10-BX10 -> 0 | BZ10: =BM10 -> 0 | CA10: =AK10 -> 0 | CB10: =BZ10-CA10 -> 0 | CC10: Marketplace (IT Assets Disposition) | CD10: 0 | CE10: =AM10-AL10-AA10 -> 1576 | CF10: =BO10-BN10 -> 1733.9 | CG10: =INT((D10- IF(MONTH(D10) >= 4, DATE(YEAR(D10), 4, 1), DATE(YEAR(D10)-1, 4, 1))) / 7) + 1 -> 1 | CH10: 0 | CI10: 0 | CJ10: =_xlfn.XLOOKUP(AP10,POC!B:B,POC!D:D) -> #N/A | CK10: =AY10-Q10 -> 157.9 | CL10: =CK10-Y10+Z10 -> 157.9 | CM10: =BO10-AM10 -> 157.9 | CN10: =AY10*118% -> 2046.002 | CO10: =-Q10*118% -> -1859.68 | CP10: =-BZ10*118% -> 0 | CQ10: =-CA10*118% -> 0 | CR10: =SUM(CN10:CQ10) -> 186.322 | CS10: Telangana - HO | CT10: Telangana - HO | CU10: =MID(G10,3,10) -> AADCC6184H | CV10: =MID(AR10,3,10) -> AARFT3586D | CW10: =H10&F10 -> 2026290000000087CHAITANYA INDIA FIN CREDIT PRIVATE LIMITED
B11: ="Q" & IF(ROUNDUP(MONTH(D11)/3,0)-1=0,4,ROUNDUP(MONTH(D11)/3,0)-1) -> Q1 | C11: =TEXT(AN11,"mmm-yy") -> Apr-26 | D11: 46115 | E11: SH04260307 | F11: CYIENT LIMITED | G11: 36AAACI4487J1Z9 | H11: 9102515564 | I11: 46105 | J11: 25-26/PUR/027036 | K11: 46115 | L11: TS | N11: UPS Battery Scrap | O11: 44 | P11: 4340.95 | Q11: =O11*P11 -> 191001.8 | R11: 0 | S11: =O11-R11 -> 44 | T11: 0 | U11: 0 | V11: 0 | W11: 0 | X11: 0 | Y11: 0 | Z11: 0 | AA11: 0 | AB11: =Y11+AA11+Z11 -> 0 | AC11: 0 | AD11: 0 | AE11: 0 | AF11: 0 | AG11: 0 | AH11: 0 | AI11: 0 | AJ11: 0 | AK11: 0 | AL11: =(BN11*P11/AX11)+AB11/O11*(BN11/AX11) -> 0 | AM11: =Q11+AB11+AL11+AK11+AJ11+T11+AE11 -> 191001.8 | AN11: 46116 | AO11: 36/IAD/27IN00002 | AP11: 832139000055796981 | AQ11: RETECK ENVIROTECH PRIVATE LIMITED | AR11: 27AAHCR2638B1ZK | AS11: Hyderabad Telangana 500081 | AT11: Vadgaon | AU11: Maharashtra | AW11: 44 | AX11: 4672.905 | AY11: =AW11*AX11 -> 205607.82 | AZ11: =AW11=O11 -> TRUE | BA11: 0 | BB11: =AW11-BA11 -> 44 | BC11: 0 | BD11: Regular | BE11: 0 | BF11: 0 | BG11: 0 | BH11: 0 | BI11: 0 | BJ11: 0 | BK11: 0 | BL11: 0 | BM11: 0 | BN11: =AY11*$BM$3 -> 0 | BO11: =AY11+BL11+BM11+BN11+BC11+BG11 -> 205607.82 | BP11: =BO11-AM11 -> 14606.02 | BQ11: =IF(BP11>=0,"Positive Margin","Negative Margin") -> Positive Margin | BR11: No Provision | BS11: =AY11-Y11-Q11-AA11-T11+BC11 -> 14606.02 | BT11: =IF(BS11<0, "Negative Margin at Inception", "Positive Margin at Inception") -> Positive Margin at Inception | BU11: =IFERROR(BP11/BO11,"0") -> 0.071038251 | BV11: =IF(BU11<1%,"Less Than 1%",IF(BU11>2%,"More than 2%",IF(BU11>=1%,"1% - 2%"))) -> More than 2% | BW11: =BM11+BN11 -> 0 | BX11: =AL11+AK11 -> 0 | BY11: =BW11-BX11 -> 0 | BZ11: =BM11 -> 0 | CA11: =AK11 -> 0 | CB11: =BZ11-CA11 -> 0 | CC11: Marketplace (IT Assets Disposition) | CD11: 0 | CE11: =AM11-AL11-AA11 -> 191001.8 | CF11: =BO11-BN11 -> 205607.82 | CG11: =INT((D11- IF(MONTH(D11) >= 4, DATE(YEAR(D11), 4, 1), DATE(YEAR(D11)-1, 4, 1))) / 7) + 1 -> 1 | CH11: 0 | CI11: 0 | CJ11: =_xlfn.XLOOKUP(AP11,POC!B:B,POC!D:D) -> #N/A | CK11: =AY11-Q11 -> 14606.02 | CL11: =CK11-Y11+Z11 -> 14606.02 | CM11: =BO11-AM11 -> 14606.02 | CN11: =AY11*118% -> 242617.23 | CO11: =-Q11*118% -> -225382.12 | CP11: =-BZ11*118% -> 0 | CQ11: =-CA11*118% -> 0 | CR11: =SUM(CN11:CQ11) -> 17235.104 | CS11: Telangana - HO | CT11: Telangana - HO | CU11: =MID(G11,3,10) -> AAACI4487J | CV11: =MID(AR11,3,10) -> AAHCR2638B | CW11: =H11&F11 -> 9102515564CYIENT LIMITED
B12: ="Q" & IF(ROUNDUP(MONTH(D12)/3,0)-1=0,4,ROUNDUP(MONTH(D12)/3,0)-1) -> Q1 | C12: =TEXT(AN12,"mmm-yy") -> Apr-26 | D12: 46115 | E12: SH04260307 | F12: CYIENT LIMITED | G12: 36AAACI4487J1Z9 | H12: 9102515564 | I12: 46105 | J12: 25-26/PUR/027036 | K12: 46115 | L12: TS | N12: UPS Battery Scrap | O12: 40 | P12: 464.95 | Q12: =O12*P12 -> 18598 | R12: 0 | S12: =O12-R12 -> 40 | T12: 0 | U12: 0 | V12: 0 | W12: 0 | X12: 0 | Y12: 0 | Z12: 0 | AA12: 0 | AB12: =Y12+AA12+Z12 -> 0 | AC12: 0 | AD12: 0 | AE12: 0 | AF12: 0 | AG12: 0 | AH12: 0 | AI12: 0 | AJ12: 0 | AK12: 0 | AL12: =(BN12*P12/AX12)+AB12/O12*(BN12/AX12) -> 0 | AM12: =Q12+AB12+AL12+AK12+AJ12+T12+AE12 -> 18598 | AN12: 46116 | AO12: 36/IAD/27IN00002 | AP12: 832139000055796981 | AQ12: RETECK ENVIROTECH PRIVATE LIMITED | AR12: 27AAHCR2638B1ZK | AS12: Hyderabad Telangana 500081 | AT12: Vadgaon | AU12: Maharashtra | AW12: 40 | AX12: 500.505 | AY12: =AW12*AX12 -> 20020.2 | AZ12: =AW12=O12 -> TRUE | BA12: 0 | BB12: =AW12-BA12 -> 40 | BC12: 0 | BD12: Regular | BE12: 0 | BF12: 0 | BG12: 0 | BH12: 0 | BI12: 0 | BJ12: 0 | BK12: 0 | BL12: 0 | BM12: 0 | BN12: =AY12*$BM$3 -> 0 | BO12: =AY12+BL12+BM12+BN12+BC12+BG12 -> 20020.2 | BP12: =BO12-AM12 -> 1422.2 | BQ12: =IF(BP12>=0,"Positive Margin","Negative Margin") -> Positive Margin | BR12: No Provision | BS12: =AY12-Y12-Q12-AA12-T12+BC12 -> 1422.2 | BT12: =IF(BS12<0, "Negative Margin at Inception", "Positive Margin at Inception") -> Positive Margin at Inception | BU12: =IFERROR(BP12/BO12,"0") -> 0.071038251 | BV12: =IF(BU12<1%,"Less Than 1%",IF(BU12>2%,"More than 2%",IF(BU12>=1%,"1% - 2%"))) -> More than 2% | BW12: =BM12+BN12 -> 0 | BX12: =AL12+AK12 -> 0 | BY12: =BW12-BX12 -> 0 | BZ12: =BM12 -> 0 | CA12: =AK12 -> 0 | CB12: =BZ12-CA12 -> 0 | CC12: Marketplace (IT Assets Disposition) | CD12: 0 | CE12: =AM12-AL12-AA12 -> 18598 | CF12: =BO12-BN12 -> 20020.2 | CG12: =INT((D12- IF(MONTH(D12) >= 4, DATE(YEAR(D12), 4, 1), DATE(YEAR(D12)-1, 4, 1))) / 7) + 1 -> 1 | CH12: 0 | CI12: 0 | CJ12: =_xlfn.XLOOKUP(AP12,POC!B:B,POC!D:D) -> #N/A | CK12: =AY12-Q12 -> 1422.2 | CL12: =CK12-Y12+Z12 -> 1422.2 | CM12: =BO12-AM12 -> 1422.2 | CN12: =AY12*118% -> 23623.836 | CO12: =-Q12*118% -> -21945.64 | CP12: =-BZ12*118% -> 0 | CQ12: =-CA12*118% -> 0 | CR12: =SUM(CN12:CQ12) -> 1678.196 | CS12: Telangana - HO | CT12: Telangana - HO | CU12: =MID(G12,3,10) -> AAACI4487J | CV12: =MID(AR12,3,10) -> AAHCR2638B | CW12: =H12&F12 -> 9102515564CYIENT LIMITED
B13: ="Q" & IF(ROUNDUP(MONTH(D13)/3,0)-1=0,4,ROUNDUP(MONTH(D13)/3,0)-1) -> Q1 | C13: =TEXT(AN13,"mmm-yy") -> Apr-26 | D13: 46115 | E13: SH04260307 | F13: CYIENT LIMITED | G13: 36AAACI4487J1Z9 | H13: 9102515564 | I13: 46105 | J13: 25-26/PUR/027036 | K13: 46115 | L13: TS | N13: UPS Battery Scrap | O13: 15 | P13: 763.73 | Q13: =O13*P13 -> 11455.95 | R13: 0 | S13: =O13-R13 -> 15 | T13: 0 | U13: 0 | V13: 0 | W13: 0 | X13: 0 | Y13: 0 | Z13: 0 | AA13: 0 | AB13: =Y13+AA13+Z13 -> 0 | AC13: 0 | AD13: 0 | AE13: 0 | AF13: 0 | AG13: 0 | AH13: 0 | AI13: 0 | AJ13: 0 | AK13: 0 | AL13: =(BN13*P13/AX13)+AB13/O13*(BN13/AX13) -> 0 | AM13: =Q13+AB13+AL13+AK13+AJ13+T13+AE13 -> 11455.95 | AN13: 46116 | AO13: 36/IAD/27IN00002 | AP13: 832139000055796981 | AQ13: RETECK ENVIROTECH PRIVATE LIMITED | AR13: 27AAHCR2638B1ZK | AS13: Hyderabad Telangana 500081 | AT13: Vadgaon | AU13: Maharashtra | AW13: 15 | AX13: 822.128 | AY13: =AW13*AX13 -> 12331.92 | AZ13: =AW13=O13 -> TRUE | BA13: 0 | BB13: =AW13-BA13 -> 15 | BC13: 0 | BD13: Regular | BE13: 0 | BF13: 0 | BG13: 0 | BH13: 0 | BI13: 0 | BJ13: 0 | BK13: 0 | BL13: 0 | BM13: 0 | BN13: =AY13*$BM$3 -> 0 | BO13: =AY13+BL13+BM13+BN13+BC13+BG13 -> 12331.92 | BP13: =BO13-AM13 -> 875.97 | BQ13: =IF(BP13>=0,"Positive Margin","Negative Margin") -> Positive Margin | BR13: No Provision | BS13: =AY13-Y13-Q13-AA13-T13+BC13 -> 875.97 | BT13: =IF(BS13<0, "Negative Margin at Inception", "Positive Margin at Inception") -> Positive Margin at Inception | BU13: =IFERROR(BP13/BO13,"0") -> 0.071032735 | BV13: =IF(BU13<1%,"Less Than 1%",IF(BU13>2%,"More than 2%",IF(BU13>=1%,"1% - 2%"))) -> More than 2% | BW13: =BM13+BN13 -> 0 | BX13: =AL13+AK13 -> 0 | BY13: =BW13-BX13 -> 0 | BZ13: =BM13 -> 0 | CA13: =AK13 -> 0 | CB13: =BZ13-CA13 -> 0 | CC13: Marketplace (IT Assets Disposition) | CD13: 0 | CE13: =AM13-AL13-AA13 -> 11455.95 | CF13: =BO13-BN13 -> 12331.92 | CG13: =INT((D13- IF(MONTH(D13) >= 4, DATE(YEAR(D13), 4, 1), DATE(YEAR(D13)-1, 4, 1))) / 7) + 1 -> 1 | CH13: 0 | CI13: 0 | CJ13: =_xlfn.XLOOKUP(AP13,POC!B:B,POC!D:D) -> #N/A | CK13: =AY13-Q13 -> 875.97 | CL13: =CK13-Y13+Z13 -> 875.97 | CM13: =BO13-AM13 -> 875.97 | CN13: =AY13*118% -> 14551.666 | CO13: =-Q13*118% -> -13518.021 | CP13: =-BZ13*118% -> 0 | CQ13: =-CA13*118% -> 0 | CR13: =SUM(CN13:CQ13) -> 1033.6446 | CS13: Telangana - HO | CT13: Telangana - HO | CU13: =MID(G13,3,10) -> AAACI4487J | CV13: =MID(AR13,3,10) -> AAHCR2638B | CW13: =H13&F13 -> 9102515564CYIENT LIMITED
B14: ="Q" & IF(ROUNDUP(MONTH(D14)/3,0)-1=0,4,ROUNDUP(MONTH(D14)/3,0)-1) -> Q1 | C14: =TEXT(AN14,"mmm-yy") -> Apr-26 | D14: 46115 | E14: SH04260307 | F14: CYIENT LIMITED | G14: 36AAACI4487J1Z9 | H14: 9102515564 | I14: 46105 | J14: 25-26/PUR/027036 | K14: 46115 | L14: TS | N14: UPS Battery Scrap | O14: 6 | P14: 461.55 | Q14: =O14*P14 -> 2769.3 | R14: 0 | S14: =O14-R14 -> 6 | T14: 0 | U14: 0 | V14: 0 | W14: 0 | X14: 0 | Y14: 0 | Z14: 0 | AA14: 0 | AB14: =Y14+AA14+Z14 -> 0 | AC14: 0 | AD14: 0 | AE14: 0 | AF14: 0 | AG14: 0 | AH14: 0 | AI14: 0 | AJ14: 0 | AK14: 0 | AL14: =(BN14*P14/AX14)+AB14/O14*(BN14/AX14) -> 0 | AM14: =Q14+AB14+AL14+AK14+AJ14+T14+AE14 -> 2769.3 | AN14: 46116 | AO14: 36/IAD/27IN00002 | AP14: 832139000055796981 | AQ14: RETECK ENVIROTECH PRIVATE LIMITED | AR14: 27AAHCR2638B1ZK | AS14: Hyderabad Telangana 500081 | AT14: Vadgaon | AU14: Maharashtra | AW14: 6 | AX14: 486.78 | AY14: =AW14*AX14 -> 2920.68 | AZ14: =AW14=O14 -> TRUE | BA14: 0 | BB14: =AW14-BA14 -> 6 | BC14: 0 | BD14: Regular | BE14: 0 | BF14: 0 | BG14: 0 | BH14: 0 | BI14: 0 | BJ14: 0 | BK14: 0 | BL14: 0 | BM14: 0 | BN14: =AY14*$BM$3 -> 0 | BO14: =AY14+BL14+BM14+BN14+BC14+BG14 -> 2920.68 | BP14: =BO14-AM14 -> 151.38 | BQ14: =IF(BP14>=0,"Positive Margin","Negative Margin") -> Positive Margin | BR14: No Provision | BS14: =AY14-Y14-Q14-AA14-T14+BC14 -> 151.38 | BT14: =IF(BS14<0, "Negative Margin at Inception", "Positive Margin at Inception") -> Positive Margin at Inception | BU14: =IFERROR(BP14/BO14,"0") -> 0.051830396 | BV14: =IF(BU14<1%,"Less Than 1%",IF(BU14>2%,"More than 2%",IF(BU14>=1%,"1% - 2%"))) -> More than 2% | BW14: =BM14+BN14 -> 0 | BX14: =AL14+AK14 -> 0 | BY14: =BW14-BX14 -> 0 | BZ14: =BM14 -> 0 | CA14: =AK14 -> 0 | CB14: =BZ14-CA14 -> 0 | CC14: Marketplace (IT Assets Disposition) | CD14: 0 | CE14: =AM14-AL14-AA14 -> 2769.3 | CF14: =BO14-BN14 -> 2920.68 | CG14: =INT((D14- IF(MONTH(D14) >= 4, DATE(YEAR(D14), 4, 1), DATE(YEAR(D14)-1, 4, 1))) / 7) + 1 -> 1 | CH14: 0 | CI14: 0 | CJ14: =_xlfn.XLOOKUP(AP14,POC!B:B,POC!D:D) -> #N/A | CK14: =AY14-Q14 -> 151.38 | CL14: =CK14-Y14+Z14 -> 151.38 | CM14: =BO14-AM14 -> 151.38 | CN14: =AY14*118% -> 3446.4024 | CO14: =-Q14*118% -> -3267.774 | CP14: =-BZ14*118% -> 0 | CQ14: =-CA14*118% -> 0 | CR14: =SUM(CN14:CQ14) -> 178.6284 | CS14: Telangana - HO | CT14: Telangana - HO | CU14: =MID(G14,3,10) -> AAACI4487J | CV14: =MID(AR14,3,10) -> AAHCR2638B | CW14: =H14&F14 -> 9102515564CYIENT LIMITED
B15: ="Q" & IF(ROUNDUP(MONTH(D15)/3,0)-1=0,4,ROUNDUP(MONTH(D15)/3,0)-1) -> Q1 | C15: =TEXT(AN15,"mmm-yy") -> Apr-26 | D15: 46115 | E15: SH04260307 | F15: CYIENT LIMITED | G15: 36AAACI4487J1Z9 | H15: 9102515564 | I15: 46105 | J15: 25-26/PUR/027036 | K15: 46115 | L15: TS | N15: UPS Battery Scrap | O15: 8 | P15: 314.93 | Q15: =O15*P15 -> 2519.44 | R15: 0 | S15: =O15-R15 -> 8 | T15: 0 | U15: 0 | V15: 0 | W15: 0 | X15: 0 | Y15: 0 | Z15: 0 | AA15: 0 | AB15: =Y15+AA15+Z15 -> 0 | AC15: 0 | AD15: 0 | AE15: 0 | AF15: 0 | AG15: 0 | AH15: 0 | AI15: 0 | AJ15: 0 | AK15: 0 | AL15: =(BN15*P15/AX15)+AB15/O15*(BN15/AX15) -> 0 | AM15: =Q15+AB15+AL15+AK15+AJ15+T15+AE15 -> 2519.44 | AN15: 46116 | AO15: 36/IAD/27IN00002 | AP15: 832139000055796981 | AQ15: RETECK ENVIROTECH PRIVATE LIMITED | AR15: 27AAHCR2638B1ZK | AS15: Hyderabad Telangana 500081 | AT15: Vadgaon | AU15: Maharashtra | AW15: 8 | AX15: 339.008 | AY15: =AW15*AX15 -> 2712.064 | AZ15: =AW15=O15 -> TRUE | BA15: 0 | BB15: =AW15-BA15 -> 8 | BC15: 0 | BD15: Regular | BE15: 0 | BF15: 0 | BG15: 0 | BH15: 0 | BI15: 0 | BJ15: 0 | BK15: 0 | BL15: 0 | BM15: 0 | BN15: =AY15*$BM$3 -> 0 | BO15: =AY15+BL15+BM15+BN15+BC15+BG15 -> 2712.064 | BP15: =BO15-AM15 -> 192.624 | BQ15: =IF(BP15>=0,"Positive Margin","Negative Margin") -> Positive Margin | BR15: No Provision | BS15: =AY15-Y15-Q15-AA15-T15+BC15 -> 192.624 | BT15: =IF(BS15<0, "Negative Margin at Inception", "Positive Margin at Inception") -> Positive Margin at Inception | BU15: =IFERROR(BP15/BO15,"0") -> 0.071024873 | BV15: =IF(BU15<1%,"Less Than 1%",IF(BU15>2%,"More than 2%",IF(BU15>=1%,"1% - 2%"))) -> More than 2% | BW15: =BM15+BN15 -> 0 | BX15: =AL15+AK15 -> 0 | BY15: =BW15-BX15 -> 0 | BZ15: =BM15 -> 0 | CA15: =AK15 -> 0 | CB15: =BZ15-CA15 -> 0 | CC15: Marketplace (IT Assets Disposition) | CD15: 0 | CE15: =AM15-AL15-AA15 -> 2519.44 | CF15: =BO15-BN15 -> 2712.064 | CG15: =INT((D15- IF(MONTH(D15) >= 4, DATE(YEAR(D15), 4, 1), DATE(YEAR(D15)-1, 4, 1))) / 7) + 1 -> 1 | CH15: 0 | CI15: 0 | CJ15: =_xlfn.XLOOKUP(AP15,POC!B:B,POC!D:D) -> #N/A | CK15: =AY15-Q15 -> 192.624 | CL15: =CK15-Y15+Z15 -> 192.624 | CM15: =BO15-AM15 -> 192.624 | CN15: =AY15*118% -> 3200.2355 | CO15: =-Q15*118% -> -2972.9392 | CP15: =-BZ15*118% -> 0 | CQ15: =-CA15*118% -> 0 | CR15: =SUM(CN15:CQ15) -> 227.29632 | CS15: Telangana - HO | CT15: Telangana - HO | CU15: =MID(G15,3,10) -> AAACI4487J | CV15: =MID(AR15,3,10) -> AAHCR2638B | CW15: =H15&F15 -> 9102515564CYIENT LIMITED
B16: ="Q" & IF(ROUNDUP(MONTH(D16)/3,0)-1=0,4,ROUNDUP(MONTH(D16)/3,0)-1) -> Q1 | C16: =TEXT(AN16,"mmm-yy") -> Apr-26 | D16: 46115 | E16: SH04260602 | F16: M/S YAKSHIT TRADING | G16: 21BGNPG9019D1ZO | H16: 01 | I16: 46115 | J16: 26-27/PUR/000104 | K16: 46120 | L16: OD | M16: OD02BK4485 | N16: ITAD Mixed E Waste | O16: 700 | P16: 141.4 | Q16: =O16*P16 -> 98980 | R16: 0 | S16: =O16-R16 -> 700 | T16: 0 | U16: 0 | V16: 0 | W16: 0 | X16: 0 | Y16: 0 | Z16: 0 | AA16: 0 | AB16: =Y16+AA16+Z16 -> 0 | AC16: 0 | AD16: 0 | AE16: 0 | AF16: 0 | AG16: 0 | AH16: 0 | AI16: 0 | AJ16: 0 | AK16: 0 | AL16: =(BN16*P16/AX16)+AB16/O16*(BN16/AX16) -> 0 | AM16: =Q16+AB16+AL16+AK16+AJ16+T16+AE16 -> 98980 | AN16: 46120 | AO16: 36/IAD/27IN00003 | AP16: 832139000069594197 | AQ16: FALAH ENTERPRISES | AR16: 29DAKPA5526G1ZP | AS16: Khurda,Odisha,752050 | AT16: Bengaluru | AU16: Karnataka | AV16: 182394915927 | AW16: 700 | AX16: 208.232 | AY16: =AW16*AX16 -> 145762.4 | AZ16: =AW16=O16 -> TRUE | BA16: 0 | BB16: =AW16-BA16 -> 700 | BC16: 0 | BD16: Regular | BE16: 0 | BF16: 0 | BG16: 0 | BH16: 0 | BI16: 0 | BJ16: 0 | BK16: 0 | BL16: 0 | BM16: 0 | BN16: =AY16*$BM$3 -> 0 | BO16: =AY16+BL16+BM16+BN16+BC16+BG16 -> 145762.4 | BP16: =BO16-AM16 -> 46782.4 | BQ16: =IF(BP16>=0,"Positive Margin","Negative Margin") -> Positive Margin | BR16: No Provision | BS16: =AY16-Y16-Q16-AA16-T16+BC16 -> 46782.4 | BT16: =IF(BS16<0, "Negative Margin at Inception", "Positive Margin at Inception") -> Positive Margin at Inception | BU16: =IFERROR(BP16/BO16,"0") -> 0.32094971 | BV16: =IF(BU16<1%,"Less Than 1%",IF(BU16>2%,"More than 2%",IF(BU16>=1%,"1% - 2%"))) -> More than 2% | BW16: =BM16+BN16 -> 0 | BX16: =AL16+AK16 -> 0 | BY16: =BW16-BX16 -> 0 | BZ16: =BM16 -> 0 | CA16: =AK16 -> 0 | CB16: =BZ16-CA16 -> 0 | CC16: Marketplace (IT Assets Disposition) | CD16: 0 | CE16: =AM16-AL16-AA16 -> 98980 | CF16: =BO16-BN16 -> 145762.4 | CG16: =INT((D16- IF(MONTH(D16) >= 4, DATE(YEAR(D16), 4, 1), DATE(YEAR(D16)-1, 4, 1))) / 7) + 1 -> 1 | CH16: 0 | CI16: 0 | CJ16: =_xlfn.XLOOKUP(AP16,POC!B:B,POC!D:D) -> #N/A | CK16: =AY16-Q16 -> 46782.4 | CL16: =CK16-Y16+Z16 -> 46782.4 | CM16: =BO16-AM16 -> 46782.4 | CN16: =AY16*118% -> 171999.63 | CO16: =-Q16*118% -> -116796.4 | CP16: =-BZ16*118% -> 0 | CQ16: =-CA16*118% -> 0 | CR16: =SUM(CN16:CQ16) -> 55203.232 | CS16: Telangana - HO | CT16: Telangana - HO | CU16: =MID(G16,3,10) -> BGNPG9019D | CV16: =MID(AR16,3,10) -> DAKPA5526G | CW16: =H16&F16 -> 01M/S YAKSHIT TRADING
B17: ="Q" & IF(ROUNDUP(MONTH(D17)/3,0)-1=0,4,ROUNDUP(MONTH(D17)/3,0)-1) -> Q1 | C17: =TEXT(AN17,"mmm-yy") -> Apr-26 | D17: 46121 | E17: SH04261306 | F17: HYDERABAD EYE INSTITUTE | G17: 21AAATH0878B1Z8 | H17: 203000016 | I17: 46121 | J17: 26-27/PUR/000668 | K17: 46128 | L17: OD | M17: OD02CK1433 | N17: ITAD Mixed E Waste(Kg) | O17: 730 | P17: 33.9 | Q17: =O17*P17 -> 24747 | R17: 0 | S17: =O17-R17 -> 730 | T17: 0 | U17: 0 | V17: 0 | W17: 0 | X17: 0 | Y17: 0 | Z17: 0 | AA17: 0 | AB17: =Y17+AA17+Z17 -> 0 | AC17: 0 | AD17: 0 | AE17: 0 | AF17: 0 | AG17: 0 | AH17: 0 | AI17: 0 | AJ17: 0 | AK17: 0 | AL17: =(BN17*P17/AX17)+AB17/O17*(BN17/AX17) -> 0 | AM17: =Q17+AB17+AL17+AK17+AJ17+T17+AE17 -> 24747 | AN17: 46128 | AO17: 36/IAD/27IN00005 | AP17: 832139000069594197 | AQ17: FALAH ENTERPRISES | AR17: 29DAKPA5526G1ZP | AS17: Khordha Odisha 751024 | AT17: Bengaluru | AU17: Karnataka | AW17: 730 | AX17: 54.005 | AY17: =AW17*AX17 -> 39423.65 | AZ17: =AW17=O17 -> TRUE | BA17: 0 | BB17: =AW17-BA17 -> 730 | BC17: 0 | BD17: Regular | BE17: 0 | BF17: 0 | BG17: 0 | BH17: 0 | BI17: 0 | BJ17: 0 | BK17: 0 | BL17: 0 | BM17: 0 | BN17: =AY17*$BM$3 -> 0 | BO17: =AY17+BL17+BM17+BN17+BC17+BG17 -> 39423.65 | BP17: =BO17-AM17 -> 14676.65 | BQ17: =IF(BP17>=0,"Positive Margin","Negative Margin") -> Positive Margin | BR17: No Provision | BS17: =AY17-Y17-Q17-AA17-T17+BC17 -> 14676.65 | BT17: =IF(BS17<0, "Negative Margin at Inception", "Positive Margin at Inception") -> Positive Margin at Inception | BU17: =IFERROR(BP17/BO17,"0") -> 0.37228034 | BV17: =IF(BU17<1%,"Less Than 1%",IF(BU17>2%,"More than 2%",IF(BU17>=1%,"1% - 2%"))) -> More than 2% | BW17: =BM17+BN17 -> 0 | BX17: =AL17+AK17 -> 0 | BY17: =BW17-BX17 -> 0 | BZ17: =BM17 -> 0 | CA17: =AK17 -> 0 | CB17: =BZ17-CA17 -> 0 | CC17: Marketplace (IT Assets Disposition) | CD17: 0 | CE17: =AM17-AL17-AA17 -> 24747 | CF17: =BO17-BN17 -> 39423.65 | CG17: =INT((D17- IF(MONTH(D17) >= 4, DATE(YEAR(D17), 4, 1), DATE(YEAR(D17)-1, 4, 1))) / 7) + 1 -> 2 | CH17: 0 | CI17: 0 | CJ17: =_xlfn.XLOOKUP(AP17,POC!B:B,POC!D:D) -> #N/A | CK17: =AY17-Q17 -> 14676.65 | CL17: =CK17-Y17+Z17 -> 14676.65 | CM17: =BO17-AM17 -> 14676.65 | CN17: =AY17*118% -> 46519.907 | CO17: =-Q17*118% -> -29201.46 | CP17: =-BZ17*118% -> 0 | CQ17: =-CA17*118% -> 0 | CR17: =SUM(CN17:CQ17) -> 17318.447 | CS17: Telangana - HO | CT17: Telangana - HO | CU17: =MID(G17,3,10) -> AAATH0878B | CV17: =MID(AR17,3,10) -> DAKPA5526G | CW17: =H17&F17 -> 203000016HYDERABAD EYE INSTITUTE
B18: ="Q" & IF(ROUNDUP(MONTH(D18)/3,0)-1=0,4,ROUNDUP(MONTH(D18)/3,0)-1) -> Q1 | C18: =TEXT(AN18,"mmm-yy") -> Apr-26 | D18: 46126 | E18: SH042614012 | F18: CHAITANYA INDIA FIN CREDIT PRIVATE LIMITED | G18: 29AADCC6184H1ZE | H18: 2026290000000086 | I18: 46094 | J18: 26-27/PUR/000516 | K18: 46126 | L18: KA | N18: ITAD Mixed E Waste | O18: 37 | P18: 847 | Q18: =O18*P18 -> 31339 | R18: 0 | S18: =O18-R18 -> 37 | T18: 0 | U18: 0 | V18: 0 | W18: 0 | X18: 0 | Y18: 0 | Z18: 0 | AA18: 0 | AB18: =Y18+AA18+Z18 -> 0 | AC18: 0 | AD18: 0 | AE18: 0 | AF18: 0 | AG18: 0 | AH18: 0 | AI18: 0 | AJ18: 0 | AK18: 0 | AL18: =(BN18*P18/AX18)+AB18/O18*(BN18/AX18) -> 0 | AM18: =Q18+AB18+AL18+AK18+AJ18+T18+AE18 -> 31339 | AN18: 46126 | AO18: 29/IAD/27IN00003 | AP18: 832139000046796207 | AQ18: TRADEWIND BUSINESS SOLUTIONS LLP | AR18: 07AARFT3586D1ZR | AS18: Bengaluru,Karnataka,560070 | AT18: New Delhi | AU18: Delhi | AW18: 37 | AX18: 932.2 | AY18: =AW18*AX18 -> 34491.4 | AZ18: =AW18=O18 -> TRUE | BA18: 0 | BB18: =AW18-BA18 -> 37 | BC18: 0 | BD18: Regular | BE18: 0 | BF18: 0 | BG18: 0 | BH18: 0 | BI18: 0 | BJ18: 0 | BK18: 0 | BL18: 0 | BM18: 0 | BN18: =AY18*$BM$3 -> 0 | BO18: =AY18+BL18+BM18+BN18+BC18+BG18 -> 34491.4 | BP18: =BO18-AM18 -> 3152.4 | BQ18: =IF(BP18>=0,"Positive Margin","Negative Margin") -> Positive Margin | BR18: No Provision | BS18: =AY18-Y18-Q18-AA18-T18+BC18 -> 3152.4 | BT18: =IF(BS18<0, "Negative Margin at Inception", "Positive Margin at Inception") -> Positive Margin at Inception | BU18: =IFERROR(BP18/BO18,"0") -> 0.091396696 | BV18: =IF(BU18<1%,"Less Than 1%",IF(BU18>2%,"More than 2%",IF(BU18>=1%,"1% - 2%"))) -> More than 2% | BW18: =BM18+BN18 -> 0 | BX18: =AL18+AK18 -> 0 | BY18: =BW18-BX18 -> 0 | BZ18: =BM18 -> 0 | CA18: =AK18 -> 0 | CB18: =BZ18-CA18 -> 0 | CC18: Marketplace (IT Assets Disposition) | CD18: 0 | CE18: =AM18-AL18-AA18 -> 31339 | CF18: =BO18-BN18 -> 34491.4 | CG18: =INT((D18- IF(MONTH(D18) >= 4, DATE(YEAR(D18), 4, 1), DATE(YEAR(D18)-1, 4, 1))) / 7) + 1 -> 2 | CH18: 0 | CI18: 0 | CJ18: =_xlfn.XLOOKUP(AP18,POC!B:B,POC!D:D) -> #N/A | CK18: =AY18-Q18 -> 3152.4 | CL18: =CK18-Y18+Z18 -> 3152.4 | CM18: =BO18-AM18 -> 3152.4 | CN18: =AY18*118% -> 40699.852 | CO18: =-Q18*118% -> -36980.02 | CP18: =-BZ18*118% -> 0 | CQ18: =-CA18*118% -> 0 | CR18: =SUM(CN18:CQ18) -> 3719.832 | CS18: Telangana - HO | CT18: Telangana - HO | CU18: =MID(G18,3,10) -> AADCC6184H | CV18: =MID(AR18,3,10) -> AARFT3586D | CW18: =H18&F18 -> 2026290000000086CHAITANYA INDIA FIN CREDIT PRIVATE LIMITED
B19: ="Q" & IF(ROUNDUP(MONTH(D19)/3,0)-1=0,4,ROUNDUP(MONTH(D19)/3,0)-1) -> Q1 | C19: =TEXT(AN19,"mmm-yy") -> Apr-26 | D19: 46126 | E19: SH042614012 | F19: CHAITANYA INDIA FIN CREDIT PRIVATE LIMITED | G19: 29AADCC6184H1ZE | H19: 2026290000000086 | I19: 46094 | J19: 26-27/PUR/000516 | K19: 46126 | L19: KA | N19: ITAD Mixed E Waste | O19: 101 | P19: 1576 | Q19: =O19*P19 -> 159176 | R19: 0 | S19: =O19-R19 -> 101 | T19: 0 | U19: 0 | V19: 0 | W19: 0 | X19: 0 | Y19: 0 | Z19: 0 | AA19: 0 | AB19: =Y19+AA19+Z19 -> 0 | AC19: 0 | AD19: 0 | AE19: 0 | AF19: 0 | AG19: 0 | AH19: 0 | AI19: 0 | AJ19: 0 | AK19: 0 | AL19: =(BN19*P19/AX19)+AB19/O19*(BN19/AX19) -> 0 | AM19: =Q19+AB19+AL19+AK19+AJ19+T19+AE19 -> 159176 | AN19: 46126 | AO19: 29/IAD/27IN00003 | AP19: 832139000046796207 | AQ19: TRADEWIND BUSINESS SOLUTIONS LLP | AR19: 07AARFT3586D1ZR | AS19: Bengaluru,Karnataka,560070 | AT19: New Delhi | AU19: Delhi | AW19: 101 | AX19: 1733.9 | AY19: =AW19*AX19 -> 175123.9 | AZ19: =AW19=O19 -> TRUE | BA19: 0 | BB19: =AW19-BA19 -> 101 | BC19: 0 | BD19: Regular | BE19: 0 | BF19: 0 | BG19: 0 | BH19: 0 | BI19: 0 | BJ19: 0 | BK19: 0 | BL19: 0 | BM19: 0 | BN19: =AY19*$BM$3 -> 0 | BO19: =AY19+BL19+BM19+BN19+BC19+BG19 -> 175123.9 | BP19: =BO19-AM19 -> 15947.9 | BQ19: =IF(BP19>=0,"Positive Margin","Negative Margin") -> Positive Margin | BR19: No Provision | BS19: =AY19-Y19-Q19-AA19-T19+BC19 -> 15947.9 | BT19: =IF(BS19<0, "Negative Margin at Inception", "Positive Margin at Inception") -> Positive Margin at Inception | BU19: =IFERROR(BP19/BO19,"0") -> 0.091066382 | BV19: =IF(BU19<1%,"Less Than 1%",IF(BU19>2%,"More than 2%",IF(BU19>=1%,"1% - 2%"))) -> More than 2% | BW19: =BM19+BN19 -> 0 | BX19: =AL19+AK19 -> 0 | BY19: =BW19-BX19 -> 0 | BZ19: =BM19 -> 0 | CA19: =AK19 -> 0 | CB19: =BZ19-CA19 -> 0 | CC19: Marketplace (IT Assets Disposition) | CD19: 0 | CE19: =AM19-AL19-AA19 -> 159176 | CF19: =BO19-BN19 -> 175123.9 | CG19: =INT((D19- IF(MONTH(D19) >= 4, DATE(YEAR(D19), 4, 1), DATE(YEAR(D19)-1, 4, 1))) / 7) + 1 -> 2 | CH19: 0 | CI19: 0 | CJ19: =_xlfn.XLOOKUP(AP19,POC!B:B,POC!D:D) -> #N/A | CK19: =AY19-Q19 -> 15947.9 | CL19: =CK19-Y19+Z19 -> 15947.9 | CM19: =BO19-AM19 -> 15947.9 | CN19: =AY19*118% -> 206646.2 | CO19: =-Q19*118% -> -187827.68 | CP19: =-BZ19*118% -> 0 | CQ19: =-CA19*118% -> 0 | CR19: =SUM(CN19:CQ19) -> 18818.522 | CS19: Telangana - HO | CT19: Telangana - HO | CU19: =MID(G19,3,10) -> AADCC6184H | CV19: =MID(AR19,3,10) -> AARFT3586D | CW19: =H19&F19 -> 2026290000000086CHAITANYA INDIA FIN CREDIT PRIVATE LIMITED
