Workbook

Sheet Summary
U2: ="As on"& " "&TEXT(Details!P64,"dd-mmm-yyyy") -> As on 21-Jun-2026 | V2: Non-Ferrous | AK2: Ferrous | AZ2: M3
D3: =TEXT(D5,"mmm-yy") -> Apr-26 | E3: =TEXT(E5,"mmm-yy") -> May-26 | F3: =TEXT(F5,"mmm-yy") -> Jun-26 | G3: =TEXT(G5,"mmm-yy") -> Jul-26 | H3: =TEXT(H5,"mmm-yy") -> Aug-26 | I3: =TEXT(I5,"mmm-yy") -> Sep-26 | J3: =TEXT(J5,"mmm-yy") -> Oct-26 | K3: =TEXT(K5,"mmm-yy") -> Nov-26 | ... O3: =TEXT(O5,"mmm-yy") -> Mar-27 | V3: Apr-25 | W3: =E3 -> May-26 | X3: =F3 -> Jun-26 | Y3: =G3 -> Jul-26 | Z3: =H3 -> Aug-26 | AA3: =I3 -> Sep-26 | AB3: =J3 -> Oct-26 | AC3: =K3 -> Nov-26 | AD3: =L3 -> Dec-26 | ... AG3: =O3 -> Mar-27 | AK3: =D3 -> Apr-26 | AL3: =E3 -> May-26 | AM3: =F3 -> Jun-26 | AN3: =G3 -> Jul-26 | AO3: =H3 -> Aug-26 | AP3: =I3 -> Sep-26 | AQ3: =J3 -> Oct-26 | AR3: =K3 -> Nov-26 | ... AV3: =O3 -> Mar-27 | AZ3: =TEXT(AZ5,"mmm-yy") -> Apr-26 | BA3: =TEXT(BA5,"mmm-yy") -> May-26 | BB3: =TEXT(BB5,"mmm-yy") -> Jun-26 | BC3: =TEXT(BC5,"mmm-yy") -> Jul-26 | BD3: =TEXT(BD5,"mmm-yy") -> Aug-26 | BE3: =TEXT(BE5,"mmm-yy") -> Sep-26 | BF3: =TEXT(BF5,"mmm-yy") -> Oct-26 | BG3: =TEXT(BG5,"mmm-yy") -> Nov-26 | ... BK3: =TEXT(BK5,"mmm-yy") -> Mar-27
D4: 30 | E4: 31 | F4: 21 | G4: 0 | H4: 0 | I4: 0 | J4: 0 | K4: 0 | L4: 0 | M4: 0 | N4: 0 | O4: 0 | P4: =SUM(D4:O4) -> 82 | V4: =D4 -> 30 | W4: =E4 -> 31 | X4: =F4 -> 21 | Y4: =G4 -> 0 | Z4: =H4 -> 0 | AA4: =I4 -> 0 | AB4: =J4 -> 0 | AC4: =K4 -> 0 | ... AH4: =P4 -> 82 | AK4: =D4 -> 30 | AL4: =E4 -> 31 | AM4: =F4 -> 21 | AN4: =G4 -> 0 | AO4: =H4 -> 0 | AP4: =I4 -> 0 | AQ4: =J4 -> 0 | AR4: =K4 -> 0 | ... AW4: =P4 -> 82 | AZ4: =D4 -> 30 | BA4: =E4 -> 31 | BB4: =F4 -> 21 | BC4: =G4 -> 0 | BD4: =H4 -> 0 | BE4: =I4 -> 0 | BF4: =J4 -> 0 | BG4: =K4 -> 0 | ... BL4: =P4 -> 82
C5: Marketplace (End Generator) | D5: 46113 | E5: 46143 | F5: 46174 | G5: 46204 | H5: 46235 | I5: 46266 | J5: 46296 | K5: 46327 | L5: 46357 | M5: 46388 | N5: 46419 | O5: 46447 | P5: FY 2026-27 | U5: Non-Ferrous | V5: =D5 -> 46113 | W5: =E5 -> 46143 | X5: =F5 -> 46174 | Y5: =G5 -> 46204 | Z5: =H5 -> 46235 | AA5: =I5 -> 46266 | AB5: =J5 -> 46296 | AC5: =K5 -> 46327 | ... AH5: =P5 -> FY 2026-27 | AJ5: Ferrous | AK5: =V5 -> 46113 | AL5: =W5 -> 46143 | AM5: =X5 -> 46174 | AN5: =Y5 -> 46204 | AO5: =Z5 -> 46235 | AP5: =AA5 -> 46266 | AQ5: =AB5 -> 46296 | AR5: =AC5 -> 46327 | ... AW5: =AH5 -> FY 2026-27 | AY5: M3 | AZ5: =AK5 -> 46113 | BA5: =AL5 -> 46143 | BB5: =AM5 -> 46174 | BC5: =AN5 -> 46204 | BD5: =AO5 -> 46235 | BE5: =AP5 -> 46266 | BF5: =AQ5 -> 46296 | BG5: =AR5 -> 46327 | ... BL5: =AW5 -> FY 2026-27 | BN5: Check
C6: Quantity (MT) | D6: 276.706 | E6: 129.15 | F6: =SUMIFS(Details!$BB$5:$BB$53,Details!$C$5:$C$53,Summary!F$5)/1000 -> 114.015 | G6: =SUMIFS(Details!$BB$5:$BB$53,Details!$C$5:$C$53,Summary!G$5)/1000 -> 0 | H6: =SUMIFS(Details!$BB$5:$BB$53,Details!$C$5:$C$53,Summary!H$5)/1000 -> 0 | I6: =SUMIFS(Details!$BB$5:$BB$53,Details!$C$5:$C$53,Summary!I$5)/1000 -> 0 | J6: =SUMIFS(Details!$BB$5:$BB$53,Details!$C$5:$C$53,Summary!J$5)/1000 -> 0 | K6: =SUMIFS(Details!$BB$5:$BB$53,Details!$C$5:$C$53,Summary!K$5)/1000 -> 0 | L6: =SUMIFS(Details!$BB$5:$BB$53,Details!$C$5:$C$53,Summary!L$5)/1000 -> 0 | M6: =SUMIFS(Details!$BB$5:$BB$53,Details!$C$5:$C$53,Summary!M$5)/1000 -> 0 | ... O6: =SUMIFS(Details!$BB$5:$BB$53,Details!$C$5:$C$53,Summary!O$5)/1000 -> 0 | P6: =SUM(D6:O6) -> 519.871 | Q6: =Details!BB54/1000 -> 519.761 | R6: =P6-Q6 -> 0.11 | T6: =-R6 -> -0.11 | U6: Quantity (MT) | V6: =SUMIFS(Details!$S$5:$S$53,Details!$C$5:$C$53,Summary!V$5,Details!$CK$5:$CK$53,Summary!$U$5)/1000 -> 26.99 | W6: =SUMIFS(Details!$S$5:$S$53,Details!$C$5:$C$53,Summary!W$5,Details!$CK$5:$CK$53,Summary!$U$5)/1000 -> 25.43 | X6: =SUMIFS(Details!$S$5:$S$53,Details!$C$5:$C$53,Summary!X$5,Details!$CK$5:$CK$53,Summary!$U$5)/1000 -> 14.385 | Y6: =SUMIFS(Details!$S$5:$S$53,Details!$C$5:$C$53,Summary!Y$5,Details!$CK$5:$CK$53,Summary!$U$5)/1000 -> 0 | Z6: =SUMIFS(Details!$S$5:$S$53,Details!$C$5:$C$53,Summary!Z$5,Details!$CK$5:$CK$53,Summary!$U$5)/1000 -> 0 | AA6: =SUMIFS(Details!$S$5:$S$53,Details!$C$5:$C$53,Summary!AA$5,Details!$CK$5:$CK$53,Summary!$U$5)/1000 -> 0 | AB6: =SUMIFS(Details!$S$5:$S$53,Details!$C$5:$C$53,Summary!AB$5,Details!$CK$5:$CK$53,Summary!$U$5)/1000 -> 0 | AC6: =SUMIFS(Details!$S$5:$S$53,Details!$C$5:$C$53,Summary!AC$5,Details!$CK$5:$CK$53,Summary!$U$5)/1000 -> 0 | ... AG6: =SUMIFS(Details!$S$5:$S$53,Details!$C$5:$C$53,Summary!AG$5,Details!$CK$5:$CK$53,Summary!$U$5)/1000 -> 0 | AH6: =SUM(V6:AG6) -> 66.805 | AJ6: Quantity (MT) | AK6: =SUMIFS(Details!$S$5:$S$53,Details!$C$5:$C$53,Summary!AK$5,Details!$CK$5:$CK$53,Summary!$AJ$5)/1000 -> 249.605 | AL6: =SUMIFS(Details!$S$5:$S$53,Details!$C$5:$C$53,Summary!AL$5,Details!$CK$5:$CK$53,Summary!$AJ$5)/1000 -> 104.47 | AM6: =SUMIFS(Details!$S$5:$S$53,Details!$C$5:$C$53,Summary!AM$5,Details!$CK$5:$CK$53,Summary!$AJ$5)/1000 -> 99.631 | AN6: =SUMIFS(Details!$S$5:$S$53,Details!$C$5:$C$53,Summary!AN$5,Details!$CK$5:$CK$53,Summary!$AJ$5)/1000 -> 0 | AO6: =SUMIFS(Details!$S$5:$S$53,Details!$C$5:$C$53,Summary!AO$5,Details!$CK$5:$CK$53,Summary!$AJ$5)/1000 -> 0 | AP6: =SUMIFS(Details!$S$5:$S$53,Details!$C$5:$C$53,Summary!AP$5,Details!$CK$5:$CK$53,Summary!$AJ$5)/1000 -> 0 | AQ6: =SUMIFS(Details!$S$5:$S$53,Details!$C$5:$C$53,Summary!AQ$5,Details!$CK$5:$CK$53,Summary!$AJ$5)/1000 -> 0 | AR6: =SUMIFS(Details!$S$5:$S$53,Details!$C$5:$C$53,Summary!AR$5,Details!$CK$5:$CK$53,Summary!$AJ$5)/1000 -> 0 | ... AV6: =SUMIFS(Details!$S$5:$S$53,Details!$C$5:$C$53,Summary!AV$5,Details!$CK$5:$CK$53,Summary!$AJ$5)/1000 -> 0 | AW6: =SUM(AK6:AV6) -> 453.706 | AY6: Quantity (MT) | AZ6: =SUMIFS(Details!$S$5:$S$53,Details!$C$5:$C$53,Summary!AZ$5,Details!$CK$5:$CK$53,Summary!$AY$5)/1000 -> 0 | BA6: =SUMIFS(Details!$S$5:$S$53,Details!$C$5:$C$53,Summary!BA$5,Details!$CK$5:$CK$53,Summary!$AY$5)/1000 -> 0 | BB6: =SUMIFS(Details!$S$5:$S$53,Details!$C$5:$C$53,Summary!BB$5,Details!$CK$5:$CK$53,Summary!$AY$5)/1000 -> 0 | BC6: =SUMIFS(Details!$S$5:$S$53,Details!$C$5:$C$53,Summary!BC$5,Details!$CK$5:$CK$53,Summary!$AY$5)/1000 -> 0 | BD6: =SUMIFS(Details!$S$5:$S$53,Details!$C$5:$C$53,Summary!BD$5,Details!$CK$5:$CK$53,Summary!$AY$5)/1000 -> 0 | BE6: =SUMIFS(Details!$S$5:$S$53,Details!$C$5:$C$53,Summary!BE$5,Details!$CK$5:$CK$53,Summary!$AY$5)/1000 -> 0 | BF6: =SUMIFS(Details!$S$5:$S$53,Details!$C$5:$C$53,Summary!BF$5,Details!$CK$5:$CK$53,Summary!$AY$5)/1000 -> 0 | BG6: =SUMIFS(Details!$S$5:$S$53,Details!$C$5:$C$53,Summary!BG$5,Details!$CK$5:$CK$53,Summary!$AY$5)/1000 -> 0 | ... BK6: =SUMIFS(Details!$S$5:$S$53,Details!$C$5:$C$53,Summary!BK$5,Details!$CK$5:$CK$53,Summary!$AY$5)/1000 -> 0 | BL6: =SUM(AZ6:BK6) -> 0 | BN6: =(AH6+AW6+BL6)-P6 -> 0.64 | CI6: =E6 -> 129.15 | CJ6: =T6+CI6 -> 129.04
C7: Sales | D7: 16902407 | E7: 11693868 | F7: =SUMIFS(Details!$BQ$5:$BQ$53,Details!$C$5:$C$53,Summary!F$5) -> 8359215.8 | G7: =SUMIFS(Details!$BQ$5:$BQ$53,Details!$C$5:$C$53,Summary!G$5) -> 0 | H7: =SUMIFS(Details!$BQ$5:$BQ$53,Details!$C$5:$C$53,Summary!H$5) -> 0 | I7: =SUMIFS(Details!$BQ$5:$BQ$53,Details!$C$5:$C$53,Summary!I$5) -> 0 | J7: =SUMIFS(Details!$BQ$5:$BQ$53,Details!$C$5:$C$53,Summary!J$5) -> 0 | K7: =SUMIFS(Details!$BQ$5:$BQ$53,Details!$C$5:$C$53,Summary!K$5) -> 0 | L7: =SUMIFS(Details!$BQ$5:$BQ$53,Details!$C$5:$C$53,Summary!L$5) -> 0 | M7: =SUMIFS(Details!$BQ$5:$BQ$53,Details!$C$5:$C$53,Summary!M$5) -> 0 | ... O7: =SUMIFS(Details!$BQ$5:$BQ$53,Details!$C$5:$C$53,Summary!O$5) -> 0 | P7: =SUM(D7:O7) -> 36955490 | Q7: =Details!BQ54 -> 37120499 | R7: =P7-Q7 -> -165008.1 | T7: =-R7 -> 165008.1 | U7: Sales | V7: =SUMIFS(Details!$BQ$5:$BQ$53,Details!$C$5:$C$53,Summary!V$5,Details!$CK$5:$CK$53,Summary!$U$5) -> 8931160 | W7: =SUMIFS(Details!$BQ$5:$BQ$53,Details!$C$5:$C$53,Summary!W$5,Details!$CK$5:$CK$53,Summary!$U$5) -> 8709308 | X7: =SUMIFS(Details!$BQ$5:$BQ$53,Details!$C$5:$C$53,Summary!X$5,Details!$CK$5:$CK$53,Summary!$U$5) -> 4932219.5 | Y7: =SUMIFS(Details!$BQ$5:$BQ$53,Details!$C$5:$C$53,Summary!Y$5,Details!$CK$5:$CK$53,Summary!$U$5) -> 0 | Z7: =SUMIFS(Details!$BQ$5:$BQ$53,Details!$C$5:$C$53,Summary!Z$5,Details!$CK$5:$CK$53,Summary!$U$5) -> 0 | AA7: =SUMIFS(Details!$BQ$5:$BQ$53,Details!$C$5:$C$53,Summary!AA$5,Details!$CK$5:$CK$53,Summary!$U$5) -> 0 | AB7: =SUMIFS(Details!$BQ$5:$BQ$53,Details!$C$5:$C$53,Summary!AB$5,Details!$CK$5:$CK$53,Summary!$U$5) -> 0 | AC7: =SUMIFS(Details!$BQ$5:$BQ$53,Details!$C$5:$C$53,Summary!AC$5,Details!$CK$5:$CK$53,Summary!$U$5) -> 0 | ... AG7: =SUMIFS(Details!$BQ$5:$BQ$53,Details!$C$5:$C$53,Summary!AG$5,Details!$CK$5:$CK$53,Summary!$U$5) -> 0 | AH7: =SUM(V7:AG7) -> 22572688 | AJ7: Sales | AK7: =SUMIFS(Details!$BQ$5:$BQ$53,Details!$C$5:$C$53,Summary!AK$5,Details!$CK$5:$CK$53,Summary!$AJ$5) -> 7989785.8 | AL7: =SUMIFS(Details!$BQ$5:$BQ$53,Details!$C$5:$C$53,Summary!AL$5,Details!$CK$5:$CK$53,Summary!$AJ$5) -> 3124279 | AM7: =SUMIFS(Details!$BQ$5:$BQ$53,Details!$C$5:$C$53,Summary!AM$5,Details!$CK$5:$CK$53,Summary!$AJ$5) -> 3426996.2 | AN7: =SUMIFS(Details!$BQ$5:$BQ$53,Details!$C$5:$C$53,Summary!AN$5,Details!$CK$5:$CK$53,Summary!$AJ$5) -> 0 | AO7: =SUMIFS(Details!$BQ$5:$BQ$53,Details!$C$5:$C$53,Summary!AO$5,Details!$CK$5:$CK$53,Summary!$AJ$5) -> 0 | AP7: =SUMIFS(Details!$BQ$5:$BQ$53,Details!$C$5:$C$53,Summary!AP$5,Details!$CK$5:$CK$53,Summary!$AJ$5) -> 0 | AQ7: =SUMIFS(Details!$BQ$5:$BQ$53,Details!$C$5:$C$53,Summary!AQ$5,Details!$CK$5:$CK$53,Summary!$AJ$5) -> 0 | AR7: =SUMIFS(Details!$BQ$5:$BQ$53,Details!$C$5:$C$53,Summary!AR$5,Details!$CK$5:$CK$53,Summary!$AJ$5) -> 0 | ... AV7: =SUMIFS(Details!$BQ$5:$BQ$53,Details!$C$5:$C$53,Summary!AV$5,Details!$CK$5:$CK$53,Summary!$AJ$5) -> 0 | AW7: =SUM(AK7:AV7) -> 14541061 | AY7: Sales | AZ7: =SUMIFS(Details!$BQ$5:$BQ$53,Details!$C$5:$C$53,Summary!AZ$5,Details!$CK$5:$CK$53,Summary!$AY$5) -> 0 | BA7: =SUMIFS(Details!$BQ$5:$BQ$53,Details!$C$5:$C$53,Summary!BA$5,Details!$CK$5:$CK$53,Summary!$AY$5) -> 0 | BB7: =SUMIFS(Details!$BQ$5:$BQ$53,Details!$C$5:$C$53,Summary!BB$5,Details!$CK$5:$CK$53,Summary!$AY$5) -> 0 | BC7: =SUMIFS(Details!$BQ$5:$BQ$53,Details!$C$5:$C$53,Summary!BC$5,Details!$CK$5:$CK$53,Summary!$AY$5) -> 0 | BD7: =SUMIFS(Details!$BQ$5:$BQ$53,Details!$C$5:$C$53,Summary!BD$5,Details!$CK$5:$CK$53,Summary!$AY$5) -> 0 | BE7: =SUMIFS(Details!$BQ$5:$BQ$53,Details!$C$5:$C$53,Summary!BE$5,Details!$CK$5:$CK$53,Summary!$AY$5) -> 0 | BF7: =SUMIFS(Details!$BQ$5:$BQ$53,Details!$C$5:$C$53,Summary!BF$5,Details!$CK$5:$CK$53,Summary!$AY$5) -> 0 | BG7: =SUMIFS(Details!$BQ$5:$BQ$53,Details!$C$5:$C$53,Summary!BG$5,Details!$CK$5:$CK$53,Summary!$AY$5) -> 0 | ... BK7: =SUMIFS(Details!$BQ$5:$BQ$53,Details!$C$5:$C$53,Summary!BK$5,Details!$CK$5:$CK$53,Summary!$AY$5) -> 0 | BL7: =SUM(AZ7:BK7) -> 0 | BN7: =(AH7+AW7+BL7)-P7 -> 158258.1 | CI7: =E7 -> 11693868 | CJ7: =T7+CI7 -> 11858876
C8: Purchases | D8: 16663815 | E8: 11364387 | F8: =SUMIFS(Details!$AM$5:$AM$53,Details!$C$5:$C$53,Summary!F$5)-SUMIFS(Details!$AB$5:$AB$53,Details!$C$5:$C$53,Summary!F$5) -> 8135007 | G8: =SUMIFS(Details!$AM$5:$AM$53,Details!$C$5:$C$53,Summary!G$5)-SUMIFS(Details!$AB$5:$AB$53,Details!$C$5:$C$53,Summary!G$5) -> 0 | H8: =SUMIFS(Details!$AM$5:$AM$53,Details!$C$5:$C$53,Summary!H$5)-SUMIFS(Details!$AB$5:$AB$53,Details!$C$5:$C$53,Summary!H$5) -> 0 | I8: =SUMIFS(Details!$AM$5:$AM$53,Details!$C$5:$C$53,Summary!I$5)-SUMIFS(Details!$AB$5:$AB$53,Details!$C$5:$C$53,Summary!I$5) -> 0 | J8: =SUMIFS(Details!$AM$5:$AM$53,Details!$C$5:$C$53,Summary!J$5)-SUMIFS(Details!$AB$5:$AB$53,Details!$C$5:$C$53,Summary!J$5) -> 0 | K8: =SUMIFS(Details!$AM$5:$AM$53,Details!$C$5:$C$53,Summary!K$5)-SUMIFS(Details!$AB$5:$AB$53,Details!$C$5:$C$53,Summary!K$5) -> 0 | L8: =SUMIFS(Details!$AM$5:$AM$53,Details!$C$5:$C$53,Summary!L$5)-SUMIFS(Details!$AB$5:$AB$53,Details!$C$5:$C$53,Summary!L$5) -> 0 | M8: =SUMIFS(Details!$AM$5:$AM$53,Details!$C$5:$C$53,Summary!M$5)-SUMIFS(Details!$AB$5:$AB$53,Details!$C$5:$C$53,Summary!M$5) -> 0 | ... O8: =SUMIFS(Details!$AM$5:$AM$53,Details!$C$5:$C$53,Summary!O$5)-SUMIFS(Details!$AB$5:$AB$53,Details!$C$5:$C$53,Summary!O$5) -> 0 | P8: =SUM(D8:O8) -> 36163209 | Q8: =Details!P55 -> 36323313 | R8: =P8-Q8 -> -160104.08 | T8: =-R8 -> 160104.08 | U8: Purchases | V8: =SUMIFS(Details!$AM$5:$AM$53,Details!$C$5:$C$53,Summary!V$5,Details!$CK$5:$CK$53,Summary!$U$5)-SUMIFS(Details!$AB$5:$AB$53,Details!$C$5:$C$53,Summary!V$5,Details!$CK$5:$CK$53,Summary!$U$5) -> 8673578.9 | W8: =SUMIFS(Details!$AM$5:$AM$53,Details!$C$5:$C$53,Summary!W$5,Details!$CK$5:$CK$53,Summary!$U$5)-SUMIFS(Details!$AB$5:$AB$53,Details!$C$5:$C$53,Summary!W$5,Details!$CK$5:$CK$53,Summary!$U$5) -> 8465886.5 | X8: =SUMIFS(Details!$AM$5:$AM$53,Details!$C$5:$C$53,Summary!X$5,Details!$CK$5:$CK$53,Summary!$U$5)-SUMIFS(Details!$AB$5:$AB$53,Details!$C$5:$C$53,Summary!X$5,Details!$CK$5:$CK$53,Summary!$U$5) -> 4784088.3 | Y8: =SUMIFS(Details!$AM$5:$AM$53,Details!$C$5:$C$53,Summary!Y$5,Details!$CK$5:$CK$53,Summary!$U$5)-SUMIFS(Details!$AB$5:$AB$53,Details!$C$5:$C$53,Summary!Y$5,Details!$CK$5:$CK$53,Summary!$U$5) -> 0 | Z8: =SUMIFS(Details!$AM$5:$AM$53,Details!$C$5:$C$53,Summary!Z$5,Details!$CK$5:$CK$53,Summary!$U$5)-SUMIFS(Details!$AB$5:$AB$53,Details!$C$5:$C$53,Summary!Z$5,Details!$CK$5:$CK$53,Summary!$U$5) -> 0 | AA8: =SUMIFS(Details!$AM$5:$AM$53,Details!$C$5:$C$53,Summary!AA$5,Details!$CK$5:$CK$53,Summary!$U$5)-SUMIFS(Details!$AB$5:$AB$53,Details!$C$5:$C$53,Summary!AA$5,Details!$CK$5:$CK$53,Summary!$U$5) -> 0 | AB8: =SUMIFS(Details!$AM$5:$AM$53,Details!$C$5:$C$53,Summary!AB$5,Details!$CK$5:$CK$53,Summary!$U$5)-SUMIFS(Details!$AB$5:$AB$53,Details!$C$5:$C$53,Summary!AB$5,Details!$CK$5:$CK$53,Summary!$U$5) -> 0 | AC8: =SUMIFS(Details!$AM$5:$AM$53,Details!$C$5:$C$53,Summary!AC$5,Details!$CK$5:$CK$53,Summary!$U$5)-SUMIFS(Details!$AB$5:$AB$53,Details!$C$5:$C$53,Summary!AC$5,Details!$CK$5:$CK$53,Summary!$U$5) -> 0 | ... AG8: =SUMIFS(Details!$AM$5:$AM$53,Details!$C$5:$C$53,Summary!AG$5,Details!$CK$5:$CK$53,Summary!$U$5)-SUMIFS(Details!$AB$5:$AB$53,Details!$C$5:$C$53,Summary!AG$5,Details!$CK$5:$CK$53,Summary!$U$5) -> 0 | AH8: =SUM(V8:AG8) -> 21923554 | AJ8: Purchases | AK8: =SUMIFS(Details!$AM$5:$AM$53,Details!$C$5:$C$53,Summary!AK$5,Details!$CK$5:$CK$53,Summary!$AJ$5)-SUMIFS(Details!$AB$5:$AB$53,Details!$C$5:$C$53,Summary!AK$5,Details!$CK$5:$CK$53,Summary!$AJ$5) -> 7980660.2 | AL8: =SUMIFS(Details!$AM$5:$AM$53,Details!$C$5:$C$53,Summary!AL$5,Details!$CK$5:$CK$53,Summary!$AJ$5)-SUMIFS(Details!$AB$5:$AB$53,Details!$C$5:$C$53,Summary!AL$5,Details!$CK$5:$CK$53,Summary!$AJ$5) -> 3061430.7 | AM8: =SUMIFS(Details!$AM$5:$AM$53,Details!$C$5:$C$53,Summary!AM$5,Details!$CK$5:$CK$53,Summary!$AJ$5)-SUMIFS(Details!$AB$5:$AB$53,Details!$C$5:$C$53,Summary!AM$5,Details!$CK$5:$CK$53,Summary!$AJ$5) -> 3350918.8 | AN8: =SUMIFS(Details!$AM$5:$AM$53,Details!$C$5:$C$53,Summary!AN$5,Details!$CK$5:$CK$53,Summary!$AJ$5)-SUMIFS(Details!$AB$5:$AB$53,Details!$C$5:$C$53,Summary!AN$5,Details!$CK$5:$CK$53,Summary!$AJ$5) -> 0 | AO8: =SUMIFS(Details!$AM$5:$AM$53,Details!$C$5:$C$53,Summary!AO$5,Details!$CK$5:$CK$53,Summary!$AJ$5)-SUMIFS(Details!$AB$5:$AB$53,Details!$C$5:$C$53,Summary!AO$5,Details!$CK$5:$CK$53,Summary!$AJ$5) -> 0 | AP8: =SUMIFS(Details!$AM$5:$AM$53,Details!$C$5:$C$53,Summary!AP$5,Details!$CK$5:$CK$53,Summary!$AJ$5)-SUMIFS(Details!$AB$5:$AB$53,Details!$C$5:$C$53,Summary!AP$5,Details!$CK$5:$CK$53,Summary!$AJ$5) -> 0 | AQ8: =SUMIFS(Details!$AM$5:$AM$53,Details!$C$5:$C$53,Summary!AQ$5,Details!$CK$5:$CK$53,Summary!$AJ$5)-SUMIFS(Details!$AB$5:$AB$53,Details!$C$5:$C$53,Summary!AQ$5,Details!$CK$5:$CK$53,Summary!$AJ$5) -> 0 | AR8: =SUMIFS(Details!$AM$5:$AM$53,Details!$C$5:$C$53,Summary!AR$5,Details!$CK$5:$CK$53,Summary!$AJ$5)-SUMIFS(Details!$AB$5:$AB$53,Details!$C$5:$C$53,Summary!AR$5,Details!$CK$5:$CK$53,Summary!$AJ$5) -> 0 | ... AV8: =SUMIFS(Details!$AM$5:$AM$53,Details!$C$5:$C$53,Summary!AV$5,Details!$CK$5:$CK$53,Summary!$AJ$5)-SUMIFS(Details!$AB$5:$AB$53,Details!$C$5:$C$53,Summary!AV$5,Details!$CK$5:$CK$53,Summary!$AJ$5) -> 0 | AW8: =SUM(AK8:AV8) -> 14393010 | AY8: Purchases | AZ8: =SUMIFS(Details!$AM$5:$AM$53,Details!$C$5:$C$53,Summary!AZ$5,Details!$CK$5:$CK$53,Summary!$AY$5)-SUMIFS(Details!$AB$5:$AB$53,Details!$C$5:$C$53,Summary!AZ$5,Details!$CK$5:$CK$53,Summary!$AY$5) -> 0 | BA8: =SUMIFS(Details!$AM$5:$AM$53,Details!$C$5:$C$53,Summary!BA$5,Details!$CK$5:$CK$53,Summary!$AY$5)-SUMIFS(Details!$AB$5:$AB$53,Details!$C$5:$C$53,Summary!BA$5,Details!$CK$5:$CK$53,Summary!$AY$5) -> 0 | BB8: =SUMIFS(Details!$AM$5:$AM$53,Details!$C$5:$C$53,Summary!BB$5,Details!$CK$5:$CK$53,Summary!$AY$5)-SUMIFS(Details!$AB$5:$AB$53,Details!$C$5:$C$53,Summary!BB$5,Details!$CK$5:$CK$53,Summary!$AY$5) -> 0 | BC8: =SUMIFS(Details!$AM$5:$AM$53,Details!$C$5:$C$53,Summary!BC$5,Details!$CK$5:$CK$53,Summary!$AY$5)-SUMIFS(Details!$AB$5:$AB$53,Details!$C$5:$C$53,Summary!BC$5,Details!$CK$5:$CK$53,Summary!$AY$5) -> 0 | BD8: =SUMIFS(Details!$AM$5:$AM$53,Details!$C$5:$C$53,Summary!BD$5,Details!$CK$5:$CK$53,Summary!$AY$5)-SUMIFS(Details!$AB$5:$AB$53,Details!$C$5:$C$53,Summary!BD$5,Details!$CK$5:$CK$53,Summary!$AY$5) -> 0 | BE8: =SUMIFS(Details!$AM$5:$AM$53,Details!$C$5:$C$53,Summary!BE$5,Details!$CK$5:$CK$53,Summary!$AY$5)-SUMIFS(Details!$AB$5:$AB$53,Details!$C$5:$C$53,Summary!BE$5,Details!$CK$5:$CK$53,Summary!$AY$5) -> 0 | BF8: =SUMIFS(Details!$AM$5:$AM$53,Details!$C$5:$C$53,Summary!BF$5,Details!$CK$5:$CK$53,Summary!$AY$5)-SUMIFS(Details!$AB$5:$AB$53,Details!$C$5:$C$53,Summary!BF$5,Details!$CK$5:$CK$53,Summary!$AY$5) -> 0 | BG8: =SUMIFS(Details!$AM$5:$AM$53,Details!$C$5:$C$53,Summary!BG$5,Details!$CK$5:$CK$53,Summary!$AY$5)-SUMIFS(Details!$AB$5:$AB$53,Details!$C$5:$C$53,Summary!BG$5,Details!$CK$5:$CK$53,Summary!$AY$5) -> 0 | ... BK8: =SUMIFS(Details!$AM$5:$AM$53,Details!$C$5:$C$53,Summary!BK$5,Details!$CK$5:$CK$53,Summary!$AY$5)-SUMIFS(Details!$AB$5:$AB$53,Details!$C$5:$C$53,Summary!BK$5,Details!$CK$5:$CK$53,Summary!$AY$5) -> 0 | BL8: =SUM(AZ8:BK8) -> 0 | BN8: =(AH8+AW8+BL8)-P8 -> 153354.08 | CI8: =E8 -> 11364387 | CJ8: =T8+CI8 -> 11524491
C9: Gross Margin | D9: =D7-D8 -> 238591.53 | E9: =E7-E8 -> 329480.87 | F9: =F7-F8 -> 224208.75 | G9: =G7-G8 -> 0 | H9: =H7-H8 -> 0 | I9: =I7-I8 -> 0 | J9: =J7-J8 -> 0 | K9: =K7-K8 -> 0 | ... P9: =P7-P8 -> 792281.15 | U9: Gross Margin | V9: =V7-V8 -> 257581.1 | W9: =W7-W8 -> 243421.5 | X9: =X7-X8 -> 148131.29 | Y9: =Y7-Y8 -> 0 | Z9: =Z7-Z8 -> 0 | AA9: =AA7-AA8 -> 0 | AB9: =AB7-AB8 -> 0 | AC9: =AC7-AC8 -> 0 | ... AH9: =AH7-AH8 -> 649133.89 | AJ9: Gross Margin | AK9: =AK7-AK8 -> 9125.5903 | AL9: =AL7-AL8 -> 62848.221 | AM9: =AM7-AM8 -> 76077.468 | AN9: =AN7-AN8 -> 0 | AO9: =AO7-AO8 -> 0 | AP9: =AP7-AP8 -> 0 | AQ9: =AQ7-AQ8 -> 0 | AR9: =AR7-AR8 -> 0 | ... AW9: =AW7-AW8 -> 148051.28 | AY9: Gross Margin | AZ9: =AZ7-AZ8 -> 0 | BA9: =BA7-BA8 -> 0 | BB9: =BB7-BB8 -> 0 | BC9: =BC7-BC8 -> 0 | BD9: =BD7-BD8 -> 0 | BE9: =BE7-BE8 -> 0 | BF9: =BF7-BF8 -> 0 | BG9: =BG7-BG8 -> 0 | ... BL9: =BL7-BL8 -> 0 | BN9: =(AH9+AW9+BL9)-P9 -> 4904.0175
C10: Gross Margin (%) | D10: =IFERROR((D9/D7),0) -> 0.014115832 | E10: =IFERROR((E9/E7),0) -> 0.028175525 | F10: =IFERROR((F9/F7),0) -> 0.026821745 | G10: =IFERROR((G9/G7),0) -> 0 | H10: =IFERROR((H9/H7),0) -> 0 | I10: =IFERROR((I9/I7),0) -> 0 | J10: =IFERROR((J9/J7),0) -> 0 | K10: =IFERROR((K9/K7),0) -> 0 | ... P10: =IFERROR((P9/P7),0) -> 0.021438794 | U10: Gross Margin (%) | V10: =IFERROR((V9/V7),0) -> 0.028840722 | W10: =IFERROR((W9/W7),0) -> 0.02794958 | X10: =IFERROR((X9/X7),0) -> 0.030033393 | Y10: =IFERROR((Y9/Y7),0) -> 0 | Z10: =IFERROR((Z9/Z7),0) -> 0 | AA10: =IFERROR((AA9/AA7),0) -> 0 | AB10: =IFERROR((AB9/AB7),0) -> 0 | AC10: =IFERROR((AC9/AC7),0) -> 0 | ... AH10: =IFERROR((AH9/AH7),0) -> 0.028757492 | AJ10: Gross Margin (%) | AK10: =IFERROR((AK9/AK7),0) -> 0.0011421571 | AL10: =IFERROR((AL9/AL7),0) -> 0.020116072 | AM10: =IFERROR((AM9/AM7),0) -> 0.022199461 | AN10: =IFERROR((AN9/AN7),0) -> 0 | AO10: =IFERROR((AO9/AO7),0) -> 0 | AP10: =IFERROR((AP9/AP7),0) -> 0 | AQ10: =IFERROR((AQ9/AQ7),0) -> 0 | AR10: =IFERROR((AR9/AR7),0) -> 0 | ... AW10: =IFERROR((AW9/AW7),0) -> 0.010181601 | AY10: Gross Margin (%) | AZ10: =IFERROR((AZ9/AZ7),0) -> 0 | BA10: =IFERROR((BA9/BA7),0) -> 0 | BB10: =IFERROR((BB9/BB7),0) -> 0 | BC10: =IFERROR((BC9/BC7),0) -> 0 | BD10: =IFERROR((BD9/BD7),0) -> 0 | BE10: =IFERROR((BE9/BE7),0) -> 0 | BF10: =IFERROR((BF9/BF7),0) -> 0 | BG10: =IFERROR((BG9/BG7),0) -> 0 | ... BL10: =IFERROR((BL9/BL7),0) -> 0 | BN10: =(AH10+AW10+BL10)-P10 -> 0.017500299
C11: Transportation Charges | D11: =SUMIFS(Details!$AB$5:$AB$53,Details!$C$5:$C$53,Summary!D$5) -> 0 | E11: =SUMIFS(Details!$AB$5:$AB$53,Details!$C$5:$C$53,Summary!E$5) -> 0 | F11: =SUMIFS(Details!$AB$5:$AB$53,Details!$C$5:$C$53,Summary!F$5) -> 0 | G11: =SUMIFS(Details!$AB$5:$AB$53,Details!$C$5:$C$53,Summary!G$5) -> 0 | H11: =SUMIFS(Details!$AB$5:$AB$53,Details!$C$5:$C$53,Summary!H$5) -> 0 | I11: =SUMIFS(Details!$AB$5:$AB$53,Details!$C$5:$C$53,Summary!I$5) -> 0 | J11: =SUMIFS(Details!$AB$5:$AB$53,Details!$C$5:$C$53,Summary!J$5) -> 0 | K11: =SUMIFS(Details!$AB$5:$AB$53,Details!$C$5:$C$53,Summary!K$5) -> 0 | ... O11: =SUMIFS(Details!$AB$5:$AB$53,Details!$C$5:$C$53,Summary!O$5) -> 0 | P11: =SUM(D11:O11) -> 0 | Q11: =Details!AB54 -> 0 | R11: =P11-Q11 -> 0 | T11: =-R11 -> 0 | U11: Quantity (MT) | V11: =SUMIFS(Details!$S$5:$S$53,Details!$C$5:$C$53,Summary!V$5,Details!$CK$5:$CK$53,Summary!$U$5)/1000 -> 26.99 | W11: =SUMIFS(Details!$S$5:$S$53,Details!$C$5:$C$53,Summary!W$5,Details!$CK$5:$CK$53,Summary!$U$5)/1000 -> 25.43 | X11: =SUMIFS(Details!$S$5:$S$53,Details!$C$5:$C$53,Summary!X$5,Details!$CK$5:$CK$53,Summary!$U$5)/1000 -> 14.385 | Y11: =SUMIFS(Details!$S$5:$S$53,Details!$C$5:$C$53,Summary!Y$5,Details!$CK$5:$CK$53,Summary!$U$5)/1000 -> 0 | Z11: =SUMIFS(Details!$S$5:$S$53,Details!$C$5:$C$53,Summary!Z$5,Details!$CK$5:$CK$53,Summary!$U$5)/1000 -> 0 | AA11: =SUMIFS(Details!$S$5:$S$53,Details!$C$5:$C$53,Summary!AA$5,Details!$CK$5:$CK$53,Summary!$U$5)/1000 -> 0 | AB11: =SUMIFS(Details!$S$5:$S$53,Details!$C$5:$C$53,Summary!AB$5,Details!$CK$5:$CK$53,Summary!$U$5)/1000 -> 0 | AC11: =SUMIFS(Details!$S$5:$S$53,Details!$C$5:$C$53,Summary!AC$5,Details!$CK$5:$CK$53,Summary!$U$5)/1000 -> 0 | ... AG11: =SUMIFS(Details!$S$5:$S$53,Details!$C$5:$C$53,Summary!AG$5,Details!$CK$5:$CK$53,Summary!$U$5)/1000 -> 0 | AH11: =SUM(V11:AG11) -> 66.805 | AJ11: Quantity (MT) | AK11: =SUMIFS(Details!$S$5:$S$53,Details!$C$5:$C$53,Summary!AK$5,Details!$CK$5:$CK$53,Summary!$AJ$5)/1000 -> 249.605 | AL11: =SUMIFS(Details!$S$5:$S$53,Details!$C$5:$C$53,Summary!AL$5,Details!$CK$5:$CK$53,Summary!$AJ$5)/1000 -> 104.47 | AM11: =SUMIFS(Details!$S$5:$S$53,Details!$C$5:$C$53,Summary!AM$5,Details!$CK$5:$CK$53,Summary!$AJ$5)/1000 -> 99.631 | AN11: =SUMIFS(Details!$S$5:$S$53,Details!$C$5:$C$53,Summary!AN$5,Details!$CK$5:$CK$53,Summary!$AJ$5)/1000 -> 0 | AO11: =SUMIFS(Details!$S$5:$S$53,Details!$C$5:$C$53,Summary!AO$5,Details!$CK$5:$CK$53,Summary!$AJ$5)/1000 -> 0 | AP11: =SUMIFS(Details!$S$5:$S$53,Details!$C$5:$C$53,Summary!AP$5,Details!$CK$5:$CK$53,Summary!$AJ$5)/1000 -> 0 | AQ11: =SUMIFS(Details!$S$5:$S$53,Details!$C$5:$C$53,Summary!AQ$5,Details!$CK$5:$CK$53,Summary!$AJ$5)/1000 -> 0 | AR11: =SUMIFS(Details!$S$5:$S$53,Details!$C$5:$C$53,Summary!AR$5,Details!$CK$5:$CK$53,Summary!$AJ$5)/1000 -> 0 | ... AV11: =SUMIFS(Details!$S$5:$S$53,Details!$C$5:$C$53,Summary!AV$5,Details!$CK$5:$CK$53,Summary!$AJ$5)/1000 -> 0 | AW11: =SUM(AK11:AV11) -> 453.706 | AY11: Quantity (MT) | AZ11: =SUMIFS(Details!$S$5:$S$53,Details!$C$5:$C$53,Summary!AZ$5,Details!$CK$5:$CK$53,Summary!$AY$5)/1000 -> 0 | BA11: =SUMIFS(Details!$S$5:$S$53,Details!$C$5:$C$53,Summary!BA$5,Details!$CK$5:$CK$53,Summary!$AY$5)/1000 -> 0 | BB11: =SUMIFS(Details!$S$5:$S$53,Details!$C$5:$C$53,Summary!BB$5,Details!$CK$5:$CK$53,Summary!$AY$5)/1000 -> 0 | BC11: =SUMIFS(Details!$S$5:$S$53,Details!$C$5:$C$53,Summary!BC$5,Details!$CK$5:$CK$53,Summary!$AY$5)/1000 -> 0 | BD11: =SUMIFS(Details!$S$5:$S$53,Details!$C$5:$C$53,Summary!BD$5,Details!$CK$5:$CK$53,Summary!$AY$5)/1000 -> 0 | BE11: =SUMIFS(Details!$S$5:$S$53,Details!$C$5:$C$53,Summary!BE$5,Details!$CK$5:$CK$53,Summary!$AY$5)/1000 -> 0 | BF11: =SUMIFS(Details!$S$5:$S$53,Details!$C$5:$C$53,Summary!BF$5,Details!$CK$5:$CK$53,Summary!$AY$5)/1000 -> 0 | BG11: =SUMIFS(Details!$S$5:$S$53,Details!$C$5:$C$53,Summary!BG$5,Details!$CK$5:$CK$53,Summary!$AY$5)/1000 -> 0 | ... BK11: =SUMIFS(Details!$S$5:$S$53,Details!$C$5:$C$53,Summary!BK$5,Details!$CK$5:$CK$53,Summary!$AY$5)/1000 -> 0 | BL11: =SUM(AZ11:BK11) -> 0 | BN11: =(AH11+AW11+BL11)-P11 -> 520.511 | CI11: =E11 -> 0 | CJ11: =T11+CI11 -> 0
C12: Operational Cost | D12: =SUMIFS(Details!$AC$5:$AC$53,Details!$C$5:$C$53,Summary!D$5) -> 0 | E12: =SUMIFS(Details!$AC$5:$AC$53,Details!$C$5:$C$53,Summary!E$5) -> 0 | F12: =SUMIFS(Details!$AC$5:$AC$53,Details!$C$5:$C$53,Summary!F$5) -> 0 | G12: =SUMIFS(Details!$AC$5:$AC$53,Details!$C$5:$C$53,Summary!G$5) -> 0 | H12: =SUMIFS(Details!$AC$5:$AC$53,Details!$C$5:$C$53,Summary!H$5) -> 0 | I12: =SUMIFS(Details!$AC$5:$AC$53,Details!$C$5:$C$53,Summary!I$5) -> 0 | J12: =SUMIFS(Details!$AC$5:$AC$53,Details!$C$5:$C$53,Summary!J$5) -> 0 | K12: =SUMIFS(Details!$AC$5:$AC$53,Details!$C$5:$C$53,Summary!K$5) -> 0 | ... O12: =SUMIFS(Details!$AC$5:$AC$53,Details!$C$5:$C$53,Summary!O$5) -> 0 | P12: =SUM(D12:O12) -> 0 | R12: =P12-Q12 -> 0 | T12: =-R12 -> 0 | U12: Quantity (MT) | V12: =SUMIFS(Details!$S$5:$S$53,Details!$C$5:$C$53,Summary!V$5,Details!$CK$5:$CK$53,Summary!$U$5)/1000 -> 26.99 | W12: =SUMIFS(Details!$S$5:$S$53,Details!$C$5:$C$53,Summary!W$5,Details!$CK$5:$CK$53,Summary!$U$5)/1000 -> 25.43 | X12: =SUMIFS(Details!$S$5:$S$53,Details!$C$5:$C$53,Summary!X$5,Details!$CK$5:$CK$53,Summary!$U$5)/1000 -> 14.385 | Y12: =SUMIFS(Details!$S$5:$S$53,Details!$C$5:$C$53,Summary!Y$5,Details!$CK$5:$CK$53,Summary!$U$5)/1000 -> 0 | Z12: =SUMIFS(Details!$S$5:$S$53,Details!$C$5:$C$53,Summary!Z$5,Details!$CK$5:$CK$53,Summary!$U$5)/1000 -> 0 | AA12: =SUMIFS(Details!$S$5:$S$53,Details!$C$5:$C$53,Summary!AA$5,Details!$CK$5:$CK$53,Summary!$U$5)/1000 -> 0 | AB12: =SUMIFS(Details!$S$5:$S$53,Details!$C$5:$C$53,Summary!AB$5,Details!$CK$5:$CK$53,Summary!$U$5)/1000 -> 0 | AC12: =SUMIFS(Details!$S$5:$S$53,Details!$C$5:$C$53,Summary!AC$5,Details!$CK$5:$CK$53,Summary!$U$5)/1000 -> 0 | ... AG12: =SUMIFS(Details!$S$5:$S$53,Details!$C$5:$C$53,Summary!AG$5,Details!$CK$5:$CK$53,Summary!$U$5)/1000 -> 0 | AH12: =SUM(V12:AG12) -> 66.805 | AJ12: Quantity (MT) | AK12: =SUMIFS(Details!$S$5:$S$53,Details!$C$5:$C$53,Summary!AK$5,Details!$CK$5:$CK$53,Summary!$AJ$5)/1000 -> 249.605 | AL12: =SUMIFS(Details!$S$5:$S$53,Details!$C$5:$C$53,Summary!AL$5,Details!$CK$5:$CK$53,Summary!$AJ$5)/1000 -> 104.47 | AM12: =SUMIFS(Details!$S$5:$S$53,Details!$C$5:$C$53,Summary!AM$5,Details!$CK$5:$CK$53,Summary!$AJ$5)/1000 -> 99.631 | AN12: =SUMIFS(Details!$S$5:$S$53,Details!$C$5:$C$53,Summary!AN$5,Details!$CK$5:$CK$53,Summary!$AJ$5)/1000 -> 0 | AO12: =SUMIFS(Details!$S$5:$S$53,Details!$C$5:$C$53,Summary!AO$5,Details!$CK$5:$CK$53,Summary!$AJ$5)/1000 -> 0 | AP12: =SUMIFS(Details!$S$5:$S$53,Details!$C$5:$C$53,Summary!AP$5,Details!$CK$5:$CK$53,Summary!$AJ$5)/1000 -> 0 | AQ12: =SUMIFS(Details!$S$5:$S$53,Details!$C$5:$C$53,Summary!AQ$5,Details!$CK$5:$CK$53,Summary!$AJ$5)/1000 -> 0 | AR12: =SUMIFS(Details!$S$5:$S$53,Details!$C$5:$C$53,Summary!AR$5,Details!$CK$5:$CK$53,Summary!$AJ$5)/1000 -> 0 | ... AV12: =SUMIFS(Details!$S$5:$S$53,Details!$C$5:$C$53,Summary!AV$5,Details!$CK$5:$CK$53,Summary!$AJ$5)/1000 -> 0 | AW12: =SUM(AK12:AV12) -> 453.706 | AY12: Quantity (MT) | AZ12: =SUMIFS(Details!$S$5:$S$53,Details!$C$5:$C$53,Summary!AZ$5,Details!$CK$5:$CK$53,Summary!$AY$5)/1000 -> 0 | BA12: =SUMIFS(Details!$S$5:$S$53,Details!$C$5:$C$53,Summary!BA$5,Details!$CK$5:$CK$53,Summary!$AY$5)/1000 -> 0 | BB12: =SUMIFS(Details!$S$5:$S$53,Details!$C$5:$C$53,Summary!BB$5,Details!$CK$5:$CK$53,Summary!$AY$5)/1000 -> 0 | BC12: =SUMIFS(Details!$S$5:$S$53,Details!$C$5:$C$53,Summary!BC$5,Details!$CK$5:$CK$53,Summary!$AY$5)/1000 -> 0 | BD12: =SUMIFS(Details!$S$5:$S$53,Details!$C$5:$C$53,Summary!BD$5,Details!$CK$5:$CK$53,Summary!$AY$5)/1000 -> 0 | BE12: =SUMIFS(Details!$S$5:$S$53,Details!$C$5:$C$53,Summary!BE$5,Details!$CK$5:$CK$53,Summary!$AY$5)/1000 -> 0 | BF12: =SUMIFS(Details!$S$5:$S$53,Details!$C$5:$C$53,Summary!BF$5,Details!$CK$5:$CK$53,Summary!$AY$5)/1000 -> 0 | BG12: =SUMIFS(Details!$S$5:$S$53,Details!$C$5:$C$53,Summary!BG$5,Details!$CK$5:$CK$53,Summary!$AY$5)/1000 -> 0 | ... BK12: =SUMIFS(Details!$S$5:$S$53,Details!$C$5:$C$53,Summary!BK$5,Details!$CK$5:$CK$53,Summary!$AY$5)/1000 -> 0 | BL12: =SUM(AZ12:BK12) -> 0 | BN12: =(AH12+AW12+BL12)-P12 -> 520.511 | CI12: =E12 -> 0 | CJ12: =T12+CI12 -> 0
C13: Net Margin | D13: =D9-D11-D12 -> 238591.53 | E13: =E9-E11-E12 -> 329480.87 | F13: =F9-F11-F12 -> 224208.75 | G13: =G9-G11-G12 -> 0 | H13: =H9-H11-H12 -> 0 | I13: =I9-I11-I12 -> 0 | J13: =J9-J11-J12 -> 0 | K13: =K9-K11-K12 -> 0 | ... P13: =P9-P11-P12 -> 792281.15 | U13: Net Margin | V13: =V9-V11-V12 -> 257527.12 | W13: =W9-W11-W12 -> 243370.64 | X13: =X9-X11-X12 -> 148102.52 | Y13: =Y9-Y11-Y12 -> 0 | Z13: =Z9-Z11-Z12 -> 0 | AA13: =AA9-AA11-AA12 -> 0 | AB13: =AB9-AB11-AB12 -> 0 | AC13: =AC9-AC11-AC12 -> 0 | ... AH13: =AH9-AH11-AH12 -> 649000.28 | AJ13: Net Margin | AK13: =AK9-AK11-AK12 -> 8626.3803 | AL13: =AL9-AL11-AL12 -> 62639.281 | AM13: =AM9-AM11-AM12 -> 75878.206 | AN13: =AN9-AN11-AN12 -> 0 | AO13: =AO9-AO11-AO12 -> 0 | AP13: =AP9-AP11-AP12 -> 0 | AQ13: =AQ9-AQ11-AQ12 -> 0 | AR13: =AR9-AR11-AR12 -> 0 | ... AW13: =AW9-AW11-AW12 -> 147143.87 | AY13: Net Margin | AZ13: =AZ9-AZ11-AZ12 -> 0 | BA13: =BA9-BA11-BA12 -> 0 | BB13: =BB9-BB11-BB12 -> 0 | BC13: =BC9-BC11-BC12 -> 0 | BD13: =BD9-BD11-BD12 -> 0 | BE13: =BE9-BE11-BE12 -> 0 | BF13: =BF9-BF11-BF12 -> 0 | BG13: =BG9-BG11-BG12 -> 0 | ... BL13: =BL9-BL11-BL12 -> 0 | BN13: =(AH13+AW13+BL13)-P13 -> 3862.9955
C14: Net Margin (%) | D14: =IFERROR((D13/D7),0) -> 0.014115832 | E14: =IFERROR((E13/E7),0) -> 0.028175525 | F14: =IFERROR((F13/F7),0) -> 0.026821745 | G14: =IFERROR((G13/G7),0) -> 0 | H14: =IFERROR((H13/H7),0) -> 0 | I14: =IFERROR((I13/I7),0) -> 0 | J14: =IFERROR((J13/J7),0) -> 0 | K14: =IFERROR((K13/K7),0) -> 0 | ... P14: =IFERROR((P13/P7),0) -> 0.021438794 | U14: Net Margin (%) | V14: =IFERROR((V13/V7),0) -> 0.028834678 | W14: =IFERROR((W13/W7),0) -> 0.027943741 | X14: =IFERROR((X13/X7),0) -> 0.03002756 | Y14: =IFERROR((Y13/Y7),0) -> 0 | Z14: =IFERROR((Z13/Z7),0) -> 0 | AA14: =IFERROR((AA13/AA7),0) -> 0 | AB14: =IFERROR((AB13/AB7),0) -> 0 | AC14: =IFERROR((AC13/AC7),0) -> 0 | ... AH14: =IFERROR((AH13/AH7),0) -> 0.028751573 | AJ14: Net Margin (%) | AK14: =IFERROR((AK13/AK7),0) -> 0.001079676 | AL14: =IFERROR((AL13/AL7),0) -> 0.020049196 | AM14: =IFERROR((AM13/AM7),0) -> 0.022141316 | AN14: =IFERROR((AN13/AN7),0) -> 0 | AO14: =IFERROR((AO13/AO7),0) -> 0 | AP14: =IFERROR((AP13/AP7),0) -> 0 | AQ14: =IFERROR((AQ13/AQ7),0) -> 0 | AR14: =IFERROR((AR13/AR7),0) -> 0 | ... AW14: =IFERROR((AW13/AW7),0) -> 0.010119197 | AY14: Net Margin (%) | AZ14: =IFERROR((AZ13/AZ7),0) -> 0 | BA14: =IFERROR((BA13/BA7),0) -> 0 | BB14: =IFERROR((BB13/BB7),0) -> 0 | BC14: =IFERROR((BC13/BC7),0) -> 0 | BD14: =IFERROR((BD13/BD7),0) -> 0 | BE14: =IFERROR((BE13/BE7),0) -> 0 | BF14: =IFERROR((BF13/BF7),0) -> 0 | BG14: =IFERROR((BG13/BG7),0) -> 0 | ... BL14: =IFERROR((BL13/BL7),0) -> 0 | BN14: =(AH14+AW14+BL14)-P14 -> 0.017431977
C15: Other Income | D15: =SUMIFS(Details!$BQ$58:$BQ$59,Details!$C$58:$C$59,Summary!D$5) -> 0 | E15: =SUMIFS(Details!$BQ$58:$BQ$59,Details!$C$58:$C$59,Summary!E$5) -> 108894 | F15: =SUMIFS(Details!$BQ$58:$BQ$59,Details!$C$58:$C$59,Summary!F$5) -> 0 | G15: =SUMIFS(Details!$BQ$58:$BQ$59,Details!$C$58:$C$59,Summary!G$5) -> 0 | H15: =SUMIFS(Details!$BQ$58:$BQ$59,Details!$C$58:$C$59,Summary!H$5) -> 0 | I15: =SUMIFS(Details!$BQ$58:$BQ$59,Details!$C$58:$C$59,Summary!I$5) -> 0 | J15: =SUMIFS(Details!$BQ$58:$BQ$59,Details!$C$58:$C$59,Summary!J$5) -> 0 | K15: =SUMIFS(Details!$BQ$58:$BQ$59,Details!$C$58:$C$59,Summary!K$5) -> 0 | ... O15: =SUMIFS(Details!$BQ$58:$BQ$59,Details!$C$58:$C$59,Summary!O$5) -> 0 | P15: =SUM(D15:O15) -> 108894 | U15: Other Income | V15: =SUMIFS(Details!$BQ$58:$BQ$59,Details!$C$58:$C$59,Summary!V$5,Details!$CK$58:$CK$59,Summary!$U$5) -> 0 | W15: =SUMIFS(Details!$BQ$58:$BQ$59,Details!$C$58:$C$59,Summary!W$5,Details!$CK$58:$CK$59,Summary!$U$5) -> 0 | X15: =SUMIFS(Details!$BQ$58:$BQ$59,Details!$C$58:$C$59,Summary!X$5,Details!$CK$58:$CK$59,Summary!$U$5) -> 0 | Y15: =SUMIFS(Details!$BQ$58:$BQ$59,Details!$C$58:$C$59,Summary!Y$5,Details!$CK$58:$CK$59,Summary!$U$5) -> 0 | Z15: =SUMIFS(Details!$BQ$58:$BQ$59,Details!$C$58:$C$59,Summary!Z$5,Details!$CK$58:$CK$59,Summary!$U$5) -> 0 | AA15: =SUMIFS(Details!$BQ$58:$BQ$59,Details!$C$58:$C$59,Summary!AA$5,Details!$CK$58:$CK$59,Summary!$U$5) -> 0 | AB15: =SUMIFS(Details!$BQ$58:$BQ$59,Details!$C$58:$C$59,Summary!AB$5,Details!$CK$58:$CK$59,Summary!$U$5) -> 0 | AC15: =SUMIFS(Details!$BQ$58:$BQ$59,Details!$C$58:$C$59,Summary!AC$5,Details!$CK$58:$CK$59,Summary!$U$5) -> 0 | ... AG15: =SUMIFS(Details!$BQ$58:$BQ$59,Details!$C$58:$C$59,Summary!AG$5,Details!$CK$58:$CK$59,Summary!$U$5) -> 0 | AH15: =SUM(V15:AG15) -> 0 | AJ15: Other Income | AK15: =SUMIFS(Details!$BQ$58:$BQ$59,Details!$C$58:$C$59,Summary!AK$5,Details!$CK$58:$CK$59,Summary!$AJ$5) -> 0 | AL15: =SUMIFS(Details!$BQ$58:$BQ$59,Details!$C$58:$C$59,Summary!AL$5,Details!$CK$58:$CK$59,Summary!$AJ$5) -> 0 | AM15: =SUMIFS(Details!$BQ$58:$BQ$59,Details!$C$58:$C$59,Summary!AM$5,Details!$CK$58:$CK$59,Summary!$AJ$5) -> 0 | AN15: =SUMIFS(Details!$BQ$58:$BQ$59,Details!$C$58:$C$59,Summary!AN$5,Details!$CK$58:$CK$59,Summary!$AJ$5) -> 0 | AO15: =SUMIFS(Details!$BQ$58:$BQ$59,Details!$C$58:$C$59,Summary!AO$5,Details!$CK$58:$CK$59,Summary!$AJ$5) -> 0 | AP15: =SUMIFS(Details!$BQ$58:$BQ$59,Details!$C$58:$C$59,Summary!AP$5,Details!$CK$58:$CK$59,Summary!$AJ$5) -> 0 | AQ15: =SUMIFS(Details!$BQ$58:$BQ$59,Details!$C$58:$C$59,Summary!AQ$5,Details!$CK$58:$CK$59,Summary!$AJ$5) -> 0 | AR15: =SUMIFS(Details!$BQ$58:$BQ$59,Details!$C$58:$C$59,Summary!AR$5,Details!$CK$58:$CK$59,Summary!$AJ$5) -> 0 | ... AV15: =SUMIFS(Details!$BQ$58:$BQ$59,Details!$C$58:$C$59,Summary!AV$5,Details!$CK$58:$CK$59,Summary!$AJ$5) -> 0 | AW15: =SUM(AK15:AV15) -> 0 | AY15: Other Income | AZ15: =SUMIFS(Details!$BQ$58:$BQ$59,Details!$C$58:$C$59,Summary!AZ$5,Details!$CK$58:$CK$59,Summary!$AY$5) -> 0 | BA15: =SUMIFS(Details!$BQ$58:$BQ$59,Details!$C$58:$C$59,Summary!BA$5,Details!$CK$58:$CK$59,Summary!$AY$5) -> 0 | BB15: =SUMIFS(Details!$BQ$58:$BQ$59,Details!$C$58:$C$59,Summary!BB$5,Details!$CK$58:$CK$59,Summary!$AY$5) -> 0 | BC15: =SUMIFS(Details!$BQ$58:$BQ$59,Details!$C$58:$C$59,Summary!BC$5,Details!$CK$58:$CK$59,Summary!$AY$5) -> 0 | BD15: =SUMIFS(Details!$BQ$58:$BQ$59,Details!$C$58:$C$59,Summary!BD$5,Details!$CK$58:$CK$59,Summary!$AY$5) -> 0 | BE15: =SUMIFS(Details!$BQ$58:$BQ$59,Details!$C$58:$C$59,Summary!BE$5,Details!$CK$58:$CK$59,Summary!$AY$5) -> 0 | BF15: =SUMIFS(Details!$BQ$58:$BQ$59,Details!$C$58:$C$59,Summary!BF$5,Details!$CK$58:$CK$59,Summary!$AY$5) -> 0 | BG15: =SUMIFS(Details!$BQ$58:$BQ$59,Details!$C$58:$C$59,Summary!BG$5,Details!$CK$58:$CK$59,Summary!$AY$5) -> 0 | ... BK15: =SUMIFS(Details!$BQ$58:$BQ$59,Details!$C$58:$C$59,Summary!BK$5,Details!$CK$58:$CK$59,Summary!$AY$5) -> 0 | BL15: =SUM(AZ15:BK15) -> 0 | BN15: =(AH15+AW15+BL15)-P15 -> -108894
C16: Transport Charges (%) | D16: =IFERROR((D11/D7),0) -> 0 | E16: =IFERROR((E11/E7),0) -> 0 | F16: =IFERROR((F11/F7),0) -> 0 | G16: =IFERROR((G11/G7),0) -> 0 | H16: =IFERROR((H11/H7),0) -> 0 | I16: =IFERROR((I11/I7),0) -> 0 | J16: =IFERROR((J11/J7),0) -> 0 | K16: =IFERROR((K11/K7),0) -> 0 | ... P16: =IFERROR((P11/P7),0) -> 0 | U16: Transport Charges (%) | V16: =IFERROR((V11/V7),0) -> 3.0220039e-06 | W16: =IFERROR((W11/W7),0) -> 2.9198646e-06 | X16: =IFERROR((X11/X7),0) -> 2.9165368e-06 | Y16: =IFERROR((Y11/Y7),0) -> 0 | Z16: =IFERROR((Z11/Z7),0) -> 0 | AA16: =IFERROR((AA11/AA7),0) -> 0 | AB16: =IFERROR((AB11/AB7),0) -> 0 | AC16: =IFERROR((AC11/AC7),0) -> 0 | ... AH16: =IFERROR((AH11/AH7),0) -> 2.9595501e-06 | AJ16: Transport Charges (%) | AK16: =IFERROR((AK11/AK7),0) -> 3.1240512e-05 | AL16: =IFERROR((AL11/AL7),0) -> 3.3438115e-05 | AM16: =IFERROR((AM11/AM7),0) -> 2.9072398e-05 | AN16: =IFERROR((AN11/AN7),0) -> 0 | AO16: =IFERROR((AO11/AO7),0) -> 0 | AP16: =IFERROR((AP11/AP7),0) -> 0 | AQ16: =IFERROR((AQ11/AQ7),0) -> 0 | AR16: =IFERROR((AR11/AR7),0) -> 0 | ... AW16: =IFERROR((AW11/AW7),0) -> 3.1201712e-05 | AY16: Transport Charges (%) | AZ16: =IFERROR((AZ11/AZ7),0) -> 0 | BA16: =IFERROR((BA11/BA7),0) -> 0 | BB16: =IFERROR((BB11/BB7),0) -> 0 | BC16: =IFERROR((BC11/BC7),0) -> 0 | BD16: =IFERROR((BD11/BD7),0) -> 0 | BE16: =IFERROR((BE11/BE7),0) -> 0 | BF16: =IFERROR((BF11/BF7),0) -> 0 | BG16: =IFERROR((BG11/BG7),0) -> 0 | ... BL16: =IFERROR((BL11/BL7),0) -> 0 | BN16: =(AH16+AW16+BL16)-P16 -> 3.4161262e-05
C17: Revenue Per Kg | D17: =IFERROR(D7/(D6*1000),0) -> 61.084351 | E17: =IFERROR(E7/(E6*1000),0) -> 90.544856 | F17: =IFERROR(F7/(F6*1000),0) -> 73.316807 | G17: =IFERROR(G7/(G6*1000),0) -> 0 | H17: =IFERROR(H7/(H6*1000),0) -> 0 | I17: =IFERROR(I7/(I6*1000),0) -> 0 | J17: =IFERROR(J7/(J6*1000),0) -> 0 | K17: =IFERROR(K7/(K6*1000),0) -> 0 | ... O17: =IFERROR(O7/(O6*1000),0) -> 0 | P17: =P7/(P6*1000) -> 71.085886 | U17: Revenue Per Kg | V17: =IFERROR(V7/(V6*1000),0) -> 330.90626 | W17: =IFERROR(W7/(W6*1000),0) -> 342.48164 | X17: =IFERROR(X7/(X6*1000),0) -> 342.87241 | Y17: =IFERROR(Y7/(Y6*1000),0) -> 0 | Z17: =IFERROR(Z7/(Z6*1000),0) -> 0 | AA17: =IFERROR(AA7/(AA6*1000),0) -> 0 | AB17: =IFERROR(AB7/(AB6*1000),0) -> 0 | AC17: =IFERROR(AC7/(AC6*1000),0) -> 0 | ... AG17: =IFERROR(AG7/(AG6*1000),0) -> 0 | AH17: =AH7/(AH6*1000) -> 337.88919 | AJ17: Revenue Per Kg | AK17: =IFERROR(AK7/(AK6*1000),0) -> 32.009719 | AL17: =IFERROR(AL7/(AL6*1000),0) -> 29.905992 | AM17: =IFERROR(AM7/(AM6*1000),0) -> 34.396887 | AN17: =IFERROR(AN7/(AN6*1000),0) -> 0 | AO17: =IFERROR(AO7/(AO6*1000),0) -> 0 | AP17: =IFERROR(AP7/(AP6*1000),0) -> 0 | AQ17: =IFERROR(AQ7/(AQ6*1000),0) -> 0 | AR17: =IFERROR(AR7/(AR6*1000),0) -> 0 | ... AV17: =IFERROR(AV7/(AV6*1000),0) -> 0 | AW17: =AW7/(AW6*1000) -> 32.049523 | AY17: Revenue Per Kg | AZ17: =IFERROR(AZ7/(AZ6*1000),0) -> 0 | BA17: =IFERROR(BA7/(BA6*1000),0) -> 0 | BB17: =IFERROR(BB7/(BB6*1000),0) -> 0 | BC17: =IFERROR(BC7/(BC6*1000),0) -> 0 | BD17: =IFERROR(BD7/(BD6*1000),0) -> 0 | BE17: =IFERROR(BE7/(BE6*1000),0) -> 0 | BF17: =IFERROR(BF7/(BF6*1000),0) -> 0 | BG17: =IFERROR(BG7/(BG6*1000),0) -> 0 | ... BK17: =IFERROR(BK7/(BK6*1000),0) -> 0 | BL17: =BL7/(BL6*1000) -> #DIV/0!
C18: Purchase Cost Per Kg | D18: =IFERROR(D8/(D6*1000),0) -> 60.222095 | E18: =IFERROR(E8/(E6*1000),0) -> 87.993707 | F18: =IFERROR(F8/(F6*1000),0) -> 71.350323 | G18: =IFERROR(G8/(G6*1000),0) -> 0 | H18: =IFERROR(H8/(H6*1000),0) -> 0 | I18: =IFERROR(I8/(I6*1000),0) -> 0 | J18: =IFERROR(J8/(J6*1000),0) -> 0 | K18: =IFERROR(K8/(K6*1000),0) -> 0 | ... O18: =IFERROR(O8/(O6*1000),0) -> 0 | P18: =P8/(P6*1000) -> 69.56189 | U18: Purchase Cost Per Kg | V18: =IFERROR(V8/(V6*1000),0) -> 321.36269 | W18: =IFERROR(W8/(W6*1000),0) -> 332.90942 | X18: =IFERROR(X8/(X6*1000),0) -> 332.57478 | Y18: =IFERROR(Y8/(Y6*1000),0) -> 0 | Z18: =IFERROR(Z8/(Z6*1000),0) -> 0 | AA18: =IFERROR(AA8/(AA6*1000),0) -> 0 | AB18: =IFERROR(AB8/(AB6*1000),0) -> 0 | AC18: =IFERROR(AC8/(AC6*1000),0) -> 0 | ... AG18: =IFERROR(AG8/(AG6*1000),0) -> 0 | AH18: =AH8/(AH6*1000) -> 328.17235 | AJ18: Purchase Cost Per Kg | AK18: =IFERROR(AK8/(AK6*1000),0) -> 31.973159 | AL18: =IFERROR(AL8/(AL6*1000),0) -> 29.304401 | AM18: =IFERROR(AM8/(AM6*1000),0) -> 33.633295 | AN18: =IFERROR(AN8/(AN6*1000),0) -> 0 | AO18: =IFERROR(AO8/(AO6*1000),0) -> 0 | AP18: =IFERROR(AP8/(AP6*1000),0) -> 0 | AQ18: =IFERROR(AQ8/(AQ6*1000),0) -> 0 | AR18: =IFERROR(AR8/(AR6*1000),0) -> 0 | ... AV18: =IFERROR(AV8/(AV6*1000),0) -> 0 | AW18: =AW8/(AW6*1000) -> 31.723208 | AY18: Purchase Cost Per Kg | AZ18: =IFERROR(AZ8/(AZ6*1000),0) -> 0 | BA18: =IFERROR(BA8/(BA6*1000),0) -> 0 | BB18: =IFERROR(BB8/(BB6*1000),0) -> 0 | BC18: =IFERROR(BC8/(BC6*1000),0) -> 0 | BD18: =IFERROR(BD8/(BD6*1000),0) -> 0 | BE18: =IFERROR(BE8/(BE6*1000),0) -> 0 | BF18: =IFERROR(BF8/(BF6*1000),0) -> 0 | BG18: =IFERROR(BG8/(BG6*1000),0) -> 0 | ... BK18: =IFERROR(BK8/(BK6*1000),0) -> 0 | BL18: =BL8/(BL6*1000) -> #DIV/0!
C19: Transportation Charges Per Kg | D19: =IFERROR(D11/(D6*1000),0) -> 0 | E19: =IFERROR(E11/(E6*1000),0) -> 0 | F19: =IFERROR(F11/(F6*1000),0) -> 0 | G19: =IFERROR(G11/(G6*1000),0) -> 0 | H19: =IFERROR(H11/(H6*1000),0) -> 0 | I19: =IFERROR(I11/(I6*1000),0) -> 0 | J19: =IFERROR(J11/(J6*1000),0) -> 0 | K19: =IFERROR(K11/(K6*1000),0) -> 0 | ... O19: =IFERROR(O11/(O6*1000),0) -> 0 | P19: =P11/(P6*1000) -> 0 | U19: Transportation Charges Per Kg | V19: =IFERROR(V11/(V6*1000),0) -> 0.001 | W19: =IFERROR(W11/(W6*1000),0) -> 0.001 | X19: =IFERROR(X11/(X6*1000),0) -> 0.001 | Y19: =IFERROR(Y11/(Y6*1000),0) -> 0 | Z19: =IFERROR(Z11/(Z6*1000),0) -> 0 | AA19: =IFERROR(AA11/(AA6*1000),0) -> 0 | AB19: =IFERROR(AB11/(AB6*1000),0) -> 0 | AC19: =IFERROR(AC11/(AC6*1000),0) -> 0 | ... AG19: =IFERROR(AG11/(AG6*1000),0) -> 0 | AH19: =AH11/(AH6*1000) -> 0.001 | AJ19: Transportation Charges Per Kg | AK19: =IFERROR(AK11/(AK6*1000),0) -> 0.001 | AL19: =IFERROR(AL11/(AL6*1000),0) -> 0.001 | AM19: =IFERROR(AM11/(AM6*1000),0) -> 0.001 | AN19: =IFERROR(AN11/(AN6*1000),0) -> 0 | AO19: =IFERROR(AO11/(AO6*1000),0) -> 0 | AP19: =IFERROR(AP11/(AP6*1000),0) -> 0 | AQ19: =IFERROR(AQ11/(AQ6*1000),0) -> 0 | AR19: =IFERROR(AR11/(AR6*1000),0) -> 0 | ... AV19: =IFERROR(AV11/(AV6*1000),0) -> 0 | AW19: =AW11/(AW6*1000) -> 0.001 | AY19: Transportation Charges Per Kg | AZ19: =IFERROR(AZ11/(AZ6*1000),0) -> 0 | BA19: =IFERROR(BA11/(BA6*1000),0) -> 0 | BB19: =IFERROR(BB11/(BB6*1000),0) -> 0 | BC19: =IFERROR(BC11/(BC6*1000),0) -> 0 | BD19: =IFERROR(BD11/(BD6*1000),0) -> 0 | BE19: =IFERROR(BE11/(BE6*1000),0) -> 0 | BF19: =IFERROR(BF11/(BF6*1000),0) -> 0 | BG19: =IFERROR(BG11/(BG6*1000),0) -> 0 | ... BK19: =IFERROR(BK11/(BK6*1000),0) -> 0 | BL19: =BL11/(BL6*1000) -> #DIV/0!
C20: No. of Transactions | D20: {=IFERROR(ROWS(_xlfn.UNIQUE(_xlfn._xlws.FILTER(Details!$E$5:$E$53,(Details!$C$5:$C$53)=Summary!D$3))),0)} -> 22 | E20: {=IFERROR(ROWS(_xlfn.UNIQUE(_xlfn._xlws.FILTER(Details!$E$5:$E$53,(Details!$C$5:$C$53)=Summary!E$3))),0)} -> 16 | F20: {=IFERROR(ROWS(_xlfn.UNIQUE(_xlfn._xlws.FILTER(Details!$E$5:$E$53,(Details!$C$5:$C$53)=Summary!F$3))),0)} -> 9 | G20: {=IFERROR(ROWS(_xlfn.UNIQUE(_xlfn._xlws.FILTER(Details!$E$5:$E$53,(Details!$C$5:$C$53)=Summary!G$3))),0)} -> 0 | H20: {=IFERROR(ROWS(_xlfn.UNIQUE(_xlfn._xlws.FILTER(Details!$E$5:$E$53,(Details!$C$5:$C$53)=Summary!H$3))),0)} -> 0 | I20: {=IFERROR(ROWS(_xlfn.UNIQUE(_xlfn._xlws.FILTER(Details!$E$5:$E$53,(Details!$C$5:$C$53)=Summary!I$3))),0)} -> 0 | J20: {=IFERROR(ROWS(_xlfn.UNIQUE(_xlfn._xlws.FILTER(Details!$E$5:$E$53,(Details!$C$5:$C$53)=Summary!J$3))),0)} -> 0 | K20: {=IFERROR(ROWS(_xlfn.UNIQUE(_xlfn._xlws.FILTER(Details!$E$5:$E$53,(Details!$C$5:$C$53)=Summary!K$3))),0)} -> 0 | ... O20: {=IFERROR(ROWS(_xlfn.UNIQUE(_xlfn._xlws.FILTER(Details!$E$5:$E$53,(Details!$C$5:$C$53)=Summary!O$3))),0)} -> 0 | P20: =SUM(D20:O20) -> 47 | U20: No. of Transactions | V20: {=IFERROR(ROWS(_xlfn.UNIQUE(_xlfn._xlws.FILTER(Details!$E$5:$E$53,(Details!$C$5:$C$53=Summary!V$3)*(Details!$CK$5:$CK$53=$U$5)))),0)} -> 0 | W20: {=IFERROR(ROWS(_xlfn.UNIQUE(_xlfn._xlws.FILTER(Details!$E$5:$E$53,(Details!$C$5:$C$53=Summary!W$3)*(Details!$CK$5:$CK$53=$U$5)))),0)} -> 0 | X20: {=IFERROR(ROWS(_xlfn.UNIQUE(_xlfn._xlws.FILTER(Details!$E$5:$E$53,(Details!$C$5:$C$53=Summary!X$3)*(Details!$CK$5:$CK$53=$U$5)))),0)} -> 0 | Y20: {=IFERROR(ROWS(_xlfn.UNIQUE(_xlfn._xlws.FILTER(Details!$E$5:$E$53,(Details!$C$5:$C$53=Summary!Y$3)*(Details!$CK$5:$CK$53=$U$5)))),0)} -> 0 | Z20: {=IFERROR(ROWS(_xlfn.UNIQUE(_xlfn._xlws.FILTER(Details!$E$5:$E$53,(Details!$C$5:$C$53=Summary!Z$3)*(Details!$CK$5:$CK$53=$U$5)))),0)} -> 0 | AA20: {=IFERROR(ROWS(_xlfn.UNIQUE(_xlfn._xlws.FILTER(Details!$E$5:$E$53,(Details!$C$5:$C$53=Summary!AA$3)*(Details!$CK$5:$CK$53=$U$5)))),0)} -> 0 | AB20: {=IFERROR(ROWS(_xlfn.UNIQUE(_xlfn._xlws.FILTER(Details!$E$5:$E$53,(Details!$C$5:$C$53=Summary!AB$3)*(Details!$CK$5:$CK$53=$U$5)))),0)} -> 0 | AC20: {=IFERROR(ROWS(_xlfn.UNIQUE(_xlfn._xlws.FILTER(Details!$E$5:$E$53,(Details!$C$5:$C$53=Summary!AC$3)*(Details!$CK$5:$CK$53=$U$5)))),0)} -> 0 | ... AG20: {=IFERROR(ROWS(_xlfn.UNIQUE(_xlfn._xlws.FILTER(Details!$E$5:$E$53,(Details!$C$5:$C$53=Summary!AG$3)*(Details!$CK$5:$CK$53=$U$5)))),0)} -> 0 | AH20: =SUM(V20:AG20) -> 0 | AJ20: No. of Transactions | AK20: {=IFERROR(ROWS(_xlfn.UNIQUE(_xlfn._xlws.FILTER(Details!$E$5:$E$53,(Details!$C$5:$C$53=Summary!AK$3)*(Details!$CK$5:$CK$53=$AJ$5)))),0)} -> 0 | AL20: {=IFERROR(ROWS(_xlfn.UNIQUE(_xlfn._xlws.FILTER(Details!$E$5:$E$53,(Details!$C$5:$C$53=Summary!AL$3)*(Details!$CK$5:$CK$53=$AJ$5)))),0)} -> 0 | AM20: {=IFERROR(ROWS(_xlfn.UNIQUE(_xlfn._xlws.FILTER(Details!$E$5:$E$53,(Details!$C$5:$C$53=Summary!AM$3)*(Details!$CK$5:$CK$53=$AJ$5)))),0)} -> 0 | AN20: {=IFERROR(ROWS(_xlfn.UNIQUE(_xlfn._xlws.FILTER(Details!$E$5:$E$53,(Details!$C$5:$C$53=Summary!AN$3)*(Details!$CK$5:$CK$53=$AJ$5)))),0)} -> 0 | AO20: {=IFERROR(ROWS(_xlfn.UNIQUE(_xlfn._xlws.FILTER(Details!$E$5:$E$53,(Details!$C$5:$C$53=Summary!AO$3)*(Details!$CK$5:$CK$53=$AJ$5)))),0)} -> 0 | AP20: {=IFERROR(ROWS(_xlfn.UNIQUE(_xlfn._xlws.FILTER(Details!$E$5:$E$53,(Details!$C$5:$C$53=Summary!AP$3)*(Details!$CK$5:$CK$53=$AJ$5)))),0)} -> 0 | AQ20: {=IFERROR(ROWS(_xlfn.UNIQUE(_xlfn._xlws.FILTER(Details!$E$5:$E$53,(Details!$C$5:$C$53=Summary!AQ$3)*(Details!$CK$5:$CK$53=$AJ$5)))),0)} -> 0 | AR20: {=IFERROR(ROWS(_xlfn.UNIQUE(_xlfn._xlws.FILTER(Details!$E$5:$E$53,(Details!$C$5:$C$53=Summary!AR$3)*(Details!$CK$5:$CK$53=$AJ$5)))),0)} -> 0 | ... AV20: {=IFERROR(ROWS(_xlfn.UNIQUE(_xlfn._xlws.FILTER(Details!$E$5:$E$53,(Details!$C$5:$C$53=Summary!AV$3)*(Details!$CK$5:$CK$53=$AJ$5)))),0)} -> 0 | AW20: =SUM(AK20:AV20) -> 0 | AY20: No. of Transactions | AZ20: {=IFERROR(ROWS(_xlfn.UNIQUE(_xlfn._xlws.FILTER(Details!$E$5:$E$53,(Details!$C$5:$C$53=Summary!AZ$3)*(Details!$CK$5:$CK$53=$AY$5)))),0)} -> 0 | BA20: {=IFERROR(ROWS(_xlfn.UNIQUE(_xlfn._xlws.FILTER(Details!$E$5:$E$53,(Details!$C$5:$C$53=Summary!BA$3)*(Details!$CK$5:$CK$53=$AY$5)))),0)} -> 0 | BB20: {=IFERROR(ROWS(_xlfn.UNIQUE(_xlfn._xlws.FILTER(Details!$E$5:$E$53,(Details!$C$5:$C$53=Summary!BB$3)*(Details!$CK$5:$CK$53=$AY$5)))),0)} -> 0 | BC20: {=IFERROR(ROWS(_xlfn.UNIQUE(_xlfn._xlws.FILTER(Details!$E$5:$E$53,(Details!$C$5:$C$53=Summary!BC$3)*(Details!$CK$5:$CK$53=$AY$5)))),0)} -> 0 | BD20: {=IFERROR(ROWS(_xlfn.UNIQUE(_xlfn._xlws.FILTER(Details!$E$5:$E$53,(Details!$C$5:$C$53=Summary!BD$3)*(Details!$CK$5:$CK$53=$AY$5)))),0)} -> 0 | BE20: {=IFERROR(ROWS(_xlfn.UNIQUE(_xlfn._xlws.FILTER(Details!$E$5:$E$53,(Details!$C$5:$C$53=Summary!BE$3)*(Details!$CK$5:$CK$53=$AY$5)))),0)} -> 0 | BF20: {=IFERROR(ROWS(_xlfn.UNIQUE(_xlfn._xlws.FILTER(Details!$E$5:$E$53,(Details!$C$5:$C$53=Summary!BF$3)*(Details!$CK$5:$CK$53=$AY$5)))),0)} -> 0 | BG20: {=IFERROR(ROWS(_xlfn.UNIQUE(_xlfn._xlws.FILTER(Details!$E$5:$E$53,(Details!$C$5:$C$53=Summary!BG$3)*(Details!$CK$5:$CK$53=$AY$5)))),0)} -> 0 | ... BK20: {=IFERROR(ROWS(_xlfn.UNIQUE(_xlfn._xlws.FILTER(Details!$E$5:$E$53,(Details!$C$5:$C$53=Summary!BK$3)*(Details!$CK$5:$CK$53=$AY$5)))),0)} -> 0 | BL20: =SUM(AZ20:BK20) -> 0 | BN20: =(AH20+AW20+BL20)-P20 -> -47
C21: No. of Sellers (Aggregators) | D21: {=IFERROR(ROWS(_xlfn.UNIQUE(_xlfn._xlws.FILTER(Details!$F$5:$F$53,(Details!$C$5:$C$53)=Summary!D$3))),0)} -> 5 | E21: {=IFERROR(ROWS(_xlfn.UNIQUE(_xlfn._xlws.FILTER(Details!$F$5:$F$53,(Details!$C$5:$C$53)=Summary!E$3))),0)} -> 3 | F21: {=IFERROR(ROWS(_xlfn.UNIQUE(_xlfn._xlws.FILTER(Details!$F$5:$F$53,(Details!$C$5:$C$53)=Summary!F$3))),0)} -> 4 | G21: {=IFERROR(ROWS(_xlfn.UNIQUE(_xlfn._xlws.FILTER(Details!$F$5:$F$53,(Details!$C$5:$C$53)=Summary!G$3))),0)} -> 0 | H21: {=IFERROR(ROWS(_xlfn.UNIQUE(_xlfn._xlws.FILTER(Details!$F$5:$F$53,(Details!$C$5:$C$53)=Summary!H$3))),0)} -> 0 | I21: {=IFERROR(ROWS(_xlfn.UNIQUE(_xlfn._xlws.FILTER(Details!$F$5:$F$53,(Details!$C$5:$C$53)=Summary!I$3))),0)} -> 0 | J21: {=IFERROR(ROWS(_xlfn.UNIQUE(_xlfn._xlws.FILTER(Details!$F$5:$F$53,(Details!$C$5:$C$53)=Summary!J$3))),0)} -> 0 | K21: {=IFERROR(ROWS(_xlfn.UNIQUE(_xlfn._xlws.FILTER(Details!$F$5:$F$53,(Details!$C$5:$C$53)=Summary!K$3))),0)} -> 0 | ... O21: {=IFERROR(ROWS(_xlfn.UNIQUE(_xlfn._xlws.FILTER(Details!$F$5:$F$53,(Details!$C$5:$C$53)=Summary!O$3))),0)} -> 0 | P21: ='Supplier Metrics'!J2 -> 8 | U21: No. of Sellers (Aggregators) | V21: {=IFERROR(ROWS(_xlfn.UNIQUE(_xlfn._xlws.FILTER(Details!$F$5:$F$53,(Details!$C$5:$C$53=Summary!V$3)*(Details!$CK$5:$CK$53=$U$5)))),0)} -> 0 | W21: {=IFERROR(ROWS(_xlfn.UNIQUE(_xlfn._xlws.FILTER(Details!$F$5:$F$53,(Details!$C$5:$C$53=Summary!W$3)*(Details!$CK$5:$CK$53=$U$5)))),0)} -> 0 | X21: {=IFERROR(ROWS(_xlfn.UNIQUE(_xlfn._xlws.FILTER(Details!$F$5:$F$53,(Details!$C$5:$C$53=Summary!X$3)*(Details!$CK$5:$CK$53=$U$5)))),0)} -> 0 | Y21: {=IFERROR(ROWS(_xlfn.UNIQUE(_xlfn._xlws.FILTER(Details!$F$5:$F$53,(Details!$C$5:$C$53=Summary!Y$3)*(Details!$CK$5:$CK$53=$U$5)))),0)} -> 0 | Z21: {=IFERROR(ROWS(_xlfn.UNIQUE(_xlfn._xlws.FILTER(Details!$F$5:$F$53,(Details!$C$5:$C$53=Summary!Z$3)*(Details!$CK$5:$CK$53=$U$5)))),0)} -> 0 | AA21: {=IFERROR(ROWS(_xlfn.UNIQUE(_xlfn._xlws.FILTER(Details!$F$5:$F$53,(Details!$C$5:$C$53=Summary!AA$3)*(Details!$CK$5:$CK$53=$U$5)))),0)} -> 0 | AB21: {=IFERROR(ROWS(_xlfn.UNIQUE(_xlfn._xlws.FILTER(Details!$F$5:$F$53,(Details!$C$5:$C$53=Summary!AB$3)*(Details!$CK$5:$CK$53=$U$5)))),0)} -> 0 | AC21: {=IFERROR(ROWS(_xlfn.UNIQUE(_xlfn._xlws.FILTER(Details!$F$5:$F$53,(Details!$C$5:$C$53=Summary!AC$3)*(Details!$CK$5:$CK$53=$U$5)))),0)} -> 0 | ... AG21: {=IFERROR(ROWS(_xlfn.UNIQUE(_xlfn._xlws.FILTER(Details!$F$5:$F$53,(Details!$C$5:$C$53=Summary!AG$3)*(Details!$CK$5:$CK$53=$U$5)))),0)} -> 0 | AH21: =COUNTIF('Supplier Metrics'!I:I,Summary!U5) -> 1 | AJ21: No. of Sellers (Aggregators) | AK21: {=IFERROR(ROWS(_xlfn.UNIQUE(_xlfn._xlws.FILTER(Details!$F$5:$F$53,(Details!$C$5:$C$53=Summary!AK$3)*(Details!$CK$5:$CK$53=$AJ$5)))),0)} -> 0 | AL21: {=IFERROR(ROWS(_xlfn.UNIQUE(_xlfn._xlws.FILTER(Details!$F$5:$F$53,(Details!$C$5:$C$53=Summary!AL$3)*(Details!$CK$5:$CK$53=$AJ$5)))),0)} -> 0 | AM21: {=IFERROR(ROWS(_xlfn.UNIQUE(_xlfn._xlws.FILTER(Details!$F$5:$F$53,(Details!$C$5:$C$53=Summary!AM$3)*(Details!$CK$5:$CK$53=$AJ$5)))),0)} -> 0 | AN21: {=IFERROR(ROWS(_xlfn.UNIQUE(_xlfn._xlws.FILTER(Details!$F$5:$F$53,(Details!$C$5:$C$53=Summary!AN$3)*(Details!$CK$5:$CK$53=$AJ$5)))),0)} -> 0 | AO21: {=IFERROR(ROWS(_xlfn.UNIQUE(_xlfn._xlws.FILTER(Details!$F$5:$F$53,(Details!$C$5:$C$53=Summary!AO$3)*(Details!$CK$5:$CK$53=$AJ$5)))),0)} -> 0 | AP21: {=IFERROR(ROWS(_xlfn.UNIQUE(_xlfn._xlws.FILTER(Details!$F$5:$F$53,(Details!$C$5:$C$53=Summary!AP$3)*(Details!$CK$5:$CK$53=$AJ$5)))),0)} -> 0 | AQ21: {=IFERROR(ROWS(_xlfn.UNIQUE(_xlfn._xlws.FILTER(Details!$F$5:$F$53,(Details!$C$5:$C$53=Summary!AQ$3)*(Details!$CK$5:$CK$53=$AJ$5)))),0)} -> 0 | AR21: {=IFERROR(ROWS(_xlfn.UNIQUE(_xlfn._xlws.FILTER(Details!$F$5:$F$53,(Details!$C$5:$C$53=Summary!AR$3)*(Details!$CK$5:$CK$53=$AJ$5)))),0)} -> 0 | ... AV21: {=IFERROR(ROWS(_xlfn.UNIQUE(_xlfn._xlws.FILTER(Details!$F$5:$F$53,(Details!$C$5:$C$53=Summary!AV$3)*(Details!$CK$5:$CK$53=$AJ$5)))),0)} -> 0 | AW21: =COUNTIF('Supplier Metrics'!I:I,Summary!AJ5) -> 7 | AY21: No. of Sellers (Aggregators) | AZ21: {=IFERROR(ROWS(_xlfn.UNIQUE(_xlfn._xlws.FILTER(Details!$F$5:$F$53,(Details!$C$5:$C$53=Summary!AZ$3)*(Details!$CK$5:$CK$53=$AY$5)))),0)} -> 0 | BA21: {=IFERROR(ROWS(_xlfn.UNIQUE(_xlfn._xlws.FILTER(Details!$F$5:$F$53,(Details!$C$5:$C$53=Summary!BA$3)*(Details!$CK$5:$CK$53=$AY$5)))),0)} -> 0 | BB21: {=IFERROR(ROWS(_xlfn.UNIQUE(_xlfn._xlws.FILTER(Details!$F$5:$F$53,(Details!$C$5:$C$53=Summary!BB$3)*(Details!$CK$5:$CK$53=$AY$5)))),0)} -> 0 | BC21: {=IFERROR(ROWS(_xlfn.UNIQUE(_xlfn._xlws.FILTER(Details!$F$5:$F$53,(Details!$C$5:$C$53=Summary!BC$3)*(Details!$CK$5:$CK$53=$AY$5)))),0)} -> 0 | BD21: {=IFERROR(ROWS(_xlfn.UNIQUE(_xlfn._xlws.FILTER(Details!$F$5:$F$53,(Details!$C$5:$C$53=Summary!BD$3)*(Details!$CK$5:$CK$53=$AY$5)))),0)} -> 0 | BE21: {=IFERROR(ROWS(_xlfn.UNIQUE(_xlfn._xlws.FILTER(Details!$F$5:$F$53,(Details!$C$5:$C$53=Summary!BE$3)*(Details!$CK$5:$CK$53=$AY$5)))),0)} -> 0 | BF21: {=IFERROR(ROWS(_xlfn.UNIQUE(_xlfn._xlws.FILTER(Details!$F$5:$F$53,(Details!$C$5:$C$53=Summary!BF$3)*(Details!$CK$5:$CK$53=$AY$5)))),0)} -> 0 | BG21: {=IFERROR(ROWS(_xlfn.UNIQUE(_xlfn._xlws.FILTER(Details!$F$5:$F$53,(Details!$C$5:$C$53=Summary!BG$3)*(Details!$CK$5:$CK$53=$AY$5)))),0)} -> 0 | ... BK21: {=IFERROR(ROWS(_xlfn.UNIQUE(_xlfn._xlws.FILTER(Details!$F$5:$F$53,(Details!$C$5:$C$53=Summary!BK$3)*(Details!$CK$5:$CK$53=$AY$5)))),0)} -> 0 | BL21: =COUNTIF('Supplier Metrics'!I:I,Summary!AY5) -> 0 | BN21: =(AH21+AW21+BL21)-P21 -> 0
C22: No. of Buyers (Recyclers) | D22: {=IFERROR(ROWS(_xlfn.UNIQUE(_xlfn._xlws.FILTER(Details!$AQ$5:$AQ$53,(Details!$C$5:$C$53)=Summary!D$3))),0)} -> 4 | E22: {=IFERROR(ROWS(_xlfn.UNIQUE(_xlfn._xlws.FILTER(Details!$AQ$5:$AQ$53,(Details!$C$5:$C$53)=Summary!E$3))),0)} -> 4 | F22: {=IFERROR(ROWS(_xlfn.UNIQUE(_xlfn._xlws.FILTER(Details!$AQ$5:$AQ$53,(Details!$C$5:$C$53)=Summary!F$3))),0)} -> 6 | G22: {=IFERROR(ROWS(_xlfn.UNIQUE(_xlfn._xlws.FILTER(Details!$AQ$5:$AQ$53,(Details!$C$5:$C$53)=Summary!G$3))),0)} -> 0 | H22: {=IFERROR(ROWS(_xlfn.UNIQUE(_xlfn._xlws.FILTER(Details!$AQ$5:$AQ$53,(Details!$C$5:$C$53)=Summary!H$3))),0)} -> 0 | I22: {=IFERROR(ROWS(_xlfn.UNIQUE(_xlfn._xlws.FILTER(Details!$AQ$5:$AQ$53,(Details!$C$5:$C$53)=Summary!I$3))),0)} -> 0 | J22: {=IFERROR(ROWS(_xlfn.UNIQUE(_xlfn._xlws.FILTER(Details!$AQ$5:$AQ$53,(Details!$C$5:$C$53)=Summary!J$3))),0)} -> 0 | K22: {=IFERROR(ROWS(_xlfn.UNIQUE(_xlfn._xlws.FILTER(Details!$AQ$5:$AQ$53,(Details!$C$5:$C$53)=Summary!K$3))),0)} -> 0 | ... O22: {=IFERROR(ROWS(_xlfn.UNIQUE(_xlfn._xlws.FILTER(Details!$AQ$5:$AQ$53,(Details!$C$5:$C$53)=Summary!O$3))),0)} -> 0 | P22: ='Buyer Metrics'!C3 -> 8 | U22: No. of Buyers (Recyclers) | V22: {=IFERROR(ROWS(_xlfn.UNIQUE(_xlfn._xlws.FILTER(Details!$AQ$5:$AQ$53,(Details!$C$5:$C$53=Summary!V$3)*(Details!$CK$5:$CK$53=$U$5)))),0)} -> 0 | W22: {=IFERROR(ROWS(_xlfn.UNIQUE(_xlfn._xlws.FILTER(Details!$AQ$5:$AQ$53,(Details!$C$5:$C$53=Summary!W$3)*(Details!$CK$5:$CK$53=$U$5)))),0)} -> 0 | X22: {=IFERROR(ROWS(_xlfn.UNIQUE(_xlfn._xlws.FILTER(Details!$AQ$5:$AQ$53,(Details!$C$5:$C$53=Summary!X$3)*(Details!$CK$5:$CK$53=$U$5)))),0)} -> 0 | Y22: {=IFERROR(ROWS(_xlfn.UNIQUE(_xlfn._xlws.FILTER(Details!$AQ$5:$AQ$53,(Details!$C$5:$C$53=Summary!Y$3)*(Details!$CK$5:$CK$53=$U$5)))),0)} -> 0 | Z22: {=IFERROR(ROWS(_xlfn.UNIQUE(_xlfn._xlws.FILTER(Details!$AQ$5:$AQ$53,(Details!$C$5:$C$53=Summary!Z$3)*(Details!$CK$5:$CK$53=$U$5)))),0)} -> 0 | AA22: {=IFERROR(ROWS(_xlfn.UNIQUE(_xlfn._xlws.FILTER(Details!$AQ$5:$AQ$53,(Details!$C$5:$C$53=Summary!AA$3)*(Details!$CK$5:$CK$53=$U$5)))),0)} -> 0 | AB22: {=IFERROR(ROWS(_xlfn.UNIQUE(_xlfn._xlws.FILTER(Details!$AQ$5:$AQ$53,(Details!$C$5:$C$53=Summary!AB$3)*(Details!$CK$5:$CK$53=$U$5)))),0)} -> 0 | AC22: {=IFERROR(ROWS(_xlfn.UNIQUE(_xlfn._xlws.FILTER(Details!$AQ$5:$AQ$53,(Details!$C$5:$C$53=Summary!AC$3)*(Details!$CK$5:$CK$53=$U$5)))),0)} -> 0 | ... AG22: {=IFERROR(ROWS(_xlfn.UNIQUE(_xlfn._xlws.FILTER(Details!$AQ$5:$AQ$53,(Details!$C$5:$C$53=Summary!AG$3)*(Details!$CK$5:$CK$53=$U$5)))),0)} -> 0 | AH22: =COUNTIFS('Buyer Metrics'!F:F,Summary!U5) -> 2 | AJ22: No. of Buyers (Recyclers) | AK22: {=IFERROR(ROWS(_xlfn.UNIQUE(_xlfn._xlws.FILTER(Details!$AQ$5:$AQ$53,(Details!$C$5:$C$53=Summary!AK$3)*(Details!$CK$5:$CK$53=$AJ$5)))),0)} -> 0 | AL22: {=IFERROR(ROWS(_xlfn.UNIQUE(_xlfn._xlws.FILTER(Details!$AQ$5:$AQ$53,(Details!$C$5:$C$53=Summary!AL$3)*(Details!$CK$5:$CK$53=$AJ$5)))),0)} -> 0 | AM22: {=IFERROR(ROWS(_xlfn.UNIQUE(_xlfn._xlws.FILTER(Details!$AQ$5:$AQ$53,(Details!$C$5:$C$53=Summary!AM$3)*(Details!$CK$5:$CK$53=$AJ$5)))),0)} -> 0 | AN22: {=IFERROR(ROWS(_xlfn.UNIQUE(_xlfn._xlws.FILTER(Details!$AQ$5:$AQ$53,(Details!$C$5:$C$53=Summary!AN$3)*(Details!$CK$5:$CK$53=$AJ$5)))),0)} -> 0 | AO22: {=IFERROR(ROWS(_xlfn.UNIQUE(_xlfn._xlws.FILTER(Details!$AQ$5:$AQ$53,(Details!$C$5:$C$53=Summary!AO$3)*(Details!$CK$5:$CK$53=$AJ$5)))),0)} -> 0 | AP22: {=IFERROR(ROWS(_xlfn.UNIQUE(_xlfn._xlws.FILTER(Details!$AQ$5:$AQ$53,(Details!$C$5:$C$53=Summary!AP$3)*(Details!$CK$5:$CK$53=$AJ$5)))),0)} -> 0 | AQ22: {=IFERROR(ROWS(_xlfn.UNIQUE(_xlfn._xlws.FILTER(Details!$AQ$5:$AQ$53,(Details!$C$5:$C$53=Summary!AQ$3)*(Details!$CK$5:$CK$53=$AJ$5)))),0)} -> 0 | AR22: {=IFERROR(ROWS(_xlfn.UNIQUE(_xlfn._xlws.FILTER(Details!$AQ$5:$AQ$53,(Details!$C$5:$C$53=Summary!AR$3)*(Details!$CK$5:$CK$53=$AJ$5)))),0)} -> 0 | ... AV22: {=IFERROR(ROWS(_xlfn.UNIQUE(_xlfn._xlws.FILTER(Details!$AQ$5:$AQ$53,(Details!$C$5:$C$53=Summary!AV$3)*(Details!$CK$5:$CK$53=$AJ$5)))),0)} -> 0 | AW22: =COUNTIFS('Buyer Metrics'!F:F,Summary!AJ5) -> 6 | AY22: No. of Buyers (Recyclers) | AZ22: {=IFERROR(ROWS(_xlfn.UNIQUE(_xlfn._xlws.FILTER(Details!$AQ$5:$AQ$53,(Details!$C$5:$C$53=Summary!AZ$3)*(Details!$CK$5:$CK$53=$AY$5)))),0)} -> 0 | BA22: {=IFERROR(ROWS(_xlfn.UNIQUE(_xlfn._xlws.FILTER(Details!$AQ$5:$AQ$53,(Details!$C$5:$C$53=Summary!BA$3)*(Details!$CK$5:$CK$53=$AY$5)))),0)} -> 0 | BB22: {=IFERROR(ROWS(_xlfn.UNIQUE(_xlfn._xlws.FILTER(Details!$AQ$5:$AQ$53,(Details!$C$5:$C$53=Summary!BB$3)*(Details!$CK$5:$CK$53=$AY$5)))),0)} -> 0 | BC22: {=IFERROR(ROWS(_xlfn.UNIQUE(_xlfn._xlws.FILTER(Details!$AQ$5:$AQ$53,(Details!$C$5:$C$53=Summary!BC$3)*(Details!$CK$5:$CK$53=$AY$5)))),0)} -> 0 | BD22: {=IFERROR(ROWS(_xlfn.UNIQUE(_xlfn._xlws.FILTER(Details!$AQ$5:$AQ$53,(Details!$C$5:$C$53=Summary!BD$3)*(Details!$CK$5:$CK$53=$AY$5)))),0)} -> 0 | BE22: {=IFERROR(ROWS(_xlfn.UNIQUE(_xlfn._xlws.FILTER(Details!$AQ$5:$AQ$53,(Details!$C$5:$C$53=Summary!BE$3)*(Details!$CK$5:$CK$53=$AY$5)))),0)} -> 0 | BF22: {=IFERROR(ROWS(_xlfn.UNIQUE(_xlfn._xlws.FILTER(Details!$AQ$5:$AQ$53,(Details!$C$5:$C$53=Summary!BF$3)*(Details!$CK$5:$CK$53=$AY$5)))),0)} -> 0 | BG22: {=IFERROR(ROWS(_xlfn.UNIQUE(_xlfn._xlws.FILTER(Details!$AQ$5:$AQ$53,(Details!$C$5:$C$53=Summary!BG$3)*(Details!$CK$5:$CK$53=$AY$5)))),0)} -> 0 | ... BK22: {=IFERROR(ROWS(_xlfn.UNIQUE(_xlfn._xlws.FILTER(Details!$AQ$5:$AQ$53,(Details!$C$5:$C$53=Summary!BK$3)*(Details!$CK$5:$CK$53=$AY$5)))),0)} -> 0 | BL22: =COUNTIFS('Buyer Metrics'!F:F,Summary!AY5) -> 0 | BN22: =(AH22+AW22+BL22)-P22 -> 0
