Workbook

Sheet Summary
D2: =TEXT(D4, "mmm-yy") -> Apr-26 | E2: =TEXT(E4, "mmm-yy") -> May-26 | F2: =TEXT(F4, "mmm-yy") -> Jun-26 | G2: =TEXT(G4, "mmm-yy") -> Jul-26 | H2: =TEXT(H4, "mmm-yy") -> Aug-26 | I2: =TEXT(I4, "mmm-yy") -> Sep-26 | J2: =TEXT(J4, "mmm-yy") -> Oct-26 | K2: =TEXT(K4, "mmm-yy") -> Nov-26 | ... O2: =TEXT(O4, "mmm-yy") -> Mar-27
D3: 30 | E3: 31 | F3: 21 | G3: 0 | H3: 0 | I3: 0 | J3: 0 | K3: 0 | L3: 0 | M3: 0 | N3: 0 | O3: 0 | P3: =SUM(D3:O3) -> 82
C4: Marketplace (Rewerse) | D4: 46113 | E4: 46143 | F4: 46174 | G4: 46204 | H4: 46235 | I4: 46266 | J4: 46296 | K4: 46327 | L4: 46357 | M4: 46388 | N4: 46419 | O4: 46447 | P4: FY 2026-27
C5: Quantity (MT) | D5: 66.68 | E5: =SUMIFS(Details!$BB$4:$BB$78,Details!$C$4:$C$78,Summary!E$4)/1000 -> 104.875 | F5: =SUMIFS(Details!$BB$4:$BB$78,Details!$C$4:$C$78,Summary!F$4)/1000 -> 78.795 | G5: =SUMIFS(Details!$BB$4:$BB$78,Details!$C$4:$C$78,Summary!G$4)/1000 -> 0 | H5: =SUMIFS(Details!$BB$4:$BB$78,Details!$C$4:$C$78,Summary!H$4)/1000 -> 0 | I5: =SUMIFS(Details!$BB$4:$BB$78,Details!$C$4:$C$78,Summary!I$4)/1000 -> 0 | J5: =SUMIFS(Details!$BB$4:$BB$78,Details!$C$4:$C$78,Summary!J$4)/1000 -> 0 | K5: =SUMIFS(Details!$BB$4:$BB$78,Details!$C$4:$C$78,Summary!K$4)/1000 -> 0 | L5: =SUMIFS(Details!$BB$4:$BB$78,Details!$C$4:$C$78,Summary!L$4)/1000 -> 0 | ... O5: =SUMIFS(Details!$BB$4:$BB$78,Details!$C$4:$C$78,Summary!O$4)/1000 -> 0 | P5: =SUM(D5:O5) -> 250.35 | Q5: =Details!BB79/1000 -> 250.35 | R5: =P5-Q5 -> 0
C6: Net Revenue | D6: 3196586.2 | E6: =SUMIFS(Details!$BO$4:$BO$78,Details!$C$4:$C$78,Summary!E$4) -> 5917999.6 | F6: =SUMIFS(Details!$BO$4:$BO$78,Details!$C$4:$C$78,Summary!F$4) -> 5820545.2 | G6: =SUMIFS(Details!$BO$4:$BO$78,Details!$C$4:$C$78,Summary!G$4) -> 0 | H6: =SUMIFS(Details!$BO$4:$BO$78,Details!$C$4:$C$78,Summary!H$4) -> 0 | I6: =SUMIFS(Details!$BO$4:$BO$78,Details!$C$4:$C$78,Summary!I$4) -> 0 | J6: =SUMIFS(Details!$BO$4:$BO$78,Details!$C$4:$C$78,Summary!J$4) -> 0 | K6: =SUMIFS(Details!$BO$4:$BO$78,Details!$C$4:$C$78,Summary!K$4) -> 0 | L6: =SUMIFS(Details!$BO$4:$BO$78,Details!$C$4:$C$78,Summary!L$4) -> 0 | ... O6: =SUMIFS(Details!$BO$4:$BO$78,Details!$C$4:$C$78,Summary!O$4) -> 0 | P6: =SUM(D6:O6) -> 14935131 | Q6: =Details!BO79 -> 14964433 | R6: =P6-Q6 -> -29302.12
C7: Purchases | D7: 2734490 | E7: =SUMIFS(Details!$AM$4:$AM$78,Details!$C$4:$C$78,Summary!E$4)-SUMIFS(Details!$AB$4:$AB$78,Details!$C$4:$C$78,Summary!E$4) -> 4656790 | F7: =SUMIFS(Details!$AM$4:$AM$78,Details!$C$4:$C$78,Summary!F$4)-SUMIFS(Details!$AB$4:$AB$78,Details!$C$4:$C$78,Summary!F$4) -> 4432995 | G7: =SUMIFS(Details!$AM$4:$AM$78,Details!$C$4:$C$78,Summary!G$4)-SUMIFS(Details!$AB$4:$AB$78,Details!$C$4:$C$78,Summary!G$4) -> 0 | H7: =SUMIFS(Details!$AM$4:$AM$78,Details!$C$4:$C$78,Summary!H$4)-SUMIFS(Details!$AB$4:$AB$78,Details!$C$4:$C$78,Summary!H$4) -> 0 | I7: =SUMIFS(Details!$AM$4:$AM$78,Details!$C$4:$C$78,Summary!I$4)-SUMIFS(Details!$AB$4:$AB$78,Details!$C$4:$C$78,Summary!I$4) -> 0 | J7: =SUMIFS(Details!$AM$4:$AM$78,Details!$C$4:$C$78,Summary!J$4)-SUMIFS(Details!$AB$4:$AB$78,Details!$C$4:$C$78,Summary!J$4) -> 0 | K7: =SUMIFS(Details!$AM$4:$AM$78,Details!$C$4:$C$78,Summary!K$4)-SUMIFS(Details!$AB$4:$AB$78,Details!$C$4:$C$78,Summary!K$4) -> 0 | L7: =SUMIFS(Details!$AM$4:$AM$78,Details!$C$4:$C$78,Summary!L$4)-SUMIFS(Details!$AB$4:$AB$78,Details!$C$4:$C$78,Summary!L$4) -> 0 | ... O7: =SUMIFS(Details!$AM$4:$AM$78,Details!$C$4:$C$78,Summary!O$4)-SUMIFS(Details!$AB$4:$AB$78,Details!$C$4:$C$78,Summary!O$4) -> 0 | P7: =SUM(D7:O7) -> 11824275 | Q7: =Details!P80 -> 11824275 | R7: =P7-Q7 -> 0
C8: Gross Margin | D8: =D6-D7 -> 462096.25 | E8: =E6-E7 -> 1261209.6 | F8: =F6-F7 -> 1387550.2 | G8: =G6-G7 -> 0 | H8: =H6-H7 -> 0 | I8: =I6-I7 -> 0 | J8: =J6-J7 -> 0 | K8: =K6-K7 -> 0 | ... O8: =O6-O7 -> 0 | P8: =SUM(D8:O8) -> 3110856.1
C9: Gross Margin (%) | D9: =IFERROR((D8/D6),0) -> 0.14455929 | E9: =IFERROR((E8/E6),0) -> 0.21311417 | F9: =IFERROR((F8/F6),0) -> 0.23838836 | G9: =IFERROR((G8/G6),0) -> 0 | H9: =IFERROR((H8/H6),0) -> 0 | I9: =IFERROR((I8/I6),0) -> 0 | J9: =IFERROR((J8/J6),0) -> 0 | K9: =IFERROR((K8/K6),0) -> 0 | ... P9: =IFERROR((P8/P6),0) -> 0.20829118
C10: Transportation Charges | D10: =SUMIFS(Details!$AB$4:$AB$78,Details!$C$4:$C$78,Summary!D$4) -> 0 | E10: =SUMIFS(Details!$AB$4:$AB$78,Details!$C$4:$C$78,Summary!E$4) -> 0 | F10: =SUMIFS(Details!$AB$4:$AB$78,Details!$C$4:$C$78,Summary!F$4) -> 0 | G10: =SUMIFS(Details!$AB$4:$AB$78,Details!$C$4:$C$78,Summary!G$4) -> 0 | H10: =SUMIFS(Details!$AB$4:$AB$78,Details!$C$4:$C$78,Summary!H$4) -> 0 | I10: =SUMIFS(Details!$AB$4:$AB$78,Details!$C$4:$C$78,Summary!I$4) -> 0 | J10: =SUMIFS(Details!$AB$4:$AB$78,Details!$C$4:$C$78,Summary!J$4) -> 0 | K10: =SUMIFS(Details!$AB$4:$AB$78,Details!$C$4:$C$78,Summary!K$4) -> 0 | ... O10: =SUMIFS(Details!$AB$4:$AB$78,Details!$C$4:$C$78,Summary!O$4) -> 0 | P10: =SUM(D10:O10) -> 0 | Q10: =Details!AB79 -> 0 | R10: =P10-Q10 -> 0
C11: Operational Cost | D11: =Details!AC83 -> 857135.62 | E11: =Details!AC84 -> 1348111.9 | F11: =Details!AC85 -> 1112867.4 | G11: =SUMIFS(Details!$AC$4:$AC$86,Details!$C$4:$C$86,Summary!G$4) -> 0 | H11: =SUMIFS(Details!$AC$4:$AC$86,Details!$C$4:$C$86,Summary!H$4) -> 0 | I11: =SUMIFS(Details!$AC$4:$AC$86,Details!$C$4:$C$86,Summary!I$4) -> 0 | J11: =SUMIFS(Details!$AC$4:$AC$86,Details!$C$4:$C$86,Summary!J$4) -> 0 | K11: =SUMIFS(Details!$AC$4:$AC$86,Details!$C$4:$C$86,Summary!K$4) -> 0 | L11: =SUMIFS(Details!$AC$4:$AC$86,Details!$C$4:$C$86,Summary!L$4) -> 0 | M11: =SUMIFS(Details!$AC$4:$AC$86,Details!$C$4:$C$86,Summary!M$4) -> 0 | N11: =SUMIFS(Details!$AC$4:$AC$86,Details!$C$4:$C$86,Summary!N$4) -> 0 | O11: =SUMIFS(Details!$AC$4:$AC$86,Details!$C$4:$C$86,Summary!O$4) -> 0 | P11: =SUM(D11:O11) -> 3318114.9
C12: Net Margin | D12: =D6-D7-D10-D11 -> -395039.37 | E12: =E6-E7-E10-E11 -> -86902.286 | F12: =F6-F7-F10-F11 -> 274682.81 | G12: =G6-G7-G10-G11 -> 0 | H12: =H6-H7-H10-H11 -> 0 | I12: =I6-I7-I10-I11 -> 0 | J12: =J6-J7-J10-J11 -> 0 | K12: =K6-K7-K10-K11 -> 0 | ... O12: =O6-O7-O10-O11 -> 0 | P12: =SUM(D12:O12) -> -207258.85
C13: Net Margin (%) | D13: =IFERROR((D12/D6),0) -> -0.12358164 | E13: =IFERROR((E12/E6),0) -> -0.014684402 | F13: =IFERROR((F12/F6),0) -> 0.047191937 | G13: =IFERROR((G12/G6),0) -> 0 | H13: =IFERROR((H12/H6),0) -> 0 | I13: =IFERROR((I12/I6),0) -> 0 | J13: =IFERROR((J12/J6),0) -> 0 | K13: =IFERROR((K12/K6),0) -> 0 | ... P13: =IFERROR((P12/P6),0) -> -0.01387727
C14: Other Income | D14: =SUMIFS(Details!$BO$83:$BO$86,Details!$C$83:$C$86,Summary!D$4) -> 0 | E14: =SUMIFS(Details!$BO$83:$BO$86,Details!$C$83:$C$86,Summary!E$4) -> 0 | F14: =SUMIFS(Details!$BO$83:$BO$86,Details!$C$83:$C$86,Summary!F$4) -> 0 | G14: =SUMIFS(Details!$BO$83:$BO$86,Details!$C$83:$C$86,Summary!G$4) -> 0 | H14: =SUMIFS(Details!$BO$83:$BO$86,Details!$C$83:$C$86,Summary!H$4) -> 0 | I14: =SUMIFS(Details!$BO$83:$BO$86,Details!$C$83:$C$86,Summary!I$4) -> 0 | J14: =SUMIFS(Details!$BO$83:$BO$86,Details!$C$83:$C$86,Summary!J$4) -> 0 | K14: =SUMIFS(Details!$BO$83:$BO$86,Details!$C$83:$C$86,Summary!K$4) -> 0 | ... O14: =SUMIFS(Details!$BO$83:$BO$86,Details!$C$83:$C$86,Summary!O$4) -> 0 | P14: =SUM(D14:O14) -> 0
C15: Transport Charges (%) | D15: =IFERROR((D10/D6),0) -> 0 | E15: =IFERROR((E10/E6),0) -> 0 | F15: =IFERROR((F10/F6),0) -> 0 | G15: =IFERROR((G10/G6),0) -> 0 | H15: =IFERROR((H10/H6),0) -> 0 | I15: =IFERROR((I10/I6),0) -> 0 | J15: =IFERROR((J10/J6),0) -> 0 | K15: =IFERROR((K10/K6),0) -> 0 | ... P15: =IFERROR((P10/P6),0) -> 0
C16: Revenue Per Kg | D16: =+D6/(D5*1000) -> 47.939206 | E16: =+E6/(E5*1000) -> 56.429078 | F16: =+F6/(F5*1000) -> 73.869475 | G16: =+G6/(G5*1000) -> #DIV/0! | H16: =+H6/(H5*1000) -> #DIV/0! | I16: =+I6/(I5*1000) -> #DIV/0! | J16: =+J6/(J5*1000) -> #DIV/0! | K16: =+K6/(K5*1000) -> #DIV/0! | ... P16: =+P6/(P5*1000) -> 59.657004
C17: Purchase Cost Per Kg | D17: =+D7/(D5*1000) -> 41.009148 | E17: =+E7/(E5*1000) -> 44.403242 | F17: =+F7/(F5*1000) -> 56.259852 | G17: =+G7/(G5*1000) -> #DIV/0! | H17: =+H7/(H5*1000) -> #DIV/0! | I17: =+I7/(I5*1000) -> #DIV/0! | J17: =+J7/(J5*1000) -> #DIV/0! | K17: =+K7/(K5*1000) -> #DIV/0! | ... P17: =+P7/(P5*1000) -> 47.230977
C18: Transportation Charges Per Kg | D18: =D10/(D5*1000) -> 0 | E18: =E10/(E5*1000) -> 0 | F18: =F10/(F5*1000) -> 0 | G18: =G10/(G5*1000) -> #DIV/0! | H18: =H10/(H5*1000) -> #DIV/0! | I18: =I10/(I5*1000) -> #DIV/0! | J18: =J10/(J5*1000) -> #DIV/0! | K18: =K10/(K5*1000) -> #DIV/0! | ... P18: =P10/(P5*1000) -> 0
C19: No. of Transactions | D19: {=IFERROR(ROWS(_xlfn.UNIQUE(_xlfn._xlws.FILTER(Details!$AO$5:$AO$78, (Details!$C$5:$C$78)=Summary!D$2))),0)-1} -> 6 | E19: {=IFERROR(ROWS(_xlfn.UNIQUE(_xlfn._xlws.FILTER(Details!$AO$5:$AO$78, (Details!$C$5:$C$78)=Summary!E$2))),0)} -> 11 | F19: {=IFERROR(ROWS(_xlfn.UNIQUE(_xlfn._xlws.FILTER(Details!$AO$5:$AO$78, (Details!$C$5:$C$78)=Summary!F$2))),0)} -> 8 | G19: {=IFERROR(ROWS(_xlfn.UNIQUE(_xlfn._xlws.FILTER(Details!$AO$5:$AO$78, (Details!$C$5:$C$78)=Summary!G$2))),0)} -> 0 | H19: {=IFERROR(ROWS(_xlfn.UNIQUE(_xlfn._xlws.FILTER(Details!$AO$5:$AO$78, (Details!$C$5:$C$78)=Summary!H$2))),0)} -> 0 | I19: {=IFERROR(ROWS(_xlfn.UNIQUE(_xlfn._xlws.FILTER(Details!$AO$5:$AO$78, (Details!$C$5:$C$78)=Summary!I$2))),0)} -> 0 | J19: {=IFERROR(ROWS(_xlfn.UNIQUE(_xlfn._xlws.FILTER(Details!$AO$5:$AO$78, (Details!$C$5:$C$78)=Summary!J$2))),0)} -> 0 | K19: {=IFERROR(ROWS(_xlfn.UNIQUE(_xlfn._xlws.FILTER(Details!$AO$5:$AO$78, (Details!$C$5:$C$78)=Summary!K$2))),0)} -> 0 | L19: {=IFERROR(ROWS(_xlfn.UNIQUE(_xlfn._xlws.FILTER(Details!$AO$5:$AO$78, (Details!$C$5:$C$78)=Summary!L$2))),0)} -> 0 | ... O19: {=IFERROR(ROWS(_xlfn.UNIQUE(_xlfn._xlws.FILTER(Details!$AO$5:$AO$78, (Details!$C$5:$C$78)=Summary!O$2))),0)} -> 0 | P19: =SUM(D19:O19) -> 25
C20: No. of Sellers (Aggregators) | D20: {=IFERROR(ROWS(_xlfn.UNIQUE(_xlfn._xlws.FILTER(MID(Details!$G$5:$G$78,3,10), (Details!$C$5:$C$78)=Summary!D$2))),0)} -> 1 | E20: {=IFERROR(ROWS(_xlfn.UNIQUE(_xlfn._xlws.FILTER(MID(Details!$G$5:$G$78,3,10), (Details!$C$5:$C$78)=Summary!E$2))),0)} -> 1 | F20: {=IFERROR(ROWS(_xlfn.UNIQUE(_xlfn._xlws.FILTER(MID(Details!$G$5:$G$78,3,10), (Details!$C$5:$C$78)=Summary!F$2))),0)} -> 1 | G20: {=IFERROR(ROWS(_xlfn.UNIQUE(_xlfn._xlws.FILTER(MID(Details!$G$5:$G$78,3,10), (Details!$C$5:$C$78)=Summary!G$2))),0)} -> 0 | H20: {=IFERROR(ROWS(_xlfn.UNIQUE(_xlfn._xlws.FILTER(MID(Details!$G$5:$G$78,3,10), (Details!$C$5:$C$78)=Summary!H$2))),0)} -> 0 | I20: {=IFERROR(ROWS(_xlfn.UNIQUE(_xlfn._xlws.FILTER(MID(Details!$G$5:$G$78,3,10), (Details!$C$5:$C$78)=Summary!I$2))),0)} -> 0 | J20: {=IFERROR(ROWS(_xlfn.UNIQUE(_xlfn._xlws.FILTER(MID(Details!$G$5:$G$78,3,10), (Details!$C$5:$C$78)=Summary!J$2))),0)} -> 0 | K20: {=IFERROR(ROWS(_xlfn.UNIQUE(_xlfn._xlws.FILTER(MID(Details!$G$5:$G$78,3,10), (Details!$C$5:$C$78)=Summary!K$2))),0)} -> 0 | ... O20: {=IFERROR(ROWS(_xlfn.UNIQUE(_xlfn._xlws.FILTER(MID(Details!$G$5:$G$78,3,10), (Details!$C$5:$C$78)=Summary!O$2))),0)} -> 0 | P20: ='Supplier Metrics'!E2 -> 1
C21: No. of Buyers (Recyclers) | D21: {=IFERROR(ROWS(_xlfn.UNIQUE(_xlfn._xlws.FILTER(MID(Details!$AR$5:$AR$78,3,10), (Details!$C$5:$C$78)=Summary!D$2))),0)} -> 1 | E21: {=IFERROR(ROWS(_xlfn.UNIQUE(_xlfn._xlws.FILTER(MID(Details!$AR$5:$AR$78,3,10), (Details!$C$5:$C$78)=Summary!E$2))),0)} -> 1 | F21: {=IFERROR(ROWS(_xlfn.UNIQUE(_xlfn._xlws.FILTER(MID(Details!$AR$5:$AR$78,3,10), (Details!$C$5:$C$78)=Summary!F$2))),0)} -> 3 | G21: {=IFERROR(ROWS(_xlfn.UNIQUE(_xlfn._xlws.FILTER(MID(Details!$AR$5:$AR$78,3,10), (Details!$C$5:$C$78)=Summary!G$2))),0)} -> 0 | H21: {=IFERROR(ROWS(_xlfn.UNIQUE(_xlfn._xlws.FILTER(MID(Details!$AR$5:$AR$78,3,10), (Details!$C$5:$C$78)=Summary!H$2))),0)} -> 0 | I21: {=IFERROR(ROWS(_xlfn.UNIQUE(_xlfn._xlws.FILTER(MID(Details!$AR$5:$AR$78,3,10), (Details!$C$5:$C$78)=Summary!I$2))),0)} -> 0 | J21: {=IFERROR(ROWS(_xlfn.UNIQUE(_xlfn._xlws.FILTER(MID(Details!$AR$5:$AR$78,3,10), (Details!$C$5:$C$78)=Summary!J$2))),0)} -> 0 | K21: {=IFERROR(ROWS(_xlfn.UNIQUE(_xlfn._xlws.FILTER(MID(Details!$AR$5:$AR$78,3,10), (Details!$C$5:$C$78)=Summary!K$2))),0)} -> 0 | ... O21: {=IFERROR(ROWS(_xlfn.UNIQUE(_xlfn._xlws.FILTER(MID(Details!$AR$5:$AR$78,3,10), (Details!$C$5:$C$78)=Summary!O$2))),0)} -> 0 | P21: ='Buyer Metrics'!B3 -> 3
C22: Full Rejections | D22: {=IFERROR(ROWS(_xlfn.UNIQUE(_xlfn._xlws.FILTER(Details!$E$5:$E$78,(Details!$C$5:$C$78=Summary!D$2)*(Details!$BR$5:$BR$78=Summary!$C$22)))),0)} -> 0 | E22: {=IFERROR(ROWS(_xlfn.UNIQUE(_xlfn._xlws.FILTER(Details!$E$5:$E$78,(Details!$C$5:$C$78=Summary!E$2)*(Details!$BR$5:$BR$78=Summary!$C$22)))),0)} -> 0 | F22: {=IFERROR(ROWS(_xlfn.UNIQUE(_xlfn._xlws.FILTER(Details!$E$5:$E$78,(Details!$C$5:$C$78=Summary!F$2)*(Details!$BR$5:$BR$78=Summary!$C$22)))),0)} -> 0 | G22: {=IFERROR(ROWS(_xlfn.UNIQUE(_xlfn._xlws.FILTER(Details!$E$5:$E$78,(Details!$C$5:$C$78=Summary!G$2)*(Details!$BR$5:$BR$78=Summary!$C$22)))),0)} -> 0 | H22: {=IFERROR(ROWS(_xlfn.UNIQUE(_xlfn._xlws.FILTER(Details!$E$5:$E$78,(Details!$C$5:$C$78=Summary!H$2)*(Details!$BR$5:$BR$78=Summary!$C$22)))),0)} -> 0 | I22: {=IFERROR(ROWS(_xlfn.UNIQUE(_xlfn._xlws.FILTER(Details!$E$5:$E$78,(Details!$C$5:$C$78=Summary!I$2)*(Details!$BR$5:$BR$78=Summary!$C$22)))),0)} -> 0 | J22: {=IFERROR(ROWS(_xlfn.UNIQUE(_xlfn._xlws.FILTER(Details!$E$5:$E$78,(Details!$C$5:$C$78=Summary!J$2)*(Details!$BR$5:$BR$78=Summary!$C$22)))),0)} -> 0 | K22: {=IFERROR(ROWS(_xlfn.UNIQUE(_xlfn._xlws.FILTER(Details!$E$5:$E$78,(Details!$C$5:$C$78=Summary!K$2)*(Details!$BR$5:$BR$78=Summary!$C$22)))),0)} -> 0 | ... O22: {=IFERROR(ROWS(_xlfn.UNIQUE(_xlfn._xlws.FILTER(Details!$E$5:$E$78,(Details!$C$5:$C$78=Summary!O$2)*(Details!$BR$5:$BR$78=Summary!$C$22)))),0)} -> 0 | P22: =SUM(D22:O22) -> 0
C23: Receivable | D23: 6409082 | E23: 11960843 | F23: 13783192 | G23: 0 | H23: 0 | I23: 0 | J23: 0 | K23: 0 | L23: 0 | M23: 0 | N23: 0 | O23: 0 | P23: =F23 -> 13783192
C24: DSO (Days) | D24: =IFERROR(((D23/(D6*1.18))*D3),0) -> 50.973992 | E24: =IFERROR(((E23/(E6*1.18))*E3),0) -> 53.096579 | F24: =IFERROR(((F23/(F6*1.18))*F3),0) -> 42.142804 | G24: =IFERROR(((G23/(G6*1.18))*G3),0) -> 0 | H24: =IFERROR(((H23/(H6*1.18))*H3),0) -> 0 | I24: =IFERROR(((I23/(I6*1.18))*I3),0) -> 0 | J24: =IFERROR(((J23/(J6*1.18))*J3),0) -> 0 | K24: =IFERROR(((K23/(K6*1.18))*K3),0) -> 0 | ... O24: =IFERROR(((O23/(O6*1.18))*O3),0) -> 0 | P24: =IFERROR(((P23)/(P6*1.18)*P3),0) -> 64.13168
C25: Payable | D25: -6728200.6 | E25: -5803401.5 | F25: -6406913.3 | G25: 0 | H25: 0 | I25: 0 | J25: 0 | K25: 0 | L25: 0 | M25: 0 | N25: 0 | O25: 0 | P25: =F25 -> -6406913.3
C26: DPO (Days) | D26: =IFERROR(((D25/(D7*1.18))*D3),0) -> -62.554973 | E26: =IFERROR(((E25/(E7*1.18))*E3),0) -> -32.739772 | F26: =IFERROR(((F25/(F7*1.18))*F3),0) -> -25.721062 | G26: =IFERROR(((G25/(G7*1.18))*G3),0) -> 0 | H26: =IFERROR(((H25/(H7*1.18))*H3),0) -> 0 | I26: =IFERROR(((I25/(I7*1.18))*I3),0) -> 0 | J26: =IFERROR(((J25/(J7*1.18))*J3),0) -> 0 | K26: =IFERROR(((K25/(K7*1.18))*K3),0) -> 0 | ... P26: =IFERROR(((P25/(P7*1.18))*P3),0) -> -37.653571
C27: Working Capital Days | D27: =D24-D26 -> 113.52897 | E27: =E24-E26 -> 85.836351 | F27: =F24-F26 -> 67.863865 | G27: =G24-G26 -> 0 | H27: =H24-H26 -> 0 | I27: =I24-I26 -> 0 | J27: =J24-J26 -> 0 | K27: =K24-K26 -> 0 | ... P27: =P24-P26 -> 101.78525
C28: Credit Notes (Value - Incl. Prov) | D28: 81963.75 | E28: =-SUMIFS(Details!$BW$4:$BW$78,Details!$C$4:$C$78,Summary!E4) -> 143785.43 | F28: =-SUMIFS(Details!$BW$4:$BW$78,Details!$C$4:$C$78,Summary!F4) -> 149244.75 | G28: =-SUMIFS(Details!$BW$4:$BW$78,Details!$C$4:$C$78,Summary!G4) -> 0 | H28: =-SUMIFS(Details!$BW$4:$BW$78,Details!$C$4:$C$78,Summary!H4) -> 0 | I28: =-SUMIFS(Details!$BW$4:$BW$78,Details!$C$4:$C$78,Summary!I4) -> 0 | J28: =-SUMIFS(Details!$BW$4:$BW$78,Details!$C$4:$C$78,Summary!J4) -> 0 | K28: =-SUMIFS(Details!$BW$4:$BW$78,Details!$C$4:$C$78,Summary!K4) -> 0 | L28: =-SUMIFS(Details!$BW$4:$BW$78,Details!$C$4:$C$78,Summary!L4) -> 0 | ... O28: =-SUMIFS(Details!$BW$4:$BW$78,Details!$C$4:$C$78,Summary!O4) -> 0 | P28: =SUM(D28:O28) -> 374993.93 | Q28: =(-Details!BM79-Details!BN79) -> 345691.82 | R28: =P28-Q28 -> 29302.12
C29: Credit Notes (% to Revenue) | D29: =+D28/D6 -> 0.025641026 | E29: =+E28/E6 -> 0.02429629 | F29: =+F28/F6 -> 0.025641026 | G29: =+G28/G6 -> #DIV/0! | H29: =+H28/H6 -> #DIV/0! | I29: =+I28/I6 -> #DIV/0! | J29: =+J28/J6 -> #DIV/0! | K29: =+K28/K6 -> #DIV/0! | ... P29: =+P28/P6 -> 0.025108178
C30: Debit Notes (Value - Incl. Prov) | D30: =-SUMIFS(Details!$BX$4:$BX$78,Details!$C$4:$C$78,Summary!D4) -> 0 | E30: =-SUMIFS(Details!$BX$4:$BX$78,Details!$C$4:$C$78,Summary!E4) -> 0 | F30: =-SUMIFS(Details!$BX$4:$BX$78,Details!$C$4:$C$78,Summary!F4) -> 0 | G30: =-SUMIFS(Details!$BX$4:$BX$78,Details!$C$4:$C$78,Summary!G4) -> 0 | H30: =-SUMIFS(Details!$BX$4:$BX$78,Details!$C$4:$C$78,Summary!H4) -> 0 | I30: =-SUMIFS(Details!$BX$4:$BX$78,Details!$C$4:$C$78,Summary!I4) -> 0 | J30: =-SUMIFS(Details!$BX$4:$BX$78,Details!$C$4:$C$78,Summary!J4) -> 0 | K30: =-SUMIFS(Details!$BX$4:$BX$78,Details!$C$4:$C$78,Summary!K4) -> 0 | ... O30: =-SUMIFS(Details!$BX$4:$BX$78,Details!$C$4:$C$78,Summary!O4) -> 0 | P30: =SUM(D30:O30) -> 0 | Q30: =(-Details!AK79-Details!AL79) -> 0 | R30: =P30-Q30 -> 0
C31: Debit Notes (% to Purchase) | D31: =(D30/D7) -> 0 | E31: =(E30/E7) -> 0 | F31: =(F30/F7) -> 0 | G31: =(G30/G7) -> #DIV/0! | H31: =(H30/(H7+H10)) -> #DIV/0! | I31: =(I30/(I7+I10)) -> #DIV/0! | J31: =(J30/(J7+J10)) -> #DIV/0! | K31: =(K30/(K7+K10)) -> #DIV/0! | L31: =(L30/(L7+L10)) -> #DIV/0! | M31: =(M30/(M7+M10)) -> #DIV/0! | N31: =(N30/(N7+N10)) -> #DIV/0! | O31: =(O30/(O7+O10)) -> #DIV/0! | P31: =(P30/(P7+P10)) -> 0
C32: Indirect Expenses | D32: 226775 | E32: 226775 | F32: =E32*F3/30 -> 158742.5 | P32: =SUM(D32:F32) -> 612292.5
C33: Margin after Indirect Expenses | D33: =D12-D32 -> -621814.37 | E33: =E12-E32 -> -313677.29 | F33: =F12-F32 -> 115940.31 | G33: =G12-G32 -> 0 | H33: =H12-H32 -> 0 | I33: =I12-I32 -> 0 | J33: =J12-J32 -> 0 | K33: =K12-K32 -> 0 | ... P33: =P12-P32 -> -819551.35
C34: Margin % | D34: =D33/D6 -> -0.19452451 | E34: =E33/E6 -> -0.053003939 | F34: =F33/F6 -> 0.019919149 | G34: =G33/G6 -> #DIV/0! | H34: =H33/H6 -> #DIV/0! | I34: =I33/I6 -> #DIV/0! | J34: =J33/J6 -> #DIV/0! | K34: =K33/K6 -> #DIV/0! | ... P34: =P33/P6 -> -0.054874065
C37: KPI's without Provisions | D37: =D4 -> 46113 | E37: =E4 -> 46143 | F37: =F4 -> 46174 | G37: =G4 -> 46204 | H37: =H4 -> 46235 | I37: =I4 -> 46266 | J37: =J4 -> 46296 | K37: =K4 -> 46327 | ... P37: =P4 -> FY 2026-27
C38: Sales without Provision | D38: =D6+D57 -> 3207647.5 | E38: =E6+E57 -> 6056973.4 | F38: =F6+F57 -> 5969790 | G38: =G6+G57 -> 0 | H38: =H6+H57 -> 0 | I38: =I6+I57 -> 0 | J38: =J6+J57 -> 0 | K38: =K6+K57 -> 0 | ... O38: =O6+O57 -> 0 | P38: =SUM(D38:O38) -> 15234411
C39: Purchases without Provision | D39: =D7+D10+D56 -> 2734490 | E39: =E7+E10+E56 -> 4656790 | F39: =F7+F10+F56 -> 4432995 | G39: =G7+G10+G56 -> 0 | H39: =H7+H10+H56 -> 0 | I39: =I7+I10+I56 -> 0 | J39: =J7+J10+J56 -> 0 | K39: =K7+K10+K56 -> 0 | ... O39: =O7+O10+O56 -> 0 | P39: =SUM(D39:O39) -> 11824275
C40: Contribution without Provision | D40: =D38-D39 -> 473157.5 | E40: =E38-E39 -> 1400183.4 | F40: =F38-F39 -> 1536795 | G40: =G38-G39 -> 0 | H40: =H38-H39 -> 0 | I40: =I38-I39 -> 0 | J40: =J38-J39 -> 0 | K40: =K38-K39 -> 0 | ... P40: =P38-P39 -> 3410135.9
C41: Contribution (%) | D41: =D40/D38 -> 0.14750919 | E41: =E40/E38 -> 0.23116883 | F41: =F40/F38 -> 0.25742865 | G41: =G40/G38 -> #DIV/0! | H41: =H40/H38 -> #DIV/0! | I41: =I40/I38 -> #DIV/0! | J41: =J40/J38 -> #DIV/0! | K41: =K40/K38 -> #DIV/0! | ... P41: =P40/P38 -> 0.22384429
C43: Business Trends | D43: =D4 -> 46113 | E43: =E4 -> 46143 | F43: =F4 -> 46174 | G43: =G4 -> 46204 | H43: =H4 -> 46235 | I43: =I4 -> 46266 | J43: =J4 -> 46296 | K43: =K4 -> 46327 | ... P43: =P4 -> FY 2026-27
C44: Sales-Revenue (MoM) | D44: =IFERROR(((D6/C6)-1),0) -> 0 | E44: =IFERROR(((E6/D6)-1),0) -> 0.85134988 | F44: =IFERROR(((F6/E6)-1),0) -> -0.016467442 | G44: =IFERROR(((G6/F6)-1),0) -> -1 | H44: =IFERROR(((H6/G6)-1),0) -> 0 | I44: =IFERROR(((I6/H6)-1),0) -> 0 | J44: =IFERROR(((J6/I6)-1),0) -> 0 | K44: =IFERROR(((K6/J6)-1),0) -> 0 | ... O44: =IFERROR(((O6/N6)-1),0) -> 0 | P44: 0
...

Sheet Details
B3: Raw Data -Rewerse | F3: Purchase Details | U3: Logistic Details of the transaction | AF3: Debit Notes to Suppliers | AM3: Sales Details | BD3: DN to Customer | BH3: Credit Notes from Customers | BM3: -0.025 | BV3: CN & DN Checks | CE3: Without Provisions | CK3: Margin Buckets | CN3: Financials with GST
B4: Quarter | C4: Month | D4: Date | E4: Shipment ID | F4: Supplier Name | G4: GST Reg No. | H4: Vendor Invoice No. | I4: Vendor Invoice Date | J4: P V No. | K4: P V Date | L4: State (Origin) | M4: Vehicle No. | N4: Material | O4: Qty (Kg) | P4: Price/Kg | Q4: Purchase Price | R4: Return Qty | S4: Net Qty | T4: Basic Customs Duty | U4: Transporter Name | V4: LR NO/BILL NO | W4: J V No. | X4: JV Date | Y4: Logistics cost | Z4: Debit note on logistic cost | AA4: Logistics Provision | AB4: Total Logistics Cost | AC4: Operational Cost | AD4: Cost/Kg. | AE4: Divertion/Internal | AF4: Debit Note No. | AG4: Debit Note Date. | AH4: Debit Note No. 2 | AI4: Debit Note Date. 2 | AJ4: Full Debit Note | AK4: Actual Debit Note | AL4: Provision for DN | AM4: Total Cost | AN4: Inv. Date | AO4: Inv. No. | AP4: Customer ID | AQ4: Buyer Name | AR4: Buyer GST Number | AS4: Location (Origin) | AT4: Location (Destination) | AU4: State (Destination) | AV4: E-WayBill Number | AW4: Qty(Kg) | AX4: Rate/Kg | AY4: Amount | AZ4: Qty Check | BA4: Return Qty | BB4: Net Qty | BC4: Divertion/Internal | BD4: Return Type | BE4: Date : DN to Buyer | BF4: DN to Buyer | BG4: Amount | BH4: Credit Note No:1 | BI4: CN Date. No:1 | BJ4: Credit Note No:2 | BK4: CN Date. No:2 | BL4: Full Credit Notes | BM4: Actual Credit Note | BN4: Provision for CN | BO4: Net Revenue | BP4: Margin | BQ4: Reamrks - Margin | BR4: Remarks | BS4: LMI @ Inception | BT4: Remarks @ Inception | BU4: Margin (%) | BV4: Margin Bucket | BW4: Total CN(Inc.Provisions) | BX4: Total DN(Inc.Provisions) | BY4: Check | BZ4: Actaul CN | CA4: Actual DN | CB4: Check | CC4: Material-Short Form | CD4: Supplier Type | CE4: Month | CF4: Cost | CG4: Revenue | CH4: Week No: | CI4: Category (Material) | CJ4: Broad Category | CK4: POC Name | CL4: Gross Margin | CM4: Recykal Margin | CN4: Net Margin | CO4: Sales | CP4: Purchases | CQ4: Credit Note | CR4: Debit Note | CS4: Margin | CT4: Bill Branch | CU4: Inv Branch | CV4: Vendor PAN No | CW4: Customer PAN No | CX4: GST TDS Applicability | CY4: Cash Discount(Provision) | CZ4: Cash Discount | DA4: Cash Discount. No | DB4: CD Date
B5: ="Q" & IF(ROUNDUP(MONTH(D5)/3,0)-1=0,4,ROUNDUP(MONTH(D5)/3,0)-1) -> Q1 | C5: =TEXT(AN5,"mmm-yy") -> Apr-26 | D5: 46118 | E5: SH042606010 | F5: BLACK GOLD RECYCLING PRIVATE LIMITED | G5: 27AAMCB5608A1ZX | H5: 25/PUN/INV0270 | I5: 46118 | J5: 26-27/PUR/000107 | K5: 46118 | L5: MH | M5: DD01AC9819 | N5: PET Bottle Scrap Baled - Clear | O5: 9217 | P5: 39.5 | Q5: =O5*P5 -> 364071.5 | R5: 0 | S5: =O5-R5 -> 9217 | T5: 0 | U5: 0 | V5: 0 | W5: 0 | X5: 0 | Y5: 0 | Z5: 0 | AA5: 0 | AB5: =Y5+AA5+Z5 -> 0 | AC5: 0 | AD5: =IFERROR((Q5+AB5)/S5,0) -> 39.5 | AE5: 0 | AF5: 0 | AG5: 0 | AH5: 0 | AI5: 0 | AJ5: 0 | AK5: 0 | AL5: 0 | AM5: =Q5+AB5+AL5+AK5+AJ5+T5+AE5 -> 364071.5 | AN5: 46118 | AO5: 36/REW/27IN00001 | AP5: 832139000052985017 | AQ5: DALMIA POLYPRO INDUSTRIES PRIVATE LIMITED (27) | AR5: 27AAACD5406E1Z3 | AS5: Koregaon Bhima Maharashtra 412216 | AT5: Dindori | AU5: Maharashtra | AV5: 0 | AW5: 9217 | AX5: 46 | AY5: =AW5*AX5 -> 423982 | AZ5: =AW5=O5 -> TRUE | BA5: 0 | BB5: =AW5-BA5 -> 9217 | BC5: 0 | BD5: Regular | BE5: 0 | BF5: 0 | BG5: 0 | BH5: 0 | BI5: 0 | BJ5: 0 | BK5: 0 | BL5: 0 | BM5: 0 | BN5: =AY5*$BM$3 -> -10599.55 | BO5: =AY5+BL5+BM5+BN5+BC5+BG5 -> 413382.45 | BP5: =BO5-AM5 -> 49310.95 | BQ5: =IF(BP5>=0,"Positive Margin","Negative Margin") -> Positive Margin | BR5: CN Provision | BS5: =AY5-Y5-Q5-AA5-T5+BC5 -> 59910.5 | BT5: =IF(BS5<0, "Negative Margin at Inception", "Positive Margin at Inception") -> Positive Margin at Inception | BU5: =IFERROR(BP5/BO5,"0") -> 0.11928651 | BV5: =IF(BU5<1%,"Less Than 1%",IF(BU5>2%,"More than 2%",IF(BU5>=1%,"1% - 2%"))) -> More than 2% | BW5: =BM5+BN5 -> -10599.55 | BX5: =AL5+AK5 -> 0 | BY5: =BW5-BX5 -> -10599.55 | BZ5: =BM5 -> 0 | CA5: =AK5 -> 0 | CB5: =BZ5-CA5 -> 0 | CC5: Marketplace (Rewerse) | CD5: 0 | CE5: =TEXT(AN5,"mmm-yy") -> Apr-26 | CF5: =AM5-AL5-AA5 -> 364071.5 | CG5: =BO5-BN5 -> 423982 | CH5: =INT((D5- IF(MONTH(D5) >= 4, DATE(YEAR(D5), 4, 1), DATE(YEAR(D5)-1, 4, 1))) / 7) + 1 -> 1 | CI5: Plastic | CJ5: Plastic | CK5: =_xlfn.XLOOKUP(AR5,receivables!B:B,receivables!D:D) -> Neelesh Dixit | CL5: =AY5-Q5 -> 59910.5 | CM5: =CL5-Y5+Z5 -> 59910.5 | CN5: =BO5-AM5 -> 49310.95 | CO5: =AY5*118% -> 500298.76 | CP5: =-Q5*118% -> -429604.37 | CQ5: =-BZ5*118% -> 0 | CR5: =-CA5*118% -> 0 | CS5: =SUM(CO5:CR5) -> 70694.39 | CT5: Telangana - HO | CU5: Telangana - HO | CV5: =MID(G5,3,10) -> AAMCB5608A | CW5: =MID(AR5,3,10) -> AAACD5406E | CX5: 0 | CY5: 0 | CZ5: 0 | DA5: 0 | DB5: 0
B6: ="Q" & IF(ROUNDUP(MONTH(D6)/3,0)-1=0,4,ROUNDUP(MONTH(D6)/3,0)-1) -> Q1 | C6: =TEXT(AN6,"mmm-yy") -> Apr-26 | D6: 46118 | E6: SH042606010 | F6: BLACK GOLD RECYCLING PRIVATE LIMITED | G6: 27AAMCB5608A1ZX | H6: 25/PUN/INV0270 | I6: 46118 | J6: 26-27/PUR/000107 | K6: 46118 | L6: MH | M6: DD01AC9819 | N6: PET Bottle Scrap Baled - Green | O6: 513 | P6: 34.5 | Q6: =O6*P6 -> 17698.5 | R6: 0 | S6: =O6-R6 -> 513 | T6: 0 | U6: 0 | V6: 0 | W6: 0 | X6: 0 | Y6: 0 | Z6: 0 | AA6: 0 | AB6: =Y6+AA6+Z6 -> 0 | AC6: 0 | AD6: =IFERROR((Q6+AB6)/S6,0) -> 34.5 | AE6: 0 | AF6: 0 | AG6: 0 | AH6: 0 | AI6: 0 | AJ6: 0 | AK6: 0 | AL6: 0 | AM6: =Q6+AB6+AL6+AK6+AJ6+T6+AE6 -> 17698.5 | AN6: 46118 | AO6: 36/REW/27IN00001 | AP6: 832139000052985017 | AQ6: DALMIA POLYPRO INDUSTRIES PRIVATE LIMITED (27) | AR6: 27AAACD5406E1Z3 | AS6: Koregaon Bhima Maharashtra 412216 | AT6: Dindori | AU6: Maharashtra | AV6: 0 | AW6: 513 | AX6: 36 | AY6: =AW6*AX6 -> 18468 | AZ6: =AW6=O6 -> TRUE | BA6: 0 | BB6: =AW6-BA6 -> 513 | BC6: 0 | BD6: Regular | BE6: 0 | BF6: 0 | BG6: 0 | BH6: 0 | BI6: 0 | BJ6: 0 | BK6: 0 | BL6: 0 | BM6: 0 | BN6: =AY6*$BM$3 -> -461.7 | BO6: =AY6+BL6+BM6+BN6+BC6+BG6 -> 18006.3 | BP6: =BO6-AM6 -> 307.8 | BQ6: =IF(BP6>=0,"Positive Margin","Negative Margin") -> Positive Margin | BR6: CN Provision | BS6: =AY6-Y6-Q6-AA6-T6+BC6 -> 769.5 | BT6: =IF(BS6<0, "Negative Margin at Inception", "Positive Margin at Inception") -> Positive Margin at Inception | BU6: =IFERROR(BP6/BO6,"0") -> 0.017094017 | BV6: =IF(BU6<1%,"Less Than 1%",IF(BU6>2%,"More than 2%",IF(BU6>=1%,"1% - 2%"))) -> 1% - 2% | BW6: =BM6+BN6 -> -461.7 | BX6: =AL6+AK6 -> 0 | BY6: =BW6-BX6 -> -461.7 | BZ6: =BM6 -> 0 | CA6: =AK6 -> 0 | CB6: =BZ6-CA6 -> 0 | CC6: Marketplace (Rewerse) | CD6: 0 | CE6: =TEXT(AN6,"mmm-yy") -> Apr-26 | CF6: =AM6-AL6-AA6 -> 17698.5 | CG6: =BO6-BN6 -> 18468 | CH6: =INT((D6- IF(MONTH(D6) >= 4, DATE(YEAR(D6), 4, 1), DATE(YEAR(D6)-1, 4, 1))) / 7) + 1 -> 1 | CI6: Plastic | CJ6: Plastic | CK6: =_xlfn.XLOOKUP(AR6,receivables!B:B,receivables!D:D) -> Neelesh Dixit | CL6: =AY6-Q6 -> 769.5 | CM6: =CL6-Y6+Z6 -> 769.5 | CN6: =BO6-AM6 -> 307.8 | CO6: =AY6*118% -> 21792.24 | CP6: =-Q6*118% -> -20884.23 | CQ6: =-BZ6*118% -> 0 | CR6: =-CA6*118% -> 0 | CS6: =SUM(CO6:CR6) -> 908.01 | CT6: Telangana - HO | CU6: Telangana - HO | CV6: =MID(G6,3,10) -> AAMCB5608A | CW6: =MID(AR6,3,10) -> AAACD5406E | CX6: 0 | CY6: 0 | CZ6: 0 | DA6: 0 | DB6: 0
B7: ="Q" & IF(ROUNDUP(MONTH(D7)/3,0)-1=0,4,ROUNDUP(MONTH(D7)/3,0)-1) -> Q1 | C7: =TEXT(AN7,"mmm-yy") -> Apr-26 | D7: 46120 | E7: SH04260802 | F7: BLACK GOLD RECYCLING PRIVATE LIMITED | G7: 27AAMCB5608A1ZX | H7: 25/PUN/INV0273 | I7: 46120 | J7: 26-27/PUR/000239 | K7: 46120 | L7: MH | M7: DD01J9582 | N7: PET Bottle Scrap Baled - Clear | O7: 7945 | P7: 41 | Q7: =O7*P7 -> 325745 | R7: 0 | S7: =O7-R7 -> 7945 | T7: 0 | U7: 0 | V7: 0 | W7: 0 | X7: 0 | Y7: 0 | Z7: 0 | AA7: 0 | AB7: =Y7+AA7+Z7 -> 0 | AC7: 0 | AD7: =IFERROR((Q7+AB7)/S7,0) -> 41 | AE7: 0 | AF7: 0 | AG7: 0 | AH7: 0 | AI7: 0 | AJ7: 0 | AK7: 0 | AL7: 0 | AM7: =Q7+AB7+AL7+AK7+AJ7+T7+AE7 -> 325745 | AN7: 46120 | AO7: 36/REW/27IN00002 | AP7: 832139000052985017 | AQ7: DALMIA POLYPRO INDUSTRIES PRIVATE LIMITED (27) | AR7: 27AAACD5406E1Z3 | AS7: Koregaon Bhima Maharashtra 412216 | AT7: Dindori | AU7: Maharashtra | AV7: 0 | AW7: 7945 | AX7: 46 | AY7: =AW7*AX7 -> 365470 | AZ7: =AW7=O7 -> TRUE | BA7: 0 | BB7: =AW7-BA7 -> 7945 | BC7: 0 | BD7: Regular | BE7: 0 | BF7: 0 | BG7: 0 | BH7: 36/REW/27CN00024 | BI7: 46181 | BJ7: 0 | BK7: 0 | BL7: 0 | BM7: -4529.62 | BN7: 0 | BO7: =AY7+BL7+BM7+BN7+BC7+BG7 -> 360940.38 | BP7: =BO7-AM7 -> 35195.38 | BQ7: =IF(BP7>=0,"Positive Margin","Negative Margin") -> Positive Margin | BR7: CN Issued | BS7: =AY7-Y7-Q7-AA7-T7+BC7 -> 39725 | BT7: =IF(BS7<0, "Negative Margin at Inception", "Positive Margin at Inception") -> Positive Margin at Inception | BU7: =IFERROR(BP7/BO7,"0") -> 0.097510231 | BV7: =IF(BU7<1%,"Less Than 1%",IF(BU7>2%,"More than 2%",IF(BU7>=1%,"1% - 2%"))) -> More than 2% | BW7: =BM7+BN7 -> -4529.62 | BX7: =AL7+AK7 -> 0 | BY7: =BW7-BX7 -> -4529.62 | BZ7: =BM7 -> -4529.62 | CA7: =AK7 -> 0 | CB7: =BZ7-CA7 -> -4529.62 | CC7: Marketplace (Rewerse) | CD7: 0 | CE7: =TEXT(AN7,"mmm-yy") -> Apr-26 | CF7: =AM7-AL7-AA7 -> 325745 | CG7: =BO7-BN7 -> 360940.38 | CH7: =INT((D7- IF(MONTH(D7) >= 4, DATE(YEAR(D7), 4, 1), DATE(YEAR(D7)-1, 4, 1))) / 7) + 1 -> 2 | CI7: Plastic | CJ7: Plastic | CK7: =_xlfn.XLOOKUP(AR7,receivables!B:B,receivables!D:D) -> Neelesh Dixit | CL7: =AY7-Q7 -> 39725 | CM7: =CL7-Y7+Z7 -> 39725 | CN7: =BO7-AM7 -> 35195.38 | CO7: =AY7*118% -> 431254.6 | CP7: =-Q7*118% -> -384379.1 | CQ7: =-BZ7*118% -> 5344.9516 | CR7: =-CA7*118% -> 0 | CS7: =SUM(CO7:CR7) -> 52220.452 | CT7: Telangana - HO | CU7: Telangana - HO | CV7: =MID(G7,3,10) -> AAMCB5608A | CW7: =MID(AR7,3,10) -> AAACD5406E | CX7: 0 | CY7: 0 | CZ7: 0 | DA7: 0 | DB7: 0
B8: ="Q" & IF(ROUNDUP(MONTH(D8)/3,0)-1=0,4,ROUNDUP(MONTH(D8)/3,0)-1) -> Q1 | C8: =TEXT(AN8,"mmm-yy") -> Apr-26 | D8: 46120 | E8: SH04260802 | F8: BLACK GOLD RECYCLING PRIVATE LIMITED | G8: 27AAMCB5608A1ZX | H8: 25/PUN/INV0273 | I8: 46120 | J8: 26-27/PUR/000239 | K8: 46120 | L8: MH | M8: DD01J9582 | N8: PET Bottle Scrap Baled - Green | O8: 348 | P8: 36 | Q8: =O8*P8 -> 12528 | R8: 0 | S8: =O8-R8 -> 348 | T8: 0 | U8: 0 | V8: 0 | W8: 0 | X8: 0 | Y8: 0 | Z8: 0 | AA8: 0 | AB8: =Y8+AA8+Z8 -> 0 | AC8: 0 | AD8: =IFERROR((Q8+AB8)/S8,0) -> 36 | AE8: 0 | AF8: 0 | AG8: 0 | AH8: 0 | AI8: 0 | AJ8: 0 | AK8: 0 | AL8: 0 | AM8: =Q8+AB8+AL8+AK8+AJ8+T8+AE8 -> 12528 | AN8: 46120 | AO8: 36/REW/27IN00002 | AP8: 832139000052985017 | AQ8: DALMIA POLYPRO INDUSTRIES PRIVATE LIMITED (27) | AR8: 27AAACD5406E1Z3 | AS8: Koregaon Bhima Maharashtra 412216 | AT8: Dindori | AU8: Maharashtra | AV8: 0 | AW8: 348 | AX8: 36 | AY8: =AW8*AX8 -> 12528 | AZ8: =AW8=O8 -> TRUE | BA8: 0 | BB8: =AW8-BA8 -> 348 | BC8: 0 | BD8: Regular | BE8: 0 | BF8: 0 | BG8: 0 | BH8: 36/REW/27CN00024 | BI8: 46181 | BJ8: 0 | BK8: 0 | BL8: 0 | BM8: 0 | BN8: 0 | BO8: =AY8+BL8+BM8+BN8+BC8+BG8 -> 12528 | BP8: =BO8-AM8 -> 0 | BQ8: =IF(BP8>=0,"Positive Margin","Negative Margin") -> Positive Margin | BR8: CN Issued | BS8: =AY8-Y8-Q8-AA8-T8+BC8 -> 0 | BT8: =IF(BS8<0, "Negative Margin at Inception", "Positive Margin at Inception") -> Positive Margin at Inception | BU8: =IFERROR(BP8/BO8,"0") -> 0 | BV8: =IF(BU8<1%,"Less Than 1%",IF(BU8>2%,"More than 2%",IF(BU8>=1%,"1% - 2%"))) -> Less Than 1% | BW8: =BM8+BN8 -> 0 | BX8: =AL8+AK8 -> 0 | BY8: =BW8-BX8 -> 0 | BZ8: =BM8 -> 0 | CA8: =AK8 -> 0 | CB8: =BZ8-CA8 -> 0 | CC8: Marketplace (Rewerse) | CD8: 0 | CE8: =TEXT(AN8,"mmm-yy") -> Apr-26 | CF8: =AM8-AL8-AA8 -> 12528 | CG8: =BO8-BN8 -> 12528 | CH8: =INT((D8- IF(MONTH(D8) >= 4, DATE(YEAR(D8), 4, 1), DATE(YEAR(D8)-1, 4, 1))) / 7) + 1 -> 2 | CI8: Plastic | CJ8: Plastic | CK8: =_xlfn.XLOOKUP(AR8,receivables!B:B,receivables!D:D) -> Neelesh Dixit | CL8: =AY8-Q8 -> 0 | CM8: =CL8-Y8+Z8 -> 0 | CN8: =BO8-AM8 -> 0 | CO8: =AY8*118% -> 14783.04 | CP8: =-Q8*118% -> -14783.04 | CQ8: =-BZ8*118% -> 0 | CR8: =-CA8*118% -> 0 | CS8: =SUM(CO8:CR8) -> 0 | CT8: Telangana - HO | CU8: Telangana - HO | CV8: =MID(G8,3,10) -> AAMCB5608A | CW8: =MID(AR8,3,10) -> AAACD5406E | CX8: 0 | CY8: 0 | CZ8: 0 | DA8: 0 | DB8: 0
B9: ="Q" & IF(ROUNDUP(MONTH(D9)/3,0)-1=0,4,ROUNDUP(MONTH(D9)/3,0)-1) -> Q1 | C9: =TEXT(AN9,"mmm-yy") -> Apr-26 | D9: 46120 | E9: SH04260802 | F9: BLACK GOLD RECYCLING PRIVATE LIMITED | G9: 27AAMCB5608A1ZX | H9: 25/PUN/INV0273 | I9: 46120 | J9: 26-27/PUR/000239 | K9: 46120 | L9: MH | M9: DD01J9582 | N9: PET Liquor Bottle Scrap Baled | O9: 927 | P9: 41 | Q9: =O9*P9 -> 38007 | R9: 0 | S9: =O9-R9 -> 927 | T9: 0 | U9: 0 | V9: 0 | W9: 0 | X9: 0 | Y9: 0 | Z9: 0 | AA9: 0 | AB9: =Y9+AA9+Z9 -> 0 | AC9: 0 | AD9: =IFERROR((Q9+AB9)/S9,0) -> 41 | AE9: 0 | AF9: 0 | AG9: 0 | AH9: 0 | AI9: 0 | AJ9: 0 | AK9: 0 | AL9: 0 | AM9: =Q9+AB9+AL9+AK9+AJ9+T9+AE9 -> 38007 | AN9: 46120 | AO9: 36/REW/27IN00002 | AP9: 832139000052985017 | AQ9: DALMIA POLYPRO INDUSTRIES PRIVATE LIMITED (27) | AR9: 27AAACD5406E1Z3 | AS9: Koregaon Bhima Maharashtra 412216 | AT9: Dindori | AU9: Maharashtra | AV9: 0 | AW9: 927 | AX9: 51 | AY9: =AW9*AX9 -> 47277 | AZ9: =AW9=O9 -> TRUE | BA9: 0 | BB9: =AW9-BA9 -> 927 | BC9: 0 | BD9: Regular | BE9: 0 | BF9: 0 | BG9: 0 | BH9: 36/REW/27CN00024 | BI9: 46181 | BJ9: 0 | BK9: 0 | BL9: 0 | BM9: 0 | BN9: 0 | BO9: =AY9+BL9+BM9+BN9+BC9+BG9 -> 47277 | BP9: =BO9-AM9 -> 9270 | BQ9: =IF(BP9>=0,"Positive Margin","Negative Margin") -> Positive Margin | BR9: CN Issued | BS9: =AY9-Y9-Q9-AA9-T9+BC9 -> 9270 | BT9: =IF(BS9<0, "Negative Margin at Inception", "Positive Margin at Inception") -> Positive Margin at Inception | BU9: =IFERROR(BP9/BO9,"0") -> 0.19607843 | BV9: =IF(BU9<1%,"Less Than 1%",IF(BU9>2%,"More than 2%",IF(BU9>=1%,"1% - 2%"))) -> More than 2% | BW9: =BM9+BN9 -> 0 | BX9: =AL9+AK9 -> 0 | BY9: =BW9-BX9 -> 0 | BZ9: =BM9 -> 0 | CA9: =AK9 -> 0 | CB9: =BZ9-CA9 -> 0 | CC9: Marketplace (Rewerse) | CD9: 0 | CE9: =TEXT(AN9,"mmm-yy") -> Apr-26 | CF9: =AM9-AL9-AA9 -> 38007 | CG9: =BO9-BN9 -> 47277 | CH9: =INT((D9- IF(MONTH(D9) >= 4, DATE(YEAR(D9), 4, 1), DATE(YEAR(D9)-1, 4, 1))) / 7) + 1 -> 2 | CI9: Plastic | CJ9: Plastic | CK9: =_xlfn.XLOOKUP(AR9,receivables!B:B,receivables!D:D) -> Neelesh Dixit | CL9: =AY9-Q9 -> 9270 | CM9: =CL9-Y9+Z9 -> 9270 | CN9: =BO9-AM9 -> 9270 | CO9: =AY9*118% -> 55786.86 | CP9: =-Q9*118% -> -44848.26 | CQ9: =-BZ9*118% -> 0 | CR9: =-CA9*118% -> 0 | CS9: =SUM(CO9:CR9) -> 10938.6 | CT9: Telangana - HO | CU9: Telangana - HO | CV9: =MID(G9,3,10) -> AAMCB5608A | CW9: =MID(AR9,3,10) -> AAACD5406E | CX9: 0 | CY9: 0 | CZ9: 0 | DA9: 0 | DB9: 0
B10: ="Q" & IF(ROUNDUP(MONTH(D10)/3,0)-1=0,4,ROUNDUP(MONTH(D10)/3,0)-1) -> Q1 | C10: =TEXT(AN10,"mmm-yy") -> Apr-26 | D10: 46123 | E10: SH04261101 | F10: BLACK GOLD RECYCLING PRIVATE LIMITED | G10: 27AAMCB5608A1ZX | H10: 25/PUN/INV0280 | I10: 46123 | J10: 26-27/PUR/000399 | K10: 46123 | L10: MH | M10: MH13EP3779 | N10: PET Bottle Scrap Baled - Clear | O10: 7855 | P10: 41 | Q10: =O10*P10 -> 322055 | R10: 0 | S10: =O10-R10 -> 7855 | T10: 0 | U10: 0 | V10: 0 | W10: 0 | X10: 0 | Y10: 0 | Z10: 0 | AA10: 0 | AB10: =Y10+AA10+Z10 -> 0 | AC10: 0 | AD10: =IFERROR((Q10+AB10)/S10,0) -> 41 | AE10: 0 | AF10: 0 | AG10: 0 | AH10: 0 | AI10: 0 | AJ10: 0 | AK10: 0 | AL10: 0 | AM10: =Q10+AB10+AL10+AK10+AJ10+T10+AE10 -> 322055 | AN10: 46123 | AO10: 36/REW/27IN00003 | AP10: 832139000052985017 | AQ10: DALMIA POLYPRO INDUSTRIES PRIVATE LIMITED (27) | AR10: 27AAACD5406E1Z3 | AS10: Koregaon Bhima Maharashtra 412216 | AT10: Dindori | AU10: Maharashtra | AV10: 0 | AW10: 7855 | AX10: 46 | AY10: =AW10*AX10 -> 361330 | AZ10: =AW10=O10 -> TRUE | BA10: 0 | BB10: =AW10-BA10 -> 7855 | BC10: 0 | BD10: Regular | BE10: 0 | BF10: 0 | BG10: 0 | BH10: 36/REW/27CN00026 | BI10: 46181 | BJ10: 0 | BK10: 0 | BL10: 0 | BM10: -8421.68 | BN10: 0 | BO10: =AY10+BL10+BM10+BN10+BC10+BG10 -> 352908.32 | BP10: =BO10-AM10 -> 30853.32 | BQ10: =IF(BP10>=0,"Positive Margin","Negative Margin") -> Positive Margin | BR10: CN Issued | BS10: =AY10-Y10-Q10-AA10-T10+BC10 -> 39275 | BT10: =IF(BS10<0, "Negative Margin at Inception", "Positive Margin at Inception") -> Positive Margin at Inception | BU10: =IFERROR(BP10/BO10,"0") -> 0.087425879 | BV10: =IF(BU10<1%,"Less Than 1%",IF(BU10>2%,"More than 2%",IF(BU10>=1%,"1% - 2%"))) -> More than 2% | BW10: =BM10+BN10 -> -8421.68 | BX10: =AL10+AK10 -> 0 | BY10: =BW10-BX10 -> -8421.68 | BZ10: =BM10 -> -8421.68 | CA10: =AK10 -> 0 | CB10: =BZ10-CA10 -> -8421.68 | CC10: Marketplace (Rewerse) | CD10: 0 | CE10: =TEXT(AN10,"mmm-yy") -> Apr-26 | CF10: =AM10-AL10-AA10 -> 322055 | CG10: =BO10-BN10 -> 352908.32 | CH10: =INT((D10- IF(MONTH(D10) >= 4, DATE(YEAR(D10), 4, 1), DATE(YEAR(D10)-1, 4, 1))) / 7) + 1 -> 2 | CI10: Plastic | CJ10: Plastic | CK10: =_xlfn.XLOOKUP(AR10,receivables!B:B,receivables!D:D) -> Neelesh Dixit | CL10: =AY10-Q10 -> 39275 | CM10: =CL10-Y10+Z10 -> 39275 | CN10: =BO10-AM10 -> 30853.32 | CO10: =AY10*118% -> 426369.4 | CP10: =-Q10*118% -> -380024.9 | CQ10: =-BZ10*118% -> 9937.5824 | CR10: =-CA10*118% -> 0 | CS10: =SUM(CO10:CR10) -> 56282.082 | CT10: Telangana - HO | CU10: Telangana - HO | CV10: =MID(G10,3,10) -> AAMCB5608A | CW10: =MID(AR10,3,10) -> AAACD5406E | CX10: 0 | CY10: 0 | CZ10: 0 | DA10: 0 | DB10: 0
B11: ="Q" & IF(ROUNDUP(MONTH(D11)/3,0)-1=0,4,ROUNDUP(MONTH(D11)/3,0)-1) -> Q1 | C11: =TEXT(AN11,"mmm-yy") -> Apr-26 | D11: 46123 | E11: SH04261101 | F11: BLACK GOLD RECYCLING PRIVATE LIMITED | G11: 27AAMCB5608A1ZX | H11: 25/PUN/INV0280 | I11: 46123 | J11: 26-27/PUR/000399 | K11: 46123 | L11: MH | M11: MH13EP3779 | N11: PET Bottle Scrap Baled - Green | O11: 614 | P11: 36 | Q11: =O11*P11 -> 22104 | R11: 0 | S11: =O11-R11 -> 614 | T11: 0 | U11: 0 | V11: 0 | W11: 0 | X11: 0 | Y11: 0 | Z11: 0 | AA11: 0 | AB11: =Y11+AA11+Z11 -> 0 | AC11: 0 | AD11: =IFERROR((Q11+AB11)/S11,0) -> 36 | AE11: 0 | AF11: 0 | AG11: 0 | AH11: 0 | AI11: 0 | AJ11: 0 | AK11: 0 | AL11: 0 | AM11: =Q11+AB11+AL11+AK11+AJ11+T11+AE11 -> 22104 | AN11: 46123 | AO11: 36/REW/27IN00003 | AP11: 832139000052985017 | AQ11: DALMIA POLYPRO INDUSTRIES PRIVATE LIMITED (27) | AR11: 27AAACD5406E1Z3 | AS11: Koregaon Bhima Maharashtra 412216 | AT11: Dindori | AU11: Maharashtra | AV11: 0 | AW11: 614 | AX11: 36 | AY11: =AW11*AX11 -> 22104 | AZ11: =AW11=O11 -> TRUE | BA11: 0 | BB11: =AW11-BA11 -> 614 | BC11: 0 | BD11: Regular | BE11: 0 | BF11: 0 | BG11: 0 | BH11: 36/REW/27CN00026 | BI11: 46181 | BJ11: 0 | BK11: 0 | BL11: 0 | BM11: 0 | BN11: 0 | BO11: =AY11+BL11+BM11+BN11+BC11+BG11 -> 22104 | BP11: =BO11-AM11 -> 0 | BQ11: =IF(BP11>=0,"Positive Margin","Negative Margin") -> Positive Margin | BR11: CN Issued | BS11: =AY11-Y11-Q11-AA11-T11+BC11 -> 0 | BT11: =IF(BS11<0, "Negative Margin at Inception", "Positive Margin at Inception") -> Positive Margin at Inception | BU11: =IFERROR(BP11/BO11,"0") -> 0 | BV11: =IF(BU11<1%,"Less Than 1%",IF(BU11>2%,"More than 2%",IF(BU11>=1%,"1% - 2%"))) -> Less Than 1% | BW11: =BM11+BN11 -> 0 | BX11: =AL11+AK11 -> 0 | BY11: =BW11-BX11 -> 0 | BZ11: =BM11 -> 0 | CA11: =AK11 -> 0 | CB11: =BZ11-CA11 -> 0 | CC11: Marketplace (Rewerse) | CD11: 0 | CE11: =TEXT(AN11,"mmm-yy") -> Apr-26 | CF11: =AM11-AL11-AA11 -> 22104 | CG11: =BO11-BN11 -> 22104 | CH11: =INT((D11- IF(MONTH(D11) >= 4, DATE(YEAR(D11), 4, 1), DATE(YEAR(D11)-1, 4, 1))) / 7) + 1 -> 2 | CI11: Plastic | CJ11: Plastic | CK11: =_xlfn.XLOOKUP(AR11,receivables!B:B,receivables!D:D) -> Neelesh Dixit | CL11: =AY11-Q11 -> 0 | CM11: =CL11-Y11+Z11 -> 0 | CN11: =BO11-AM11 -> 0 | CO11: =AY11*118% -> 26082.72 | CP11: =-Q11*118% -> -26082.72 | CQ11: =-BZ11*118% -> 0 | CR11: =-CA11*118% -> 0 | CS11: =SUM(CO11:CR11) -> 0 | CT11: Telangana - HO | CU11: Telangana - HO | CV11: =MID(G11,3,10) -> AAMCB5608A | CW11: =MID(AR11,3,10) -> AAACD5406E | CX11: 0 | CY11: 0 | CZ11: 0 | DA11: 0 | DB11: 0
B12: ="Q" & IF(ROUNDUP(MONTH(D12)/3,0)-1=0,4,ROUNDUP(MONTH(D12)/3,0)-1) -> Q1 | C12: =TEXT(AN12,"mmm-yy") -> Apr-26 | D12: 46123 | E12: SH04261101 | F12: BLACK GOLD RECYCLING PRIVATE LIMITED | G12: 27AAMCB5608A1ZX | H12: 25/PUN/INV0280 | I12: 46123 | J12: 26-27/PUR/000399 | K12: 46123 | L12: MH | M12: MH13EP3779 | N12: PET Liquor Bottle Scrap Baled | O12: 596 | P12: 41 | Q12: =O12*P12 -> 24436 | R12: 0 | S12: =O12-R12 -> 596 | T12: 0 | U12: 0 | V12: 0 | W12: 0 | X12: 0 | Y12: 0 | Z12: 0 | AA12: 0 | AB12: =Y12+AA12+Z12 -> 0 | AC12: 0 | AD12: =IFERROR((Q12+AB12)/S12,0) -> 41 | AE12: 0 | AF12: 0 | AG12: 0 | AH12: 0 | AI12: 0 | AJ12: 0 | AK12: 0 | AL12: 0 | AM12: =Q12+AB12+AL12+AK12+AJ12+T12+AE12 -> 24436 | AN12: 46123 | AO12: 36/REW/27IN00003 | AP12: 832139000052985017 | AQ12: DALMIA POLYPRO INDUSTRIES PRIVATE LIMITED (27) | AR12: 27AAACD5406E1Z3 | AS12: Koregaon Bhima Maharashtra 412216 | AT12: Dindori | AU12: Maharashtra | AV12: 0 | AW12: 596 | AX12: 51 | AY12: =AW12*AX12 -> 30396 | AZ12: =AW12=O12 -> TRUE | BA12: 0 | BB12: =AW12-BA12 -> 596 | BC12: 0 | BD12: Regular | BE12: 0 | BF12: 0 | BG12: 0 | BH12: 36/REW/27CN00026 | BI12: 46181 | BJ12: 0 | BK12: 0 | BL12: 0 | BM12: 0 | BN12: 0 | BO12: =AY12+BL12+BM12+BN12+BC12+BG12 -> 30396 | BP12: =BO12-AM12 -> 5960 | BQ12: =IF(BP12>=0,"Positive Margin","Negative Margin") -> Positive Margin | BR12: CN Issued | BS12: =AY12-Y12-Q12-AA12-T12+BC12 -> 5960 | BT12: =IF(BS12<0, "Negative Margin at Inception", "Positive Margin at Inception") -> Positive Margin at Inception | BU12: =IFERROR(BP12/BO12,"0") -> 0.19607843 | BV12: =IF(BU12<1%,"Less Than 1%",IF(BU12>2%,"More than 2%",IF(BU12>=1%,"1% - 2%"))) -> More than 2% | BW12: =BM12+BN12 -> 0 | BX12: =AL12+AK12 -> 0 | BY12: =BW12-BX12 -> 0 | BZ12: =BM12 -> 0 | CA12: =AK12 -> 0 | CB12: =BZ12-CA12 -> 0 | CC12: Marketplace (Rewerse) | CD12: 0 | CE12: =TEXT(AN12,"mmm-yy") -> Apr-26 | CF12: =AM12-AL12-AA12 -> 24436 | CG12: =BO12-BN12 -> 30396 | CH12: =INT((D12- IF(MONTH(D12) >= 4, DATE(YEAR(D12), 4, 1), DATE(YEAR(D12)-1, 4, 1))) / 7) + 1 -> 2 | CI12: Plastic | CJ12: Plastic | CK12: =_xlfn.XLOOKUP(AR12,receivables!B:B,receivables!D:D) -> Neelesh Dixit | CL12: =AY12-Q12 -> 5960 | CM12: =CL12-Y12+Z12 -> 5960 | CN12: =BO12-AM12 -> 5960 | CO12: =AY12*118% -> 35867.28 | CP12: =-Q12*118% -> -28834.48 | CQ12: =-BZ12*118% -> 0 | CR12: =-CA12*118% -> 0 | CS12: =SUM(CO12:CR12) -> 7032.8 | CT12: Telangana - HO | CU12: Telangana - HO | CV12: =MID(G12,3,10) -> AAMCB5608A | CW12: =MID(AR12,3,10) -> AAACD5406E | CX12: 0 | CY12: 0 | CZ12: 0 | DA12: 0 | DB12: 0
B13: ="Q" & IF(ROUNDUP(MONTH(D13)/3,0)-1=0,4,ROUNDUP(MONTH(D13)/3,0)-1) -> Q1 | C13: =TEXT(AN13,"mmm-yy") -> Apr-26 | D13: 46127 | E13: SH04261505 | F13: BLACK GOLD RECYCLING PRIVATE LIMITED | G13: 27AAMCB5608A1ZX | H13: 25/PUN/INV0282 | I13: 46127 | J13: 26-27/PUR/000612 | K13: 46127 | L13: MH | M13: DD01AC9819 | N13: PET Bottle Scrap Baled - Clear | O13: 9044 | P13: 41 | Q13: =O13*P13 -> 370804 | R13: 0 | S13: =O13-R13 -> 9044 | T13: 0 | U13: 0 | V13: 0 | W13: 0 | X13: 0 | Y13: 0 | Z13: 0 | AA13: 0 | AB13: =Y13+AA13+Z13 -> 0 | AC13: 0 | AD13: =IFERROR((Q13+AB13)/S13,0) -> 41 | AE13: 0 | AF13: 0 | AG13: 0 | AH13: 0 | AI13: 0 | AJ13: 0 | AK13: 0 | AL13: 0 | AM13: =Q13+AB13+AL13+AK13+AJ13+T13+AE13 -> 370804 | AN13: 46127 | AO13: 36/REW/27IN00004 | AP13: 832139000052985017 | AQ13: DALMIA POLYPRO INDUSTRIES PRIVATE LIMITED (27) | AR13: 27AAACD5406E1Z3 | AS13: Koregaon Bhima Maharashtra 412216 | AT13: Dindori | AU13: Maharashtra | AV13: 0 | AW13: 9044 | AX13: 52 | AY13: =AW13*AX13 -> 470288 | AZ13: =AW13=O13 -> TRUE | BA13: 0 | BB13: =AW13-BA13 -> 9044 | BC13: 0 | BD13: Regular | BE13: 0 | BF13: 0 | BG13: 0 | BH13: 36/REW/27CN00027 | BI13: 46181 | BJ13: 0 | BK13: 0 | BL13: 0 | BM13: -12971.6 | BN13: 0 | BO13: =AY13+BL13+BM13+BN13+BC13+BG13 -> 457316.4 | BP13: =BO13-AM13 -> 86512.4 | BQ13: =IF(BP13>=0,"Positive Margin","Negative Margin") -> Positive Margin | BR13: CN Issued | BS13: =AY13-Y13-Q13-AA13-T13+BC13 -> 99484 | BT13: =IF(BS13<0, "Negative Margin at Inception", "Positive Margin at Inception") -> Positive Margin at Inception | BU13: =IFERROR(BP13/BO13,"0") -> 0.18917406 | BV13: =IF(BU13<1%,"Less Than 1%",IF(BU13>2%,"More than 2%",IF(BU13>=1%,"1% - 2%"))) -> More than 2% | BW13: =BM13+BN13 -> -12971.6 | BX13: =AL13+AK13 -> 0 | BY13: =BW13-BX13 -> -12971.6 | BZ13: =BM13 -> -12971.6 | CA13: =AK13 -> 0 | CB13: =BZ13-CA13 -> -12971.6 | CC13: Marketplace (Rewerse) | CD13: 0 | CE13: =TEXT(AN13,"mmm-yy") -> Apr-26 | CF13: =AM13-AL13-AA13 -> 370804 | CG13: =BO13-BN13 -> 457316.4 | CH13: =INT((D13- IF(MONTH(D13) >= 4, DATE(YEAR(D13), 4, 1), DATE(YEAR(D13)-1, 4, 1))) / 7) + 1 -> 3 | CI13: Plastic | CJ13: Plastic | CK13: =_xlfn.XLOOKUP(AR13,receivables!B:B,receivables!D:D) -> Neelesh Dixit | CL13: =AY13-Q13 -> 99484 | CM13: =CL13-Y13+Z13 -> 99484 | CN13: =BO13-AM13 -> 86512.4 | CO13: =AY13*118% -> 554939.84 | CP13: =-Q13*118% -> -437548.72 | CQ13: =-BZ13*118% -> 15306.488 | CR13: =-CA13*118% -> 0 | CS13: =SUM(CO13:CR13) -> 132697.61 | CT13: Telangana - HO | CU13: Telangana - HO | CV13: =MID(G13,3,10) -> AAMCB5608A | CW13: =MID(AR13,3,10) -> AAACD5406E | CX13: 0 | CY13: 0 | CZ13: 0 | DA13: 0 | DB13: 0
B14: ="Q" & IF(ROUNDUP(MONTH(D14)/3,0)-1=0,4,ROUNDUP(MONTH(D14)/3,0)-1) -> Q1 | C14: =TEXT(AN14,"mmm-yy") -> Apr-26 | D14: 46127 | E14: SH04261505 | F14: BLACK GOLD RECYCLING PRIVATE LIMITED | G14: 27AAMCB5608A1ZX | H14: 25/PUN/INV0282 | I14: 46127 | J14: 26-27/PUR/000612 | K14: 46127 | L14: MH | M14: DD01AC9819 | N14: PET Bottle Scrap Baled - Green | O14: 466 | P14: 36 | Q14: =O14*P14 -> 16776 | R14: 0 | S14: =O14-R14 -> 466 | T14: 0 | U14: 0 | V14: 0 | W14: 0 | X14: 0 | Y14: 0 | Z14: 0 | AA14: 0 | AB14: =Y14+AA14+Z14 -> 0 | AC14: 0 | AD14: =IFERROR((Q14+AB14)/S14,0) -> 36 | AE14: 0 | AF14: 0 | AG14: 0 | AH14: 0 | AI14: 0 | AJ14: 0 | AK14: 0 | AL14: 0 | AM14: =Q14+AB14+AL14+AK14+AJ14+T14+AE14 -> 16776 | AN14: 46127 | AO14: 36/REW/27IN00004 | AP14: 832139000052985017 | AQ14: DALMIA POLYPRO INDUSTRIES PRIVATE LIMITED (27) | AR14: 27AAACD5406E1Z3 | AS14: Koregaon Bhima Maharashtra 412216 | AT14: Dindori | AU14: Maharashtra | AV14: 0 | AW14: 466 | AX14: 42 | AY14: =AW14*AX14 -> 19572 | AZ14: =AW14=O14 -> TRUE | BA14: 0 | BB14: =AW14-BA14 -> 466 | BC14: 0 | BD14: Regular | BE14: 0 | BF14: 0 | BG14: 0 | BH14: 36/REW/27CN00027 | BI14: 46181 | BJ14: 0 | BK14: 0 | BL14: 0 | BM14: 0 | BN14: 0 | BO14: =AY14+BL14+BM14+BN14+BC14+BG14 -> 19572 | BP14: =BO14-AM14 -> 2796 | BQ14: =IF(BP14>=0,"Positive Margin","Negative Margin") -> Positive Margin | BR14: CN Issued | BS14: =AY14-Y14-Q14-AA14-T14+BC14 -> 2796 | BT14: =IF(BS14<0, "Negative Margin at Inception", "Positive Margin at Inception") -> Positive Margin at Inception | BU14: =IFERROR(BP14/BO14,"0") -> 0.14285714 | BV14: =IF(BU14<1%,"Less Than 1%",IF(BU14>2%,"More than 2%",IF(BU14>=1%,"1% - 2%"))) -> More than 2% | BW14: =BM14+BN14 -> 0 | BX14: =AL14+AK14 -> 0 | BY14: =BW14-BX14 -> 0 | BZ14: =BM14 -> 0 | CA14: =AK14 -> 0 | CB14: =BZ14-CA14 -> 0 | CC14: Marketplace (Rewerse) | CD14: 0 | CE14: =TEXT(AN14,"mmm-yy") -> Apr-26 | CF14: =AM14-AL14-AA14 -> 16776 | CG14: =BO14-BN14 -> 19572 | CH14: =INT((D14- IF(MONTH(D14) >= 4, DATE(YEAR(D14), 4, 1), DATE(YEAR(D14)-1, 4, 1))) / 7) + 1 -> 3 | CI14: Plastic | CJ14: Plastic | CK14: =_xlfn.XLOOKUP(AR14,receivables!B:B,receivables!D:D) -> Neelesh Dixit | CL14: =AY14-Q14 -> 2796 | CM14: =CL14-Y14+Z14 -> 2796 | CN14: =BO14-AM14 -> 2796 | CO14: =AY14*118% -> 23094.96 | CP14: =-Q14*118% -> -19795.68 | CQ14: =-BZ14*118% -> 0 | CR14: =-CA14*118% -> 0 | CS14: =SUM(CO14:CR14) -> 3299.28 | CT14: Telangana - HO | CU14: Telangana - HO | CV14: =MID(G14,3,10) -> AAMCB5608A | CW14: =MID(AR14,3,10) -> AAACD5406E | CX14: 0 | CY14: 0 | CZ14: 0 | DA14: 0 | DB14: 0
B15: ="Q" & IF(ROUNDUP(MONTH(D15)/3,0)-1=0,4,ROUNDUP(MONTH(D15)/3,0)-1) -> Q1 | C15: =TEXT(AN15,"mmm-yy") -> Apr-26 | D15: 46130 | E15: SH04261806 | F15: BLACK GOLD RECYCLING PRIVATE LIMITED | G15: 27AAMCB5608A1ZX | H15: 25/PUN/INV0285 | I15: 46130 | J15: 26-27/PUR/000939 | K15: 46130 | L15: MH | M15: DD01AC9274 | N15: PET Bottle Scrap Baled - Clear | O15: 8199 | P15: 41.5 | Q15: =O15*P15 -> 340258.5 | R15: 0 | S15: =O15-R15 -> 8199 | T15: 0 | U15: 0 | V15: 0 | W15: 0 | X15: 0 | Y15: 0 | Z15: 0 | AA15: 0 | AB15: =Y15+AA15+Z15 -> 0 | AC15: 0 | AD15: =IFERROR((Q15+AB15)/S15,0) -> 41.5 | AE15: 0 | AF15: 0 | AG15: 0 | AH15: 0 | AI15: 0 | AJ15: 0 | AK15: 0 | AL15: 0 | AM15: =Q15+AB15+AL15+AK15+AJ15+T15+AE15 -> 340258.5 | AN15: 46130 | AO15: 36/REW/27IN00005 | AP15: 832139000052985017 | AQ15: DALMIA POLYPRO INDUSTRIES PRIVATE LIMITED (27) | AR15: 27AAACD5406E1Z3 | AS15: Koregaon Bhima Maharashtra 412216 | AT15: Dindori | AU15: Maharashtra | AV15: 0 | AW15: 8199 | AX15: 52 | AY15: =AW15*AX15 -> 426348 | AZ15: =AW15=O15 -> TRUE | BA15: 0 | BB15: =AW15-BA15 -> 8199 | BC15: 0 | BD15: Regular | BE15: 0 | BF15: 0 | BG15: 0 | BH15: 36/REW/27CN00028 | BI15: 46181 | BJ15: 0 | BK15: 0 | BL15: 0 | BM15: -3076.84 | BN15: 0 | BO15: =AY15+BL15+BM15+BN15+BC15+BG15 -> 423271.16 | BP15: =BO15-AM15 -> 83012.66 | BQ15: =IF(BP15>=0,"Positive Margin","Negative Margin") -> Positive Margin | BR15: CN Issued | BS15: =AY15-Y15-Q15-AA15-T15+BC15 -> 86089.5 | BT15: =IF(BS15<0, "Negative Margin at Inception", "Positive Margin at Inception") -> Positive Margin at Inception | BU15: =IFERROR(BP15/BO15,"0") -> 0.1961217 | BV15: =IF(BU15<1%,"Less Than 1%",IF(BU15>2%,"More than 2%",IF(BU15>=1%,"1% - 2%"))) -> More than 2% | BW15: =BM15+BN15 -> -3076.84 | BX15: =AL15+AK15 -> 0 | BY15: =BW15-BX15 -> -3076.84 | BZ15: =BM15 -> -3076.84 | CA15: =AK15 -> 0 | CB15: =BZ15-CA15 -> -3076.84 | CC15: Marketplace (Rewerse) | CD15: 0 | CE15: =TEXT(AN15,"mmm-yy") -> Apr-26 | CF15: =AM15-AL15-AA15 -> 340258.5 | CG15: =BO15-BN15 -> 423271.16 | CH15: =INT((D15- IF(MONTH(D15) >= 4, DATE(YEAR(D15), 4, 1), DATE(YEAR(D15)-1, 4, 1))) / 7) + 1 -> 3 | CI15: Plastic | CJ15: Plastic | CK15: =_xlfn.XLOOKUP(AR15,receivables!B:B,receivables!D:D) -> Neelesh Dixit | CL15: =AY15-Q15 -> 86089.5 | CM15: =CL15-Y15+Z15 -> 86089.5 | CN15: =BO15-AM15 -> 83012.66 | CO15: =AY15*118% -> 503090.64 | CP15: =-Q15*118% -> -401505.03 | CQ15: =-BZ15*118% -> 3630.6712 | CR15: =-CA15*118% -> 0 | CS15: =SUM(CO15:CR15) -> 105216.28 | CT15: Telangana - HO | CU15: Telangana - HO | CV15: =MID(G15,3,10) -> AAMCB5608A | CW15: =MID(AR15,3,10) -> AAACD5406E | CX15: 0 | CY15: 0 | CZ15: 0 | DA15: 0 | DB15: 0
B16: ="Q" & IF(ROUNDUP(MONTH(D16)/3,0)-1=0,4,ROUNDUP(MONTH(D16)/3,0)-1) -> Q1 | C16: =TEXT(AN16,"mmm-yy") -> Apr-26 | D16: 46130 | E16: SH04261806 | F16: BLACK GOLD RECYCLING PRIVATE LIMITED | G16: 27AAMCB5608A1ZX | H16: 25/PUN/INV0285 | I16: 46130 | J16: 26-27/PUR/000939 | K16: 46130 | L16: MH | M16: DD01AC9274 | N16: PET Bottle Scrap Baled - Green | O16: 690 | P16: 36.5 | Q16: =O16*P16 -> 25185 | R16: 0 | S16: =O16-R16 -> 690 | T16: 0 | U16: 0 | V16: 0 | W16: 0 | X16: 0 | Y16: 0 | Z16: 0 | AA16: 0 | AB16: =Y16+AA16+Z16 -> 0 | AC16: 0 | AD16: =IFERROR((Q16+AB16)/S16,0) -> 36.5 | AE16: 0 | AF16: 0 | AG16: 0 | AH16: 0 | AI16: 0 | AJ16: 0 | AK16: 0 | AL16: 0 | AM16: =Q16+AB16+AL16+AK16+AJ16+T16+AE16 -> 25185 | AN16: 46130 | AO16: 36/REW/27IN00005 | AP16: 832139000052985017 | AQ16: DALMIA POLYPRO INDUSTRIES PRIVATE LIMITED (27) | AR16: 27AAACD5406E1Z3 | AS16: Koregaon Bhima Maharashtra 412216 | AT16: Dindori | AU16: Maharashtra | AV16: 0 | AW16: 690 | AX16: 42 | AY16: =AW16*AX16 -> 28980 | AZ16: =AW16=O16 -> TRUE | BA16: 0 | BB16: =AW16-BA16 -> 690 | BC16: 0 | BD16: Regular | BE16: 0 | BF16: 0 | BG16: 0 | BH16: 36/REW/27CN00028 | BI16: 46181 | BJ16: 0 | BK16: 0 | BL16: 0 | BM16: 0 | BN16: 0 | BO16: =AY16+BL16+BM16+BN16+BC16+BG16 -> 28980 | BP16: =BO16-AM16 -> 3795 | BQ16: =IF(BP16>=0,"Positive Margin","Negative Margin") -> Positive Margin | BR16: CN Issued | BS16: =AY16-Y16-Q16-AA16-T16+BC16 -> 3795 | BT16: =IF(BS16<0, "Negative Margin at Inception", "Positive Margin at Inception") -> Positive Margin at Inception | BU16: =IFERROR(BP16/BO16,"0") -> 0.13095238 | BV16: =IF(BU16<1%,"Less Than 1%",IF(BU16>2%,"More than 2%",IF(BU16>=1%,"1% - 2%"))) -> More than 2% | BW16: =BM16+BN16 -> 0 | BX16: =AL16+AK16 -> 0 | BY16: =BW16-BX16 -> 0 | BZ16: =BM16 -> 0 | CA16: =AK16 -> 0 | CB16: =BZ16-CA16 -> 0 | CC16: Marketplace (Rewerse) | CD16: 0 | CE16: =TEXT(AN16,"mmm-yy") -> Apr-26 | CF16: =AM16-AL16-AA16 -> 25185 | CG16: =BO16-BN16 -> 28980 | CH16: =INT((D16- IF(MONTH(D16) >= 4, DATE(YEAR(D16), 4, 1), DATE(YEAR(D16)-1, 4, 1))) / 7) + 1 -> 3 | CI16: Plastic | CJ16: Plastic | CK16: =_xlfn.XLOOKUP(AR16,receivables!B:B,receivables!D:D) -> Neelesh Dixit | CL16: =AY16-Q16 -> 3795 | CM16: =CL16-Y16+Z16 -> 3795 | CN16: =BO16-AM16 -> 3795 | CO16: =AY16*118% -> 34196.4 | CP16: =-Q16*118% -> -29718.3 | CQ16: =-BZ16*118% -> 0 | CR16: =-CA16*118% -> 0 | CS16: =SUM(CO16:CR16) -> 4478.1 | CT16: Telangana - HO | CU16: Telangana - HO | CV16: =MID(G16,3,10) -> AAMCB5608A | CW16: =MID(AR16,3,10) -> AAACD5406E | CX16: 0 | CY16: 0 | CZ16: 0 | DA16: 0 | DB16: 0
B17: ="Q" & IF(ROUNDUP(MONTH(D17)/3,0)-1=0,4,ROUNDUP(MONTH(D17)/3,0)-1) -> Q1 | C17: =TEXT(AN17,"mmm-yy") -> Apr-26 | D17: 46130 | E17: SH04261806 | F17: BLACK GOLD RECYCLING PRIVATE LIMITED | G17: 27AAMCB5608A1ZX | H17: 25/PUN/INV0285 | I17: 46130 | J17: 26-27/PUR/000939 | K17: 46130 | L17: MH | M17: DD01AC9274 | N17: PET Liquor Bottle Scrap Baled | O17: 751 | P17: 41.5 | Q17: =O17*P17 -> 31166.5 | R17: 0 | S17: =O17-R17 -> 751 | T17: 0 | U17: 0 | V17: 0 | W17: 0 | X17: 0 | Y17: 0 | Z17: 0 | AA17: 0 | AB17: =Y17+AA17+Z17 -> 0 | AC17: 0 | AD17: =IFERROR((Q17+AB17)/S17,0) -> 41.5 | AE17: 0 | AF17: 0 | AG17: 0 | AH17: 0 | AI17: 0 | AJ17: 0 | AK17: 0 | AL17: 0 | AM17: =Q17+AB17+AL17+AK17+AJ17+T17+AE17 -> 31166.5 | AN17: 46130 | AO17: 36/REW/27IN00005 | AP17: 832139000052985017 | AQ17: DALMIA POLYPRO INDUSTRIES PRIVATE LIMITED (27) | AR17: 27AAACD5406E1Z3 | AS17: Koregaon Bhima Maharashtra 412216 | AT17: Dindori | AU17: Maharashtra | AV17: 0 | AW17: 751 | AX17: 57 | AY17: =AW17*AX17 -> 42807 | AZ17: =AW17=O17 -> TRUE | BA17: 0 | BB17: =AW17-BA17 -> 751 | BC17: 0 | BD17: Regular | BE17: 0 | BF17: 0 | BG17: 0 | BH17: 36/REW/27CN00028 | BI17: 46181 | BJ17: 0 | BK17: 0 | BL17: 0 | BM17: 0 | BN17: 0 | BO17: =AY17+BL17+BM17+BN17+BC17+BG17 -> 42807 | BP17: =BO17-AM17 -> 11640.5 | BQ17: =IF(BP17>=0,"Positive Margin","Negative Margin") -> Positive Margin | BR17: CN Issued | BS17: =AY17-Y17-Q17-AA17-T17+BC17 -> 11640.5 | BT17: =IF(BS17<0, "Negative Margin at Inception", "Positive Margin at Inception") -> Positive Margin at Inception | BU17: =IFERROR(BP17/BO17,"0") -> 0.27192982 | BV17: =IF(BU17<1%,"Less Than 1%",IF(BU17>2%,"More than 2%",IF(BU17>=1%,"1% - 2%"))) -> More than 2% | BW17: =BM17+BN17 -> 0 | BX17: =AL17+AK17 -> 0 | BY17: =BW17-BX17 -> 0 | BZ17: =BM17 -> 0 | CA17: =AK17 -> 0 | CB17: =BZ17-CA17 -> 0 | CC17: Marketplace (Rewerse) | CD17: 0 | CE17: =TEXT(AN17,"mmm-yy") -> Apr-26 | CF17: =AM17-AL17-AA17 -> 31166.5 | CG17: =BO17-BN17 -> 42807 | CH17: =INT((D17- IF(MONTH(D17) >= 4, DATE(YEAR(D17), 4, 1), DATE(YEAR(D17)-1, 4, 1))) / 7) + 1 -> 3 | CI17: Plastic | CJ17: Plastic | CK17: =_xlfn.XLOOKUP(AR17,receivables!B:B,receivables!D:D) -> Neelesh Dixit | CL17: =AY17-Q17 -> 11640.5 | CM17: =CL17-Y17+Z17 -> 11640.5 | CN17: =BO17-AM17 -> 11640.5 | CO17: =AY17*118% -> 50512.26 | CP17: =-Q17*118% -> -36776.47 | CQ17: =-BZ17*118% -> 0 | CR17: =-CA17*118% -> 0 | CS17: =SUM(CO17:CR17) -> 13735.79 | CT17: Telangana - HO | CU17: Telangana - HO | CV17: =MID(G17,3,10) -> AAMCB5608A | CW17: =MID(AR17,3,10) -> AAACD5406E | CX17: 0 | CY17: 0 | CZ17: 0 | DA17: 0 | DB17: 0
B18: ="Q" & IF(ROUNDUP(MONTH(D18)/3,0)-1=0,4,ROUNDUP(MONTH(D18)/3,0)-1) -> Q1 | C18: =TEXT(AN18,"mmm-yy") -> Apr-26 | D18: 46134 | E18: SH04262206 | F18: BLACK GOLD RECYCLING PRIVATE LIMITED | G18: 27AAMCB5608A1ZX | H18: 25/PUN/INV0286 | I18: 46134 | J18: 26-27/PUR/001265 | K18: 46134 | L18: MH | M18: MH27DT1409 | N18: PET Bottle Scrap Baled - Clear | O18: 8711 | P18: 42 | Q18: =O18*P18 -> 365862 | R18: 0 | S18: =O18-R18 -> 8711 | T18: 0 | U18: 0 | V18: 0 | W18: 0 | X18: 0 | Y18: 0 | Z18: 0 | AA18: 0 | AB18: =Y18+AA18+Z18 -> 0 | AC18: 0 | AD18: =IFERROR((Q18+AB18)/S18,0) -> 42 | AE18: 0 | AF18: 0 | AG18: 0 | AH18: 0 | AI18: 0 | AJ18: 0 | AK18: 0 | AL18: 0 | AM18: =Q18+AB18+AL18+AK18+AJ18+T18+AE18 -> 365862 | AN18: 46134 | AO18: 36/REW/27IN00006 | AP18: 832139000052985017 | AQ18: DALMIA POLYPRO INDUSTRIES PRIVATE LIMITED (27) | AR18: 27AAACD5406E1Z3 | AS18: Bhima Maharashtra 412216 | AT18: Dindori | AU18: Maharashtra | AV18: 0 | AW18: 8711 | AX18: 52 | AY18: =AW18*AX18 -> 452972 | AZ18: =AW18=O18 -> TRUE | BA18: 0 | BB18: =AW18-BA18 -> 8711 | BC18: 0 | BD18: Regular | BE18: 0 | BF18: 0 | BG18: 0 | BH18: 36/REW/27CN00029 | BI18: 46181 | BJ18: 0 | BK18: 0 | BL18: 0 | BM18: -4975.88 | BN18: 0 | BO18: =AY18+BL18+BM18+BN18+BC18+BG18 -> 447996.12 | BP18: =BO18-AM18 -> 82134.12 | BQ18: =IF(BP18>=0,"Positive Margin","Negative Margin") -> Positive Margin | BR18: CN Issued | BS18: =AY18-Y18-Q18-AA18-T18+BC18 -> 87110 | BT18: =IF(BS18<0, "Negative Margin at Inception", "Positive Margin at Inception") -> Positive Margin at Inception | BU18: =IFERROR(BP18/BO18,"0") -> 0.18333668 | BV18: =IF(BU18<1%,"Less Than 1%",IF(BU18>2%,"More than 2%",IF(BU18>=1%,"1% - 2%"))) -> More than 2% | BW18: =BM18+BN18 -> -4975.88 | BX18: =AL18+AK18 -> 0 | BY18: =BW18-BX18 -> -4975.88 | BZ18: =BM18 -> -4975.88 | CA18: =AK18 -> 0 | CB18: =BZ18-CA18 -> -4975.88 | CC18: Marketplace (Rewerse) | CD18: 0 | CE18: =TEXT(AN18,"mmm-yy") -> Apr-26 | CF18: =AM18-AL18-AA18 -> 365862 | CG18: =BO18-BN18 -> 447996.12 | CH18: =INT((D18- IF(MONTH(D18) >= 4, DATE(YEAR(D18), 4, 1), DATE(YEAR(D18)-1, 4, 1))) / 7) + 1 -> 4 | CI18: Plastic | CJ18: Plastic | CK18: =_xlfn.XLOOKUP(AR18,receivables!B:B,receivables!D:D) -> Neelesh Dixit | CL18: =AY18-Q18 -> 87110 | CM18: =CL18-Y18+Z18 -> 87110 | CN18: =BO18-AM18 -> 82134.12 | CO18: =AY18*118% -> 534506.96 | CP18: =-Q18*118% -> -431717.16 | CQ18: =-BZ18*118% -> 5871.5384 | CR18: =-CA18*118% -> 0 | CS18: =SUM(CO18:CR18) -> 108661.34 | CT18: Telangana - HO | CU18: Telangana - HO | CV18: =MID(G18,3,10) -> AAMCB5608A | CW18: =MID(AR18,3,10) -> AAACD5406E | CX18: 0 | CY18: 0 | CZ18: 0 | DA18: 0 | DB18: 0
