Workbook

Sheet Enterprise
D2: =TEXT(D4, "mmm-yy") -> Apr-26 | E2: =TEXT(E4, "mmm-yy") -> May-26 | F2: =TEXT(F4, "mmm-yy") -> Jun-26 | G2: =TEXT(G4, "mmm-yy") -> Jul-26 | H2: =TEXT(H4, "mmm-yy") -> Aug-26 | I2: =TEXT(I4, "mmm-yy") -> Sep-26 | J2: =TEXT(J4, "mmm-yy") -> Oct-26 | K2: =TEXT(K4, "mmm-yy") -> Nov-26 | ... O2: =TEXT(O4, "mmm-yy") -> Mar-27
D3: 30 | E3: 31 | F3: 30 | G3: 0 | H3: 0 | I3: 0 | J3: 0 | K3: 0 | L3: 0 | M3: 0 | N3: 0 | O3: 0 | P3: =SUM(D3:O3) -> 91
C4: Marketplace (Enterprise) | D4: 46113 | E4: 46143 | F4: 46174 | G4: 46204 | H4: 46235 | I4: 46266 | J4: 46296 | K4: 46327 | L4: 46357 | M4: 46388 | N4: 46419 | O4: 46447 | P4: FY 2026-27 | W4: Apr | X4: May
C5: Quantity (MT) | D5: 202.396 | E5: 162.374 | F5: 213.291 | G5: =SUMIFS(Details!$BB$4:$BB$243,Details!$C$4:$C$243,Enterprise!G$4)/1000 -> 0 | H5: =SUMIFS(Details!$BB$4:$BB$243,Details!$C$4:$C$243,Enterprise!H$4)/1000 -> 0 | I5: =SUMIFS(Details!$BB$4:$BB$243,Details!$C$4:$C$243,Enterprise!I$4)/1000 -> 0 | J5: =SUMIFS(Details!$BB$4:$BB$243,Details!$C$4:$C$243,Enterprise!J$4)/1000 -> 0 | K5: =SUMIFS(Details!$BB$4:$BB$243,Details!$C$4:$C$243,Enterprise!K$4)/1000 -> 0 | L5: =SUMIFS(Details!$BB$4:$BB$243,Details!$C$4:$C$243,Enterprise!L$4)/1000 -> 0 | M5: =SUMIFS(Details!$BB$4:$BB$243,Details!$C$4:$C$243,Enterprise!M$4)/1000 -> 0 | N5: =SUMIFS(Details!$BB$4:$BB$243,Details!$C$4:$C$243,Enterprise!N$4)/1000 -> 0 | O5: =SUMIFS(Details!$BB$4:$BB$243,Details!$C$4:$C$243,Enterprise!O$4)/1000 -> 0 | P5: =SUM(D5:O5) -> 578.061 | Q5: =Details!BB244/1000 -> 578.061 | R5: =P5-Q5 -> 0 | W5: 128151 | X5: 124831
C6: Sales | D6: 3212253.5 | E6: 2824375 | F6: 4640707 | G6: =SUMIFS(Details!$BO$4:$BO$243,Details!$C$4:$C$243,Enterprise!G$4)-G47 -> 0 | H6: =SUMIFS(Details!$BO$4:$BO$243,Details!$C$4:$C$243,Enterprise!H$4)-H47 -> 0 | I6: =SUMIFS(Details!$BO$4:$BO$243,Details!$C$4:$C$243,Enterprise!I$4)-I47 -> 0 | J6: =SUMIFS(Details!$BO$4:$BO$243,Details!$C$4:$C$243,Enterprise!J$4)-J47 -> 0 | K6: =SUMIFS(Details!$BO$4:$BO$243,Details!$C$4:$C$243,Enterprise!K$4)-K47 -> 0 | L6: =SUMIFS(Details!$BO$4:$BO$243,Details!$C$4:$C$243,Enterprise!L$4)-L47 -> 0 | M6: =SUMIFS(Details!$BO$4:$BO$243,Details!$C$4:$C$243,Enterprise!M$4)-M47 -> 0 | N6: =SUMIFS(Details!$BO$4:$BO$243,Details!$C$4:$C$243,Enterprise!N$4)-N47 -> 0 | O6: =SUMIFS(Details!$BO$4:$BO$243,Details!$C$4:$C$243,Enterprise!O$4)-O47 -> 0 | P6: =SUM(D6:O6) -> 10677336 | Q6: =Details!BO244 -> 10677336 | R6: =P6-Q6 -> 0 | W6: 120737 | X6: 111891
C7: Purchases | D7: 2748791 | E7: 2420732 | F7: 4175968 | G7: =SUMIFS(Details!$AM$4:$AM$243,Details!$C$4:$C$243,Enterprise!G$4)-SUMIFS(Details!$AB$4:$AB$243,Details!$C$4:$C$243,Enterprise!G$4) -> 0 | H7: =SUMIFS(Details!$AM$4:$AM$243,Details!$C$4:$C$243,Enterprise!H$4)-SUMIFS(Details!$AB$4:$AB$243,Details!$C$4:$C$243,Enterprise!H$4) -> 0 | I7: =SUMIFS(Details!$AM$4:$AM$243,Details!$C$4:$C$243,Enterprise!I$4)-SUMIFS(Details!$AB$4:$AB$243,Details!$C$4:$C$243,Enterprise!I$4) -> 0 | J7: =SUMIFS(Details!$AM$4:$AM$243,Details!$C$4:$C$243,Enterprise!J$4)-SUMIFS(Details!$AB$4:$AB$243,Details!$C$4:$C$243,Enterprise!J$4) -> 0 | K7: =SUMIFS(Details!$AM$4:$AM$243,Details!$C$4:$C$243,Enterprise!K$4)-SUMIFS(Details!$AB$4:$AB$243,Details!$C$4:$C$243,Enterprise!K$4) -> 0 | L7: =SUMIFS(Details!$AM$4:$AM$243,Details!$C$4:$C$243,Enterprise!L$4)-SUMIFS(Details!$AB$4:$AB$243,Details!$C$4:$C$243,Enterprise!L$4) -> 0 | M7: =SUMIFS(Details!$AM$4:$AM$243,Details!$C$4:$C$243,Enterprise!M$4)-SUMIFS(Details!$AB$4:$AB$243,Details!$C$4:$C$243,Enterprise!M$4) -> 0 | N7: =SUMIFS(Details!$AM$4:$AM$243,Details!$C$4:$C$243,Enterprise!N$4)-SUMIFS(Details!$AB$4:$AB$243,Details!$C$4:$C$243,Enterprise!N$4) -> 0 | O7: =SUMIFS(Details!$AM$4:$AM$243,Details!$C$4:$C$243,Enterprise!O$4)-SUMIFS(Details!$AB$4:$AB$243,Details!$C$4:$C$243,Enterprise!O$4) -> 0 | P7: =SUM(D7:O7) -> 9345491 | Q7: =Details!P245 -> 9345491 | R7: =P7-Q7 -> 0 | W7: 13200 | X7: 10800
C8: Gross Margin | D8: =D6-D7 -> 463462.5 | E8: =E6-E7 -> 403643 | F8: =F6-F7 -> 464739 | G8: =G6-G7 -> 0 | H8: =H6-H7 -> 0 | I8: =I6-I7 -> 0 | J8: =J6-J7 -> 0 | K8: =K6-K7 -> 0 | ... O8: =O6-O7 -> 0 | P8: =SUM(D8:O8) -> 1331844.5 | Y8: 10725 | Z8: 18150
C9: Gross Margin (%) | D9: =IFERROR((D8/D6),0) -> 0.14427955 | E9: =IFERROR((E8/E6),0) -> 0.1429141 | F9: =IFERROR((F8/F6),0) -> 0.10014401 | G9: =IFERROR((G8/G6),0) -> 0 | H9: =IFERROR((H8/H6),0) -> 0 | I9: =IFERROR((I8/I6),0) -> 0 | J9: =IFERROR((J8/J6),0) -> 0 | K9: =IFERROR((K8/K6),0) -> 0 | ... P9: =IFERROR((P8/P6),0) -> 0.12473566 | Y9: 13527 | Z9: 1100
C10: Transportation Charges | D10: =SUMIFS(Details!$AB$4:$AB$243,Details!$C$4:$C$243,Enterprise!D$4) -> 0 | E10: =SUMIFS(Details!$AB$4:$AB$243,Details!$C$4:$C$243,Enterprise!E$4) -> 0 | F10: =SUMIFS(Details!$AB$4:$AB$243,Details!$C$4:$C$243,Enterprise!F$4) -> 0 | G10: =SUMIFS(Details!$AB$4:$AB$243,Details!$C$4:$C$243,Enterprise!G$4) -> 0 | H10: =SUMIFS(Details!$AB$4:$AB$243,Details!$C$4:$C$243,Enterprise!H$4) -> 0 | I10: =SUMIFS(Details!$AB$4:$AB$243,Details!$C$4:$C$243,Enterprise!I$4) -> 0 | J10: =SUMIFS(Details!$AB$4:$AB$243,Details!$C$4:$C$243,Enterprise!J$4) -> 0 | K10: =SUMIFS(Details!$AB$4:$AB$243,Details!$C$4:$C$243,Enterprise!K$4) -> 0 | ... O10: =SUMIFS(Details!$AB$4:$AB$243,Details!$C$4:$C$243,Enterprise!O$4) -> 0 | P10: =SUM(D10:O10) -> 0 | Q10: =Details!AB244 -> 0 | R10: =P10-Q10 -> 0 | W10: =SUM(W5:W9) -> 262088 | X10: =SUM(X5:X9) -> 247522
C11: Operational Cost | D11: =SUMIFS(Details!$AC:$AC,Details!$C:$C,Enterprise!D$4) -> 249453.07 | E11: =SUMIFS(Details!$AC:$AC,Details!$C:$C,Enterprise!E$4) -> 200125.95 | F11: =SUMIFS(Details!$AC:$AC,Details!$C:$C,Enterprise!F$4) -> 336776.48 | G11: =SUMIFS(Details!$AC:$AC,Details!$C:$C,Enterprise!G$4) -> 0 | H11: =SUMIFS(Details!$AC:$AC,Details!$C:$C,Enterprise!H$4) -> 0 | I11: =SUMIFS(Details!$AC:$AC,Details!$C:$C,Enterprise!I$4) -> 0 | J11: =SUMIFS(Details!$AC:$AC,Details!$C:$C,Enterprise!J$4) -> 0 | K11: =SUMIFS(Details!$AC:$AC,Details!$C:$C,Enterprise!K$4) -> 0 | ... O11: =SUMIFS(Details!$AC:$AC,Details!$C:$C,Enterprise!O$4) -> 0 | P11: =SUM(D11:O11) -> 786355.5 | W11: =W10-D11 -> 12634.93 | X11: =X10-E11 -> 47396.045
C12: Net Margin | D12: =D6-D7-D10-D11 -> 214009.43 | E12: =E6-E7-E10-E11 -> 203517.05 | F12: =F6-F7-F10-F11 -> 127962.52 | G12: =G6-G7-G10-G11 -> 0 | H12: =H6-H7-H10-H11 -> 0 | I12: =I6-I7-I10-I11 -> 0 | J12: =J6-J7-J10-J11 -> 0 | K12: =K6-K7-K10-K11 -> 0 | ... O12: =O6-O7-O10-O11 -> 0 | P12: =SUM(D12:O12) -> 545489
C13: Net Margin (%) | D13: =IFERROR((D12/D6),0) -> 0.066622833 | E13: =IFERROR((E12/E6),0) -> 0.072057374 | F13: =IFERROR((F12/F6),0) -> 0.027573929 | G13: =IFERROR((G12/G6),0) -> 0 | H13: =IFERROR((H12/H6),0) -> 0 | I13: =IFERROR((I12/I6),0) -> 0 | J13: =IFERROR((J12/J6),0) -> 0 | K13: =IFERROR((K12/K6),0) -> 0 | ... P13: =IFERROR((P12/P6),0) -> 0.051088495
C14: Other Income | D14: 0 | E14: 0 | F14: 0 | G14: 0 | H14: 0 | I14: 0 | J14: 0 | K14: 0 | L14: 0 | M14: 0 | N14: 0 | O14: 0 | P14: =SUM(D14:O14) -> 0
C15: Transport Charges (%) | D15: =IFERROR((D10/D6),0) -> 0 | E15: =IFERROR((E10/E6),0) -> 0 | F15: =IFERROR((F10/F6),0) -> 0 | G15: =IFERROR((G10/G6),0) -> 0 | H15: =IFERROR((H10/H6),0) -> 0 | I15: =IFERROR((I10/I6),0) -> 0 | J15: =IFERROR((J10/J6),0) -> 0 | K15: =IFERROR((K10/K6),0) -> 0 | ... P15: =IFERROR((P10/P6),0) -> 0
C16: Revenue Per Kg | D16: =+D6/(D5*1000) -> 15.871131 | E16: =+E6/(E5*1000) -> 17.394256 | F16: =+F6/(F5*1000) -> 21.757632 | G16: =+G6/(G5*1000) -> #DIV/0! | H16: =+H6/(H5*1000) -> #DIV/0! | I16: =+I6/(I5*1000) -> #DIV/0! | J16: =+J6/(J5*1000) -> #DIV/0! | K16: =+K6/(K5*1000) -> #DIV/0! | ... P16: =+P6/(P5*1000) -> 18.470949
C17: Purchase Cost Per Kg | D17: =+D7/(D5*1000) -> 13.581252 | E17: =+E7/(E5*1000) -> 14.908372 | F17: =+F7/(F5*1000) -> 19.578735 | G17: =+G7/(G5*1000) -> #DIV/0! | H17: =+H7/(H5*1000) -> #DIV/0! | I17: =+I7/(I5*1000) -> #DIV/0! | J17: =+J7/(J5*1000) -> #DIV/0! | K17: =+K7/(K5*1000) -> #DIV/0! | ... P17: =+P7/(P5*1000) -> 16.166963
C18: Transportation Charges Per Kg | D18: =D10/(D5*1000) -> 0 | E18: =E10/(E5*1000) -> 0 | F18: =F10/(F5*1000) -> 0 | G18: =G10/(G5*1000) -> #DIV/0! | H18: =H10/(H5*1000) -> #DIV/0! | I18: =I10/(I5*1000) -> #DIV/0! | J18: =J10/(J5*1000) -> #DIV/0! | K18: =K10/(K5*1000) -> #DIV/0! | ... P18: =P10/(P5*1000) -> 0
C19: No. of Transactions | D19: {=IFERROR(ROWS(_xlfn.UNIQUE(_xlfn._xlws.FILTER(Details!$AO$5:$AO$243, (Details!$C$5:$C$243)=Enterprise!D$2))),0)} -> 65 | E19: {=IFERROR(ROWS(_xlfn.UNIQUE(_xlfn._xlws.FILTER(Details!$AO$5:$AO$243, (Details!$C$5:$C$243)=Enterprise!E$2))),0)} -> 46 | F19: {=IFERROR(ROWS(_xlfn.UNIQUE(_xlfn._xlws.FILTER(Details!$AO$5:$AO$243, (Details!$C$5:$C$243)=Enterprise!F$2))),0)} -> 56 | G19: {=IFERROR(ROWS(_xlfn.UNIQUE(_xlfn._xlws.FILTER(Details!$AO$5:$AO$243, (Details!$C$5:$C$243)=Enterprise!G$2))),0)} -> 0 | H19: {=IFERROR(ROWS(_xlfn.UNIQUE(_xlfn._xlws.FILTER(Details!$AO$5:$AO$243, (Details!$C$5:$C$243)=Enterprise!H$2))),0)} -> 0 | I19: {=IFERROR(ROWS(_xlfn.UNIQUE(_xlfn._xlws.FILTER(Details!$AO$5:$AO$243, (Details!$C$5:$C$243)=Enterprise!I$2))),0)} -> 0 | J19: {=IFERROR(ROWS(_xlfn.UNIQUE(_xlfn._xlws.FILTER(Details!$AO$5:$AO$243, (Details!$C$5:$C$243)=Enterprise!J$2))),0)} -> 0 | K19: {=IFERROR(ROWS(_xlfn.UNIQUE(_xlfn._xlws.FILTER(Details!$AO$5:$AO$243, (Details!$C$5:$C$243)=Enterprise!K$2))),0)} -> 0 | ... O19: {=IFERROR(ROWS(_xlfn.UNIQUE(_xlfn._xlws.FILTER(Details!$AO$5:$AO$243, (Details!$C$5:$C$243)=Enterprise!O$2))),0)} -> 0 | P19: =SUM(D19:O19) -> 167
C20: No. of Sellers (Aggregators) | D20: {=IFERROR(ROWS(_xlfn.UNIQUE(_xlfn._xlws.FILTER(MID(Details!$G$5:$G$243,3,10), (Details!$C$5:$C$243)=Enterprise!D$2))),0)} -> 1 | E20: {=IFERROR(ROWS(_xlfn.UNIQUE(_xlfn._xlws.FILTER(MID(Details!$G$5:$G$243,3,10), (Details!$C$5:$C$243)=Enterprise!E$2))),0)} -> 2 | F20: {=IFERROR(ROWS(_xlfn.UNIQUE(_xlfn._xlws.FILTER(MID(Details!$G$5:$G$243,3,10), (Details!$C$5:$C$243)=Enterprise!F$2))),0)} -> 3 | G20: {=IFERROR(ROWS(_xlfn.UNIQUE(_xlfn._xlws.FILTER(MID(Details!$G$5:$G$243,3,10), (Details!$C$5:$C$243)=Enterprise!G$2))),0)} -> 0 | H20: {=IFERROR(ROWS(_xlfn.UNIQUE(_xlfn._xlws.FILTER(MID(Details!$G$5:$G$243,3,10), (Details!$C$5:$C$243)=Enterprise!H$2))),0)} -> 0 | I20: {=IFERROR(ROWS(_xlfn.UNIQUE(_xlfn._xlws.FILTER(MID(Details!$G$5:$G$243,3,10), (Details!$C$5:$C$243)=Enterprise!I$2))),0)} -> 0 | J20: {=IFERROR(ROWS(_xlfn.UNIQUE(_xlfn._xlws.FILTER(MID(Details!$G$5:$G$243,3,10), (Details!$C$5:$C$243)=Enterprise!J$2))),0)} -> 0 | K20: {=IFERROR(ROWS(_xlfn.UNIQUE(_xlfn._xlws.FILTER(MID(Details!$G$5:$G$243,3,10), (Details!$C$5:$C$243)=Enterprise!K$2))),0)} -> 0 | ... O20: {=IFERROR(ROWS(_xlfn.UNIQUE(_xlfn._xlws.FILTER(MID(Details!$G$5:$G$243,3,10), (Details!$C$5:$C$243)=Enterprise!O$2))),0)} -> 0 | P20: ='AP & AR'!B2 -> 23
C21: No. of Buyers (Recyclers) | D21: {=IFERROR(ROWS(_xlfn.UNIQUE(_xlfn._xlws.FILTER(MID(Details!$AR$5:$AR$243,3,10), (Details!$C$5:$C$243)=Enterprise!D$2))),0)} -> 5 | E21: {=IFERROR(ROWS(_xlfn.UNIQUE(_xlfn._xlws.FILTER(MID(Details!$AR$5:$AR$243,3,10), (Details!$C$5:$C$243)=Enterprise!E$2))),0)} -> 3 | F21: {=IFERROR(ROWS(_xlfn.UNIQUE(_xlfn._xlws.FILTER(MID(Details!$AR$5:$AR$243,3,10), (Details!$C$5:$C$243)=Enterprise!F$2))),0)} -> 4 | G21: {=IFERROR(ROWS(_xlfn.UNIQUE(_xlfn._xlws.FILTER(MID(Details!$AR$5:$AR$243,3,10), (Details!$C$5:$C$243)=Enterprise!G$2))),0)} -> 0 | H21: {=IFERROR(ROWS(_xlfn.UNIQUE(_xlfn._xlws.FILTER(MID(Details!$AR$5:$AR$243,3,10), (Details!$C$5:$C$243)=Enterprise!H$2))),0)} -> 0 | I21: {=IFERROR(ROWS(_xlfn.UNIQUE(_xlfn._xlws.FILTER(MID(Details!$AR$5:$AR$243,3,10), (Details!$C$5:$C$243)=Enterprise!I$2))),0)} -> 0 | J21: {=IFERROR(ROWS(_xlfn.UNIQUE(_xlfn._xlws.FILTER(MID(Details!$AR$5:$AR$243,3,10), (Details!$C$5:$C$243)=Enterprise!J$2))),0)} -> 0 | K21: {=IFERROR(ROWS(_xlfn.UNIQUE(_xlfn._xlws.FILTER(MID(Details!$AR$5:$AR$243,3,10), (Details!$C$5:$C$243)=Enterprise!K$2))),0)} -> 0 | ... O21: {=IFERROR(ROWS(_xlfn.UNIQUE(_xlfn._xlws.FILTER(MID(Details!$AR$5:$AR$243,3,10), (Details!$C$5:$C$243)=Enterprise!O$2))),0)} -> 0 | P21: ='AP & AR'!G2 -> 7
C22: Full Sales Returns (Nos) | D22: 0 | E22: 0 | F22: 0 | G22: 0 | H22: 0 | I22: 0 | J22: 0 | K22: 0 | L22: 0 | M22: 0 | N22: 0 | O22: 0 | P22: =SUM(D22:O22) -> 0
C23: Receivable | D23: 2546227 | E23: 2029170 | F23: 1674994.1 | P23: =F23 -> 1674994.1
C24: DSO (Days) | D24: =IFERROR(((D23/(D6*1.18))*D3),0) -> 20.15239 | E24: =IFERROR(((E23/(E6*1.18))*E3),0) -> 18.874513 | F24: =IFERROR(((F23/(F6*1.18))*F3),0) -> 9.1763165 | G24: =IFERROR(((G23/(G6*1.18))*G3),0) -> 0 | H24: =IFERROR(((H23/(H6*1.18))*H3),0) -> 0 | I24: =IFERROR(((I23/(I6*1.18))*I3),0) -> 0 | J24: =IFERROR(((J23/(J6*1.18))*J3),0) -> 0 | K24: =IFERROR(((K23/(K6*1.18))*K3),0) -> 0 | ... O24: =IFERROR(((O23/(O6*1.18))*O3),0) -> 0 | P24: =IFERROR(((P23)/(P6*1.18)*P3),0) -> 12.097894
C25: Processing Cost | D25: 0 | E25: 0 | F25: 0 | G25: 0 | H25: 0 | I25: 0 | J25: 0 | K25: 0 | L25: 0 | M25: 0 | N25: 0 | O25: 0 | P25: =SUM(D25:O25) -> 0
C26: Finance Cost | D26: 0 | E26: 0 | F26: 0 | G26: 0 | H26: 0 | I26: 0 | J26: 0 | K26: 0 | L26: 0 | M26: 0 | N26: 0 | O26: 0 | P26: =SUM(D26:O26) -> 0
C27: Indirect Expences | D27: 0 | E27: 0 | F27: 0 | G27: 0 | H27: 0 | I27: 0 | J27: 0 | K27: 0 | L27: 0 | M27: 0 | N27: 0 | O27: 0 | P27: =SUM(D27:O27) -> 0
C28: Margin after Opex & Finance Cost | D28: =D12-D27 -> 214009.43 | E28: =E12-E27 -> 203517.05 | F28: =F12-F27 -> 127962.52 | G28: =G12-G27 -> 0 | H28: =H12-H27 -> 0 | I28: =I12-I27 -> 0 | J28: =J12-J27 -> 0 | K28: =K12-K27 -> 0 | ... P28: =P12-P27 -> 545489
C29: CM % | D29: =D28/D6 -> 0.066622833 | E29: =E28/E6 -> 0.072057374 | F29: =F28/F6 -> 0.027573929 | G29: =G28/G6 -> #DIV/0! | H29: =H28/H6 -> #DIV/0! | I29: =I28/I6 -> #DIV/0! | J29: =J28/J6 -> #DIV/0! | K29: =K28/K6 -> #DIV/0! | ... P29: =P28/P6 -> 0.051088495

Sheet IB
C3: =Enterprise!D3 -> 30 | D3: 31 | E3: =Enterprise!F3 -> 30 | F3: =Enterprise!G3 -> 0 | G3: =Enterprise!H3 -> 0 | H3: =Enterprise!I3 -> 0 | I3: =Enterprise!J3 -> 0 | J3: =Enterprise!K3 -> 0 | K3: =Enterprise!L3 -> 0 | L3: =Enterprise!M3 -> 0 | ... N3: =Enterprise!O3 -> 0 | O3: =SUM(C3:N3) -> 91
B4: IB(B2B & Warehouse) | C4: 46113 | D4: 46143 | E4: 46174 | F4: 46204 | G4: 46235 | H4: 46266 | I4: 46296 | J4: 46327 | K4: 46357 | L4: 46388 | M4: 46419 | N4: 46447 | O4: FY 2026-27
B5: Quantity (MT) | C5: =Enterprise!D5+'Processing Centre'!AA5 -> 217.213 | D5: =Enterprise!E5+'Processing Centre'!AB5 -> 319.474 | E5: =Enterprise!F5+'Processing Centre'!AC5 -> 267.056 | O5: =SUM(C5:N5) -> 803.743
B6: Sales | C6: =Enterprise!D6+'Processing Centre'!AA6 -> 4092280.5 | D6: =Enterprise!E6+'Processing Centre'!AB6 -> 7861789.7 | E6: =Enterprise!F6+'Processing Centre'!AC6 -> 6384823 | O6: =SUM(C6:N6) -> 18338893
B7: Purchases | C7: =Enterprise!D7+'Processing Centre'!AA7 -> 3558699.2 | D7: =Enterprise!E7+'Processing Centre'!AB7 -> 7174755.9 | E7: =Enterprise!F7+'Processing Centre'!AC7 -> 5652950.9 | O7: =SUM(C7:N7) -> 16386406
B8: Gross Margin | C8: =C6-C7 -> 533581.29 | D8: =D6-D7 -> 687033.75 | E8: =E6-E7 -> 731872.12 | O8: =SUM(C8:N8) -> 1952487.2
B9: Gross Margin (%) | C9: =IFERROR((C8/C6),0) -> 0.13038727 | D9: =IFERROR((D8/D6),0) -> 0.087388976 | E9: =IFERROR((E8/E6),0) -> 0.11462685 | O9: =IFERROR((O8/O6),0) -> 0.10646701
B10: Transportation Charges | C10: ='Processing Centre'!AA10+Enterprise!D10 -> 0 | D10: ='Processing Centre'!AB10+Enterprise!E10 -> 0 | E10: ='Processing Centre'!AC10+Enterprise!F10 -> 0 | O10: =SUM(C10:N10) -> 0
B11: Operational Cost | C11: ='Processing Centre'!AA11+Enterprise!D11 -> 653123.07 | D11: ='Processing Centre'!AB11+Enterprise!E11 -> 413045.95 | E11: ='Processing Centre'!AC11+Enterprise!F11 -> 853956.48 | O11: =SUM(C11:N11) -> 1920125.5
B12: Net Margin | C12: =C6-C7-C10-C11 -> -119541.78 | D12: =D6-D7-D10-D11 -> 273987.8 | E12: =E6-E7-E10-E11 -> -122084.35 | O12: =SUM(C12:N12) -> 32361.663
B13: Net Margin (%) | C13: =IFERROR((C12/C6),0) -> -0.029211531 | D13: =IFERROR((D12/D6),0) -> 0.034850563 | E13: =IFERROR((E12/E6),0) -> -0.019121024 | O13: =IFERROR((O12/O6),0) -> 0.0017646464
B14: Other Income | C14: =Enterprise!D14+'Processing Centre'!AA14 -> 0 | D14: =Enterprise!E14+'Processing Centre'!AB14 -> 0 | E14: =Enterprise!F14+'Processing Centre'!AC14 -> 0 | O14: =SUM(C14:N14) -> 0
B15: Transport Charges (%) | C15: =IFERROR((C10/C6),0) -> 0 | D15: =IFERROR((D10/D6),0) -> 0 | E15: =IFERROR((E10/E6),0) -> 0 | O15: =IFERROR((O10/O6),0) -> 0
B16: Revenue Per Kg | C16: =+C6/(C5*1000) -> 18.839943 | D16: =+D6/(D5*1000) -> 24.608543 | E16: =+E6/(E5*1000) -> 23.90818 | O16: =+O6/(O5*1000) -> 22.816862
B17: Purchase Cost Per Kg | C17: =+C7/(C5*1000) -> 16.383454 | D17: =+D7/(D5*1000) -> 22.458028 | E17: =+E7/(E5*1000) -> 21.167661 | O17: =+O7/(O5*1000) -> 20.387619
B18: Transportation Charges Per Kg | C18: =C10/(C5*1000) -> 0 | D18: =D10/(D5*1000) -> 0 | E18: =E10/(E5*1000) -> 0 | O18: =O10/(O5*1000) -> 0
B19: No. of Transactions | C19: ='Processing Centre'!AA19+Enterprise!D19 -> 69 | D19: ='Processing Centre'!AB19+Enterprise!E19 -> 49 | E19: ='Processing Centre'!AC19+Enterprise!F19 -> 56 | O19: =SUM(C19:N19) -> 174
B20: No. of Sellers (Aggregators) | C20: ='Processing Centre'!AA20+Enterprise!D20 -> 4 | D20: ='Processing Centre'!AB20+Enterprise!E20 -> 4 | E20: ='Processing Centre'!AC20+Enterprise!F20 -> 3 | O20: ='AP & AR'!C22 -> 20
B21: No. of Buyers (Recyclers) | C21: ='Processing Centre'!AA21+Enterprise!D21 -> 8 | D21: ='Processing Centre'!AB21+Enterprise!E21 -> 5 | E21: ='Processing Centre'!AC21+Enterprise!F21 -> 4 | O21: ='AP & AR'!B22 -> 7
B22: Full Sales Returns (Nos) | C22: ='Processing Centre'!AA22+Enterprise!D22 -> 0 | D22: ='Processing Centre'!AB22+Enterprise!E22 -> 0 | E22: ='Processing Centre'!AC22+Enterprise!F22 -> 0 | O22: =SUM(C22:N22) -> 0
B23: Receivable | C23: =Enterprise!D23+'Processing Centre'!AA23 -> 6579198.9 | D23: 6008355.5 | E23: 3653279.7 | O23: =E23 -> 3653279.7
B24: DSO (Days) | C24: =IFERROR(((C23/(C6*1.18))*C3),0) -> 40.873974 | D24: =IFERROR(((D23/(D6*1.18))*D3),0) -> 20.077697 | E24: =IFERROR(((E23/(E6*1.18))*E3),0) -> 14.546996 | O24: =IFERROR(((O23/(O6*1.18))*O3),0) -> 15.362758
B25: Finance Cost | C25: ='Processing Centre'!AA25 -> 17250.437 | D25: ='Processing Centre'!AB25 -> 21592.228 | E25: ='Processing Centre'!AC25 -> 6891.7351 | O25: =SUM(C25:N25) -> 45734.4
B26: Indirect Expences | C26: ='Processing Centre'!AA26 -> 254388.13 | D26: ='Processing Centre'!AB26 -> 312234.81 | E26: ='Processing Centre'!AC26 -> 161501.44 | O26: =SUM(C26:N26) -> 728124.38
B27: Margin after Opex & Finance Cost | C27: ='Processing Centre'!AA27 -> -605189.77 | D27: ='Processing Centre'!AB27 -> -263356.29 | E27: ='Processing Centre'!AC27 -> -418440.06 | O27: =SUM(C27:N27) -> -1286986.1
B28: CM % | C28: =C27/C6 -> -0.1478857 | D28: =D27/D6 -> -0.033498262 | E28: =E27/E6 -> -0.065536673 | O28: =O27/O6 -> -0.070177961

Sheet Processing Centre
C3: 0 | D3: 0 | E3: 0 | F3: 0 | G3: 0 | H3: 0 | I3: 0 | J3: 0 | K3: 30 | L3: 31 | M3: 28 | N3: 31 | O3: 30 | P3: 31 | Q3: 30 | R3: 31 | S3: 31 | T3: 30 | U3: 31 | V3: 30 | W3: 31 | X3: 31 | Y3: 28 | Z3: 31 | AA3: 30 | AB3: 31 | AC3: 30 | AD3: =SUM(C3:AC3) -> 576 | AE3: =SUM(C3:N3) -> 120 | AF3: =SUM(O3:Z3) -> 365 | AG3: =SUM(AA3:AC3) -> 91
B4: Marketplace Warehouse(IB) | C4: Apr-24 | D4: May-24 | E4: Jun-24 | F4: Jul-24 | G4: Aug-24 | H4: Sep-24 | I4: Oct-24 | J4: Nov-24 | K4: Dec-24 | L4: Jan-25 | M4: Feb-25 | N4: 45717 | O4: Apr-25 | P4: May-25 | Q4: Jun-25 | R4: Jul-25 | S4: Aug-25 | T4: Sep-25 | U4: Oct-25 | V4: Nov-25 | W4: Dec-25 | X4: Jan-26 | Y4: Feb-26 | Z4: Mar-26 | AA4: Apr-26 | AB4: May-26 | AC4: 46174 | AD4: Till Date | AE4: FY 2024-25 | AF4: FY 2025-26 | AG4: FY 2026-27
B5: Quantity (MT) | C5: =SUMIFS('Details PC'!$AE$7:$AE$421,'Details PC'!$W$7:$W$421,'Processing Centre'!C$4)/1000 -> 0 | D5: =SUMIFS('Details PC'!$AE$7:$AE$421,'Details PC'!$W$7:$W$421,'Processing Centre'!D$4)/1000 -> 0 | E5: =SUMIFS('Details PC'!$AE$7:$AE$421,'Details PC'!$W$7:$W$421,'Processing Centre'!E$4)/1000 -> 0 | F5: =SUMIFS('Details PC'!$AE$7:$AE$421,'Details PC'!$W$7:$W$421,'Processing Centre'!F$4)/1000 -> 0 | G5: =SUMIFS('Details PC'!$AE$7:$AE$421,'Details PC'!$W$7:$W$421,'Processing Centre'!G$4)/1000 -> 0 | H5: =SUMIFS('Details PC'!$AE$7:$AE$421,'Details PC'!$W$7:$W$421,'Processing Centre'!H$4)/1000 -> 0 | I5: =SUMIFS('Details PC'!$AE$7:$AE$421,'Details PC'!$W$7:$W$421,'Processing Centre'!I$4)/1000 -> 0 | J5: =SUMIFS('Details PC'!$AE$7:$AE$421,'Details PC'!$W$7:$W$421,'Processing Centre'!J$4)/1000 -> 0 | K5: =SUMIFS('Details PC'!$AK$5:$AK$421,'Details PC'!$W$5:$W$421,'Processing Centre'!K$4)/1000 -> 70.8 | L5: =SUMIFS('Details PC'!$AK$5:$AK$421,'Details PC'!$W$5:$W$421,'Processing Centre'!L$4)/1000 -> 51.56 | M5: =SUMIFS('Details PC'!$AK$5:$AK$421,'Details PC'!$W$5:$W$421,'Processing Centre'!M$4)/1000 -> 82.5237 | N5: =SUMIFS('Details PC'!$AK$5:$AK$421,'Details PC'!$W$5:$W$421,'Processing Centre'!N$4)/1000 -> 205.41 | O5: =SUMIFS('Details PC'!$AK$5:$AK$421,'Details PC'!$W$5:$W$421,'Processing Centre'!O$4)/1000 -> 240.65 | P5: =SUMIFS('Details PC'!$AK$5:$AK$421,'Details PC'!$W$5:$W$421,'Processing Centre'!P$4)/1000 -> 77.855 | Q5: =SUMIFS('Details PC'!$AK$5:$AK$421,'Details PC'!$W$5:$W$421,'Processing Centre'!Q$4)/1000 -> 263.19 | R5: =SUMIFS('Details PC'!$AK$5:$AK$421,'Details PC'!$W$5:$W$421,'Processing Centre'!R$4)/1000 -> 291.8 | ... Z5: =SUMIFS('Details PC'!$AK$5:$AK$421,'Details PC'!$W$5:$W$421,'Processing Centre'!Z$4)/1000 -> 148.3172 | AA5: 14.817 | AB5: 157.1 | AC5: 53.765 | AD5: =SUM(C5:AB5) -> 4644.5129 | AE5: =SUM(C5:N5) -> 410.2937 | AF5: =SUM(O5:Z5) -> 4062.3022 | AG5: =SUM(AA5:AC5) -> 225.682
B6: Sales | C6: =SUMIFS('Details PC'!$AG$5:$AG$421,'Details PC'!$W$5:$W$421,'Processing Centre'!C$4)+SUMIFS('Details PC'!$AH$5:$AH$421,'Details PC'!$W$5:$W$421,'Processing Centre'!C$4) -> 0 | D6: =SUMIFS('Details PC'!$AG$5:$AG$421,'Details PC'!$W$5:$W$421,'Processing Centre'!D$4)+SUMIFS('Details PC'!$AH$5:$AH$421,'Details PC'!$W$5:$W$421,'Processing Centre'!D$4) -> 0 | E6: =SUMIFS('Details PC'!$AG$5:$AG$421,'Details PC'!$W$5:$W$421,'Processing Centre'!E$4)+SUMIFS('Details PC'!$AH$5:$AH$421,'Details PC'!$W$5:$W$421,'Processing Centre'!E$4) -> 0 | F6: =SUMIFS('Details PC'!$AG$5:$AG$421,'Details PC'!$W$5:$W$421,'Processing Centre'!F$4)+SUMIFS('Details PC'!$AH$5:$AH$421,'Details PC'!$W$5:$W$421,'Processing Centre'!F$4) -> 0 | G6: =SUMIFS('Details PC'!$AG$5:$AG$421,'Details PC'!$W$5:$W$421,'Processing Centre'!G$4)+SUMIFS('Details PC'!$AH$5:$AH$421,'Details PC'!$W$5:$W$421,'Processing Centre'!G$4) -> 0 | H6: =SUMIFS('Details PC'!$AG$5:$AG$421,'Details PC'!$W$5:$W$421,'Processing Centre'!H$4)+SUMIFS('Details PC'!$AH$5:$AH$421,'Details PC'!$W$5:$W$421,'Processing Centre'!H$4) -> 0 | I6: =SUMIFS('Details PC'!$AG$5:$AG$421,'Details PC'!$W$5:$W$421,'Processing Centre'!I$4)+SUMIFS('Details PC'!$AH$5:$AH$421,'Details PC'!$W$5:$W$421,'Processing Centre'!I$4) -> 0 | J6: =SUMIFS('Details PC'!$AG$5:$AG$421,'Details PC'!$W$5:$W$421,'Processing Centre'!J$4)+SUMIFS('Details PC'!$AH$5:$AH$421,'Details PC'!$W$5:$W$421,'Processing Centre'!J$4) -> 0 | ... Z6: =SUMIFS('Details PC'!$AG$5:$AG$421,'Details PC'!$W$5:$W$421,'Processing Centre'!Z$4)+SUMIFS('Details PC'!$AH$5:$AH$421,'Details PC'!$W$5:$W$421,'Processing Centre'!Z$4) -> 5118069.8 | AA6: 880027 | AB6: 5037414.7 | AC6: 1744116 | AD6: =SUM(C6:AB6) -> 1.6688297e+08 | AE6: =SUM(C6:N6) -> 15977724 | AF6: =SUM(O6:Z6) -> 1.449878e+08 | AG6: =SUM(AA6:AC6) -> 7661557.7
B7: Purchases | C7: =SUMIFS('Details PC'!$AL$5:$AL$421,'Details PC'!$W$5:$W$421,'Processing Centre'!C$4) -> 0 | D7: =SUMIFS('Details PC'!$AL$5:$AL$421,'Details PC'!$W$5:$W$421,'Processing Centre'!D$4) -> 0 | E7: =SUMIFS('Details PC'!$AL$5:$AL$421,'Details PC'!$W$5:$W$421,'Processing Centre'!E$4) -> 0 | F7: =SUMIFS('Details PC'!$AL$5:$AL$421,'Details PC'!$W$5:$W$421,'Processing Centre'!F$4) -> 0 | G7: =SUMIFS('Details PC'!$AL$5:$AL$421,'Details PC'!$W$5:$W$421,'Processing Centre'!G$4) -> 0 | H7: =SUMIFS('Details PC'!$AL$5:$AL$421,'Details PC'!$W$5:$W$421,'Processing Centre'!H$4) -> 0 | I7: =SUMIFS('Details PC'!$AL$5:$AL$421,'Details PC'!$W$5:$W$421,'Processing Centre'!I$4) -> 0 | J7: =SUMIFS('Details PC'!$AL$5:$AL$421,'Details PC'!$W$5:$W$421,'Processing Centre'!J$4) -> 0 | ... Z7: =SUMIFS('Details PC'!$AL$5:$AL$421,'Details PC'!$W$5:$W$421,'Processing Centre'!Z$4) -> 4889984.8 | AA7: 809908.21 | AB7: 4754023.9 | AC7: 1476982.9 | AD7: =SUM(C7:AB7) -> 1.5833101e+08 | AE7: =SUM(C7:N7) -> 13550583 | AF7: =SUM(O7:Z7) -> 1.392165e+08 | AG7: =SUM(AA7:AC7) -> 7040915
B8: Gross Margin | C8: =IFERROR((C6-C7),0) -> 0 | D8: =IFERROR((D6-D7),0) -> 0 | E8: =IFERROR((E6-E7),0) -> 0 | F8: =IFERROR((F6-F7),0) -> 0 | G8: =IFERROR((G6-G7),0) -> 0 | H8: =IFERROR((H6-H7),0) -> 0 | I8: =IFERROR((I6-I7),0) -> 0 | J8: =IFERROR((J6-J7),0) -> 0 | ... AC8: =IFERROR((AC6-AC7),0) -> 267133.12 | AD8: =SUM(C8:AB8) -> 8551954.3 | AE8: =IFERROR((AE6-AE7),0) -> 2427141.5 | AF8: =AF6-AF7 -> 5771303.2 | AG8: =SUM(AA8:AC8) -> 620642.66
B9: Gross Margin (%) | C9: =IFERROR((C8/C6),0) -> 0 | D9: =IFERROR((D8/D6),0) -> 0 | E9: =IFERROR((E8/E6),0) -> 0 | F9: =IFERROR((F8/F6),0) -> 0 | G9: =IFERROR((G8/G6),0) -> 0 | H9: =IFERROR((H8/H6),0) -> 0 | I9: =IFERROR((I8/I6),0) -> 0 | J9: =IFERROR((J8/J6),0) -> 0 | ... AG9: =IFERROR((AG8/AG6),0) -> 0.081007373
B10: Transportation Charges | C10: 0 | D10: 0 | E10: 0 | F10: 0 | G10: 0 | H10: 0 | I10: 0 | J10: 0 | K10: 0 | L10: 0 | M10: 0 | N10: 0 | O10: 0 | P10: 0 | Q10: 0 | R10: 0 | S10: 0 | T10: 0 | U10: 0 | V10: 0 | W10: 0 | X10: 0 | Y10: 0 | Z10: 0 | AA10: 0 | AB10: 0 | AC10: 0 | AD10: =SUM(C10:AA10) -> 0 | AE10: =SUM(K10:N10) -> 0 | AF10: =SUM(O10:Z10) -> 0 | AG10: =AA10 -> 0
B11: Processing Cost | K11: =SUMIFS('Details PC'!$T:$T,'Details PC'!$D:$D,'Processing Centre'!K4,'Details PC'!$E:$E,"Operational Cost") -> 200000 | L11: =SUMIFS('Details PC'!$T:$T,'Details PC'!$D:$D,'Processing Centre'!L4,'Details PC'!$E:$E,"Operational Cost") -> 750000 | M11: =SUMIFS('Details PC'!$T:$T,'Details PC'!$D:$D,'Processing Centre'!M4,'Details PC'!$E:$E,"Operational Cost") -> 43000 | N11: =SUMIFS('Details PC'!$T:$T,'Details PC'!$D:$D,'Processing Centre'!N4,'Details PC'!$E:$E,"Operational Cost") -> 112605 | O11: =SUMIFS('Details PC'!$T:$T,'Details PC'!$D:$D,'Processing Centre'!O4,'Details PC'!$E:$E,"Operational Cost") -> 5700 | P11: =SUMIFS('Details PC'!$T:$T,'Details PC'!$D:$D,'Processing Centre'!P4,'Details PC'!$E:$E,"Operational Cost") -> 636817 | Q11: =SUMIFS('Details PC'!$T:$T,'Details PC'!$D:$D,'Processing Centre'!Q4,'Details PC'!$E:$E,"Operational Cost") -> 544481 | R11: =SUMIFS('Details PC'!$T:$T,'Details PC'!$D:$D,'Processing Centre'!R4,'Details PC'!$E:$E,"Operational Cost") -> 1264704 | ... AC11: =SUMIFS('Details PC'!$T:$T,'Details PC'!$D:$D,'Processing Centre'!AC4,'Details PC'!$E:$E,"Operational Cost") -> 517180 | AD11: =SUM(C11:AB11) -> 14637341 | AE11: =SUM(C11:N11) -> 1105605 | AF11: =SUM(O11:Z11) -> 12915146 | AG11: =SUM(AA11:AC11) -> 1133770
B12: Net Margin | C12: =C8-C11 -> 0 | D12: =D8-D11 -> 0 | E12: =E8-E11 -> 0 | F12: =F8-F11 -> 0 | G12: =G8-G11 -> 0 | H12: =H8-H11 -> 0 | I12: =I8-I11 -> 0 | J12: =J8-J11 -> 0 | ... AC12: =AC8-AC11 -> -250046.88 | AD12: =SUM(C12:AB12) -> -6085387.2 | AE12: =AE8-AE11 -> 1321536.5 | AF12: =AF8-AF11 -> -7143843.2 | AG12: =SUM(AA12:AC12) -> -513127.34
B13: Net Margin (%) | C13: =IFERROR((C12/C6),0) -> 0 | D13: =IFERROR((D12/D6),0) -> 0 | E13: =IFERROR((E12/E6),0) -> 0 | F13: =IFERROR((F12/F6),0) -> 0 | G13: =IFERROR((G12/G6),0) -> 0 | H13: =IFERROR((H12/H6),0) -> 0 | I13: =IFERROR((I12/I6),0) -> 0 | J13: =IFERROR((J12/J6),0) -> 0 | ... AG13: =IFERROR((AG12/AG6),0) -> -0.066974284
B14: Other Income | C14: 0 | D14: 0 | E14: 0 | F14: 0 | G14: 0 | H14: 0 | I14: 0 | J14: 0 | K14: 0 | L14: 0 | M14: 0 | N14: 0 | O14: 0 | P14: 0 | Q14: 0 | R14: 0 | S14: 0 | T14: 0 | U14: 0 | V14: 0 | W14: 0 | X14: 0 | Y14: 0 | Z14: 0 | AA14: 0 | AB14: 0 | AC14: 0 | AD14: 0 | AE14: 0 | AF14: 0 | AG14: =AA14 -> 0
B15: Transport Charges (%) | C15: =IFERROR((C10/C6),0) -> 0 | D15: =IFERROR((D10/D6),0) -> 0 | E15: =IFERROR((E10/E6),0) -> 0 | F15: =IFERROR((F10/F6),0) -> 0 | G15: =IFERROR((G10/G6),0) -> 0 | H15: =IFERROR((H10/H6),0) -> 0 | I15: =IFERROR((I10/I6),0) -> 0 | J15: =IFERROR((J10/J6),0) -> 0 | ... AF15: =IFERROR((AF10/AF6),0) -> 0 | AG15: =AA15 -> 0
B16: Revenue Per Kg | C16: =IFERROR(+C6/(C5*1000),0) -> 0 | D16: =IFERROR(+D6/(D5*1000),0) -> 0 | E16: =IFERROR(+E6/(E5*1000),0) -> 0 | F16: =IFERROR(+F6/(F5*1000),0) -> 0 | G16: =IFERROR(+G6/(G5*1000),0) -> 0 | H16: =IFERROR(+H6/(H5*1000),0) -> 0 | I16: =IFERROR(+I6/(I5*1000),0) -> 0 | J16: =IFERROR(+J6/(J5*1000),0) -> 0 | ... AF16: =IFERROR(+AF6/(AF5*1000),0) -> 35.691043 | AG16: =+AG6/(AG5*1000) -> 33.948466
B17: Purchase Cost Per Kg | C17: =IFERROR(+C7/(C5*1000),0) -> 0 | D17: =IFERROR(+D7/(D5*1000),0) -> 0 | E17: =IFERROR(+E7/(E5*1000),0) -> 0 | F17: =IFERROR(+F7/(F5*1000),0) -> 0 | G17: =IFERROR(+G7/(G5*1000),0) -> 0 | H17: =IFERROR(+H7/(H5*1000),0) -> 0 | I17: =IFERROR(+I7/(I5*1000),0) -> 0 | J17: =IFERROR(+J7/(J5*1000),0) -> 0 | ... AF17: =IFERROR(+AF7/(AF5*1000),0) -> 34.270345 | AG17: =+AG7/(AG5*1000) -> 31.19839
B18: Transportation Charges Per Kg | C18: =IFERROR(C10/(C5*1000),0) -> 0 | D18: =IFERROR(D10/(D5*1000),0) -> 0 | E18: =IFERROR(E10/(E5*1000),0) -> 0 | F18: =IFERROR(F10/(F5*1000),0) -> 0 | G18: =IFERROR(G10/(G5*1000),0) -> 0 | H18: =IFERROR(H10/(H5*1000),0) -> 0 | I18: =IFERROR(I10/(I5*1000),0) -> 0 | J18: =IFERROR(J10/(J5*1000),0) -> 0 | ... AF18: =IFERROR(AF10/(AF5*1000),0) -> 0 | AG18: =AA18 -> 0
B19: No. of Transactions | C19: {=IFERROR(ROWS(_xlfn.UNIQUE(_xlfn._xlws.FILTER('Details PC'!$AA$5:$AA$421,'Details PC'!$W$5:$W$421='Processing Centre'!C$4))),0)} -> 0 | D19: {=IFERROR(ROWS(_xlfn.UNIQUE(_xlfn._xlws.FILTER('Details PC'!$AA$5:$AA$421,'Details PC'!$W$5:$W$421='Processing Centre'!D$4))),0)} -> 0 | E19: {=IFERROR(ROWS(_xlfn.UNIQUE(_xlfn._xlws.FILTER('Details PC'!$AA$5:$AA$421,'Details PC'!$W$5:$W$421='Processing Centre'!E$4))),0)} -> 0 | F19: {=IFERROR(ROWS(_xlfn.UNIQUE(_xlfn._xlws.FILTER('Details PC'!$AA$5:$AA$421,'Details PC'!$W$5:$W$421='Processing Centre'!F$4))),0)} -> 0 | G19: {=IFERROR(ROWS(_xlfn.UNIQUE(_xlfn._xlws.FILTER('Details PC'!$AA$5:$AA$421,'Details PC'!$W$5:$W$421='Processing Centre'!G$4))),0)} -> 0 | H19: {=IFERROR(ROWS(_xlfn.UNIQUE(_xlfn._xlws.FILTER('Details PC'!$AA$5:$AA$421,'Details PC'!$W$5:$W$421='Processing Centre'!H$4))),0)} -> 0 | I19: {=IFERROR(ROWS(_xlfn.UNIQUE(_xlfn._xlws.FILTER('Details PC'!$AA$5:$AA$421,'Details PC'!$W$5:$W$421='Processing Centre'!I$4))),0)} -> 0 | J19: {=IFERROR(ROWS(_xlfn.UNIQUE(_xlfn._xlws.FILTER('Details PC'!$AA$5:$AA$421,'Details PC'!$W$5:$W$421='Processing Centre'!J$4))),0)} -> 0 | ... Z19: {=IFERROR(ROWS(_xlfn.UNIQUE(_xlfn._xlws.FILTER('Details PC'!$AA$5:$AA$421,'Details PC'!$W$5:$W$421='Processing Centre'!Z$4))),0)} -> 12 | AA19: {=IFERROR(ROWS(_xlfn.UNIQUE(_xlfn._xlws.FILTER('Details PC'!$AA$5:$AA$522,'Details PC'!$W$5:$W$522='Processing Centre'!AA$4))),0)} -> 4 | AB19: {=IFERROR(ROWS(_xlfn.UNIQUE(_xlfn._xlws.FILTER('Details PC'!$AA$5:$AA$522,'Details PC'!$W$5:$W$522='Processing Centre'!AB$4))),0)} -> 3 | AC19: {=IFERROR(ROWS(_xlfn.UNIQUE(_xlfn._xlws.FILTER('Details PC'!$AA$5:$AA$522,'Details PC'!$W$5:$W$522='Processing Centre'!AC$4))),0)} -> 0 | AD19: =SUM(C19:AB19) -> 219 | AE19: =SUM(C19:N19) -> 11 | AF19: =SUM(O19:Z19) -> 201 | AG19: =SUM(AA19:AC19) -> 7
B20: No. of Sellers (Aggregators) | C20: {=IFERROR(ROWS(_xlfn.UNIQUE(_xlfn._xlws.FILTER('Details PC'!$H$5:$H$421,'Details PC'!$W$5:$W$421='Processing Centre'!C$4))),0)} -> 0 | D20: {=IFERROR(ROWS(_xlfn.UNIQUE(_xlfn._xlws.FILTER('Details PC'!$H$5:$H$421,'Details PC'!$W$5:$W$421='Processing Centre'!D$4))),0)} -> 0 | E20: {=IFERROR(ROWS(_xlfn.UNIQUE(_xlfn._xlws.FILTER('Details PC'!$H$5:$H$421,'Details PC'!$W$5:$W$421='Processing Centre'!E$4))),0)} -> 0 | F20: {=IFERROR(ROWS(_xlfn.UNIQUE(_xlfn._xlws.FILTER('Details PC'!$H$5:$H$421,'Details PC'!$W$5:$W$421='Processing Centre'!F$4))),0)} -> 0 | G20: {=IFERROR(ROWS(_xlfn.UNIQUE(_xlfn._xlws.FILTER('Details PC'!$H$5:$H$421,'Details PC'!$W$5:$W$421='Processing Centre'!G$4))),0)} -> 0 | H20: {=IFERROR(ROWS(_xlfn.UNIQUE(_xlfn._xlws.FILTER('Details PC'!$H$5:$H$421,'Details PC'!$W$5:$W$421='Processing Centre'!H$4))),0)} -> 0 | I20: {=IFERROR(ROWS(_xlfn.UNIQUE(_xlfn._xlws.FILTER('Details PC'!$H$5:$H$421,'Details PC'!$W$5:$W$421='Processing Centre'!I$4))),0)} -> 0 | J20: {=IFERROR(ROWS(_xlfn.UNIQUE(_xlfn._xlws.FILTER('Details PC'!$H$5:$H$421,'Details PC'!$W$5:$W$421='Processing Centre'!J$4))),0)} -> 0 | ... AC20: {=IFERROR(ROWS(_xlfn.UNIQUE(_xlfn._xlws.FILTER('Details PC'!$H$5:$H$421,'Details PC'!$W$5:$W$421='Processing Centre'!AC$4))),0)} -> 0 | AD20: =ROWS(_xlfn.UNIQUE('Details PC'!H5:H421))-1 -> 16 | AE20: {=IFERROR(ROWS(_xlfn.UNIQUE(_xlfn._xlws.FILTER('Details PC'!$H$5:$H$421,'Details PC'!$C$5:$C$421=AE4))),0)} -> 4 | AF20: {=IFERROR(ROWS(_xlfn.UNIQUE(_xlfn._xlws.FILTER('Details PC'!$H$5:$H$421,'Details PC'!$C$5:$C$421=AF4))),0)} -> 14 | AG20: =SUM(AA20:AC20) -> 5
B21: No. of Buyers (Recyclers) | C21: {=IFERROR(ROWS(_xlfn.UNIQUE(_xlfn._xlws.FILTER('Details PC'!$AB$5:$AB$421,'Details PC'!$W$5:$W$421='Processing Centre'!C$4))),0)} -> 0 | D21: {=IFERROR(ROWS(_xlfn.UNIQUE(_xlfn._xlws.FILTER('Details PC'!$AB$5:$AB$421,'Details PC'!$W$5:$W$421='Processing Centre'!D$4))),0)} -> 0 | E21: {=IFERROR(ROWS(_xlfn.UNIQUE(_xlfn._xlws.FILTER('Details PC'!$AB$5:$AB$421,'Details PC'!$W$5:$W$421='Processing Centre'!E$4))),0)} -> 0 | F21: {=IFERROR(ROWS(_xlfn.UNIQUE(_xlfn._xlws.FILTER('Details PC'!$AB$5:$AB$421,'Details PC'!$W$5:$W$421='Processing Centre'!F$4))),0)} -> 0 | G21: {=IFERROR(ROWS(_xlfn.UNIQUE(_xlfn._xlws.FILTER('Details PC'!$AB$5:$AB$421,'Details PC'!$W$5:$W$421='Processing Centre'!G$4))),0)} -> 0 | H21: {=IFERROR(ROWS(_xlfn.UNIQUE(_xlfn._xlws.FILTER('Details PC'!$AB$5:$AB$421,'Details PC'!$W$5:$W$421='Processing Centre'!H$4))),0)} -> 0 | I21: {=IFERROR(ROWS(_xlfn.UNIQUE(_xlfn._xlws.FILTER('Details PC'!$AB$5:$AB$421,'Details PC'!$W$5:$W$421='Processing Centre'!I$4))),0)} -> 0 | J21: {=IFERROR(ROWS(_xlfn.UNIQUE(_xlfn._xlws.FILTER('Details PC'!$AB$5:$AB$421,'Details PC'!$W$5:$W$421='Processing Centre'!J$4))),0)} -> 0 | ... AC21: {=IFERROR(ROWS(_xlfn.UNIQUE(_xlfn._xlws.FILTER('Details PC'!$AB$5:$AB$421,'Details PC'!$W$5:$W$421='Processing Centre'!AC$4))),0)} -> 0 | AD21: =ROWS(_xlfn.UNIQUE('Details PC'!AB5:AB421))-1 -> 23 | AE21: {=IFERROR(ROWS(_xlfn.UNIQUE(_xlfn._xlws.FILTER('Details PC'!$AB$5:$AB$421,'Details PC'!$V$5:$V$421='Processing Centre'!AE$4))),0)} -> 7 | AF21: {=IFERROR(ROWS(_xlfn.UNIQUE(_xlfn._xlws.FILTER('Details PC'!$AB$5:$AB$421,'Details PC'!$V$5:$V$421='Processing Centre'!AF$4))),0)} -> 19 | AG21: =SUM(AA21:AC21) -> 5
B22: Full Sales Returns (Nos) | C22: 0 | D22: 0 | E22: 0 | F22: 0 | G22: 0 | H22: 0 | I22: 0 | J22: 0 | K22: 0 | L22: 0 | M22: 0 | N22: 0 | O22: 0 | P22: 0 | Q22: 0 | R22: 0 | S22: 0 | T22: 0 | U22: 0 | V22: 0 | W22: 0 | X22: 0 | Y22: 0 | Z22: 0 | AA22: 0 | AB22: 0 | AC22: 0 | AD22: =SUM(C22:AB22) -> 0 | AE22: =SUM(D22:N22) -> 0 | AF22: =SUM(O22:Z22) -> 0 | AG22: =AA22 -> 0
B23: Receivable | C23: 0 | D23: 0 | E23: 0 | F23: 0 | G23: 0 | H23: 0 | I23: 0 | J23: 0 | K23: 0 | L23: 3684158 | M23: 4840740 | N23: 5071174 | O23: 9109058 | P23: 9064031.6 | Q23: 14603523 | R23: 20048166 | S23: 20753319 | T23: 27967133 | U23: 10286916 | V23: 15585783 | W23: 17202350 | X23: 19983005 | Y23: 22412228 | Z23: 5596657.2 | AA23: 4032971.9 | AB23: 4781142.7 | AC23: 1978285.6 | AD23: =AVERAGE(L23:AB23) -> 12648374 | AE23: =AVERAGE(K23:N23) -> 3399018 | AF23: =AVERAGE(O23:Z23) -> 16051014 | AG23: =AC23 -> 1978285.6
B24: DSO (Days) | C24: =IFERROR(((C23/(C6*1.18))*C3),0) -> 0 | D24: =IFERROR(((D23/(D6*1.18))*D3),0) -> 0 | E24: =IFERROR(((E23/(E6*1.18))*E3),0) -> 0 | F24: =IFERROR(((F23/(F6*1.18))*F3),0) -> 0 | G24: =IFERROR(((G23/(G6*1.18))*G3),0) -> 0 | H24: =IFERROR(((H23/(H6*1.18))*H3),0) -> 0 | I24: =IFERROR(((I23/(I6*1.18))*I3),0) -> 0 | J24: =IFERROR(((J23/(J6*1.18))*J3),0) -> 0 | ... AC24: =IFERROR(((AC23/(AC6*1.18))*AC3),0) -> 28.837186 | AD24: =IFERROR(((AD23)/(AD6*1.18)*AD3),0) -> 36.996715 | AE24: =IFERROR(((AE23)/(AE6*1.18)*AE3),0) -> 21.634047 | AF24: =IFERROR(((AF23)/(AF6*1.18)*AF3),0) -> 34.243794 | AG24: =IFERROR(((AG23)/(AG6*1.18)*AG3),0) -> 19.912753
B25: Finance Cost | C25: =SUMIFS('Details PC'!$AQ$5:$AQ$421,'Details PC'!$W$5:$W$421,'Processing Centre'!C$4) -> 0 | D25: =SUMIFS('Details PC'!$AQ$5:$AQ$421,'Details PC'!$W$5:$W$421,'Processing Centre'!D$4) -> 0 | E25: =SUMIFS('Details PC'!$AQ$5:$AQ$421,'Details PC'!$W$5:$W$421,'Processing Centre'!E$4) -> 0 | F25: =SUMIFS('Details PC'!$AQ$5:$AQ$421,'Details PC'!$W$5:$W$421,'Processing Centre'!F$4) -> 0 | G25: =SUMIFS('Details PC'!$AQ$5:$AQ$421,'Details PC'!$W$5:$W$421,'Processing Centre'!G$4) -> 0 | H25: =SUMIFS('Details PC'!$AQ$5:$AQ$421,'Details PC'!$W$5:$W$421,'Processing Centre'!H$4) -> 0 | I25: =SUMIFS('Details PC'!$AQ$5:$AQ$421,'Details PC'!$W$5:$W$421,'Processing Centre'!I$4) -> 0 | J25: =SUMIFS('Details PC'!$AQ$5:$AQ$421,'Details PC'!$W$5:$W$421,'Processing Centre'!J$4) -> 0 | ... AC25: =SUMIFS('Details PC'!$AQ$5:$AQ$421,'Details PC'!$W$5:$W$421,'Processing Centre'!AC$4) -> 6891.7351 | AD25: =SUM(C25:AB25) -> 2884762.6 | AE25: =SUM(C25:N25) -> 360975.95 | AF25: =SUM(O25:Z25) -> 2484944 | AG25: =SUM(AA25:AC25) -> 45734.4
B26: Indirect Expences | C26: =SUMIFS('Opex & Capex Detail'!$I:$I,'Opex & Capex Detail'!$C:$C,'Processing Centre'!C$4) -> 95641 | D26: =SUMIFS('Opex & Capex Detail'!$I:$I,'Opex & Capex Detail'!$C:$C,'Processing Centre'!D$4) -> 180281 | E26: =SUMIFS('Opex & Capex Detail'!$I:$I,'Opex & Capex Detail'!$C:$C,'Processing Centre'!E$4) -> 165624 | F26: =SUMIFS('Opex & Capex Detail'!$I:$I,'Opex & Capex Detail'!$C:$C,'Processing Centre'!F$4) -> 152871.7 | G26: =SUMIFS('Opex & Capex Detail'!$I:$I,'Opex & Capex Detail'!$C:$C,'Processing Centre'!G$4) -> 117600.5 | H26: =SUMIFS('Opex & Capex Detail'!$I:$I,'Opex & Capex Detail'!$C:$C,'Processing Centre'!H$4) -> 106651.3 | I26: =SUMIFS('Opex & Capex Detail'!$I:$I,'Opex & Capex Detail'!$C:$C,'Processing Centre'!I$4) -> 90985.44 | J26: =SUMIFS('Opex & Capex Detail'!$I:$I,'Opex & Capex Detail'!$C:$C,'Processing Centre'!J$4) -> 241504 | ... AB26: =SUMIFS('Opex & Capex Detail'!$I:$I,'Opex & Capex Detail'!$C:$C,'Processing Centre'!AB$4) -> 312234.81 | AC26: =AB26*AC5/AB5+'Opex & Capex Detail'!I676 -> 161501.44 | AD26: =SUM(C26:AB26) -> 11991990 | AE26: =SUM(C26:N26) -> 3286831.9 | AF26: =SUM(O26:Z26) -> 8138535.7 | AG26: =SUM(AA26:AC26) -> 728124.38
B27: Margin after Opex & Finance Cost | K27: =K12-K26-K25 -> 65856.895 | L27: =L12-L26-L25 -> -1024049.7 | M27: =M12-M26-M25 -> -154831.09 | N27: =N12-N26-N25 -> -62088.484 | O27: =O12-O26-O25 -> 638651.15 | P27: =P12-P26-P25 -> -1509100.9 | Q27: =Q12-Q26-Q25 -> -138203.67 | R27: =R12-R26-R25 -> -662931.28 | ... AF27: =AF12-AF26-AF25 -> -17767323 | AG27: =SUM(AA27:AC27) -> -1286986.1
B28: CM % | K28: =K27/K6 -> 0.022838746 | L28: =L27/L6 -> -0.49794304 | M28: =M27/M6 -> -0.045104985 | N28: =N27/N6 -> -0.0081642499 | O28: =O27/O6 -> 0.067003278 | P28: =P27/P6 -> -0.4768242 | Q28: =Q27/Q6 -> -0.01390735 | R28: =R27/R6 -> -0.06312914 | ... AG28: =AG27/AG6 -> -0.1679797
B30: Inventory Details(MT) | C30: =C4 -> Apr-24 | D30: =D4 -> May-24 | E30: =E4 -> Jun-24 | F30: =F4 -> Jul-24 | G30: =G4 -> Aug-24 | H30: =H4 -> Sep-24 | I30: =I4 -> Oct-24 | J30: =J4 -> Nov-24 | ... Z30: =Z4 -> Mar-26 | AA30: 46113 | AB30: 46143 | AC30: 46174 | AD30: Till Date
B31: Opening Qty | C31: 0 | D31: =C34 -> 0 | E31: =D34 -> 0 | F31: =E34 -> 0 | G31: =F34 -> 0 | H31: =G34 -> 0 | I31: =H34 -> 0 | J31: =I34 -> 0 | K31: =J34 -> 0 | ... Z31: =Y34 -> 318440.3 | AA31: =Z34-52206 -> 138714.1 | AB31: =AA34-52206 -> 87221.1 | AC31: =AB34-52206 -> -73544.9 | AD31: 0
B32: Purchase Qty | C32: =SUMIFS('Details PC'!$R$5:$R$421,'Details PC'!$D$5:$D$421,'Processing Centre'!C$30)/1000 -> 0 | D32: =SUMIFS('Details PC'!$R$5:$R$421,'Details PC'!$D$5:$D$421,'Processing Centre'!D$30)/1000 -> 0 | E32: =SUMIFS('Details PC'!$R$5:$R$421,'Details PC'!$D$5:$D$421,'Processing Centre'!E$30)/1000 -> 0 | F32: =SUMIFS('Details PC'!$R$5:$R$421,'Details PC'!$D$5:$D$421,'Processing Centre'!F$30)/1000 -> 0 | G32: =SUMIFS('Details PC'!$R$5:$R$421,'Details PC'!$D$5:$D$421,'Processing Centre'!G$30)/1000 -> 0 | H32: =SUMIFS('Details PC'!$R$5:$R$421,'Details PC'!$D$5:$D$421,'Processing Centre'!H$30)/1000 -> 0 | I32: =SUMIFS('Details PC'!$R$5:$R$421,'Details PC'!$D$5:$D$421,'Processing Centre'!I$30)/1000 -> 0 | J32: =SUMIFS('Details PC'!$R$5:$R$421,'Details PC'!$D$5:$D$421,'Processing Centre'!J$30)/1000 -> 0 | K32: =SUMIFS('Details PC'!$R$5:$R$421,'Details PC'!$D$5:$D$421,'Processing Centre'!K$30) -> 800270 | L32: =SUMIFS('Details PC'!$R$5:$R$421,'Details PC'!$D$5:$D$421,'Processing Centre'!L$30) -> 91800 | M32: =SUMIFS('Details PC'!$R$5:$R$421,'Details PC'!$D$5:$D$421,'Processing Centre'!M$30) -> 35640 | N32: =SUMIFS('Details PC'!$R$5:$R$421,'Details PC'!$D$5:$D$421,'Processing Centre'!N$30) -> 13040 | O32: =SUMIFS('Details PC'!$R$5:$R$421,'Details PC'!$D$5:$D$421,'Processing Centre'!O$30) -> 181330 | P32: =SUMIFS('Details PC'!$R$5:$R$421,'Details PC'!$D$5:$D$421,'Processing Centre'!P$30) -> 79660 | Q32: =SUMIFS('Details PC'!$R$5:$R$421,'Details PC'!$D$5:$D$421,'Processing Centre'!Q$30) -> 851400 | R32: =SUMIFS('Details PC'!$R$5:$R$421,'Details PC'!$D$5:$D$421,'Processing Centre'!R$30) -> 335580 | ... AC32: =SUMIFS('Details PC'!$R$5:$R$421,'Details PC'!$D$5:$D$421,'Processing Centre'!AC$30) -> 91562 | AD32: =SUM(C32:AA32) -> 4679046
B33: Sale Qty | C33: =C5 -> 0 | D33: =D5 -> 0 | E33: =E5 -> 0 | F33: =F5 -> 0 | G33: =G5 -> 0 | H33: =H5 -> 0 | I33: =I5 -> 0 | J33: =J5 -> 0 | K33: =SUMIFS('Details PC'!$AK$5:$AK$421,'Details PC'!$W$5:$W$421,'Processing Centre'!K$4) -> 70800 | L33: =SUMIFS('Details PC'!$AK$5:$AK$421,'Details PC'!$W$5:$W$421,'Processing Centre'!L$4) -> 51560 | M33: =SUMIFS('Details PC'!$AK$5:$AK$421,'Details PC'!$W$5:$W$421,'Processing Centre'!M$4) -> 82523.7 | N33: =SUMIFS('Details PC'!$AK$5:$AK$421,'Details PC'!$W$5:$W$421,'Processing Centre'!N$4) -> 205410 | O33: =SUMIFS('Details PC'!$AK$5:$AK$421,'Details PC'!$W$5:$W$421,'Processing Centre'!O$4) -> 240650 | P33: =SUMIFS('Details PC'!$AK$5:$AK$421,'Details PC'!$W$5:$W$421,'Processing Centre'!P$4) -> 77855 | Q33: =SUMIFS('Details PC'!$AK$5:$AK$421,'Details PC'!$W$5:$W$421,'Processing Centre'!Q$4) -> 263190 | R33: =SUMIFS('Details PC'!$AK$5:$AK$421,'Details PC'!$W$5:$W$421,'Processing Centre'!R$4) -> 291800 | ... AC33: =SUMIFS('Details PC'!$AK$5:$AK$421,'Details PC'!$W$5:$W$421,'Processing Centre'!AC$4) -> 53765 | AD33: =SUM(C33:AA33) -> 4487412.9
B34: Closing Qty | C34: =C31+C32-C33 -> 0 | D34: =D31+D32-D33 -> 0 | E34: =E31+E32-E33 -> 0 | F34: =F31+F32-F33 -> 0 | G34: =G31+G32-G33 -> 0 | H34: =H31+H32-H33 -> 0 | I34: =I31+I32-I33 -> 0 | J34: =J31+J32-J33 -> 0 | ... AD34: =AD31+AD32-AD33 -> 191633.1

Sheet Details PC
O1: =R3-AE3 -> 13505.1 | AI1: =AI3-AJ1 -> 1.6688873e+08 | AJ1: 1738352.2 | AL1: =AL2/(AG3+AH3) -> 0.052299353
AL2: =(AG3+AH3)-AL3 -> 8819087.4
R3: =SUBTOTAL(9,R5:R421) -> 4819148 | T3: =SUBTOTAL(9,T5:T421) -> 1.6020377e+08 | AE3: =SUBTOTAL(9,AE5:AE421) -> 4805642.9 | AG3: =SUBTOTAL(9,AG5:AG421) -> 1.7291257e+08 | AH3: =SUBTOTAL(9,AH5:AH421) -> -4285489.1 | AI3: =SUBTOTAL(9,AI5:AI421) -> 1.6862708e+08 | AJ3: =SUBTOTAL(9,AJ5:AJ421) -> 107365 | AK3: =SUBTOTAL(9,AK5:AK421) -> 4698277.9 | AL3: =SUBTOTAL(9,AL5:AL421) -> 1.59808e+08 | AM3: =SUBTOTAL(9,AM5:AM421) -> 8819087.4 | AN3: =AM3/(AG3+AH3) -> 0.052299353 | AO3: =SUBTOTAL(9,AO5:AO421) -> 1.6034225e+08 | AQ3: =SUBTOTAL(9,AQ5:AQ421) -> 2891654.4 | AR3: =SUBTOTAL(9,AR5:AR421) -> 5927433 | AS3: =AR3/(AG3+AH3) -> 0.035151133
A4: z | B4: SI No | C4: Financial Year | D4: Month | E4: Order Type | F4: Bill Date | G4: CF.SO Number | H4: Vendor Name | I4: GST Identification Number (GSTIN) | J4: Bill Number | K4: CF.Supplier Invoice Date | L4: CF.Purchase | M4: CF.Voucher Date | N4: Source of Supply | O4: CF.Vehicle No | P4: Material_Generic | Q4: Item Name | R4: Purchase Qty | S4: Rate | T4: Taxable Value/Basic Cost | U4: Classification | V4: Financial Year | W4: Month | X4: LOT No | Y4: SO Number | Z4: Sale Date | AA4: Sale Invoice No | AB4: Buyer Name | AC4: Material_Generic | AD4: Material Name | AE4: Qty | AF4: Rate | AG4: Sale Taxable Value | AH4: CN Amount | AI4: Net Sale | AJ4: Return Qty | AK4: Net Qty | AL4: Purchases Angst Sale | AM4: Gross Margin | AN4: % | AO4: Purchases(Inc Inward Cost) | AP4: Days | AQ4: Finance Cost | AR4: Final Margin | AS4: (%)
B5: 1 | C5: FY 2024-25 | D5: =TEXT(F5,"mmm-yy") -> Dec-24 | E5: Regular | F5: 45628 | G5: 002 | H5: Tata Motors Passenger Vehicle Ltd | I5: 27AAHCT8301P1ZT | J5: MH6100765970 | K5: 45628 | L5: 24-25/PUR/11922 | M5: 45638 | N5: MH | O5: MH12EQ8475 | P5: MS Scrap | Q5: Scrap Dismantled & in cut size structural steel | R5: 8840 | S5: 33.121 | T5: =R5*S5 -> 292789.64 | U5: Regular | V5: Fy 2024-25 | W5: =TEXT(Z5,"mmm-yy") -> Dec-24 | X5: B1244K | Y5: MPPUNE/001 | Z5: 45641 | AA5: 25/MPPIB/INV0314 | AB5: Prajapati Foundry Private Limited | AC5: MS Scrap | AD5: MS Scrap (Casting) | AE5: 22510 | AF5: 38 | AG5: =AE5*AF5 -> 855380 | AH5: 0 | AI5: =AG5+AH5 -> 855380 | AJ5: 0 | AK5: =AE5-AJ5 -> 22510 | AL5: =AE5*S5 -> 745553.71 | AM5: =(AG5+AH5)-AL5 -> 109826.29 | AN5: =IFERROR(AM5/(AG5+AH5),0) -> 0.12839474 | AO5: =AE5*S5 -> 745553.71 | AP5: =(Z5-K5) -> 13 | AQ5: =T5*9.35%*AP5/365 -> 975.02961 | AR5: =AM5-AQ5 -> 108851.26 | AS5: =AR5/(AG5+AH5) -> 0.12725486
B6: =B5+1 -> 2 | C6: FY 2024-25 | D6: =TEXT(F6,"mmm-yy") -> Dec-24 | E6: Regular | F6: 45637 | G6: SH12241108 | H6: Tata Motors Passenger Vehicle Ltd | I6: 27AAHCT8301P1ZT | J6: MH6100797898 | K6: 45637 | L6: 24-25/PUR/11888 | M6: 45637 | N6: MH | O6: MH16AY3962 | P6: MS Scrap | Q6: Used/Scrapped/Defaced Dies and Fixtures | R6: 29550 | S6: 32.3 | T6: =R6*S6 -> 954465 | U6: Regular | V6: Fy 2024-25 | W6: =TEXT(Z6,"mmm-yy") -> Dec-24 | X6: B1244K | Y6: MPPUNE/002 | Z6: 45649 | AA6: 25/MPPIB/INV0322 | AB6: Kalyani Foundry Works | AC6: MS Scrap | AD6: MS Scrap (Casting) | AE6: 22790 | AF6: 42 | AG6: =AE6*AF6 -> 957180 | AH6: 0 | AI6: =AG6+AH6 -> 957180 | AJ6: 0 | AK6: =AE6-AJ6 -> 22790 | AL6: =AE6*S6 -> 736117 | AM6: =(AG6+AH6)-AL6 -> 221063 | AN6: =IFERROR(AM6/(AG6+AH6),0) -> 0.23095238 | AO6: =AE6*S6 -> 736117 | AP6: =(Z6-K6) -> 12 | AQ6: =T6*9.35%*AP6/365 -> 2933.9993 | AR6: =AM6-AQ6 -> 218129 | AS6: =AR6/(AG6+AH6) -> 0.22788713
B7: =B6+1 -> 3 | C7: FY 2024-25 | D7: =TEXT(F7,"mmm-yy") -> Dec-24 | E7: Regular | F7: 45637 | G7: SH12241106 | H7: Tata Motors Passenger Vehicle Ltd | I7: 27AAHCT8301P1ZT | J7: MH6100797313 | K7: 45637 | L7: 24-25/PUR/11879 | M7: 45637 | N7: MH | O7: MH25U7780 | P7: MS Scrap | Q7: Used/Scrapped/Defaced Dies and Fixtures | R7: 22390 | S7: 32.3 | T7: =R7*S7 -> 723197 | U7: Regular | V7: Fy 2024-25 | W7: =TEXT(Z7,"mmm-yy") -> Dec-24 | X7: B1244K | Y7: MPPUNE/003 | Z7: 45657 | AA7: 25/MPPIB/INV0331 | AB7: Kalyani Foundry Works | AC7: MS Scrap | AD7: MS Scrap (Casting) | AE7: 25500 | AF7: 42 | AG7: =AE7*AF7 -> 1071000 | AH7: 0 | AI7: =AG7+AH7 -> 1071000 | AJ7: 0 | AK7: =AE7-AJ7 -> 25500 | AL7: =AE7*S7 -> 823650 | AM7: =(AG7+AH7)-AL7 -> 247350 | AN7: =IFERROR(AM7/(AG7+AH7),0) -> 0.23095238 | AO7: =AE7*S7 -> 823650 | AP7: =(Z7-K7) -> 20 | AQ7: =T7*9.35%*AP7/365 -> 3705.1463 | AR7: =AM7-AQ7 -> 243644.85 | AS7: =AR7/(AG7+AH7) -> 0.22749286
B8: =B7+1 -> 4 | C8: FY 2024-25 | D8: =TEXT(F8,"mmm-yy") -> Dec-24 | E8: Regular | F8: 45638 | G8: 004 | H8: Tata Motors Passenger Vehicle Ltd | I8: 27AAHCT8301P1ZT | J8: MH6100696842 | K8: 45609 | L8: 24-25/PUR/11925 | M8: 45638 | N8: MH | O8: MH12EQ8475 | P8: MS Scrap | Q8: Scrap Dismantled & in cut size structural steel | R8: 9050 | S8: 33.121 | T8: =R8*S8 -> 299745.05 | U8: Regular | V8: Fy 2024-25 | W8: =TEXT(Z8,"mmm-yy") -> Jan-25 | X8: B1244K | Y8: MPPUNE/004 | Z8: 45667 | AA8: 25/MPPIB/INV0338 | AB8: Prajapati Foundry Private Limited | AC8: MS Scrap | AD8: MS Scrap (Casting) | AE8: 25910 | AF8: 38 | AG8: =AE8*AF8 -> 984580 | AH8: -5320 | AI8: =AG8+AH8 -> 979260 | AJ8: 0 | AK8: =AE8-AJ8 -> 25910 | AL8: =AE8*S8 -> 858165.11 | AM8: =(AG8+AH8)-AL8 -> 121094.89 | AN8: =IFERROR(AM8/(AG8+AH8),0) -> 0.12365959 | AO8: =AE8*S8 -> 858165.11 | AP8: =(Z8-K8) -> 58 | AQ8: =T8*9.35%*AP8/365 -> 4453.4723 | AR8: =AM8-AQ8 -> 116641.42 | AS8: =AR8/(AG8+AH8) -> 0.1191118
B9: =B8+1 -> 5 | C9: FY 2024-25 | D9: =TEXT(F9,"mmm-yy") -> Dec-24 | E9: Regular | F9: 45638 | G9: 015 | H9: Tata Motors Passenger Vehicle Ltd | I9: 27AAHCT8301P1ZT | J9: MH6100675953 | K9: 45602 | L9: 24-25/PUR/11940 | M9: 45638 | N9: MH | O9: MH48T2266 | P9: MS Scrap | Q9: Used/Scrapped/Defaced Dies and Fixtures | R9: 25040 | S9: 33.521 | T9: =R9*S9 -> 839365.84 | U9: Regular | V9: Fy 2024-25 | W9: =TEXT(Z9,"mmm-yy") -> Jan-25 | X9: B1244K | Y9: MPPUNE/005 | Z9: 45676 | AA9: 25/MPPIB/INV0339 | AB9: Kalyani Foundry Works | AC9: MS Scrap | AD9: MS Scrap (Casting) | AE9: 25650 | AF9: 42 | AG9: =AE9*AF9 -> 1077300 | AH9: 0 | AI9: =AG9+AH9 -> 1077300 | AJ9: 0 | AK9: =AE9-AJ9 -> 25650 | AL9: =AE9*S9 -> 859813.65 | AM9: =(AG9+AH9)-AL9 -> 217486.35 | AN9: =IFERROR(AM9/(AG9+AH9),0) -> 0.20188095 | AO9: =AE9*S9 -> 859813.65 | AP9: =(Z9-K9) -> 74 | AQ9: =T9*9.35%*AP9/365 -> 15911.157 | AR9: =AM9-AQ9 -> 201575.19 | AS9: =AR9/(AG9+AH9) -> 0.18711148
B10: =B9+1 -> 6 | C10: FY 2024-25 | D10: =TEXT(F10,"mmm-yy") -> Dec-24 | E10: Regular | F10: 45638 | G10: 014 | H10: Tata Motors Passenger Vehicle Ltd | I10: 27AAHCT8301P1ZT | J10: MH6100675959 | K10: 45602 | L10: 24-25/PUR/11937 | M10: 45638 | N10: MH | O10: MH04HD3353 | P10: MS Scrap | Q10: Used/Scrapped/Defaced Dies and Fixtures | R10: 25820 | S10: 33.521 | T10: =R10*S10 -> 865512.22 | U10: Regular | V10: Fy 2024-25 | W10: =TEXT(Z10,"mmm-yy") -> Feb-25 | X10: B1244K | Y10: MPPUNE/006 | Z10: 45696 | AA10: 25/MPPIB/INV0364 | AB10: Shree Balaji Metal Trading Company | AC10: CRC | AD10: Brass Scrap | AE10: 433.7 | AF10: 485 | AG10: =AE10*AF10 -> 210344.5 | AH10: -9700 | AI10: =AG10+AH10 -> 200644.5 | AJ10: 0 | AK10: =AE10-AJ10 -> 433.7 | AL10: =AE10*S10 -> 14538.058 | AM10: =(AG10+AH10)-AL10 -> 186106.44 | AN10: =IFERROR(AM10/(AG10+AH10),0) -> 0.9275432 | AO10: =AE10*S10 -> 14538.058 | AP10: =(Z10-K10) -> 94 | AQ10: =T10*9.35%*AP10/365 -> 20841.06 | AR10: =AM10-AQ10 -> 165265.38 | AS10: =AR10/(AG10+AH10) -> 0.82367263
B11: =B10+1 -> 7 | C11: FY 2024-25 | D11: =TEXT(F11,"mmm-yy") -> Dec-24 | E11: Regular | F11: 45638 | G11: 010 | H11: Tata Motors Passenger Vehicle Ltd | I11: 27AAHCT8301P1ZT | J11: MH6100679115 | K11: 45603 | L11: 24-25/PUR/11932 | M11: 45638 | N11: MH | O11: MH12MV6966 | P11: MS Scrap | Q11: Used/Scrapped/Defaced Dies and Fixtures | R11: 25190 | S11: 33.521 | T11: =R11*S11 -> 844393.99 | U11: Regular | V11: Fy 2024-25 | W11: =TEXT(Z11,"mmm-yy") -> Feb-25 | X11: B1244K | Y11: MPPUNE/007 | Z11: 45698 | AA11: 25/MPPIB/INV0367 | AB11: Affan Tools | AC11: CRC | AD11: MS Scrap (D2) | AE11: 1050 | AF11: 52 | AG11: =AE11*AF11 -> 54600 | AH11: 0 | AI11: =AG11+AH11 -> 54600 | AJ11: 0 | AK11: =AE11-AJ11 -> 1050 | AL11: =AE11*S11 -> 35197.05 | AM11: =(AG11+AH11)-AL11 -> 19402.95 | AN11: =IFERROR(AM11/(AG11+AH11),0) -> 0.35536538 | AO11: =AE11*S11 -> 35197.05 | AP11: =(Z11-K11) -> 95 | AQ11: =T11*9.35%*AP11/365 -> 20548.848 | AR11: =AM11-AQ11 -> -1145.8983 | AS11: =AR11/(AG11+AH11) -> -0.020987148
B12: =B11+1 -> 8 | C12: FY 2024-25 | D12: =TEXT(F12,"mmm-yy") -> Dec-24 | E12: Regular | F12: 45638 | G12: 011 | H12: Tata Motors Passenger Vehicle Ltd | I12: 27AAHCT8301P1ZT | J12: MH6100679114 | K12: 45603 | L12: 24-25/PUR/11933 | M12: 45638 | N12: MH | O12: MH48T2266 | P12: MS Scrap | Q12: Used/Scrapped/Defaced Dies and Fixtures | R12: 20280 | S12: 33.521 | T12: =R12*S12 -> 679805.88 | U12: Regular | V12: Fy 2024-25 | W12: =TEXT(Z12,"mmm-yy") -> Feb-25 | X12: B1244K | Y12: MPPUNE/008 | Z12: 45705 | AA12: 25/MPPIB/INV0378 | AB12: Kalyani Foundry Works | AC12: MS Scrap | AD12: MS Scrap (Casting) | AE12: 22170 | AF12: 42 | AG12: =AE12*AF12 -> 931140 | AH12: 0 | AI12: =AG12+AH12 -> 931140 | AJ12: 0 | AK12: =AE12-AJ12 -> 22170 | AL12: =AE12*S12 -> 743160.57 | AM12: =(AG12+AH12)-AL12 -> 187979.43 | AN12: =IFERROR(AM12/(AG12+AH12),0) -> 0.20188095 | AO12: =AE12*S12 -> 743160.57 | AP12: =(Z12-K12) -> 102 | AQ12: =T12*9.35%*AP12/365 -> 17762.49 | AR12: =AM12-AQ12 -> 170216.94 | AS12: =AR12/(AG12+AH12) -> 0.18280488
B13: =B12+1 -> 9 | C13: FY 2024-25 | D13: =TEXT(F13,"mmm-yy") -> Dec-24 | E13: Regular | F13: 45638 | G13: 013 | H13: Tata Motors Passenger Vehicle Ltd | I13: 27AAHCT8301P1ZT | J13: MH6100679113 | K13: 45603 | L13: 24-25/PUR/11936 | M13: 45638 | N13: MH | O13: MH04HD3714 | P13: MS Scrap | Q13: Used/Scrapped/Defaced Dies and Fixtures | R13: 17620 | S13: 33.521 | T13: =R13*S13 -> 590640.02 | U13: Regular | V13: Fy 2024-25 | W13: =TEXT(Z13,"mmm-yy") -> Feb-25 | X13: B1244K | Y13: MPPUNE/009 | Z13: 45711 | AA13: 25/MPPIB/INV0388 | AB13: Kalyani Foundry Works | AC13: MS Scrap | AD13: MS Scrap (Casting) | AE13: 24330 | AF13: 42 | AG13: =AE13*AF13 -> 1021860 | AH13: 0 | AI13: =AG13+AH13 -> 1021860 | AJ13: 0 | AK13: =AE13-AJ13 -> 24330 | AL13: =AE13*S13 -> 815565.93 | AM13: =(AG13+AH13)-AL13 -> 206294.07 | AN13: =IFERROR(AM13/(AG13+AH13),0) -> 0.20188095 | AO13: =AE13*S13 -> 815565.93 | AP13: =(Z13-K13) -> 108 | AQ13: =T13*9.35%*AP13/365 -> 16340.501 | AR13: =AM13-AQ13 -> 189953.57 | AS13: =AR13/(AG13+AH13) -> 0.18589001
B14: =B13+1 -> 10 | C14: FY 2024-25 | D14: =TEXT(F14,"mmm-yy") -> Dec-24 | E14: Regular | F14: 45638 | G14: 012 | H14: Tata Motors Passenger Vehicle Ltd | I14: 27AAHCT8301P1ZT | J14: MH6100679069 | K14: 45603 | L14: 24-25/PUR/11934 | M14: 45638 | N14: MH | O14: MH04HD3353 | P14: MS Scrap | Q14: Used/Scrapped/Defaced Dies and Fixtures | R14: 21200 | S14: 33.521 | T14: =R14*S14 -> 710645.2 | U14: Regular | V14: Fy 2024-25 | W14: =TEXT(Z14,"mmm-yy") -> Feb-25 | X14: M&M | Y14: MPPUNE/010 | Z14: 45714 | AA14: 25/MPPIB/INV0392 | AB14: Yash Enterprises | AC14: CRC | AD14: Defaced Light & Heavy metallic Auto components | AE14: 12940 | AF14: 35.7 | AG14: =AE14*AF14 -> 461958 | AH14: 0 | AI14: =AG14+AH14 -> 461958 | AJ14: 0 | AK14: =AE14-AJ14 -> 12940 | AL14: =AE14*S14 -> 433761.74 | AM14: =(AG14+AH14)-AL14 -> 28196.26 | AN14: =IFERROR(AM14/(AG14+AH14),0) -> 0.061036415 | AO14: =AE14*S14 -> 433761.74 | AP14: =(Z14-K14) -> 111 | AQ14: =T14*9.35%*AP14/365 -> 20206.661 | AR14: =AM14-AQ14 -> 7989.5992 | AS14: =AR14/(AG14+AH14) -> 0.017295077
B15: =B14+1 -> 11 | C15: FY 2024-25 | D15: =TEXT(F15,"mmm-yy") -> Dec-24 | E15: Regular | F15: 45638 | G15: 007 | H15: Tata Motors Passenger Vehicle Ltd | I15: 27AAHCT8301P1ZT | J15: MH6100682260 | K15: 45604 | L15: 24-25/PUR/11929 | M15: 45638 | N15: MH | O15: MH04HD3714 | P15: MS Scrap | Q15: Used/Scrapped/Defaced Dies and Fixtures | R15: 29120 | S15: 33.521 | T15: =R15*S15 -> 976131.52 | U15: Regular | V15: Fy 2024-25 | W15: =TEXT(Z15,"mmm-yy") -> Feb-25 | X15: A13K | Y15: MPPUNE/011 | Z15: 45716 | AA15: 25/MPPIB/INV0396 | AB15: Yash Enterprises | AC15: CRC | AD15: Scrap Dismantled & in cut size structural steel | AE15: 21600 | AF15: 35.3 | AG15: =AE15*AF15 -> 762480 | AH15: 0 | AI15: =AG15+AH15 -> 762480 | AJ15: 0 | AK15: =AE15-AJ15 -> 21600 | AL15: =AE15*S15 -> 724053.6 | AM15: =(AG15+AH15)-AL15 -> 38426.4 | AN15: =IFERROR(AM15/(AG15+AH15),0) -> 0.050396601 | AO15: =AE15*S15 -> 724053.6 | AP15: =(Z15-K15) -> 112 | AQ15: =T15*9.35%*AP15/365 -> 28005.614 | AR15: =AM15-AQ15 -> 10420.786 | AS15: =AR15/(AG15+AH15) -> 0.013666962
B16: =B15+1 -> 12 | C16: FY 2024-25 | D16: =TEXT(F16,"mmm-yy") -> Dec-24 | E16: Regular | F16: 45638 | G16: 009 | H16: Tata Motors Passenger Vehicle Ltd | I16: 27AAHCT8301P1ZT | J16: MH6100681729 | K16: 45604 | L16: 24-25/PUR/11931 | M16: 45638 | N16: MH | O16: MH04HD3353 | P16: MS Scrap | Q16: Used/Scrapped/Defaced Dies and Fixtures | R16: 26990 | S16: 33.521 | T16: =R16*S16 -> 904731.79 | U16: Regular | V16: Fy 2024-25 | W16: =TEXT(Z16,"mmm-yy") -> Mar-25 | X16: B1244K | Y16: MPPUNE/012 | Z16: 45719 | AA16: 25/MPPIB/INV0404 | AB16: Prajapati Casting Foundry Private Limited | AC16: MS Scrap | AD16: MS Scrap (Casting) | AE16: 20900 | AF16: 38.5 | AG16: =AE16*AF16 -> 804650 | AH16: 0 | AI16: =AG16+AH16 -> 804650 | AJ16: 0 | AK16: =AE16-AJ16 -> 20900 | AL16: =AE16*S16 -> 700588.9 | AM16: =(AG16+AH16)-AL16 -> 104061.1 | AN16: =IFERROR(AM16/(AG16+AH16),0) -> 0.12932468 | AO16: =AE16*S16 -> 700588.9 | AP16: =(Z16-K16) -> 115 | AQ16: =T16*9.35%*AP16/365 -> 26652.407 | AR16: =AM16-AQ16 -> 77408.693 | AS16: =AR16/(AG16+AH16) -> 0.096201694
B17: =B16+1 -> 13 | C17: FY 2024-25 | D17: =TEXT(F17,"mmm-yy") -> Dec-24 | E17: Regular | F17: 45638 | G17: 008 | H17: Tata Motors Passenger Vehicle Ltd | I17: 27AAHCT8301P1ZT | J17: MH6100683932 | K17: 45605 | L17: 24-25/PUR/11930 | M17: 45638 | N17: MH | O17: MH12MV6966 | P17: MS Scrap | Q17: Used/Scrapped/Defaced Dies and Fixtures | R17: 29550 | S17: 33.521 | T17: =R17*S17 -> 990545.55 | U17: Regular | V17: Fy 2024-25 | W17: =TEXT(Z17,"mmm-yy") -> Mar-25 | X17: B1244K | Y17: MPPUNE/013 | Z17: 45719 | AA17: 25/MPPIB/INV0402 | AB17: Madhuban Trade Steels Private Limited | AC17: MS Scrap | AD17: MS Scrap (Casting) | AE17: 22860 | AF17: 36.5 | AG17: =AE17*AF17 -> 834390 | AH17: 0 | AI17: =AG17+AH17 -> 834390 | AJ17: 0 | AK17: =AE17-AJ17 -> 22860 | AL17: =AE17*S17 -> 766290.06 | AM17: =(AG17+AH17)-AL17 -> 68099.94 | AN17: =IFERROR(AM17/(AG17+AH17),0) -> 0.081616438 | AO17: =AE17*S17 -> 766290.06 | AP17: =(Z17-K17) -> 114 | AQ17: =T17*9.35%*AP17/365 -> 28926.644 | AR17: =AM17-AQ17 -> 39173.296 | AS17: =AR17/(AG17+AH17) -> 0.046948425
... B41: =B40+1 -> 37 | C41: FY 2024-25 | D41: =TEXT(F41,"mmm-yy") -> Jan-25 | E41: Regular | F41: 45673 | G41: 020 | H41: Tata Motors Ltd | I41: 27AAACT2727Q1ZW | J41: MH0100935797 | K41: 45673 | L41: 24-25/PUR/13395 | M41: 45675 | N41: MH | O41: MH12KP9590 | P41: MS Scrap | Q41: Scrap Dismantled & in cut size structural steel | R41: 6800 | S41: 32.121 | T41: =R41*S41 -> 218422.8 | U41: Regular | V41: Fy 2025-26 | W41: =TEXT(Z41,"mmm-yy") -> Apr-25 | X41: B514CA | Y41: MPPUNE/0037 | Z41: 45772 | AA41: 26/MPPIB/INV0068 | AB41: Yash Enterprises | AC41: MS Scrap | AD41: Scrap steel forging | AE41: 11660 | AF41: 34.8 | AG41: =AE41*AF41 -> 405768 | AH41: 0 | AI41: =AG41+AH41 -> 405768 | AJ41: 0 | AK41: =AE41-AJ41 -> 11660 | AL41: =AE41*S41 -> 374530.86 | AM41: =(AG41+AH41)-AL41 -> 31237.14 | AN41: =IFERROR(AM41/(AG41+AH41),0) -> 0.076982759 | AO41: =AE41*S41 -> 374530.86 | AP41: =(Z41-K41) -> 99 | AQ41: =T41*9.35%*AP41/365 -> 5539.262 | AR41: =AM41-AQ41 -> 25697.878 | AS41: =AR41/(AG41+AH41) -> 0.063331455
B42: =B41+1 -> 38 | C42: FY 2024-25 | D42: =TEXT(F42,"mmm-yy") -> Jan-25 | E42: Regular | F42: 45675 | G42: 021 | H42: Tata Motors Passenger Vehicle Ltd | I42: 27AAHCT8301P1ZT | J42: MH6100933162 | K42: 45675 | L42: 24-25/PUR/13441 | M42: 45677 | N42: MH | O42: MH12KP9590 | P42: Commercial | Q42: Scrap Gascut Aluminium | R42: 2760 | S42: 84.521 | T42: =R42*S42 -> 233277.96 | U42: Regular | V42: Fy 2025-26 | W42: =TEXT(Z42,"mmm-yy") -> May-25 | X42: Suyash | Y42: MPPUNE/0038 | Z42: 45785 | AA42: 26/MPPIB/INV0096 | AB42: Prajapati Foundry Private Limited | AC42: CRC | AD42: MS Scrap (CRC) | AE42: 7550 | AF42: 40 | AG42: =AE42*AF42 -> 302000 | AH42: -302000 | AI42: =AG42+AH42 -> 0 | AJ42: 7550 | AK42: =AE42-AJ42 -> 0 | AL42: =AE42*S42 -> 638133.55 | AM42: =(AG42+AH42)-AL42 -> -638133.55 | AN42: =IFERROR(AM42/(AG42+AH42),0) -> 0 | AO42: =AE42*S42 -> 638133.55 | AR42: =AM42-AQ42 -> -638133.55
