Workbook

Sheet Summary
T2: ="As on"& " "&TEXT(Details!P22,"dd-mmm-yyyy") -> As on 14-Jun-2026 | U2: Non-Ferrous | AJ2: Ferrous | AY2: M3
D3: =TEXT(D5,"mmm-yy") -> Apr-26 | E3: =TEXT(E5,"mmm-yy") -> May-26 | F3: =TEXT(F5,"mmm-yy") -> Jun-26 | G3: =TEXT(G5,"mmm-yy") -> Jul-26 | H3: =TEXT(H5,"mmm-yy") -> Aug-26 | I3: =TEXT(I5,"mmm-yy") -> Sep-26 | J3: =TEXT(J5,"mmm-yy") -> Oct-26 | K3: =TEXT(K5,"mmm-yy") -> Nov-26 | ... O3: =TEXT(O5,"mmm-yy") -> Mar-27 | U3: Apr-25 | V3: =E3 -> May-26 | W3: =F3 -> Jun-26 | X3: =G3 -> Jul-26 | Y3: =H3 -> Aug-26 | Z3: =I3 -> Sep-26 | AA3: =J3 -> Oct-26 | AB3: =K3 -> Nov-26 | AC3: =L3 -> Dec-26 | ... AF3: =O3 -> Mar-27 | AJ3: =D3 -> Apr-26 | AK3: =E3 -> May-26 | AL3: =F3 -> Jun-26 | AM3: =G3 -> Jul-26 | AN3: =H3 -> Aug-26 | AO3: =I3 -> Sep-26 | AP3: =J3 -> Oct-26 | AQ3: =K3 -> Nov-26 | ... AU3: =O3 -> Mar-27 | AY3: =TEXT(AY5,"mmm-yy") -> Apr-26 | AZ3: =TEXT(AZ5,"mmm-yy") -> May-26 | BA3: =TEXT(BA5,"mmm-yy") -> Jun-26 | BB3: =TEXT(BB5,"mmm-yy") -> Jul-26 | BC3: =TEXT(BC5,"mmm-yy") -> Aug-26 | BD3: =TEXT(BD5,"mmm-yy") -> Sep-26 | BE3: =TEXT(BE5,"mmm-yy") -> Oct-26 | BF3: =TEXT(BF5,"mmm-yy") -> Nov-26 | ... BJ3: =TEXT(BJ5,"mmm-yy") -> Mar-27
D4: 30 | E4: 31 | F4: 14 | G4: 0 | H4: 0 | I4: 0 | J4: 0 | K4: 0 | L4: 0 | M4: 0 | N4: 0 | O4: 0 | P4: =SUM(D4:O4) -> 75 | U4: =D4 -> 30 | V4: =E4 -> 31 | W4: =F4 -> 14 | X4: =G4 -> 0 | Y4: =H4 -> 0 | Z4: =I4 -> 0 | AA4: =J4 -> 0 | AB4: =K4 -> 0 | ... AG4: =P4 -> 75 | AJ4: =D4 -> 30 | AK4: =E4 -> 31 | AL4: =F4 -> 14 | AM4: =G4 -> 0 | AN4: =H4 -> 0 | AO4: =I4 -> 0 | AP4: =J4 -> 0 | AQ4: =K4 -> 0 | ... AV4: =P4 -> 75 | AY4: =D4 -> 30 | AZ4: =E4 -> 31 | BA4: =F4 -> 14 | BB4: =G4 -> 0 | BC4: =H4 -> 0 | BD4: =I4 -> 0 | BE4: =J4 -> 0 | BF4: =K4 -> 0 | ... BK4: =P4 -> 75
C5: Marketplace (M4) | D5: 46113 | E5: 46143 | F5: 46174 | G5: 46204 | H5: 46235 | I5: 46266 | J5: 46296 | K5: 46327 | L5: 46357 | M5: 46388 | N5: 46419 | O5: 46447 | P5: FY 2026-27 | T5: Non-Ferrous | U5: =D5 -> 46113 | V5: =E5 -> 46143 | W5: =F5 -> 46174 | X5: =G5 -> 46204 | Y5: =H5 -> 46235 | Z5: =I5 -> 46266 | AA5: =J5 -> 46296 | AB5: =K5 -> 46327 | ... AG5: =P5 -> FY 2026-27 | AI5: Ferrous | AJ5: =U5 -> 46113 | AK5: =V5 -> 46143 | AL5: =W5 -> 46174 | AM5: =X5 -> 46204 | AN5: =Y5 -> 46235 | AO5: =Z5 -> 46266 | AP5: =AA5 -> 46296 | AQ5: =AB5 -> 46327 | ... AV5: =AG5 -> FY 2026-27 | AX5: M3 | AY5: =AJ5 -> 46113 | AZ5: =AK5 -> 46143 | BA5: =AL5 -> 46174 | BB5: =AM5 -> 46204 | BC5: =AN5 -> 46235 | BD5: =AO5 -> 46266 | BE5: =AP5 -> 46296 | BF5: =AQ5 -> 46327 | ... BK5: =AV5 -> FY 2026-27 | BM5: Check
C6: Quantity (MT) | D6: =SUMIFS(Details!$BB$5:$BB$11,Details!$C$5:$C$11,Summary!D$5) -> 62 | E6: =SUMIFS(Details!$BB$5:$BB$11,Details!$C$5:$C$11,Summary!E$5) -> 66 | F6: =SUMIFS(Details!$BB$5:$BB$11,Details!$C$5:$C$11,Summary!F$5) -> 70 | G6: =SUMIFS(Details!$BB$5:$BB$11,Details!$C$5:$C$11,Summary!G$5) -> 0 | H6: =SUMIFS(Details!$BB$5:$BB$11,Details!$C$5:$C$11,Summary!H$5) -> 0 | I6: =SUMIFS(Details!$BB$5:$BB$11,Details!$C$5:$C$11,Summary!I$5) -> 0 | J6: =SUMIFS(Details!$BB$5:$BB$11,Details!$C$5:$C$11,Summary!J$5) -> 0 | K6: =SUMIFS(Details!$BB$5:$BB$11,Details!$C$5:$C$11,Summary!K$5) -> 0 | ... O6: =SUMIFS(Details!$BB$5:$BB$11,Details!$C$5:$C$11,Summary!O$5) -> 0 | P6: =SUM(D6:O6) -> 198 | Q6: =Details!BB12 -> 198 | R6: =P6-Q6 -> 0 | T6: Quantity (MT) | U6: =SUMIFS(Details!$S$5:$S$11,Details!$C$5:$C$11,Summary!U$5,Details!$CK$5:$CK$11,Summary!$T$5)/1000 -> 0 | V6: =SUMIFS(Details!$S$5:$S$11,Details!$C$5:$C$11,Summary!V$5,Details!$CK$5:$CK$11,Summary!$T$5)/1000 -> 0 | W6: =SUMIFS(Details!$S$5:$S$11,Details!$C$5:$C$11,Summary!W$5,Details!$CK$5:$CK$11,Summary!$T$5)/1000 -> 0 | X6: =SUMIFS(Details!$S$5:$S$11,Details!$C$5:$C$11,Summary!X$5,Details!$CK$5:$CK$11,Summary!$T$5)/1000 -> 0 | Y6: =SUMIFS(Details!$S$5:$S$11,Details!$C$5:$C$11,Summary!Y$5,Details!$CK$5:$CK$11,Summary!$T$5)/1000 -> 0 | Z6: =SUMIFS(Details!$S$5:$S$11,Details!$C$5:$C$11,Summary!Z$5,Details!$CK$5:$CK$11,Summary!$T$5)/1000 -> 0 | AA6: =SUMIFS(Details!$S$5:$S$11,Details!$C$5:$C$11,Summary!AA$5,Details!$CK$5:$CK$11,Summary!$T$5)/1000 -> 0 | AB6: =SUMIFS(Details!$S$5:$S$11,Details!$C$5:$C$11,Summary!AB$5,Details!$CK$5:$CK$11,Summary!$T$5)/1000 -> 0 | ... AF6: =SUMIFS(Details!$S$5:$S$11,Details!$C$5:$C$11,Summary!AF$5,Details!$CK$5:$CK$11,Summary!$T$5)/1000 -> 0 | AG6: =SUM(U6:AF6) -> 0 | AI6: Quantity (MT) | AJ6: =SUMIFS(Details!$S$5:$S$11,Details!$C$5:$C$11,Summary!AJ$5,Details!$CK$5:$CK$11,Summary!$AI$5)/1000 -> 0 | AK6: =SUMIFS(Details!$S$5:$S$11,Details!$C$5:$C$11,Summary!AK$5,Details!$CK$5:$CK$11,Summary!$AI$5)/1000 -> 0 | AL6: =SUMIFS(Details!$S$5:$S$11,Details!$C$5:$C$11,Summary!AL$5,Details!$CK$5:$CK$11,Summary!$AI$5)/1000 -> 0 | AM6: =SUMIFS(Details!$S$5:$S$11,Details!$C$5:$C$11,Summary!AM$5,Details!$CK$5:$CK$11,Summary!$AI$5)/1000 -> 0 | AN6: =SUMIFS(Details!$S$5:$S$11,Details!$C$5:$C$11,Summary!AN$5,Details!$CK$5:$CK$11,Summary!$AI$5)/1000 -> 0 | AO6: =SUMIFS(Details!$S$5:$S$11,Details!$C$5:$C$11,Summary!AO$5,Details!$CK$5:$CK$11,Summary!$AI$5)/1000 -> 0 | AP6: =SUMIFS(Details!$S$5:$S$11,Details!$C$5:$C$11,Summary!AP$5,Details!$CK$5:$CK$11,Summary!$AI$5)/1000 -> 0 | AQ6: =SUMIFS(Details!$S$5:$S$11,Details!$C$5:$C$11,Summary!AQ$5,Details!$CK$5:$CK$11,Summary!$AI$5)/1000 -> 0 | ... AU6: =SUMIFS(Details!$S$5:$S$11,Details!$C$5:$C$11,Summary!AU$5,Details!$CK$5:$CK$11,Summary!$AI$5)/1000 -> 0 | AV6: =SUM(AJ6:AU6) -> 0 | AX6: Quantity (MT) | AY6: =SUMIFS(Details!$S$5:$S$11,Details!$C$5:$C$11,Summary!AY$5,Details!$CK$5:$CK$11,Summary!$AX$5)/1000 -> 0 | AZ6: =SUMIFS(Details!$S$5:$S$11,Details!$C$5:$C$11,Summary!AZ$5,Details!$CK$5:$CK$11,Summary!$AX$5)/1000 -> 0 | BA6: =SUMIFS(Details!$S$5:$S$11,Details!$C$5:$C$11,Summary!BA$5,Details!$CK$5:$CK$11,Summary!$AX$5)/1000 -> 0 | BB6: =SUMIFS(Details!$S$5:$S$11,Details!$C$5:$C$11,Summary!BB$5,Details!$CK$5:$CK$11,Summary!$AX$5)/1000 -> 0 | BC6: =SUMIFS(Details!$S$5:$S$11,Details!$C$5:$C$11,Summary!BC$5,Details!$CK$5:$CK$11,Summary!$AX$5)/1000 -> 0 | BD6: =SUMIFS(Details!$S$5:$S$11,Details!$C$5:$C$11,Summary!BD$5,Details!$CK$5:$CK$11,Summary!$AX$5)/1000 -> 0 | BE6: =SUMIFS(Details!$S$5:$S$11,Details!$C$5:$C$11,Summary!BE$5,Details!$CK$5:$CK$11,Summary!$AX$5)/1000 -> 0 | BF6: =SUMIFS(Details!$S$5:$S$11,Details!$C$5:$C$11,Summary!BF$5,Details!$CK$5:$CK$11,Summary!$AX$5)/1000 -> 0 | ... BJ6: =SUMIFS(Details!$S$5:$S$11,Details!$C$5:$C$11,Summary!BJ$5,Details!$CK$5:$CK$11,Summary!$AX$5)/1000 -> 0 | BK6: =SUM(AY6:BJ6) -> 0 | BM6: =(AG6+AV6+BK6)-P6 -> -198
C7: Sales | D7: =SUMIFS(Details!$BQ$5:$BQ$11,Details!$C$5:$C$11,Summary!D$5) -> 32860 | E7: =SUMIFS(Details!$BQ$5:$BQ$11,Details!$C$5:$C$11,Summary!E$5) -> 34980 | F7: =SUMIFS(Details!$BQ$5:$BQ$11,Details!$C$5:$C$11,Summary!F$5) -> 19950 | G7: =SUMIFS(Details!$BQ$5:$BQ$11,Details!$C$5:$C$11,Summary!G$5) -> 0 | H7: =SUMIFS(Details!$BQ$5:$BQ$11,Details!$C$5:$C$11,Summary!H$5) -> 0 | I7: =SUMIFS(Details!$BQ$5:$BQ$11,Details!$C$5:$C$11,Summary!I$5) -> 0 | J7: =SUMIFS(Details!$BQ$5:$BQ$11,Details!$C$5:$C$11,Summary!J$5) -> 0 | K7: =SUMIFS(Details!$BQ$5:$BQ$11,Details!$C$5:$C$11,Summary!K$5) -> 0 | ... O7: =SUMIFS(Details!$BQ$5:$BQ$11,Details!$C$5:$C$11,Summary!O$5) -> 0 | P7: =SUM(D7:O7) -> 87790 | Q7: =Details!BQ12 -> 87790 | R7: =P7-Q7 -> 0 | T7: Sales | U7: =SUMIFS(Details!$BQ$5:$BQ$11,Details!$C$5:$C$11,Summary!U$5,Details!$CK$5:$CK$11,Summary!$T$5) -> 0 | V7: =SUMIFS(Details!$BQ$5:$BQ$11,Details!$C$5:$C$11,Summary!V$5,Details!$CK$5:$CK$11,Summary!$T$5) -> 0 | W7: =SUMIFS(Details!$BQ$5:$BQ$11,Details!$C$5:$C$11,Summary!W$5,Details!$CK$5:$CK$11,Summary!$T$5) -> 0 | X7: =SUMIFS(Details!$BQ$5:$BQ$11,Details!$C$5:$C$11,Summary!X$5,Details!$CK$5:$CK$11,Summary!$T$5) -> 0 | Y7: =SUMIFS(Details!$BQ$5:$BQ$11,Details!$C$5:$C$11,Summary!Y$5,Details!$CK$5:$CK$11,Summary!$T$5) -> 0 | Z7: =SUMIFS(Details!$BQ$5:$BQ$11,Details!$C$5:$C$11,Summary!Z$5,Details!$CK$5:$CK$11,Summary!$T$5) -> 0 | AA7: =SUMIFS(Details!$BQ$5:$BQ$11,Details!$C$5:$C$11,Summary!AA$5,Details!$CK$5:$CK$11,Summary!$T$5) -> 0 | AB7: =SUMIFS(Details!$BQ$5:$BQ$11,Details!$C$5:$C$11,Summary!AB$5,Details!$CK$5:$CK$11,Summary!$T$5) -> 0 | ... AF7: =SUMIFS(Details!$BQ$5:$BQ$11,Details!$C$5:$C$11,Summary!AF$5,Details!$CK$5:$CK$11,Summary!$T$5) -> 0 | AG7: =SUM(U7:AF7) -> 0 | AI7: Sales | AJ7: =SUMIFS(Details!$BQ$5:$BQ$11,Details!$C$5:$C$11,Summary!AJ$5,Details!$CK$5:$CK$11,Summary!$AI$5) -> 0 | AK7: =SUMIFS(Details!$BQ$5:$BQ$11,Details!$C$5:$C$11,Summary!AK$5,Details!$CK$5:$CK$11,Summary!$AI$5) -> 0 | AL7: =SUMIFS(Details!$BQ$5:$BQ$11,Details!$C$5:$C$11,Summary!AL$5,Details!$CK$5:$CK$11,Summary!$AI$5) -> 0 | AM7: =SUMIFS(Details!$BQ$5:$BQ$11,Details!$C$5:$C$11,Summary!AM$5,Details!$CK$5:$CK$11,Summary!$AI$5) -> 0 | AN7: =SUMIFS(Details!$BQ$5:$BQ$11,Details!$C$5:$C$11,Summary!AN$5,Details!$CK$5:$CK$11,Summary!$AI$5) -> 0 | AO7: =SUMIFS(Details!$BQ$5:$BQ$11,Details!$C$5:$C$11,Summary!AO$5,Details!$CK$5:$CK$11,Summary!$AI$5) -> 0 | AP7: =SUMIFS(Details!$BQ$5:$BQ$11,Details!$C$5:$C$11,Summary!AP$5,Details!$CK$5:$CK$11,Summary!$AI$5) -> 0 | AQ7: =SUMIFS(Details!$BQ$5:$BQ$11,Details!$C$5:$C$11,Summary!AQ$5,Details!$CK$5:$CK$11,Summary!$AI$5) -> 0 | ... AU7: =SUMIFS(Details!$BQ$5:$BQ$11,Details!$C$5:$C$11,Summary!AU$5,Details!$CK$5:$CK$11,Summary!$AI$5) -> 0 | AV7: =SUM(AJ7:AU7) -> 0 | AX7: Sales | AY7: =SUMIFS(Details!$BQ$5:$BQ$11,Details!$C$5:$C$11,Summary!AY$5,Details!$CK$5:$CK$11,Summary!$AX$5) -> 0 | AZ7: =SUMIFS(Details!$BQ$5:$BQ$11,Details!$C$5:$C$11,Summary!AZ$5,Details!$CK$5:$CK$11,Summary!$AX$5) -> 0 | BA7: =SUMIFS(Details!$BQ$5:$BQ$11,Details!$C$5:$C$11,Summary!BA$5,Details!$CK$5:$CK$11,Summary!$AX$5) -> 0 | BB7: =SUMIFS(Details!$BQ$5:$BQ$11,Details!$C$5:$C$11,Summary!BB$5,Details!$CK$5:$CK$11,Summary!$AX$5) -> 0 | BC7: =SUMIFS(Details!$BQ$5:$BQ$11,Details!$C$5:$C$11,Summary!BC$5,Details!$CK$5:$CK$11,Summary!$AX$5) -> 0 | BD7: =SUMIFS(Details!$BQ$5:$BQ$11,Details!$C$5:$C$11,Summary!BD$5,Details!$CK$5:$CK$11,Summary!$AX$5) -> 0 | BE7: =SUMIFS(Details!$BQ$5:$BQ$11,Details!$C$5:$C$11,Summary!BE$5,Details!$CK$5:$CK$11,Summary!$AX$5) -> 0 | BF7: =SUMIFS(Details!$BQ$5:$BQ$11,Details!$C$5:$C$11,Summary!BF$5,Details!$CK$5:$CK$11,Summary!$AX$5) -> 0 | ... BJ7: =SUMIFS(Details!$BQ$5:$BQ$11,Details!$C$5:$C$11,Summary!BJ$5,Details!$CK$5:$CK$11,Summary!$AX$5) -> 0 | BK7: =SUM(AY7:BJ7) -> 0 | BM7: =(AG7+AV7+BK7)-P7 -> -87790
C8: Purchases | D8: =SUMIFS(Details!$AM$5:$AM$11,Details!$C$5:$C$11,Summary!D$5)-SUMIFS(Details!$AB$5:$AB$11,Details!$C$5:$C$11,Summary!D$5) -> 29400 | E8: =SUMIFS(Details!$AM$5:$AM$11,Details!$C$5:$C$11,Summary!E$5)-SUMIFS(Details!$AB$5:$AB$11,Details!$C$5:$C$11,Summary!E$5) -> 30900 | F8: =SUMIFS(Details!$AM$5:$AM$11,Details!$C$5:$C$11,Summary!F$5)-SUMIFS(Details!$AB$5:$AB$11,Details!$C$5:$C$11,Summary!F$5) -> 8900 | G8: =SUMIFS(Details!$AM$5:$AM$11,Details!$C$5:$C$11,Summary!G$5)-SUMIFS(Details!$AB$5:$AB$11,Details!$C$5:$C$11,Summary!G$5) -> 0 | H8: =SUMIFS(Details!$AM$5:$AM$11,Details!$C$5:$C$11,Summary!H$5)-SUMIFS(Details!$AB$5:$AB$11,Details!$C$5:$C$11,Summary!H$5) -> 0 | I8: =SUMIFS(Details!$AM$5:$AM$11,Details!$C$5:$C$11,Summary!I$5)-SUMIFS(Details!$AB$5:$AB$11,Details!$C$5:$C$11,Summary!I$5) -> 0 | J8: =SUMIFS(Details!$AM$5:$AM$11,Details!$C$5:$C$11,Summary!J$5)-SUMIFS(Details!$AB$5:$AB$11,Details!$C$5:$C$11,Summary!J$5) -> 0 | K8: =SUMIFS(Details!$AM$5:$AM$11,Details!$C$5:$C$11,Summary!K$5)-SUMIFS(Details!$AB$5:$AB$11,Details!$C$5:$C$11,Summary!K$5) -> 0 | ... O8: =SUMIFS(Details!$AM$5:$AM$11,Details!$C$5:$C$11,Summary!O$5)-SUMIFS(Details!$AB$5:$AB$11,Details!$C$5:$C$11,Summary!O$5) -> 0 | P8: =SUM(D8:O8) -> 69200 | Q8: =Details!P13 -> 69200 | R8: =P8-Q8 -> 0 | T8: Purchases | U8: =SUMIFS(Details!$AM$5:$AM$11,Details!$C$5:$C$11,Summary!U$5,Details!$CK$5:$CK$11,Summary!$T$5)-SUMIFS(Details!$AB$5:$AB$11,Details!$C$5:$C$11,Summary!U$5,Details!$CK$5:$CK$11,Summary!$T$5) -> 0 | V8: =SUMIFS(Details!$AM$5:$AM$11,Details!$C$5:$C$11,Summary!V$5,Details!$CK$5:$CK$11,Summary!$T$5)-SUMIFS(Details!$AB$5:$AB$11,Details!$C$5:$C$11,Summary!V$5,Details!$CK$5:$CK$11,Summary!$T$5) -> 0 | W8: =SUMIFS(Details!$AM$5:$AM$11,Details!$C$5:$C$11,Summary!W$5,Details!$CK$5:$CK$11,Summary!$T$5)-SUMIFS(Details!$AB$5:$AB$11,Details!$C$5:$C$11,Summary!W$5,Details!$CK$5:$CK$11,Summary!$T$5) -> 0 | X8: =SUMIFS(Details!$AM$5:$AM$11,Details!$C$5:$C$11,Summary!X$5,Details!$CK$5:$CK$11,Summary!$T$5)-SUMIFS(Details!$AB$5:$AB$11,Details!$C$5:$C$11,Summary!X$5,Details!$CK$5:$CK$11,Summary!$T$5) -> 0 | Y8: =SUMIFS(Details!$AM$5:$AM$11,Details!$C$5:$C$11,Summary!Y$5,Details!$CK$5:$CK$11,Summary!$T$5)-SUMIFS(Details!$AB$5:$AB$11,Details!$C$5:$C$11,Summary!Y$5,Details!$CK$5:$CK$11,Summary!$T$5) -> 0 | Z8: =SUMIFS(Details!$AM$5:$AM$11,Details!$C$5:$C$11,Summary!Z$5,Details!$CK$5:$CK$11,Summary!$T$5)-SUMIFS(Details!$AB$5:$AB$11,Details!$C$5:$C$11,Summary!Z$5,Details!$CK$5:$CK$11,Summary!$T$5) -> 0 | AA8: =SUMIFS(Details!$AM$5:$AM$11,Details!$C$5:$C$11,Summary!AA$5,Details!$CK$5:$CK$11,Summary!$T$5)-SUMIFS(Details!$AB$5:$AB$11,Details!$C$5:$C$11,Summary!AA$5,Details!$CK$5:$CK$11,Summary!$T$5) -> 0 | AB8: =SUMIFS(Details!$AM$5:$AM$11,Details!$C$5:$C$11,Summary!AB$5,Details!$CK$5:$CK$11,Summary!$T$5)-SUMIFS(Details!$AB$5:$AB$11,Details!$C$5:$C$11,Summary!AB$5,Details!$CK$5:$CK$11,Summary!$T$5) -> 0 | ... AF8: =SUMIFS(Details!$AM$5:$AM$11,Details!$C$5:$C$11,Summary!AF$5,Details!$CK$5:$CK$11,Summary!$T$5)-SUMIFS(Details!$AB$5:$AB$11,Details!$C$5:$C$11,Summary!AF$5,Details!$CK$5:$CK$11,Summary!$T$5) -> 0 | AG8: =SUM(U8:AF8) -> 0 | AI8: Purchases | AJ8: =SUMIFS(Details!$AM$5:$AM$11,Details!$C$5:$C$11,Summary!AJ$5,Details!$CK$5:$CK$11,Summary!$AI$5)-SUMIFS(Details!$AB$5:$AB$11,Details!$C$5:$C$11,Summary!AJ$5,Details!$CK$5:$CK$11,Summary!$AI$5) -> 0 | AK8: =SUMIFS(Details!$AM$5:$AM$11,Details!$C$5:$C$11,Summary!AK$5,Details!$CK$5:$CK$11,Summary!$AI$5)-SUMIFS(Details!$AB$5:$AB$11,Details!$C$5:$C$11,Summary!AK$5,Details!$CK$5:$CK$11,Summary!$AI$5) -> 0 | AL8: =SUMIFS(Details!$AM$5:$AM$11,Details!$C$5:$C$11,Summary!AL$5,Details!$CK$5:$CK$11,Summary!$AI$5)-SUMIFS(Details!$AB$5:$AB$11,Details!$C$5:$C$11,Summary!AL$5,Details!$CK$5:$CK$11,Summary!$AI$5) -> 0 | AM8: =SUMIFS(Details!$AM$5:$AM$11,Details!$C$5:$C$11,Summary!AM$5,Details!$CK$5:$CK$11,Summary!$AI$5)-SUMIFS(Details!$AB$5:$AB$11,Details!$C$5:$C$11,Summary!AM$5,Details!$CK$5:$CK$11,Summary!$AI$5) -> 0 | AN8: =SUMIFS(Details!$AM$5:$AM$11,Details!$C$5:$C$11,Summary!AN$5,Details!$CK$5:$CK$11,Summary!$AI$5)-SUMIFS(Details!$AB$5:$AB$11,Details!$C$5:$C$11,Summary!AN$5,Details!$CK$5:$CK$11,Summary!$AI$5) -> 0 | AO8: =SUMIFS(Details!$AM$5:$AM$11,Details!$C$5:$C$11,Summary!AO$5,Details!$CK$5:$CK$11,Summary!$AI$5)-SUMIFS(Details!$AB$5:$AB$11,Details!$C$5:$C$11,Summary!AO$5,Details!$CK$5:$CK$11,Summary!$AI$5) -> 0 | AP8: =SUMIFS(Details!$AM$5:$AM$11,Details!$C$5:$C$11,Summary!AP$5,Details!$CK$5:$CK$11,Summary!$AI$5)-SUMIFS(Details!$AB$5:$AB$11,Details!$C$5:$C$11,Summary!AP$5,Details!$CK$5:$CK$11,Summary!$AI$5) -> 0 | AQ8: =SUMIFS(Details!$AM$5:$AM$11,Details!$C$5:$C$11,Summary!AQ$5,Details!$CK$5:$CK$11,Summary!$AI$5)-SUMIFS(Details!$AB$5:$AB$11,Details!$C$5:$C$11,Summary!AQ$5,Details!$CK$5:$CK$11,Summary!$AI$5) -> 0 | ... AU8: =SUMIFS(Details!$AM$5:$AM$11,Details!$C$5:$C$11,Summary!AU$5,Details!$CK$5:$CK$11,Summary!$AI$5)-SUMIFS(Details!$AB$5:$AB$11,Details!$C$5:$C$11,Summary!AU$5,Details!$CK$5:$CK$11,Summary!$AI$5) -> 0 | AV8: =SUM(AJ8:AU8) -> 0 | AX8: Purchases | AY8: =SUMIFS(Details!$AM$5:$AM$11,Details!$C$5:$C$11,Summary!AY$5,Details!$CK$5:$CK$11,Summary!$AX$5)-SUMIFS(Details!$AB$5:$AB$11,Details!$C$5:$C$11,Summary!AY$5,Details!$CK$5:$CK$11,Summary!$AX$5) -> 0 | AZ8: =SUMIFS(Details!$AM$5:$AM$11,Details!$C$5:$C$11,Summary!AZ$5,Details!$CK$5:$CK$11,Summary!$AX$5)-SUMIFS(Details!$AB$5:$AB$11,Details!$C$5:$C$11,Summary!AZ$5,Details!$CK$5:$CK$11,Summary!$AX$5) -> 0 | BA8: =SUMIFS(Details!$AM$5:$AM$11,Details!$C$5:$C$11,Summary!BA$5,Details!$CK$5:$CK$11,Summary!$AX$5)-SUMIFS(Details!$AB$5:$AB$11,Details!$C$5:$C$11,Summary!BA$5,Details!$CK$5:$CK$11,Summary!$AX$5) -> 0 | BB8: =SUMIFS(Details!$AM$5:$AM$11,Details!$C$5:$C$11,Summary!BB$5,Details!$CK$5:$CK$11,Summary!$AX$5)-SUMIFS(Details!$AB$5:$AB$11,Details!$C$5:$C$11,Summary!BB$5,Details!$CK$5:$CK$11,Summary!$AX$5) -> 0 | BC8: =SUMIFS(Details!$AM$5:$AM$11,Details!$C$5:$C$11,Summary!BC$5,Details!$CK$5:$CK$11,Summary!$AX$5)-SUMIFS(Details!$AB$5:$AB$11,Details!$C$5:$C$11,Summary!BC$5,Details!$CK$5:$CK$11,Summary!$AX$5) -> 0 | BD8: =SUMIFS(Details!$AM$5:$AM$11,Details!$C$5:$C$11,Summary!BD$5,Details!$CK$5:$CK$11,Summary!$AX$5)-SUMIFS(Details!$AB$5:$AB$11,Details!$C$5:$C$11,Summary!BD$5,Details!$CK$5:$CK$11,Summary!$AX$5) -> 0 | BE8: =SUMIFS(Details!$AM$5:$AM$11,Details!$C$5:$C$11,Summary!BE$5,Details!$CK$5:$CK$11,Summary!$AX$5)-SUMIFS(Details!$AB$5:$AB$11,Details!$C$5:$C$11,Summary!BE$5,Details!$CK$5:$CK$11,Summary!$AX$5) -> 0 | BF8: =SUMIFS(Details!$AM$5:$AM$11,Details!$C$5:$C$11,Summary!BF$5,Details!$CK$5:$CK$11,Summary!$AX$5)-SUMIFS(Details!$AB$5:$AB$11,Details!$C$5:$C$11,Summary!BF$5,Details!$CK$5:$CK$11,Summary!$AX$5) -> 0 | ... BJ8: =SUMIFS(Details!$AM$5:$AM$11,Details!$C$5:$C$11,Summary!BJ$5,Details!$CK$5:$CK$11,Summary!$AX$5)-SUMIFS(Details!$AB$5:$AB$11,Details!$C$5:$C$11,Summary!BJ$5,Details!$CK$5:$CK$11,Summary!$AX$5) -> 0 | BK8: =SUM(AY8:BJ8) -> 0 | BM8: =(AG8+AV8+BK8)-P8 -> -69200
C9: Gross Margin | D9: =D7-D8 -> 3460 | E9: =E7-E8 -> 4080 | F9: =F7-F8 -> 11050 | G9: =G7-G8 -> 0 | H9: =H7-H8 -> 0 | I9: =I7-I8 -> 0 | J9: =J7-J8 -> 0 | K9: =K7-K8 -> 0 | ... P9: =P7-P8 -> 18590 | T9: Gross Margin | U9: =U7-U8 -> 0 | V9: =V7-V8 -> 0 | W9: =W7-W8 -> 0 | X9: =X7-X8 -> 0 | Y9: =Y7-Y8 -> 0 | Z9: =Z7-Z8 -> 0 | AA9: =AA7-AA8 -> 0 | AB9: =AB7-AB8 -> 0 | ... AG9: =AG7-AG8 -> 0 | AI9: Gross Margin | AJ9: =AJ7-AJ8 -> 0 | AK9: =AK7-AK8 -> 0 | AL9: =AL7-AL8 -> 0 | AM9: =AM7-AM8 -> 0 | AN9: =AN7-AN8 -> 0 | AO9: =AO7-AO8 -> 0 | AP9: =AP7-AP8 -> 0 | AQ9: =AQ7-AQ8 -> 0 | ... AV9: =AV7-AV8 -> 0 | AX9: Gross Margin | AY9: =AY7-AY8 -> 0 | AZ9: =AZ7-AZ8 -> 0 | BA9: =BA7-BA8 -> 0 | BB9: =BB7-BB8 -> 0 | BC9: =BC7-BC8 -> 0 | BD9: =BD7-BD8 -> 0 | BE9: =BE7-BE8 -> 0 | BF9: =BF7-BF8 -> 0 | ... BK9: =BK7-BK8 -> 0 | BM9: =(AG9+AV9+BK9)-P9 -> -18590
C10: Gross Margin (%) | D10: =IFERROR((D9/D7),0) -> 0.10529519 | E10: =IFERROR((E9/E7),0) -> 0.11663808 | F10: =IFERROR((F9/F7),0) -> 0.55388471 | G10: =IFERROR((G9/G7),0) -> 0 | H10: =IFERROR((H9/H7),0) -> 0 | I10: =IFERROR((I9/I7),0) -> 0 | J10: =IFERROR((J9/J7),0) -> 0 | K10: =IFERROR((K9/K7),0) -> 0 | ... P10: =IFERROR((P9/P7),0) -> 0.21175533 | T10: Gross Margin (%) | U10: =IFERROR((U9/U7),0) -> 0 | V10: =IFERROR((V9/V7),0) -> 0 | W10: =IFERROR((W9/W7),0) -> 0 | X10: =IFERROR((X9/X7),0) -> 0 | Y10: =IFERROR((Y9/Y7),0) -> 0 | Z10: =IFERROR((Z9/Z7),0) -> 0 | AA10: =IFERROR((AA9/AA7),0) -> 0 | AB10: =IFERROR((AB9/AB7),0) -> 0 | ... AG10: =IFERROR((AG9/AG7),0) -> 0 | AI10: Gross Margin (%) | AJ10: =IFERROR((AJ9/AJ7),0) -> 0 | AK10: =IFERROR((AK9/AK7),0) -> 0 | AL10: =IFERROR((AL9/AL7),0) -> 0 | AM10: =IFERROR((AM9/AM7),0) -> 0 | AN10: =IFERROR((AN9/AN7),0) -> 0 | AO10: =IFERROR((AO9/AO7),0) -> 0 | AP10: =IFERROR((AP9/AP7),0) -> 0 | AQ10: =IFERROR((AQ9/AQ7),0) -> 0 | ... AV10: =IFERROR((AV9/AV7),0) -> 0 | AX10: Gross Margin (%) | AY10: =IFERROR((AY9/AY7),0) -> 0 | AZ10: =IFERROR((AZ9/AZ7),0) -> 0 | BA10: =IFERROR((BA9/BA7),0) -> 0 | BB10: =IFERROR((BB9/BB7),0) -> 0 | BC10: =IFERROR((BC9/BC7),0) -> 0 | BD10: =IFERROR((BD9/BD7),0) -> 0 | BE10: =IFERROR((BE9/BE7),0) -> 0 | BF10: =IFERROR((BF9/BF7),0) -> 0 | ... BK10: =IFERROR((BK9/BK7),0) -> 0 | BM10: =(AG10+AV10+BK10)-P10 -> -0.21175533
C11: Transportation Charges | D11: =SUMIFS(Details!$AB$5:$AB$11,Details!$C$5:$C$11,Summary!D$5) -> 0 | E11: =SUMIFS(Details!$AB$5:$AB$11,Details!$C$5:$C$11,Summary!E$5) -> 0 | F11: =SUMIFS(Details!$AB$5:$AB$11,Details!$C$5:$C$11,Summary!F$5) -> 0 | G11: =SUMIFS(Details!$AB$5:$AB$11,Details!$C$5:$C$11,Summary!G$5) -> 0 | H11: =SUMIFS(Details!$AB$5:$AB$11,Details!$C$5:$C$11,Summary!H$5) -> 0 | I11: =SUMIFS(Details!$AB$5:$AB$11,Details!$C$5:$C$11,Summary!I$5) -> 0 | J11: =SUMIFS(Details!$AB$5:$AB$11,Details!$C$5:$C$11,Summary!J$5) -> 0 | K11: =SUMIFS(Details!$AB$5:$AB$11,Details!$C$5:$C$11,Summary!K$5) -> 0 | ... O11: =SUMIFS(Details!$AB$5:$AB$11,Details!$C$5:$C$11,Summary!O$5) -> 0 | P11: =SUM(D11:O11) -> 0 | Q11: =Details!AB12 -> 0 | R11: =P11-Q11 -> 0 | T11: Transportation Charges | U11: =SUMIFS(Details!$AB$5:$AB$11,Details!$C$5:$C$11,Summary!U$5,Details!$CK$5:$CK$11,Summary!$T$5) -> 0 | V11: =SUMIFS(Details!$AB$5:$AB$11,Details!$C$5:$C$11,Summary!V$5,Details!$CK$5:$CK$11,Summary!$T$5) -> 0 | W11: =SUMIFS(Details!$AB$5:$AB$11,Details!$C$5:$C$11,Summary!W$5,Details!$CK$5:$CK$11,Summary!$T$5) -> 0 | X11: =SUMIFS(Details!$AB$5:$AB$11,Details!$C$5:$C$11,Summary!X$5,Details!$CK$5:$CK$11,Summary!$T$5) -> 0 | Y11: =SUMIFS(Details!$AB$5:$AB$11,Details!$C$5:$C$11,Summary!Y$5,Details!$CK$5:$CK$11,Summary!$T$5) -> 0 | Z11: =SUMIFS(Details!$AB$5:$AB$11,Details!$C$5:$C$11,Summary!Z$5,Details!$CK$5:$CK$11,Summary!$T$5) -> 0 | AA11: =SUMIFS(Details!$AB$5:$AB$11,Details!$C$5:$C$11,Summary!AA$5,Details!$CK$5:$CK$11,Summary!$T$5) -> 0 | AB11: =SUMIFS(Details!$AB$5:$AB$11,Details!$C$5:$C$11,Summary!AB$5,Details!$CK$5:$CK$11,Summary!$T$5) -> 0 | ... AF11: =SUMIFS(Details!$AB$5:$AB$11,Details!$C$5:$C$11,Summary!AF$5,Details!$CK$5:$CK$11,Summary!$T$5) -> 0 | AG11: =SUM(U11:AF11) -> 0 | AI11: Transportation Charges | AJ11: =SUMIFS(Details!$AB$5:$AB$11,Details!$C$5:$C$11,Summary!AJ$5,Details!$CK$5:$CK$11,Summary!$AI$5) -> 0 | AK11: =SUMIFS(Details!$AB$5:$AB$11,Details!$C$5:$C$11,Summary!AK$5,Details!$CK$5:$CK$11,Summary!$AI$5) -> 0 | AL11: =SUMIFS(Details!$AB$5:$AB$11,Details!$C$5:$C$11,Summary!AL$5,Details!$CK$5:$CK$11,Summary!$AI$5) -> 0 | AM11: =SUMIFS(Details!$AB$5:$AB$11,Details!$C$5:$C$11,Summary!AM$5,Details!$CK$5:$CK$11,Summary!$AI$5) -> 0 | AN11: =SUMIFS(Details!$AB$5:$AB$11,Details!$C$5:$C$11,Summary!AN$5,Details!$CK$5:$CK$11,Summary!$AI$5) -> 0 | AO11: =SUMIFS(Details!$AB$5:$AB$11,Details!$C$5:$C$11,Summary!AO$5,Details!$CK$5:$CK$11,Summary!$AI$5) -> 0 | AP11: =SUMIFS(Details!$AB$5:$AB$11,Details!$C$5:$C$11,Summary!AP$5,Details!$CK$5:$CK$11,Summary!$AI$5) -> 0 | AQ11: =SUMIFS(Details!$AB$5:$AB$11,Details!$C$5:$C$11,Summary!AQ$5,Details!$CK$5:$CK$11,Summary!$AI$5) -> 0 | ... AU11: =SUMIFS(Details!$AB$5:$AB$11,Details!$C$5:$C$11,Summary!AU$5,Details!$CK$5:$CK$11,Summary!$AI$5) -> 0 | AV11: =SUM(AJ11:AU11) -> 0 | AX11: Transportation Charges | AY11: =SUMIFS(Details!$AB$5:$AB$11,Details!$C$5:$C$11,Summary!AY$5,Details!$CK$5:$CK$11,Summary!$AX$5) -> 0 | AZ11: =SUMIFS(Details!$AB$5:$AB$11,Details!$C$5:$C$11,Summary!AZ$5,Details!$CK$5:$CK$11,Summary!$AX$5) -> 0 | BA11: =SUMIFS(Details!$AB$5:$AB$11,Details!$C$5:$C$11,Summary!BA$5,Details!$CK$5:$CK$11,Summary!$AX$5) -> 0 | BB11: =SUMIFS(Details!$AB$5:$AB$11,Details!$C$5:$C$11,Summary!BB$5,Details!$CK$5:$CK$11,Summary!$AX$5) -> 0 | BC11: =SUMIFS(Details!$AB$5:$AB$11,Details!$C$5:$C$11,Summary!BC$5,Details!$CK$5:$CK$11,Summary!$AX$5) -> 0 | BD11: =SUMIFS(Details!$AB$5:$AB$11,Details!$C$5:$C$11,Summary!BD$5,Details!$CK$5:$CK$11,Summary!$AX$5) -> 0 | BE11: =SUMIFS(Details!$AB$5:$AB$11,Details!$C$5:$C$11,Summary!BE$5,Details!$CK$5:$CK$11,Summary!$AX$5) -> 0 | BF11: =SUMIFS(Details!$AB$5:$AB$11,Details!$C$5:$C$11,Summary!BF$5,Details!$CK$5:$CK$11,Summary!$AX$5) -> 0 | ... BJ11: =SUMIFS(Details!$AB$5:$AB$11,Details!$C$5:$C$11,Summary!BJ$5,Details!$CK$5:$CK$11,Summary!$AX$5) -> 0 | BK11: =SUM(AY11:BJ11) -> 0 | BM11: =(AG11+AV11+BK11)-P11 -> 0
C12: Operational Cost | D12: =SUMIFS(Details!$AC$5:$AC$11,Details!$C$5:$C$11,Summary!D$5) -> 0 | E12: =SUMIFS(Details!$AC$5:$AC$11,Details!$C$5:$C$11,Summary!E$5) -> 0 | F12: =SUMIFS(Details!$AC$5:$AC$11,Details!$C$5:$C$11,Summary!F$5) -> 0 | G12: =SUMIFS(Details!$AC$5:$AC$11,Details!$C$5:$C$11,Summary!G$5) -> 0 | H12: =SUMIFS(Details!$AC$5:$AC$11,Details!$C$5:$C$11,Summary!H$5) -> 0 | I12: =SUMIFS(Details!$AC$5:$AC$11,Details!$C$5:$C$11,Summary!I$5) -> 0 | J12: =SUMIFS(Details!$AC$5:$AC$11,Details!$C$5:$C$11,Summary!J$5) -> 0 | K12: =SUMIFS(Details!$AC$5:$AC$11,Details!$C$5:$C$11,Summary!K$5) -> 0 | ... O12: =SUMIFS(Details!$AC$5:$AC$11,Details!$C$5:$C$11,Summary!O$5) -> 0 | P12: =SUM(D12:O12) -> 0 | T12: Operational Cost | U12: =SUMIFS(Details!$AC$5:$AC$11,Details!$C$5:$C$11,Summary!U$5,Details!$CK$5:$CK$11,Summary!$T$5) -> 0 | V12: =SUMIFS(Details!$AC$5:$AC$11,Details!$C$5:$C$11,Summary!V$5,Details!$CK$5:$CK$11,Summary!$T$5) -> 0 | W12: =SUMIFS(Details!$AC$5:$AC$11,Details!$C$5:$C$11,Summary!W$5,Details!$CK$5:$CK$11,Summary!$T$5) -> 0 | X12: =SUMIFS(Details!$AC$5:$AC$11,Details!$C$5:$C$11,Summary!X$5,Details!$CK$5:$CK$11,Summary!$T$5) -> 0 | Y12: =SUMIFS(Details!$AC$5:$AC$11,Details!$C$5:$C$11,Summary!Y$5,Details!$CK$5:$CK$11,Summary!$T$5) -> 0 | Z12: =SUMIFS(Details!$AC$5:$AC$11,Details!$C$5:$C$11,Summary!Z$5,Details!$CK$5:$CK$11,Summary!$T$5) -> 0 | AA12: =SUMIFS(Details!$AC$5:$AC$11,Details!$C$5:$C$11,Summary!AA$5,Details!$CK$5:$CK$11,Summary!$T$5) -> 0 | AB12: =SUMIFS(Details!$AC$5:$AC$11,Details!$C$5:$C$11,Summary!AB$5,Details!$CK$5:$CK$11,Summary!$T$5) -> 0 | ... AF12: =SUMIFS(Details!$AC$5:$AC$11,Details!$C$5:$C$11,Summary!AF$5,Details!$CK$5:$CK$11,Summary!$T$5) -> 0 | AG12: =SUM(U12:AF12) -> 0 | AI12: Operational Cost | AJ12: =SUMIFS(Details!$AC$5:$AC$11,Details!$C$5:$C$11,Summary!AJ$5,Details!$CK$5:$CK$11,Summary!$AI$5) -> 0 | AK12: =SUMIFS(Details!$AC$5:$AC$11,Details!$C$5:$C$11,Summary!AK$5,Details!$CK$5:$CK$11,Summary!$AI$5) -> 0 | AL12: =SUMIFS(Details!$AC$5:$AC$11,Details!$C$5:$C$11,Summary!AL$5,Details!$CK$5:$CK$11,Summary!$AI$5) -> 0 | AM12: =SUMIFS(Details!$AC$5:$AC$11,Details!$C$5:$C$11,Summary!AM$5,Details!$CK$5:$CK$11,Summary!$AI$5) -> 0 | AN12: =SUMIFS(Details!$AC$5:$AC$11,Details!$C$5:$C$11,Summary!AN$5,Details!$CK$5:$CK$11,Summary!$AI$5) -> 0 | AO12: =SUMIFS(Details!$AC$5:$AC$11,Details!$C$5:$C$11,Summary!AO$5,Details!$CK$5:$CK$11,Summary!$AI$5) -> 0 | AP12: =SUMIFS(Details!$AC$5:$AC$11,Details!$C$5:$C$11,Summary!AP$5,Details!$CK$5:$CK$11,Summary!$AI$5) -> 0 | AQ12: =SUMIFS(Details!$AC$5:$AC$11,Details!$C$5:$C$11,Summary!AQ$5,Details!$CK$5:$CK$11,Summary!$AI$5) -> 0 | ... AU12: =SUMIFS(Details!$AC$5:$AC$11,Details!$C$5:$C$11,Summary!AU$5,Details!$CK$5:$CK$11,Summary!$AI$5) -> 0 | AV12: =SUM(AJ12:AU12) -> 0 | AX12: Operational Cost | AY12: =SUMIFS(Details!$AC$5:$AC$11,Details!$C$5:$C$11,Summary!AY$5,Details!$CK$5:$CK$11,Summary!$AX$5) -> 0 | AZ12: =SUMIFS(Details!$AC$5:$AC$11,Details!$C$5:$C$11,Summary!AZ$5,Details!$CK$5:$CK$11,Summary!$AX$5) -> 0 | BA12: =SUMIFS(Details!$AC$5:$AC$11,Details!$C$5:$C$11,Summary!BA$5,Details!$CK$5:$CK$11,Summary!$AX$5) -> 0 | BB12: =SUMIFS(Details!$AC$5:$AC$11,Details!$C$5:$C$11,Summary!BB$5,Details!$CK$5:$CK$11,Summary!$AX$5) -> 0 | BC12: =SUMIFS(Details!$AC$5:$AC$11,Details!$C$5:$C$11,Summary!BC$5,Details!$CK$5:$CK$11,Summary!$AX$5) -> 0 | BD12: =SUMIFS(Details!$AC$5:$AC$11,Details!$C$5:$C$11,Summary!BD$5,Details!$CK$5:$CK$11,Summary!$AX$5) -> 0 | BE12: =SUMIFS(Details!$AC$5:$AC$11,Details!$C$5:$C$11,Summary!BE$5,Details!$CK$5:$CK$11,Summary!$AX$5) -> 0 | BF12: =SUMIFS(Details!$AC$5:$AC$11,Details!$C$5:$C$11,Summary!BF$5,Details!$CK$5:$CK$11,Summary!$AX$5) -> 0 | ... BJ12: =SUMIFS(Details!$AC$5:$AC$11,Details!$C$5:$C$11,Summary!BJ$5,Details!$CK$5:$CK$11,Summary!$AX$5) -> 0 | BK12: =SUM(AY12:BJ12) -> 0
C13: Net Margin | D13: =D9-D11-D12 -> 3460 | E13: =E9-E11-E12 -> 4080 | F13: =F9-F11-F12 -> 11050 | G13: =G9-G11-G12 -> 0 | H13: =H9-H11-H12 -> 0 | I13: =I9-I11-I12 -> 0 | J13: =J9-J11-J12 -> 0 | K13: =K9-K11-K12 -> 0 | ... P13: =P9-P11-P12 -> 18590 | T13: Net Margin | U13: =U9-U11-U12 -> 0 | V13: =V9-V11-V12 -> 0 | W13: =W9-W11-W12 -> 0 | X13: =X9-X11-X12 -> 0 | Y13: =Y9-Y11-Y12 -> 0 | Z13: =Z9-Z11-Z12 -> 0 | AA13: =AA9-AA11-AA12 -> 0 | AB13: =AB9-AB11-AB12 -> 0 | ... AG13: =AG9-AG11-AG12 -> 0 | AI13: Net Margin | AJ13: =AJ9-AJ11-AJ12 -> 0 | AK13: =AK9-AK11-AK12 -> 0 | AL13: =AL9-AL11-AL12 -> 0 | AM13: =AM9-AM11-AM12 -> 0 | AN13: =AN9-AN11-AN12 -> 0 | AO13: =AO9-AO11-AO12 -> 0 | AP13: =AP9-AP11-AP12 -> 0 | AQ13: =AQ9-AQ11-AQ12 -> 0 | ... AV13: =AV9-AV11-AV12 -> 0 | AX13: Net Margin | AY13: =AY9-AY11-AY12 -> 0 | AZ13: =AZ9-AZ11-AZ12 -> 0 | BA13: =BA9-BA11-BA12 -> 0 | BB13: =BB9-BB11-BB12 -> 0 | BC13: =BC9-BC11-BC12 -> 0 | BD13: =BD9-BD11-BD12 -> 0 | BE13: =BE9-BE11-BE12 -> 0 | BF13: =BF9-BF11-BF12 -> 0 | ... BK13: =BK9-BK11-BK12 -> 0 | BM13: =(AG13+AV13+BK13)-P13 -> -18590
C14: Net Margin (%) | D14: =IFERROR((D13/D7),0) -> 0.10529519 | E14: =IFERROR((E13/E7),0) -> 0.11663808 | F14: =IFERROR((F13/F7),0) -> 0.55388471 | G14: =IFERROR((G13/G7),0) -> 0 | H14: =IFERROR((H13/H7),0) -> 0 | I14: =IFERROR((I13/I7),0) -> 0 | J14: =IFERROR((J13/J7),0) -> 0 | K14: =IFERROR((K13/K7),0) -> 0 | ... P14: =IFERROR((P13/P7),0) -> 0.21175533 | T14: Net Margin (%) | U14: =IFERROR((U13/U7),0) -> 0 | V14: =IFERROR((V13/V7),0) -> 0 | W14: =IFERROR((W13/W7),0) -> 0 | X14: =IFERROR((X13/X7),0) -> 0 | Y14: =IFERROR((Y13/Y7),0) -> 0 | Z14: =IFERROR((Z13/Z7),0) -> 0 | AA14: =IFERROR((AA13/AA7),0) -> 0 | AB14: =IFERROR((AB13/AB7),0) -> 0 | ... AG14: =IFERROR((AG13/AG7),0) -> 0 | AI14: Net Margin (%) | AJ14: =IFERROR((AJ13/AJ7),0) -> 0 | AK14: =IFERROR((AK13/AK7),0) -> 0 | AL14: =IFERROR((AL13/AL7),0) -> 0 | AM14: =IFERROR((AM13/AM7),0) -> 0 | AN14: =IFERROR((AN13/AN7),0) -> 0 | AO14: =IFERROR((AO13/AO7),0) -> 0 | AP14: =IFERROR((AP13/AP7),0) -> 0 | AQ14: =IFERROR((AQ13/AQ7),0) -> 0 | ... AV14: =IFERROR((AV13/AV7),0) -> 0 | AX14: Net Margin (%) | AY14: =IFERROR((AY13/AY7),0) -> 0 | AZ14: =IFERROR((AZ13/AZ7),0) -> 0 | BA14: =IFERROR((BA13/BA7),0) -> 0 | BB14: =IFERROR((BB13/BB7),0) -> 0 | BC14: =IFERROR((BC13/BC7),0) -> 0 | BD14: =IFERROR((BD13/BD7),0) -> 0 | BE14: =IFERROR((BE13/BE7),0) -> 0 | BF14: =IFERROR((BF13/BF7),0) -> 0 | ... BK14: =IFERROR((BK13/BK7),0) -> 0 | BM14: =(AG14+AV14+BK14)-P14 -> -0.21175533
C15: Other Income | D15: =SUMIFS(Details!$BQ$16:$BQ$17,Details!$C$16:$C$17,Summary!D$5) -> 0 | E15: =SUMIFS(Details!$BQ$16:$BQ$17,Details!$C$16:$C$17,Summary!E$5) -> 0 | F15: =SUMIFS(Details!$BQ$16:$BQ$17,Details!$C$16:$C$17,Summary!F$5) -> 0 | G15: =SUMIFS(Details!$BQ$16:$BQ$17,Details!$C$16:$C$17,Summary!G$5) -> 0 | H15: =SUMIFS(Details!$BQ$16:$BQ$17,Details!$C$16:$C$17,Summary!H$5) -> 0 | I15: =SUMIFS(Details!$BQ$16:$BQ$17,Details!$C$16:$C$17,Summary!I$5) -> 0 | J15: =SUMIFS(Details!$BQ$16:$BQ$17,Details!$C$16:$C$17,Summary!J$5) -> 0 | K15: =SUMIFS(Details!$BQ$16:$BQ$17,Details!$C$16:$C$17,Summary!K$5) -> 0 | ... O15: =SUMIFS(Details!$BQ$16:$BQ$17,Details!$C$16:$C$17,Summary!O$5) -> 0 | P15: =SUM(D15:O15) -> 0 | T15: Other Income | U15: =SUMIFS(Details!$BQ$16:$BQ$17,Details!$C$16:$C$17,Summary!U$5,Details!$CK$16:$CK$17,Summary!$T$5) -> 0 | V15: =SUMIFS(Details!$BQ$16:$BQ$17,Details!$C$16:$C$17,Summary!V$5,Details!$CK$16:$CK$17,Summary!$T$5) -> 0 | W15: =SUMIFS(Details!$BQ$16:$BQ$17,Details!$C$16:$C$17,Summary!W$5,Details!$CK$16:$CK$17,Summary!$T$5) -> 0 | X15: =SUMIFS(Details!$BQ$16:$BQ$17,Details!$C$16:$C$17,Summary!X$5,Details!$CK$16:$CK$17,Summary!$T$5) -> 0 | Y15: =SUMIFS(Details!$BQ$16:$BQ$17,Details!$C$16:$C$17,Summary!Y$5,Details!$CK$16:$CK$17,Summary!$T$5) -> 0 | Z15: =SUMIFS(Details!$BQ$16:$BQ$17,Details!$C$16:$C$17,Summary!Z$5,Details!$CK$16:$CK$17,Summary!$T$5) -> 0 | AA15: =SUMIFS(Details!$BQ$16:$BQ$17,Details!$C$16:$C$17,Summary!AA$5,Details!$CK$16:$CK$17,Summary!$T$5) -> 0 | AB15: =SUMIFS(Details!$BQ$16:$BQ$17,Details!$C$16:$C$17,Summary!AB$5,Details!$CK$16:$CK$17,Summary!$T$5) -> 0 | ... AF15: =SUMIFS(Details!$BQ$16:$BQ$17,Details!$C$16:$C$17,Summary!AF$5,Details!$CK$16:$CK$17,Summary!$T$5) -> 0 | AG15: =SUM(U15:AF15) -> 0 | AI15: Other Income | AJ15: =SUMIFS(Details!$BQ$16:$BQ$17,Details!$C$16:$C$17,Summary!AJ$5,Details!$CK$16:$CK$17,Summary!$AI$5) -> 0 | AK15: =SUMIFS(Details!$BQ$16:$BQ$17,Details!$C$16:$C$17,Summary!AK$5,Details!$CK$16:$CK$17,Summary!$AI$5) -> 0 | AL15: =SUMIFS(Details!$BQ$16:$BQ$17,Details!$C$16:$C$17,Summary!AL$5,Details!$CK$16:$CK$17,Summary!$AI$5) -> 0 | AM15: =SUMIFS(Details!$BQ$16:$BQ$17,Details!$C$16:$C$17,Summary!AM$5,Details!$CK$16:$CK$17,Summary!$AI$5) -> 0 | AN15: =SUMIFS(Details!$BQ$16:$BQ$17,Details!$C$16:$C$17,Summary!AN$5,Details!$CK$16:$CK$17,Summary!$AI$5) -> 0 | AO15: =SUMIFS(Details!$BQ$16:$BQ$17,Details!$C$16:$C$17,Summary!AO$5,Details!$CK$16:$CK$17,Summary!$AI$5) -> 0 | AP15: =SUMIFS(Details!$BQ$16:$BQ$17,Details!$C$16:$C$17,Summary!AP$5,Details!$CK$16:$CK$17,Summary!$AI$5) -> 0 | AQ15: =SUMIFS(Details!$BQ$16:$BQ$17,Details!$C$16:$C$17,Summary!AQ$5,Details!$CK$16:$CK$17,Summary!$AI$5) -> 0 | ... AU15: =SUMIFS(Details!$BQ$16:$BQ$17,Details!$C$16:$C$17,Summary!AU$5,Details!$CK$16:$CK$17,Summary!$AI$5) -> 0 | AV15: =SUM(AJ15:AU15) -> 0 | AX15: Other Income | AY15: =SUMIFS(Details!$BQ$16:$BQ$17,Details!$C$16:$C$17,Summary!AY$5,Details!$CK$16:$CK$17,Summary!$AX$5) -> 0 | AZ15: =SUMIFS(Details!$BQ$16:$BQ$17,Details!$C$16:$C$17,Summary!AZ$5,Details!$CK$16:$CK$17,Summary!$AX$5) -> 0 | BA15: =SUMIFS(Details!$BQ$16:$BQ$17,Details!$C$16:$C$17,Summary!BA$5,Details!$CK$16:$CK$17,Summary!$AX$5) -> 0 | BB15: =SUMIFS(Details!$BQ$16:$BQ$17,Details!$C$16:$C$17,Summary!BB$5,Details!$CK$16:$CK$17,Summary!$AX$5) -> 0 | BC15: =SUMIFS(Details!$BQ$16:$BQ$17,Details!$C$16:$C$17,Summary!BC$5,Details!$CK$16:$CK$17,Summary!$AX$5) -> 0 | BD15: =SUMIFS(Details!$BQ$16:$BQ$17,Details!$C$16:$C$17,Summary!BD$5,Details!$CK$16:$CK$17,Summary!$AX$5) -> 0 | BE15: =SUMIFS(Details!$BQ$16:$BQ$17,Details!$C$16:$C$17,Summary!BE$5,Details!$CK$16:$CK$17,Summary!$AX$5) -> 0 | BF15: =SUMIFS(Details!$BQ$16:$BQ$17,Details!$C$16:$C$17,Summary!BF$5,Details!$CK$16:$CK$17,Summary!$AX$5) -> 0 | ... BJ15: =SUMIFS(Details!$BQ$16:$BQ$17,Details!$C$16:$C$17,Summary!BJ$5,Details!$CK$16:$CK$17,Summary!$AX$5) -> 0 | BK15: =SUM(AY15:BJ15) -> 0 | BM15: =(AG15+AV15+BK15)-P15 -> 0
C16: Transport Charges (%) | D16: =IFERROR((D11/D7),0) -> 0 | E16: =IFERROR((E11/E7),0) -> 0 | F16: =IFERROR((F11/F7),0) -> 0 | G16: =IFERROR((G11/G7),0) -> 0 | H16: =IFERROR((H11/H7),0) -> 0 | I16: =IFERROR((I11/I7),0) -> 0 | J16: =IFERROR((J11/J7),0) -> 0 | K16: =IFERROR((K11/K7),0) -> 0 | ... P16: =IFERROR((P11/P7),0) -> 0 | T16: Transport Charges (%) | U16: =IFERROR((U11/U7),0) -> 0 | V16: =IFERROR((V11/V7),0) -> 0 | W16: =IFERROR((W11/W7),0) -> 0 | X16: =IFERROR((X11/X7),0) -> 0 | Y16: =IFERROR((Y11/Y7),0) -> 0 | Z16: =IFERROR((Z11/Z7),0) -> 0 | AA16: =IFERROR((AA11/AA7),0) -> 0 | AB16: =IFERROR((AB11/AB7),0) -> 0 | ... AG16: =IFERROR((AG11/AG7),0) -> 0 | AI16: Transport Charges (%) | AJ16: =IFERROR((AJ11/AJ7),0) -> 0 | AK16: =IFERROR((AK11/AK7),0) -> 0 | AL16: =IFERROR((AL11/AL7),0) -> 0 | AM16: =IFERROR((AM11/AM7),0) -> 0 | AN16: =IFERROR((AN11/AN7),0) -> 0 | AO16: =IFERROR((AO11/AO7),0) -> 0 | AP16: =IFERROR((AP11/AP7),0) -> 0 | AQ16: =IFERROR((AQ11/AQ7),0) -> 0 | ... AV16: =IFERROR((AV11/AV7),0) -> 0 | AX16: Transport Charges (%) | AY16: =IFERROR((AY11/AY7),0) -> 0 | AZ16: =IFERROR((AZ11/AZ7),0) -> 0 | BA16: =IFERROR((BA11/BA7),0) -> 0 | BB16: =IFERROR((BB11/BB7),0) -> 0 | BC16: =IFERROR((BC11/BC7),0) -> 0 | BD16: =IFERROR((BD11/BD7),0) -> 0 | BE16: =IFERROR((BE11/BE7),0) -> 0 | BF16: =IFERROR((BF11/BF7),0) -> 0 | ... BK16: =IFERROR((BK11/BK7),0) -> 0 | BM16: =(AG16+AV16+BK16)-P16 -> 0
C17: Revenue Per Kg | D17: =IFERROR(D7/(D6*1000),0) -> 0.53 | E17: =IFERROR(E7/(E6*1000),0) -> 0.53 | F17: =IFERROR(F7/(F6*1000),0) -> 0.285 | G17: =IFERROR(G7/(G6*1000),0) -> 0 | H17: =IFERROR(H7/(H6*1000),0) -> 0 | I17: =IFERROR(I7/(I6*1000),0) -> 0 | J17: =IFERROR(J7/(J6*1000),0) -> 0 | K17: =IFERROR(K7/(K6*1000),0) -> 0 | ... O17: =IFERROR(O7/(O6*1000),0) -> 0 | P17: =P7/(P6*1000) -> 0.44338384 | T17: Revenue Per Kg | U17: =IFERROR(U7/(U6*1000),0) -> 0 | V17: =IFERROR(V7/(V6*1000),0) -> 0 | W17: =IFERROR(W7/(W6*1000),0) -> 0 | X17: =IFERROR(X7/(X6*1000),0) -> 0 | Y17: =IFERROR(Y7/(Y6*1000),0) -> 0 | Z17: =IFERROR(Z7/(Z6*1000),0) -> 0 | AA17: =IFERROR(AA7/(AA6*1000),0) -> 0 | AB17: =IFERROR(AB7/(AB6*1000),0) -> 0 | ... AF17: =IFERROR(AF7/(AF6*1000),0) -> 0 | AG17: =AG7/(AG6*1000) -> #DIV/0! | AI17: Revenue Per Kg | AJ17: =IFERROR(AJ7/(AJ6*1000),0) -> 0 | AK17: =IFERROR(AK7/(AK6*1000),0) -> 0 | AL17: =IFERROR(AL7/(AL6*1000),0) -> 0 | AM17: =IFERROR(AM7/(AM6*1000),0) -> 0 | AN17: =IFERROR(AN7/(AN6*1000),0) -> 0 | AO17: =IFERROR(AO7/(AO6*1000),0) -> 0 | AP17: =IFERROR(AP7/(AP6*1000),0) -> 0 | AQ17: =IFERROR(AQ7/(AQ6*1000),0) -> 0 | ... AU17: =IFERROR(AU7/(AU6*1000),0) -> 0 | AV17: =AV7/(AV6*1000) -> #DIV/0! | AX17: Revenue Per Kg | AY17: =IFERROR(AY7/(AY6*1000),0) -> 0 | AZ17: =IFERROR(AZ7/(AZ6*1000),0) -> 0 | BA17: =IFERROR(BA7/(BA6*1000),0) -> 0 | BB17: =IFERROR(BB7/(BB6*1000),0) -> 0 | BC17: =IFERROR(BC7/(BC6*1000),0) -> 0 | BD17: =IFERROR(BD7/(BD6*1000),0) -> 0 | BE17: =IFERROR(BE7/(BE6*1000),0) -> 0 | BF17: =IFERROR(BF7/(BF6*1000),0) -> 0 | ... BJ17: =IFERROR(BJ7/(BJ6*1000),0) -> 0 | BK17: =BK7/(BK6*1000) -> #DIV/0!
C18: Purchase Cost Per Kg | D18: =IFERROR(D8/(D6*1000),0) -> 0.47419355 | E18: =IFERROR(E8/(E6*1000),0) -> 0.46818182 | F18: =IFERROR(F8/(F6*1000),0) -> 0.12714286 | G18: =IFERROR(G8/(G6*1000),0) -> 0 | H18: =IFERROR(H8/(H6*1000),0) -> 0 | I18: =IFERROR(I8/(I6*1000),0) -> 0 | J18: =IFERROR(J8/(J6*1000),0) -> 0 | K18: =IFERROR(K8/(K6*1000),0) -> 0 | ... O18: =IFERROR(O8/(O6*1000),0) -> 0 | P18: =P8/(P6*1000) -> 0.34949495 | T18: Purchase Cost Per Kg | U18: =IFERROR(U8/(U6*1000),0) -> 0 | V18: =IFERROR(V8/(V6*1000),0) -> 0 | W18: =IFERROR(W8/(W6*1000),0) -> 0 | X18: =IFERROR(X8/(X6*1000),0) -> 0 | Y18: =IFERROR(Y8/(Y6*1000),0) -> 0 | Z18: =IFERROR(Z8/(Z6*1000),0) -> 0 | AA18: =IFERROR(AA8/(AA6*1000),0) -> 0 | AB18: =IFERROR(AB8/(AB6*1000),0) -> 0 | ... AF18: =IFERROR(AF8/(AF6*1000),0) -> 0 | AG18: =AG8/(AG6*1000) -> #DIV/0! | AI18: Purchase Cost Per Kg | AJ18: =IFERROR(AJ8/(AJ6*1000),0) -> 0 | AK18: =IFERROR(AK8/(AK6*1000),0) -> 0 | AL18: =IFERROR(AL8/(AL6*1000),0) -> 0 | AM18: =IFERROR(AM8/(AM6*1000),0) -> 0 | AN18: =IFERROR(AN8/(AN6*1000),0) -> 0 | AO18: =IFERROR(AO8/(AO6*1000),0) -> 0 | AP18: =IFERROR(AP8/(AP6*1000),0) -> 0 | AQ18: =IFERROR(AQ8/(AQ6*1000),0) -> 0 | ... AU18: =IFERROR(AU8/(AU6*1000),0) -> 0 | AV18: =AV8/(AV6*1000) -> #DIV/0! | AX18: Purchase Cost Per Kg | AY18: =IFERROR(AY8/(AY6*1000),0) -> 0 | AZ18: =IFERROR(AZ8/(AZ6*1000),0) -> 0 | BA18: =IFERROR(BA8/(BA6*1000),0) -> 0 | BB18: =IFERROR(BB8/(BB6*1000),0) -> 0 | BC18: =IFERROR(BC8/(BC6*1000),0) -> 0 | BD18: =IFERROR(BD8/(BD6*1000),0) -> 0 | BE18: =IFERROR(BE8/(BE6*1000),0) -> 0 | BF18: =IFERROR(BF8/(BF6*1000),0) -> 0 | ... BJ18: =IFERROR(BJ8/(BJ6*1000),0) -> 0 | BK18: =BK8/(BK6*1000) -> #DIV/0!
C19: Transportation Charges Per Kg | D19: =IFERROR(D11/(D6*1000),0) -> 0 | E19: =IFERROR(E11/(E6*1000),0) -> 0 | F19: =IFERROR(F11/(F6*1000),0) -> 0 | G19: =IFERROR(G11/(G6*1000),0) -> 0 | H19: =IFERROR(H11/(H6*1000),0) -> 0 | I19: =IFERROR(I11/(I6*1000),0) -> 0 | J19: =IFERROR(J11/(J6*1000),0) -> 0 | K19: =IFERROR(K11/(K6*1000),0) -> 0 | ... O19: =IFERROR(O11/(O6*1000),0) -> 0 | P19: =P11/(P6*1000) -> 0 | T19: Transportation Charges Per Kg | U19: =IFERROR(U11/(U6*1000),0) -> 0 | V19: =IFERROR(V11/(V6*1000),0) -> 0 | W19: =IFERROR(W11/(W6*1000),0) -> 0 | X19: =IFERROR(X11/(X6*1000),0) -> 0 | Y19: =IFERROR(Y11/(Y6*1000),0) -> 0 | Z19: =IFERROR(Z11/(Z6*1000),0) -> 0 | AA19: =IFERROR(AA11/(AA6*1000),0) -> 0 | AB19: =IFERROR(AB11/(AB6*1000),0) -> 0 | ... AF19: =IFERROR(AF11/(AF6*1000),0) -> 0 | AG19: =AG11/(AG6*1000) -> #DIV/0! | AI19: Transportation Charges Per Kg | AJ19: =IFERROR(AJ11/(AJ6*1000),0) -> 0 | AK19: =IFERROR(AK11/(AK6*1000),0) -> 0 | AL19: =IFERROR(AL11/(AL6*1000),0) -> 0 | AM19: =IFERROR(AM11/(AM6*1000),0) -> 0 | AN19: =IFERROR(AN11/(AN6*1000),0) -> 0 | AO19: =IFERROR(AO11/(AO6*1000),0) -> 0 | AP19: =IFERROR(AP11/(AP6*1000),0) -> 0 | AQ19: =IFERROR(AQ11/(AQ6*1000),0) -> 0 | ... AU19: =IFERROR(AU11/(AU6*1000),0) -> 0 | AV19: =AV11/(AV6*1000) -> #DIV/0! | AX19: Transportation Charges Per Kg | AY19: =IFERROR(AY11/(AY6*1000),0) -> 0 | AZ19: =IFERROR(AZ11/(AZ6*1000),0) -> 0 | BA19: =IFERROR(BA11/(BA6*1000),0) -> 0 | BB19: =IFERROR(BB11/(BB6*1000),0) -> 0 | BC19: =IFERROR(BC11/(BC6*1000),0) -> 0 | BD19: =IFERROR(BD11/(BD6*1000),0) -> 0 | BE19: =IFERROR(BE11/(BE6*1000),0) -> 0 | BF19: =IFERROR(BF11/(BF6*1000),0) -> 0 | ... BJ19: =IFERROR(BJ11/(BJ6*1000),0) -> 0 | BK19: =BK11/(BK6*1000) -> #DIV/0!
C20: No. of Transactions | D20: {=IFERROR(ROWS(_xlfn.UNIQUE(_xlfn._xlws.FILTER(Details!$E$5:$E$11,(Details!$C$5:$C$11)=Summary!D$3))),0)} -> 1 | E20: {=IFERROR(ROWS(_xlfn.UNIQUE(_xlfn._xlws.FILTER(Details!$E$5:$E$11,(Details!$C$5:$C$11)=Summary!E$3))),0)} -> 1 | F20: {=IFERROR(ROWS(_xlfn.UNIQUE(_xlfn._xlws.FILTER(Details!$E$5:$E$11,(Details!$C$5:$C$11)=Summary!F$3))),0)} -> 1 | G20: {=IFERROR(ROWS(_xlfn.UNIQUE(_xlfn._xlws.FILTER(Details!$E$5:$E$11,(Details!$C$5:$C$11)=Summary!G$3))),0)} -> 0 | H20: {=IFERROR(ROWS(_xlfn.UNIQUE(_xlfn._xlws.FILTER(Details!$E$5:$E$11,(Details!$C$5:$C$11)=Summary!H$3))),0)} -> 0 | I20: {=IFERROR(ROWS(_xlfn.UNIQUE(_xlfn._xlws.FILTER(Details!$E$5:$E$11,(Details!$C$5:$C$11)=Summary!I$3))),0)} -> 0 | J20: {=IFERROR(ROWS(_xlfn.UNIQUE(_xlfn._xlws.FILTER(Details!$E$5:$E$11,(Details!$C$5:$C$11)=Summary!J$3))),0)} -> 0 | K20: {=IFERROR(ROWS(_xlfn.UNIQUE(_xlfn._xlws.FILTER(Details!$E$5:$E$11,(Details!$C$5:$C$11)=Summary!K$3))),0)} -> 0 | ... O20: {=IFERROR(ROWS(_xlfn.UNIQUE(_xlfn._xlws.FILTER(Details!$E$5:$E$11,(Details!$C$5:$C$11)=Summary!O$3))),0)} -> 0 | P20: =SUM(D20:O20) -> 3 | T20: No. of Transactions | U20: {=IFERROR(ROWS(_xlfn.UNIQUE(_xlfn._xlws.FILTER(Details!$E$5:$E$11,(Details!$C$5:$C$11=Summary!U$3)*(Details!$CK$5:$CK$11=$T$5)))),0)} -> 0 | V20: {=IFERROR(ROWS(_xlfn.UNIQUE(_xlfn._xlws.FILTER(Details!$E$5:$E$11,(Details!$C$5:$C$11=Summary!V$3)*(Details!$CK$5:$CK$11=$T$5)))),0)} -> 0 | W20: {=IFERROR(ROWS(_xlfn.UNIQUE(_xlfn._xlws.FILTER(Details!$E$5:$E$11,(Details!$C$5:$C$11=Summary!W$3)*(Details!$CK$5:$CK$11=$T$5)))),0)} -> 0 | X20: {=IFERROR(ROWS(_xlfn.UNIQUE(_xlfn._xlws.FILTER(Details!$E$5:$E$11,(Details!$C$5:$C$11=Summary!X$3)*(Details!$CK$5:$CK$11=$T$5)))),0)} -> 0 | Y20: {=IFERROR(ROWS(_xlfn.UNIQUE(_xlfn._xlws.FILTER(Details!$E$5:$E$11,(Details!$C$5:$C$11=Summary!Y$3)*(Details!$CK$5:$CK$11=$T$5)))),0)} -> 0 | Z20: {=IFERROR(ROWS(_xlfn.UNIQUE(_xlfn._xlws.FILTER(Details!$E$5:$E$11,(Details!$C$5:$C$11=Summary!Z$3)*(Details!$CK$5:$CK$11=$T$5)))),0)} -> 0 | AA20: {=IFERROR(ROWS(_xlfn.UNIQUE(_xlfn._xlws.FILTER(Details!$E$5:$E$11,(Details!$C$5:$C$11=Summary!AA$3)*(Details!$CK$5:$CK$11=$T$5)))),0)} -> 0 | AB20: {=IFERROR(ROWS(_xlfn.UNIQUE(_xlfn._xlws.FILTER(Details!$E$5:$E$11,(Details!$C$5:$C$11=Summary!AB$3)*(Details!$CK$5:$CK$11=$T$5)))),0)} -> 0 | ... AF20: {=IFERROR(ROWS(_xlfn.UNIQUE(_xlfn._xlws.FILTER(Details!$E$5:$E$11,(Details!$C$5:$C$11=Summary!AF$3)*(Details!$CK$5:$CK$11=$T$5)))),0)} -> 0 | AG20: =SUM(U20:AF20) -> 0 | AI20: No. of Transactions | AJ20: {=IFERROR(ROWS(_xlfn.UNIQUE(_xlfn._xlws.FILTER(Details!$E$5:$E$11,(Details!$C$5:$C$11=Summary!AJ$3)*(Details!$CK$5:$CK$11=$AI$5)))),0)} -> 0 | AK20: {=IFERROR(ROWS(_xlfn.UNIQUE(_xlfn._xlws.FILTER(Details!$E$5:$E$11,(Details!$C$5:$C$11=Summary!AK$3)*(Details!$CK$5:$CK$11=$AI$5)))),0)} -> 0 | AL20: {=IFERROR(ROWS(_xlfn.UNIQUE(_xlfn._xlws.FILTER(Details!$E$5:$E$11,(Details!$C$5:$C$11=Summary!AL$3)*(Details!$CK$5:$CK$11=$AI$5)))),0)} -> 0 | AM20: {=IFERROR(ROWS(_xlfn.UNIQUE(_xlfn._xlws.FILTER(Details!$E$5:$E$11,(Details!$C$5:$C$11=Summary!AM$3)*(Details!$CK$5:$CK$11=$AI$5)))),0)} -> 0 | AN20: {=IFERROR(ROWS(_xlfn.UNIQUE(_xlfn._xlws.FILTER(Details!$E$5:$E$11,(Details!$C$5:$C$11=Summary!AN$3)*(Details!$CK$5:$CK$11=$AI$5)))),0)} -> 0 | AO20: {=IFERROR(ROWS(_xlfn.UNIQUE(_xlfn._xlws.FILTER(Details!$E$5:$E$11,(Details!$C$5:$C$11=Summary!AO$3)*(Details!$CK$5:$CK$11=$AI$5)))),0)} -> 0 | AP20: {=IFERROR(ROWS(_xlfn.UNIQUE(_xlfn._xlws.FILTER(Details!$E$5:$E$11,(Details!$C$5:$C$11=Summary!AP$3)*(Details!$CK$5:$CK$11=$AI$5)))),0)} -> 0 | AQ20: {=IFERROR(ROWS(_xlfn.UNIQUE(_xlfn._xlws.FILTER(Details!$E$5:$E$11,(Details!$C$5:$C$11=Summary!AQ$3)*(Details!$CK$5:$CK$11=$AI$5)))),0)} -> 0 | ... AU20: {=IFERROR(ROWS(_xlfn.UNIQUE(_xlfn._xlws.FILTER(Details!$E$5:$E$11,(Details!$C$5:$C$11=Summary!AU$3)*(Details!$CK$5:$CK$11=$AI$5)))),0)} -> 0 | AV20: =SUM(AJ20:AU20) -> 0 | AX20: No. of Transactions | AY20: {=IFERROR(ROWS(_xlfn.UNIQUE(_xlfn._xlws.FILTER(Details!$E$5:$E$11,(Details!$C$5:$C$11=Summary!AY$3)*(Details!$CK$5:$CK$11=$AX$5)))),0)} -> 0 | AZ20: {=IFERROR(ROWS(_xlfn.UNIQUE(_xlfn._xlws.FILTER(Details!$E$5:$E$11,(Details!$C$5:$C$11=Summary!AZ$3)*(Details!$CK$5:$CK$11=$AX$5)))),0)} -> 0 | BA20: {=IFERROR(ROWS(_xlfn.UNIQUE(_xlfn._xlws.FILTER(Details!$E$5:$E$11,(Details!$C$5:$C$11=Summary!BA$3)*(Details!$CK$5:$CK$11=$AX$5)))),0)} -> 0 | BB20: {=IFERROR(ROWS(_xlfn.UNIQUE(_xlfn._xlws.FILTER(Details!$E$5:$E$11,(Details!$C$5:$C$11=Summary!BB$3)*(Details!$CK$5:$CK$11=$AX$5)))),0)} -> 0 | BC20: {=IFERROR(ROWS(_xlfn.UNIQUE(_xlfn._xlws.FILTER(Details!$E$5:$E$11,(Details!$C$5:$C$11=Summary!BC$3)*(Details!$CK$5:$CK$11=$AX$5)))),0)} -> 0 | BD20: {=IFERROR(ROWS(_xlfn.UNIQUE(_xlfn._xlws.FILTER(Details!$E$5:$E$11,(Details!$C$5:$C$11=Summary!BD$3)*(Details!$CK$5:$CK$11=$AX$5)))),0)} -> 0 | BE20: {=IFERROR(ROWS(_xlfn.UNIQUE(_xlfn._xlws.FILTER(Details!$E$5:$E$11,(Details!$C$5:$C$11=Summary!BE$3)*(Details!$CK$5:$CK$11=$AX$5)))),0)} -> 0 | BF20: {=IFERROR(ROWS(_xlfn.UNIQUE(_xlfn._xlws.FILTER(Details!$E$5:$E$11,(Details!$C$5:$C$11=Summary!BF$3)*(Details!$CK$5:$CK$11=$AX$5)))),0)} -> 0 | ... BJ20: {=IFERROR(ROWS(_xlfn.UNIQUE(_xlfn._xlws.FILTER(Details!$E$5:$E$11,(Details!$C$5:$C$11=Summary!BJ$3)*(Details!$CK$5:$CK$11=$AX$5)))),0)} -> 0 | BK20: =SUM(AY20:BJ20) -> 0 | BM20: =(AG20+AV20+BK20)-P20 -> -3
C21: No. of Sellers (Aggregators) | D21: {=IFERROR(ROWS(_xlfn.UNIQUE(_xlfn._xlws.FILTER(Details!$F$5:$F$11,(Details!$C$5:$C$11)=Summary!D$3))),0)} -> 1 | E21: {=IFERROR(ROWS(_xlfn.UNIQUE(_xlfn._xlws.FILTER(Details!$F$5:$F$11,(Details!$C$5:$C$11)=Summary!E$3))),0)} -> 1 | F21: {=IFERROR(ROWS(_xlfn.UNIQUE(_xlfn._xlws.FILTER(Details!$F$5:$F$11,(Details!$C$5:$C$11)=Summary!F$3))),0)} -> 1 | G21: {=IFERROR(ROWS(_xlfn.UNIQUE(_xlfn._xlws.FILTER(Details!$F$5:$F$11,(Details!$C$5:$C$11)=Summary!G$3))),0)} -> 0 | H21: {=IFERROR(ROWS(_xlfn.UNIQUE(_xlfn._xlws.FILTER(Details!$F$5:$F$11,(Details!$C$5:$C$11)=Summary!H$3))),0)} -> 0 | I21: {=IFERROR(ROWS(_xlfn.UNIQUE(_xlfn._xlws.FILTER(Details!$F$5:$F$11,(Details!$C$5:$C$11)=Summary!I$3))),0)} -> 0 | J21: {=IFERROR(ROWS(_xlfn.UNIQUE(_xlfn._xlws.FILTER(Details!$F$5:$F$11,(Details!$C$5:$C$11)=Summary!J$3))),0)} -> 0 | K21: {=IFERROR(ROWS(_xlfn.UNIQUE(_xlfn._xlws.FILTER(Details!$F$5:$F$11,(Details!$C$5:$C$11)=Summary!K$3))),0)} -> 0 | ... O21: {=IFERROR(ROWS(_xlfn.UNIQUE(_xlfn._xlws.FILTER(Details!$F$5:$F$11,(Details!$C$5:$C$11)=Summary!O$3))),0)} -> 0 | P21: ='Supplier Metrics'!J2 -> 1 | T21: No. of Sellers (Aggregators) | U21: {=IFERROR(ROWS(_xlfn.UNIQUE(_xlfn._xlws.FILTER(Details!$F$5:$F$11,(Details!$C$5:$C$11=Summary!U$3)*(Details!$CK$5:$CK$11=$T$5)))),0)} -> 0 | V21: {=IFERROR(ROWS(_xlfn.UNIQUE(_xlfn._xlws.FILTER(Details!$F$5:$F$11,(Details!$C$5:$C$11=Summary!V$3)*(Details!$CK$5:$CK$11=$T$5)))),0)} -> 0 | W21: {=IFERROR(ROWS(_xlfn.UNIQUE(_xlfn._xlws.FILTER(Details!$F$5:$F$11,(Details!$C$5:$C$11=Summary!W$3)*(Details!$CK$5:$CK$11=$T$5)))),0)} -> 0 | X21: {=IFERROR(ROWS(_xlfn.UNIQUE(_xlfn._xlws.FILTER(Details!$F$5:$F$11,(Details!$C$5:$C$11=Summary!X$3)*(Details!$CK$5:$CK$11=$T$5)))),0)} -> 0 | Y21: {=IFERROR(ROWS(_xlfn.UNIQUE(_xlfn._xlws.FILTER(Details!$F$5:$F$11,(Details!$C$5:$C$11=Summary!Y$3)*(Details!$CK$5:$CK$11=$T$5)))),0)} -> 0 | Z21: {=IFERROR(ROWS(_xlfn.UNIQUE(_xlfn._xlws.FILTER(Details!$F$5:$F$11,(Details!$C$5:$C$11=Summary!Z$3)*(Details!$CK$5:$CK$11=$T$5)))),0)} -> 0 | AA21: {=IFERROR(ROWS(_xlfn.UNIQUE(_xlfn._xlws.FILTER(Details!$F$5:$F$11,(Details!$C$5:$C$11=Summary!AA$3)*(Details!$CK$5:$CK$11=$T$5)))),0)} -> 0 | AB21: {=IFERROR(ROWS(_xlfn.UNIQUE(_xlfn._xlws.FILTER(Details!$F$5:$F$11,(Details!$C$5:$C$11=Summary!AB$3)*(Details!$CK$5:$CK$11=$T$5)))),0)} -> 0 | ... AF21: {=IFERROR(ROWS(_xlfn.UNIQUE(_xlfn._xlws.FILTER(Details!$F$5:$F$11,(Details!$C$5:$C$11=Summary!AF$3)*(Details!$CK$5:$CK$11=$T$5)))),0)} -> 0 | AG21: =COUNTIF('Supplier Metrics'!I:I,Summary!T5) -> 0 | AI21: No. of Sellers (Aggregators) | AJ21: {=IFERROR(ROWS(_xlfn.UNIQUE(_xlfn._xlws.FILTER(Details!$F$5:$F$11,(Details!$C$5:$C$11=Summary!AJ$3)*(Details!$CK$5:$CK$11=$AI$5)))),0)} -> 0 | AK21: {=IFERROR(ROWS(_xlfn.UNIQUE(_xlfn._xlws.FILTER(Details!$F$5:$F$11,(Details!$C$5:$C$11=Summary!AK$3)*(Details!$CK$5:$CK$11=$AI$5)))),0)} -> 0 | AL21: {=IFERROR(ROWS(_xlfn.UNIQUE(_xlfn._xlws.FILTER(Details!$F$5:$F$11,(Details!$C$5:$C$11=Summary!AL$3)*(Details!$CK$5:$CK$11=$AI$5)))),0)} -> 0 | AM21: {=IFERROR(ROWS(_xlfn.UNIQUE(_xlfn._xlws.FILTER(Details!$F$5:$F$11,(Details!$C$5:$C$11=Summary!AM$3)*(Details!$CK$5:$CK$11=$AI$5)))),0)} -> 0 | AN21: {=IFERROR(ROWS(_xlfn.UNIQUE(_xlfn._xlws.FILTER(Details!$F$5:$F$11,(Details!$C$5:$C$11=Summary!AN$3)*(Details!$CK$5:$CK$11=$AI$5)))),0)} -> 0 | AO21: {=IFERROR(ROWS(_xlfn.UNIQUE(_xlfn._xlws.FILTER(Details!$F$5:$F$11,(Details!$C$5:$C$11=Summary!AO$3)*(Details!$CK$5:$CK$11=$AI$5)))),0)} -> 0 | AP21: {=IFERROR(ROWS(_xlfn.UNIQUE(_xlfn._xlws.FILTER(Details!$F$5:$F$11,(Details!$C$5:$C$11=Summary!AP$3)*(Details!$CK$5:$CK$11=$AI$5)))),0)} -> 0 | AQ21: {=IFERROR(ROWS(_xlfn.UNIQUE(_xlfn._xlws.FILTER(Details!$F$5:$F$11,(Details!$C$5:$C$11=Summary!AQ$3)*(Details!$CK$5:$CK$11=$AI$5)))),0)} -> 0 | ... AU21: {=IFERROR(ROWS(_xlfn.UNIQUE(_xlfn._xlws.FILTER(Details!$F$5:$F$11,(Details!$C$5:$C$11=Summary!AU$3)*(Details!$CK$5:$CK$11=$AI$5)))),0)} -> 0 | AV21: =COUNTIF('Supplier Metrics'!I:I,Summary!AI5) -> 0 | AX21: No. of Sellers (Aggregators) | AY21: {=IFERROR(ROWS(_xlfn.UNIQUE(_xlfn._xlws.FILTER(Details!$F$5:$F$11,(Details!$C$5:$C$11=Summary!AY$3)*(Details!$CK$5:$CK$11=$AX$5)))),0)} -> 0 | AZ21: {=IFERROR(ROWS(_xlfn.UNIQUE(_xlfn._xlws.FILTER(Details!$F$5:$F$11,(Details!$C$5:$C$11=Summary!AZ$3)*(Details!$CK$5:$CK$11=$AX$5)))),0)} -> 0 | BA21: {=IFERROR(ROWS(_xlfn.UNIQUE(_xlfn._xlws.FILTER(Details!$F$5:$F$11,(Details!$C$5:$C$11=Summary!BA$3)*(Details!$CK$5:$CK$11=$AX$5)))),0)} -> 0 | BB21: {=IFERROR(ROWS(_xlfn.UNIQUE(_xlfn._xlws.FILTER(Details!$F$5:$F$11,(Details!$C$5:$C$11=Summary!BB$3)*(Details!$CK$5:$CK$11=$AX$5)))),0)} -> 0 | BC21: {=IFERROR(ROWS(_xlfn.UNIQUE(_xlfn._xlws.FILTER(Details!$F$5:$F$11,(Details!$C$5:$C$11=Summary!BC$3)*(Details!$CK$5:$CK$11=$AX$5)))),0)} -> 0 | BD21: {=IFERROR(ROWS(_xlfn.UNIQUE(_xlfn._xlws.FILTER(Details!$F$5:$F$11,(Details!$C$5:$C$11=Summary!BD$3)*(Details!$CK$5:$CK$11=$AX$5)))),0)} -> 0 | BE21: {=IFERROR(ROWS(_xlfn.UNIQUE(_xlfn._xlws.FILTER(Details!$F$5:$F$11,(Details!$C$5:$C$11=Summary!BE$3)*(Details!$CK$5:$CK$11=$AX$5)))),0)} -> 0 | BF21: {=IFERROR(ROWS(_xlfn.UNIQUE(_xlfn._xlws.FILTER(Details!$F$5:$F$11,(Details!$C$5:$C$11=Summary!BF$3)*(Details!$CK$5:$CK$11=$AX$5)))),0)} -> 0 | ... BJ21: {=IFERROR(ROWS(_xlfn.UNIQUE(_xlfn._xlws.FILTER(Details!$F$5:$F$11,(Details!$C$5:$C$11=Summary!BJ$3)*(Details!$CK$5:$CK$11=$AX$5)))),0)} -> 0 | BK21: =COUNTIF('Supplier Metrics'!I:I,Summary!AX5) -> 0 | BM21: =(AG21+AV21+BK21)-P21 -> -1
C22: No. of Buyers (Recyclers) | D22: {=IFERROR(ROWS(_xlfn.UNIQUE(_xlfn._xlws.FILTER(Details!$AQ$5:$AQ$11,(Details!$C$5:$C$11)=Summary!D$3))),0)} -> 1 | E22: {=IFERROR(ROWS(_xlfn.UNIQUE(_xlfn._xlws.FILTER(Details!$AQ$5:$AQ$11,(Details!$C$5:$C$11)=Summary!E$3))),0)} -> 1 | F22: {=IFERROR(ROWS(_xlfn.UNIQUE(_xlfn._xlws.FILTER(Details!$AQ$5:$AQ$11,(Details!$C$5:$C$11)=Summary!F$3))),0)} -> 1 | G22: {=IFERROR(ROWS(_xlfn.UNIQUE(_xlfn._xlws.FILTER(Details!$AQ$5:$AQ$11,(Details!$C$5:$C$11)=Summary!G$3))),0)} -> 0 | H22: {=IFERROR(ROWS(_xlfn.UNIQUE(_xlfn._xlws.FILTER(Details!$AQ$5:$AQ$11,(Details!$C$5:$C$11)=Summary!H$3))),0)} -> 0 | I22: {=IFERROR(ROWS(_xlfn.UNIQUE(_xlfn._xlws.FILTER(Details!$AQ$5:$AQ$11,(Details!$C$5:$C$11)=Summary!I$3))),0)} -> 0 | J22: {=IFERROR(ROWS(_xlfn.UNIQUE(_xlfn._xlws.FILTER(Details!$AQ$5:$AQ$11,(Details!$C$5:$C$11)=Summary!J$3))),0)} -> 0 | K22: {=IFERROR(ROWS(_xlfn.UNIQUE(_xlfn._xlws.FILTER(Details!$AQ$5:$AQ$11,(Details!$C$5:$C$11)=Summary!K$3))),0)} -> 0 | ... O22: {=IFERROR(ROWS(_xlfn.UNIQUE(_xlfn._xlws.FILTER(Details!$AQ$5:$AQ$11,(Details!$C$5:$C$11)=Summary!O$3))),0)} -> 0 | P22: ='Buyer Metrics'!C3 -> 1 | T22: No. of Buyers (Recyclers) | U22: {=IFERROR(ROWS(_xlfn.UNIQUE(_xlfn._xlws.FILTER(Details!$AQ$5:$AQ$11,(Details!$C$5:$C$11=Summary!U$3)*(Details!$CK$5:$CK$11=$T$5)))),0)} -> 0 | V22: {=IFERROR(ROWS(_xlfn.UNIQUE(_xlfn._xlws.FILTER(Details!$AQ$5:$AQ$11,(Details!$C$5:$C$11=Summary!V$3)*(Details!$CK$5:$CK$11=$T$5)))),0)} -> 0 | W22: {=IFERROR(ROWS(_xlfn.UNIQUE(_xlfn._xlws.FILTER(Details!$AQ$5:$AQ$11,(Details!$C$5:$C$11=Summary!W$3)*(Details!$CK$5:$CK$11=$T$5)))),0)} -> 0 | X22: {=IFERROR(ROWS(_xlfn.UNIQUE(_xlfn._xlws.FILTER(Details!$AQ$5:$AQ$11,(Details!$C$5:$C$11=Summary!X$3)*(Details!$CK$5:$CK$11=$T$5)))),0)} -> 0 | Y22: {=IFERROR(ROWS(_xlfn.UNIQUE(_xlfn._xlws.FILTER(Details!$AQ$5:$AQ$11,(Details!$C$5:$C$11=Summary!Y$3)*(Details!$CK$5:$CK$11=$T$5)))),0)} -> 0 | Z22: {=IFERROR(ROWS(_xlfn.UNIQUE(_xlfn._xlws.FILTER(Details!$AQ$5:$AQ$11,(Details!$C$5:$C$11=Summary!Z$3)*(Details!$CK$5:$CK$11=$T$5)))),0)} -> 0 | AA22: {=IFERROR(ROWS(_xlfn.UNIQUE(_xlfn._xlws.FILTER(Details!$AQ$5:$AQ$11,(Details!$C$5:$C$11=Summary!AA$3)*(Details!$CK$5:$CK$11=$T$5)))),0)} -> 0 | AB22: {=IFERROR(ROWS(_xlfn.UNIQUE(_xlfn._xlws.FILTER(Details!$AQ$5:$AQ$11,(Details!$C$5:$C$11=Summary!AB$3)*(Details!$CK$5:$CK$11=$T$5)))),0)} -> 0 | ... AF22: {=IFERROR(ROWS(_xlfn.UNIQUE(_xlfn._xlws.FILTER(Details!$AQ$5:$AQ$11,(Details!$C$5:$C$11=Summary!AF$3)*(Details!$CK$5:$CK$11=$T$5)))),0)} -> 0 | AG22: =COUNTIFS('Buyer Metrics'!F:F,Summary!T5) -> 0 | AI22: No. of Buyers (Recyclers) | AJ22: {=IFERROR(ROWS(_xlfn.UNIQUE(_xlfn._xlws.FILTER(Details!$AQ$5:$AQ$11,(Details!$C$5:$C$11=Summary!AJ$3)*(Details!$CK$5:$CK$11=$AI$5)))),0)} -> 0 | AK22: {=IFERROR(ROWS(_xlfn.UNIQUE(_xlfn._xlws.FILTER(Details!$AQ$5:$AQ$11,(Details!$C$5:$C$11=Summary!AK$3)*(Details!$CK$5:$CK$11=$AI$5)))),0)} -> 0 | AL22: {=IFERROR(ROWS(_xlfn.UNIQUE(_xlfn._xlws.FILTER(Details!$AQ$5:$AQ$11,(Details!$C$5:$C$11=Summary!AL$3)*(Details!$CK$5:$CK$11=$AI$5)))),0)} -> 0 | AM22: {=IFERROR(ROWS(_xlfn.UNIQUE(_xlfn._xlws.FILTER(Details!$AQ$5:$AQ$11,(Details!$C$5:$C$11=Summary!AM$3)*(Details!$CK$5:$CK$11=$AI$5)))),0)} -> 0 | AN22: {=IFERROR(ROWS(_xlfn.UNIQUE(_xlfn._xlws.FILTER(Details!$AQ$5:$AQ$11,(Details!$C$5:$C$11=Summary!AN$3)*(Details!$CK$5:$CK$11=$AI$5)))),0)} -> 0 | AO22: {=IFERROR(ROWS(_xlfn.UNIQUE(_xlfn._xlws.FILTER(Details!$AQ$5:$AQ$11,(Details!$C$5:$C$11=Summary!AO$3)*(Details!$CK$5:$CK$11=$AI$5)))),0)} -> 0 | AP22: {=IFERROR(ROWS(_xlfn.UNIQUE(_xlfn._xlws.FILTER(Details!$AQ$5:$AQ$11,(Details!$C$5:$C$11=Summary!AP$3)*(Details!$CK$5:$CK$11=$AI$5)))),0)} -> 0 | AQ22: {=IFERROR(ROWS(_xlfn.UNIQUE(_xlfn._xlws.FILTER(Details!$AQ$5:$AQ$11,(Details!$C$5:$C$11=Summary!AQ$3)*(Details!$CK$5:$CK$11=$AI$5)))),0)} -> 0 | ... AU22: {=IFERROR(ROWS(_xlfn.UNIQUE(_xlfn._xlws.FILTER(Details!$AQ$5:$AQ$11,(Details!$C$5:$C$11=Summary!AU$3)*(Details!$CK$5:$CK$11=$AI$5)))),0)} -> 0 | AV22: =COUNTIFS('Buyer Metrics'!F:F,Summary!AI5) -> 0 | AX22: No. of Buyers (Recyclers) | AY22: {=IFERROR(ROWS(_xlfn.UNIQUE(_xlfn._xlws.FILTER(Details!$AQ$5:$AQ$11,(Details!$C$5:$C$11=Summary!AY$3)*(Details!$CK$5:$CK$11=$AX$5)))),0)} -> 0 | AZ22: {=IFERROR(ROWS(_xlfn.UNIQUE(_xlfn._xlws.FILTER(Details!$AQ$5:$AQ$11,(Details!$C$5:$C$11=Summary!AZ$3)*(Details!$CK$5:$CK$11=$AX$5)))),0)} -> 0 | BA22: {=IFERROR(ROWS(_xlfn.UNIQUE(_xlfn._xlws.FILTER(Details!$AQ$5:$AQ$11,(Details!$C$5:$C$11=Summary!BA$3)*(Details!$CK$5:$CK$11=$AX$5)))),0)} -> 0 | BB22: {=IFERROR(ROWS(_xlfn.UNIQUE(_xlfn._xlws.FILTER(Details!$AQ$5:$AQ$11,(Details!$C$5:$C$11=Summary!BB$3)*(Details!$CK$5:$CK$11=$AX$5)))),0)} -> 0 | BC22: {=IFERROR(ROWS(_xlfn.UNIQUE(_xlfn._xlws.FILTER(Details!$AQ$5:$AQ$11,(Details!$C$5:$C$11=Summary!BC$3)*(Details!$CK$5:$CK$11=$AX$5)))),0)} -> 0 | BD22: {=IFERROR(ROWS(_xlfn.UNIQUE(_xlfn._xlws.FILTER(Details!$AQ$5:$AQ$11,(Details!$C$5:$C$11=Summary!BD$3)*(Details!$CK$5:$CK$11=$AX$5)))),0)} -> 0 | BE22: {=IFERROR(ROWS(_xlfn.UNIQUE(_xlfn._xlws.FILTER(Details!$AQ$5:$AQ$11,(Details!$C$5:$C$11=Summary!BE$3)*(Details!$CK$5:$CK$11=$AX$5)))),0)} -> 0 | BF22: {=IFERROR(ROWS(_xlfn.UNIQUE(_xlfn._xlws.FILTER(Details!$AQ$5:$AQ$11,(Details!$C$5:$C$11=Summary!BF$3)*(Details!$CK$5:$CK$11=$AX$5)))),0)} -> 0 | ... BJ22: {=IFERROR(ROWS(_xlfn.UNIQUE(_xlfn._xlws.FILTER(Details!$AQ$5:$AQ$11,(Details!$C$5:$C$11=Summary!BJ$3)*(Details!$CK$5:$CK$11=$AX$5)))),0)} -> 0 | BK22: =COUNTIFS('Buyer Metrics'!F:F,Summary!AX5) -> 0 | BM22: =(AG22+AV22+BK22)-P22 -> -1
