Workbook

Sheet Summary
D2: =TEXT(D4, "mmm-yy") -> Apr-26 | E2: =TEXT(E4, "mmm-yy") -> May-26 | F2: =TEXT(F4, "mmm-yy") -> Jun-26 | G2: =TEXT(G4, "mmm-yy") -> Jul-26 | H2: =TEXT(H4, "mmm-yy") -> Aug-26 | I2: =TEXT(I4, "mmm-yy") -> Sep-26 | J2: =TEXT(J4, "mmm-yy") -> Oct-25 | K2: =TEXT(K4, "mmm-yy") -> Nov-25 | ... Q2: =TEXT(Q4, "mmm-yy") -> Mar-26
D3: 30 | E3: 31 | F3: 21 | G3: 0 | H3: 0 | I3: 0 | J3: 0 | K3: 0 | L3: 0 | M3: 0 | N3: 0 | O3: 0 | P3: 0 | Q3: 0 | R3: =SUM(D3:Q3) -> 82
C4: Marketplace (AFR) | D4: 46113 | E4: 46143 | F4: 46174 | G4: 46204 | H4: 46235 | I4: 46266 | J4: 45931 | K4: 45962 | L4: 46296 | M4: 46327 | N4: 45992 | O4: 46023 | P4: 46054 | Q4: 46082 | R4: FY 2026-27
C5: Quantity (MT) | D5: 19.16 | E5: =SUMIFS(Details!$BB$4:$BB$18,Details!$C$4:$C$18,Summary!E$4)/1000 -> 55.8 | F5: =SUMIFS(Details!$BB$4:$BB$18,Details!$C$4:$C$18,Summary!F$4)/1000 -> 112.91 | G5: =SUMIFS(Details!$BB$4:$BB$18,Details!$C$4:$C$18,Summary!G$4)/1000 -> 0 | H5: =SUMIFS(Details!$BB$4:$BB$18,Details!$C$4:$C$18,Summary!H$4)/1000 -> 0 | I5: =SUMIFS(Details!$BB$4:$BB$18,Details!$C$4:$C$18,Summary!I$4)/1000 -> 0 | J5: =SUMIFS(Details!$BB$4:$BB$18,Details!$C$4:$C$18,Summary!J$4)/1000 -> 0 | K5: =SUMIFS(Details!$BB$4:$BB$18,Details!$C$4:$C$18,Summary!K$4)/1000 -> 0 | L5: =SUMIFS(Details!$BB$4:$BB$18,Details!$C$4:$C$18,Summary!L$4)/1000 -> 0 | ... Q5: =SUMIFS(Details!$BB$4:$BB$18,Details!$C$4:$C$18,Summary!Q$4)/1000 -> 0 | R5: =SUM(D5:Q5) -> 187.87 | S5: =Details!BB19/1000 -> 187.87 | T5: =R5-S5 -> 0 | U5: =-T5 -> 0
C6: Sales | D6: 268100 | E6: =SUMIFS(Details!$BO$4:$BO$18,Details!$C$4:$C$18,Summary!E$4) -> 729921 | F6: =SUMIFS(Details!$BO$4:$BO$18,Details!$C$4:$C$18,Summary!F$4) -> 1028032.6 | G6: =SUMIFS(Details!$BO$4:$BO$18,Details!$C$4:$C$18,Summary!G$4) -> 0 | H6: =SUMIFS(Details!$BO$4:$BO$18,Details!$C$4:$C$18,Summary!H$4) -> 0 | I6: =SUMIFS(Details!$BO$4:$BO$18,Details!$C$4:$C$18,Summary!I$4) -> 0 | J6: =SUMIFS(Details!$BO$4:$BO$18,Details!$C$4:$C$18,Summary!J$4) -> 0 | K6: =SUMIFS(Details!$BO$4:$BO$18,Details!$C$4:$C$18,Summary!K$4) -> 0 | L6: =SUMIFS(Details!$BO$4:$BO$18,Details!$C$4:$C$18,Summary!L$4) -> 0 | ... Q6: =SUMIFS(Details!$BO$4:$BO$18,Details!$C$4:$C$18,Summary!Q$4) -> 0 | R6: =SUM(D6:Q6) -> 2026053.6 | S6: =Details!BO19 -> 2026053.6 | T6: =R6-S6+R71 -> 0 | U6: =-T6 -> 0
C7: Purchases | D7: 220225 | E7: =SUMIFS(Details!$AM$4:$AM$18,Details!$C$4:$C$18,Summary!E$4)-SUMIFS(Details!$AB$4:$AB$18,Details!$C$4:$C$18,Summary!E$4) -> 660165 | F7: =SUMIFS(Details!$AM$4:$AM$18,Details!$C$4:$C$18,Summary!F$4)-SUMIFS(Details!$AB$4:$AB$18,Details!$C$4:$C$18,Summary!F$4) -> 969640 | G7: =SUMIFS(Details!$AM$4:$AM$18,Details!$C$4:$C$18,Summary!G$4)-SUMIFS(Details!$AB$4:$AB$18,Details!$C$4:$C$18,Summary!G$4) -> 0 | H7: =SUMIFS(Details!$AM$4:$AM$18,Details!$C$4:$C$18,Summary!H$4)-SUMIFS(Details!$AB$4:$AB$18,Details!$C$4:$C$18,Summary!H$4) -> 0 | I7: =SUMIFS(Details!$AM$4:$AM$18,Details!$C$4:$C$18,Summary!I$4)-SUMIFS(Details!$AB$4:$AB$18,Details!$C$4:$C$18,Summary!I$4) -> 0 | J7: =SUMIFS(Details!$AM$4:$AM$18,Details!$C$4:$C$18,Summary!J$4)-SUMIFS(Details!$AB$4:$AB$18,Details!$C$4:$C$18,Summary!J$4) -> 0 | K7: =SUMIFS(Details!$AM$4:$AM$18,Details!$C$4:$C$18,Summary!K$4)-SUMIFS(Details!$AB$4:$AB$18,Details!$C$4:$C$18,Summary!K$4) -> 0 | L7: =SUMIFS(Details!$AM$4:$AM$18,Details!$C$4:$C$18,Summary!L$4)-SUMIFS(Details!$AB$4:$AB$18,Details!$C$4:$C$18,Summary!L$4) -> 0 | ... Q7: =SUMIFS(Details!$AM$4:$AM$18,Details!$C$4:$C$18,Summary!Q$4)-SUMIFS(Details!$AB$4:$AB$18,Details!$C$4:$C$18,Summary!Q$4) -> 0 | R7: =SUM(D7:Q7) -> 1850030 | S7: =Details!P20 -> 1850030 | T7: =R7-S7 -> 0 | U7: =-T7 -> 0
C8: Gross Margin | D8: =D6-D7 -> 47875 | E8: =E6-E7 -> 69756 | F8: =F6-F7 -> 58392.6 | G8: =G6-G7 -> 0 | H8: =H6-H7 -> 0 | I8: =I6-I7 -> 0 | J8: =J6-J7 -> 0 | K8: =K6-K7 -> 0 | ... Q8: =Q6-Q7 -> 0 | R8: =SUM(D8:Q8) -> 176023.6
C9: Gross Margin (%) | D9: =IFERROR((D8/D6),0) -> 0.17857143 | E9: =IFERROR((E8/E6),0) -> 0.095566507 | F9: =IFERROR((F8/F6),0) -> 0.056800339 | G9: =IFERROR((G8/G6),0) -> 0 | H9: =IFERROR((H8/H6),0) -> 0 | I9: =IFERROR((I8/I6),0) -> 0 | J9: =IFERROR((J8/J6),0) -> 0 | K9: =IFERROR((K8/K6),0) -> 0 | ... R9: =IFERROR((R8/R6),0) -> 0.086880031
C10: Transportation Charges | D10: 54711 | E10: =SUMIFS(Details!$AB$4:$AB$18,Details!$C$4:$C$18,Summary!E$4) -> 0 | F10: =SUMIFS(Details!$AB$4:$AB$18,Details!$C$4:$C$18,Summary!F$4) -> 0 | G10: =SUMIFS(Details!$AB$4:$AB$18,Details!$C$4:$C$18,Summary!G$4) -> 0 | H10: =SUMIFS(Details!$AB$4:$AB$18,Details!$C$4:$C$18,Summary!H$4) -> 0 | I10: =SUMIFS(Details!$AB$4:$AB$18,Details!$C$4:$C$18,Summary!I$4) -> 0 | J10: =SUMIFS(Details!$AB$4:$AB$18,Details!$C$4:$C$18,Summary!J$4) -> 0 | K10: =SUMIFS(Details!$AB$4:$AB$18,Details!$C$4:$C$18,Summary!K$4) -> 0 | L10: =SUMIFS(Details!$AB$4:$AB$18,Details!$C$4:$C$18,Summary!L$4) -> 0 | ... Q10: =SUMIFS(Details!$AB$4:$AB$18,Details!$C$4:$C$18,Summary!Q$4) -> 0 | R10: =SUM(D10:Q10) -> 54711 | S10: =Details!AB19+Details!AB35 -> 54711 | T10: =R10-S10 -> 0 | U10: =-T10 -> 0
C11: Operational Expenses | D11: =SUMIFS(Details!$AC$4:$AC$18,Details!$C$4:$C$18,Summary!D$4)+SUMIFS(Details!AM24:AM34,Details!C24:C34,Summary!D4)-SUMIFS(Details!AB24:AB34,Details!C24:C34,Summary!D4) -> 332906 | E11: =SUMIFS(Details!$AC$5:$AC$18,Details!$C$5:$C$18,Summary!E$4)+SUMIFS(Details!AM24:AM34,Details!C24:C34,Summary!E4)-SUMIFS(Details!AB24:AB34,Details!C24:C34,Summary!E4) -> 222000 | F11: =SUMIFS(Details!$AC$4:$AC$18,Details!$C$4:$C$18,Summary!F$4) -> 0 | G11: =SUMIFS(Details!$AC$4:$AC$18,Details!$C$4:$C$18,Summary!G$4) -> 0 | H11: =SUMIFS(Details!$AC$4:$AC$18,Details!$C$4:$C$18,Summary!H$4) -> 0 | I11: =SUMIFS(Details!$AC$4:$AC$18,Details!$C$4:$C$18,Summary!I$4) -> 0 | J11: =SUMIFS(Details!$AC$4:$AC$18,Details!$C$4:$C$18,Summary!J$4) -> 0 | K11: =SUMIFS(Details!$AC$4:$AC$18,Details!$C$4:$C$18,Summary!K$4) -> 0 | L11: =SUMIFS(Details!$AC$4:$AC$18,Details!$C$4:$C$18,Summary!L$4) -> 0 | M11: =SUMIFS(Details!$AC$4:$AC$18,Details!$C$4:$C$18,Summary!M$4) -> 0 | ... Q11: =SUMIFS(Details!$AC$4:$AC$18,Details!$C$4:$C$18,Summary!Q$4) -> 0 | R11: =SUM(D11:Q11) -> 554906
C12: Net Margin | D12: =D6-D7-D10-D11 -> -339742 | E12: =E6-E7-E10-E11 -> -152244 | F12: =F6-F7-F10 -> 58392.6 | G12: =G6-G7-G10 -> 0 | H12: =H6-H7-H10 -> 0 | I12: =I6-I7-I10 -> 0 | J12: =J6-J7-J10 -> 0 | K12: =K6-K7-K10 -> 0 | L12: =L6-L7-L10 -> 0 | M12: =M6-M7-M10 -> 0 | ... Q12: =Q6-Q7-Q10 -> 0 | R12: =SUM(D12:Q12) -> -433593.4
C13: Net Margin (%) | D13: =IFERROR((D12/D6),0) -> -1.2672212 | E13: =IFERROR((E12/E6),0) -> -0.208576 | F13: =IFERROR((F12/F6),0) -> 0.056800339 | G13: =IFERROR((G12/G6),0) -> 0 | H13: =IFERROR((H12/H6),0) -> 0 | I13: =IFERROR((I12/I6),0) -> 0 | J13: =IFERROR((J12/J6),0) -> 0 | K13: =IFERROR((K12/K6),0) -> 0 | ... R13: =IFERROR((R12/R6),0) -> -0.21400885
C14: Other Income | D14: 0 | E14: 0 | F14: 0 | G14: 0 | H14: 0 | I14: 0 | J14: 0 | K14: 0 | L14: 0 | M14: 0 | N14: 0 | O14: 0 | P14: 0 | Q14: 0 | R14: =SUM(D14:Q14) -> 0
C15: Transport Charges (%) | D15: =IFERROR((D10/D6),0) -> 0.20406938 | E15: =IFERROR((E10/E6),0) -> 0 | F15: =IFERROR((F10/F6),0) -> 0 | G15: =IFERROR((G10/G6),0) -> 0 | H15: =IFERROR((H10/H6),0) -> 0 | I15: =IFERROR((I10/I6),0) -> 0 | J15: =IFERROR((J10/J6),0) -> 0 | K15: =IFERROR((K10/K6),0) -> 0 | ... R15: =IFERROR((R10/R6),0) -> 0.027003728
C16: Revenue Per Kg | D16: =IFERROR(+D6/(D5*1000),0) -> 13.992693 | E16: =IFERROR(+E6/(E5*1000),0) -> 13.081022 | F16: =IFERROR(+F6/(F5*1000),0) -> 9.1048853 | G16: =IFERROR(+G6/(G5*1000),0) -> 0 | H16: =IFERROR(+H6/(H5*1000),0) -> 0 | I16: =IFERROR(+I6/(I5*1000),0) -> 0 | J16: =IFERROR(+J6/(J5*1000),0) -> 0 | K16: =IFERROR(+K6/(K5*1000),0) -> 0 | ... Q16: =IFERROR(+Q6/(Q5*1000),0) -> 0 | R16: =+R6/(R5*1000) -> 10.784338
C17: Purchase Cost Per Kg | D17: =IFERROR(+D7/(D5*1000),0) -> 11.493998 | E17: =IFERROR(+E7/(E5*1000),0) -> 11.830914 | F17: =IFERROR(+F7/(F5*1000),0) -> 8.5877247 | G17: =IFERROR(+G7/(G5*1000),0) -> 0 | H17: =IFERROR(+H7/(H5*1000),0) -> 0 | I17: =IFERROR(+I7/(I5*1000),0) -> 0 | J17: =IFERROR(+J7/(J5*1000),0) -> 0 | K17: =IFERROR(+K7/(K5*1000),0) -> 0 | ... Q17: =IFERROR(+Q7/(Q5*1000),0) -> 0 | R17: =+R7/(R5*1000) -> 9.8473945
C18: Transportation Charges Per Kg | D18: =IFERROR(D10/(D5*1000),0) -> 2.8554802 | E18: =IFERROR(E10/(E5*1000),0) -> 0 | F18: =IFERROR(F10/(F5*1000),0) -> 0 | G18: =IFERROR(G10/(G5*1000),0) -> 0 | H18: =IFERROR(H10/(H5*1000),0) -> 0 | I18: =IFERROR(I10/(I5*1000),0) -> 0 | J18: =IFERROR(J10/(J5*1000),0) -> 0 | K18: =IFERROR(K10/(K5*1000),0) -> 0 | ... Q18: =IFERROR(Q10/(Q5*1000),0) -> 0 | R18: =R10/(R5*1000) -> 0.29121733
C19: No. of Transactions | D19: {=IFERROR(ROWS(_xlfn.UNIQUE(_xlfn._xlws.FILTER(Details!$AO$5:$AO$18, (Details!$C$5:$C$18)=Summary!D$2))),0)} -> 1 | E19: {=IFERROR(ROWS(_xlfn.UNIQUE(_xlfn._xlws.FILTER(Details!$AO$5:$AO$18, (Details!$C$5:$C$18)=Summary!E$2))),0)} -> 3 | F19: {=IFERROR(ROWS(_xlfn.UNIQUE(_xlfn._xlws.FILTER(Details!$AO$5:$AO$18, (Details!$C$5:$C$18)=Summary!F$2))),0)} -> 9 | G19: {=IFERROR(ROWS(_xlfn.UNIQUE(_xlfn._xlws.FILTER(Details!$AO$5:$AO$18, (Details!$C$5:$C$18)=Summary!G$2))),0)} -> 0 | H19: {=IFERROR(ROWS(_xlfn.UNIQUE(_xlfn._xlws.FILTER(Details!$AO$5:$AO$18, (Details!$C$5:$C$18)=Summary!H$2))),0)} -> 0 | I19: {=IFERROR(ROWS(_xlfn.UNIQUE(_xlfn._xlws.FILTER(Details!$AO$5:$AO$18, (Details!$C$5:$C$18)=Summary!I$2))),0)} -> 0 | J19: {=IFERROR(ROWS(_xlfn.UNIQUE(_xlfn._xlws.FILTER(Details!$AO$5:$AO$18, (Details!$C$5:$C$18)=Summary!J$2))),0)} -> 0 | K19: {=IFERROR(ROWS(_xlfn.UNIQUE(_xlfn._xlws.FILTER(Details!$AO$5:$AO$18, (Details!$C$5:$C$18)=Summary!K$2))),0)} -> 0 | ... Q19: {=IFERROR(ROWS(_xlfn.UNIQUE(_xlfn._xlws.FILTER(Details!$AO$5:$AO$18, (Details!$C$5:$C$18)=Summary!Q$2))),0)} -> 0 | R19: =SUM(D19:Q19) -> 13
C20: No. of Sellers (Aggregators) | D20: {=IFERROR(ROWS(_xlfn.UNIQUE(_xlfn._xlws.FILTER(MID(Details!$G$5:$G$18,3,10), (Details!$C$5:$C$18)=Summary!D$2))),0)} -> 1 | E20: {=IFERROR(ROWS(_xlfn.UNIQUE(_xlfn._xlws.FILTER(MID(Details!$G$5:$G$18,3,10), (Details!$C$5:$C$18)=Summary!E$2))),0)} -> 1 | F20: {=IFERROR(ROWS(_xlfn.UNIQUE(_xlfn._xlws.FILTER(MID(Details!$G$5:$G$18,3,10), (Details!$C$5:$C$18)=Summary!F$2))),0)} -> 2 | G20: {=IFERROR(ROWS(_xlfn.UNIQUE(_xlfn._xlws.FILTER(MID(Details!$G$5:$G$18,3,10), (Details!$C$5:$C$18)=Summary!G$2))),0)} -> 0 | H20: {=IFERROR(ROWS(_xlfn.UNIQUE(_xlfn._xlws.FILTER(MID(Details!$G$5:$G$18,3,10), (Details!$C$5:$C$18)=Summary!H$2))),0)} -> 0 | I20: {=IFERROR(ROWS(_xlfn.UNIQUE(_xlfn._xlws.FILTER(MID(Details!$G$5:$G$18,3,10), (Details!$C$5:$C$18)=Summary!I$2))),0)} -> 0 | J20: {=IFERROR(ROWS(_xlfn.UNIQUE(_xlfn._xlws.FILTER(MID(Details!$G$5:$G$18,3,10), (Details!$C$5:$C$18)=Summary!J$2))),0)} -> 0 | K20: {=IFERROR(ROWS(_xlfn.UNIQUE(_xlfn._xlws.FILTER(MID(Details!$G$5:$G$18,3,10), (Details!$C$5:$C$18)=Summary!K$2))),0)} -> 0 | ... Q20: {=IFERROR(ROWS(_xlfn.UNIQUE(_xlfn._xlws.FILTER(MID(Details!$G$5:$G$18,3,10), (Details!$C$5:$C$18)=Summary!Q$2))),0)} -> 0 | R20: ='Supplier Metrics'!B2 -> 1
C21: No. of Buyers (Recyclers) | D21: {=IFERROR(ROWS(_xlfn.UNIQUE(_xlfn._xlws.FILTER(MID(Details!$AR$5:$AR$18,3,10), (Details!$C$5:$C$18)=Summary!D$2))),0)} -> 1 | E21: {=IFERROR(ROWS(_xlfn.UNIQUE(_xlfn._xlws.FILTER(MID(Details!$AR$5:$AR$18,3,10), (Details!$C$5:$C$18)=Summary!E$2))),0)} -> 1 | F21: {=IFERROR(ROWS(_xlfn.UNIQUE(_xlfn._xlws.FILTER(MID(Details!$AR$5:$AR$18,3,10), (Details!$C$5:$C$18)=Summary!F$2))),0)} -> 2 | G21: {=IFERROR(ROWS(_xlfn.UNIQUE(_xlfn._xlws.FILTER(MID(Details!$AR$5:$AR$18,3,10), (Details!$C$5:$C$18)=Summary!G$2))),0)} -> 0 | H21: {=IFERROR(ROWS(_xlfn.UNIQUE(_xlfn._xlws.FILTER(MID(Details!$AR$5:$AR$18,3,10), (Details!$C$5:$C$18)=Summary!H$2))),0)} -> 0 | I21: {=IFERROR(ROWS(_xlfn.UNIQUE(_xlfn._xlws.FILTER(MID(Details!$AR$5:$AR$18,3,10), (Details!$C$5:$C$18)=Summary!I$2))),0)} -> 0 | J21: {=IFERROR(ROWS(_xlfn.UNIQUE(_xlfn._xlws.FILTER(MID(Details!$AR$5:$AR$18,3,10), (Details!$C$5:$C$18)=Summary!J$2))),0)} -> 0 | K21: {=IFERROR(ROWS(_xlfn.UNIQUE(_xlfn._xlws.FILTER(MID(Details!$AR$5:$AR$18,3,10), (Details!$C$5:$C$18)=Summary!K$2))),0)} -> 0 | ... Q21: {=IFERROR(ROWS(_xlfn.UNIQUE(_xlfn._xlws.FILTER(MID(Details!$AR$5:$AR$18,3,10), (Details!$C$5:$C$18)=Summary!Q$2))),0)} -> 0 | R21: ='Buyer Metrics'!B3 -> 2
C22: Full Rejection | D22: {=IFERROR(ROWS(_xlfn.UNIQUE(_xlfn._xlws.FILTER(Details!$E$5:$E$18,(Details!$C$5:$C$18=Summary!D$2)*(Details!$BR$5:$BR$18=Summary!$C$22)))),0)} -> 0 | E22: {=IFERROR(ROWS(_xlfn.UNIQUE(_xlfn._xlws.FILTER(Details!$E$5:$E$18,(Details!$C$5:$C$18=Summary!E$4)*(Details!$BR$5:$BR$18=Summary!$C$22)))),0)} -> 0 | F22: {=IFERROR(ROWS(_xlfn.UNIQUE(_xlfn._xlws.FILTER(Details!$E$5:$E$18,(Details!$C$5:$C$18=Summary!F$4)*(Details!$BR$5:$BR$18=Summary!$C$22)))),0)} -> 0 | G22: {=IFERROR(ROWS(_xlfn.UNIQUE(_xlfn._xlws.FILTER(Details!$E$5:$E$18,(Details!$C$5:$C$18=Summary!G$4)*(Details!$BR$5:$BR$18=Summary!$C$22)))),0)} -> 0 | H22: {=IFERROR(ROWS(_xlfn.UNIQUE(_xlfn._xlws.FILTER(Details!$E$5:$E$18,(Details!$C$5:$C$18=Summary!H$4)*(Details!$BR$5:$BR$18=Summary!$C$22)))),0)} -> 0 | I22: {=IFERROR(ROWS(_xlfn.UNIQUE(_xlfn._xlws.FILTER(Details!$E$5:$E$18,(Details!$C$5:$C$18=Summary!I$4)*(Details!$BR$5:$BR$18=Summary!$C$22)))),0)} -> 0 | J22: {=IFERROR(ROWS(_xlfn.UNIQUE(_xlfn._xlws.FILTER(Details!$E$5:$E$18,(Details!$C$5:$C$18=Summary!J$4)*(Details!$BR$5:$BR$18=Summary!$C$22)))),0)} -> 0 | K22: {=IFERROR(ROWS(_xlfn.UNIQUE(_xlfn._xlws.FILTER(Details!$E$5:$E$18,(Details!$C$5:$C$18=Summary!K$4)*(Details!$BR$5:$BR$18=Summary!$C$22)))),0)} -> 0 | L22: {=IFERROR(ROWS(_xlfn.UNIQUE(_xlfn._xlws.FILTER(Details!$E$5:$E$18,(Details!$C$5:$C$18=Summary!L$4)*(Details!$BR$5:$BR$18=Summary!$C$22)))),0)} -> 0 | ... Q22: {=IFERROR(ROWS(_xlfn.UNIQUE(_xlfn._xlws.FILTER(Details!$E$5:$E$18,(Details!$C$5:$C$18=Summary!Q$4)*(Details!$BR$5:$BR$18=Summary!$C$22)))),0)} -> 0 | R22: =SUM(D22:Q22) -> 0
C23: Receivable | D23: 796441.6 | E23: 600884.96 | F23: 1671613.1 | G23: 0 | H23: 0 | I23: 0 | J23: 0 | K23: 0 | L23: 0 | M23: 0 | N23: 0 | O23: 0 | P23: 0 | Q23: 0 | R23: =F23 -> 1671613.1
C24: DSO (Days) | D24: =IFERROR(((D23/(D6*1.18))*D3),0) -> 75.52598 | E24: =IFERROR(((E23/(E6*1.18))*E3),0) -> 21.626944 | F24: =IFERROR(((F23/(F6*1.18))*F3),0) -> 28.937843 | G24: =IFERROR(((G23/(G6*1.18))*G3),0) -> 0 | H24: =IFERROR(((H23/(H6*1.18))*H3),0) -> 0 | I24: =IFERROR(((I23/(I6*1.18))*I3),0) -> 0 | J24: =IFERROR(((J23/(J6*1.18))*J3),0) -> 0 | K24: =IFERROR(((K23/(K6*1.18))*K3),0) -> 0 | ... Q24: =IFERROR(((Q23/(Q6*1.18))*Q3),0) -> 0 | R24: =IFERROR(((R23)/(R6*1.18)*R3),0) -> 57.334585
C25: Payable | D25: 287674.16 | E25: 561938.06 | F25: 948429.3 | G25: 0 | H25: 0 | I25: 0 | J25: 0 | K25: 0 | L25: 0 | M25: 0 | N25: 0 | O25: 0 | P25: 0 | Q25: 0 | R25: =F25 -> 948429.3
C26: DPO (Days) | D26: =IFERROR(((D25/(D7*1.18))*D3),0) -> 33.210352 | E26: =IFERROR(((E25/(E7*1.18))*E3),0) -> 22.362257 | F26: =IFERROR(((F25/(F7*1.18))*F3),0) -> 17.407313 | G26: =IFERROR(((G25/(G7*1.18))*G3),0) -> 0 | H26: =IFERROR(((H25/(H7*1.18))*H3),0) -> 0 | I26: =IFERROR(((I25/(I7*1.18))*I3),0) -> 0 | J26: =IFERROR(((J25/(J7*1.18))*J3),0) -> 0 | K26: =IFERROR(((K25/(K7*1.18))*K3),0) -> 0 | ... R26: =IFERROR(((R25/(R7*1.18))*R3),0) -> 35.625259
C27: Working Capital Days | D27: =D24-D26 -> 42.315628 | E27: =E24-E26 -> -0.73531292 | F27: =F24-F26 -> 11.530531 | G27: =G24-G26 -> 0 | H27: =H24-H26 -> 0 | I27: =I24-I26 -> 0 | J27: =J24-J26 -> 0 | K27: =K24-K26 -> 0 | ... R27: =R24-R26 -> 21.709325
C28: Credit Notes (Value - Incl. Prov) | D28: 140 | E28: =-SUMIFS(Details!$BW$4:$BW$18,Details!$C$4:$C$18,Summary!E4) -> 560 | F28: =-SUMIFS(Details!$BW$4:$BW$18,Details!$C$4:$C$18,Summary!F4) -> 0 | G28: =-SUMIFS(Details!$BW$4:$BW$18,Details!$C$4:$C$18,Summary!G4) -> 0 | H28: =-SUMIFS(Details!$BW$4:$BW$18,Details!$C$4:$C$18,Summary!H4) -> 0 | I28: =-SUMIFS(Details!$BW$4:$BW$18,Details!$C$4:$C$18,Summary!I4) -> 0 | J28: =-SUMIFS(Details!$BW$4:$BW$18,Details!$C$4:$C$18,Summary!J4) -> 0 | K28: =-SUMIFS(Details!$BW$4:$BW$18,Details!$C$4:$C$18,Summary!K4) -> 0 | L28: =-SUMIFS(Details!$BW$4:$BW$18,Details!$C$4:$C$18,Summary!L4) -> 0 | ... Q28: =-SUMIFS(Details!$BW$4:$BW$18,Details!$C$4:$C$18,Summary!Q4) -> 0 | R28: =SUM(D28:Q28) -> 700 | S28: =(Details!BM19-Details!BN19) -> -700 | T28: =R28+S28 -> 0
C29: Credit Notes (% to Revenue) | D29: =IFERROR((+D28/D6),0) -> 0.00052219321 | E29: =IFERROR((+E28/E6),0) -> 0.00076720631 | F29: =IFERROR((+F28/F6),0) -> 0 | G29: =IFERROR((+G28/G6),0) -> 0 | H29: =IFERROR((+H28/H6),0) -> 0 | I29: =IFERROR((+I28/I6),0) -> 0 | J29: =IFERROR((+J28/J6),0) -> 0 | K29: =IFERROR((+K28/K6),0) -> 0 | ... Q29: =IFERROR((+Q28/Q6),0) -> 0 | R29: =+R28/R6 -> 0.00034549925
C30: Debit Notes (Value - Incl. Prov) | D30: 115 | E30: =SUMIFS(Details!$BX$4:$BX$18,Details!$C$4:$C$18,Summary!E4) -> -460 | F30: =-SUMIFS(Details!$BX$4:$BX$18,Details!$C$4:$C$18,Summary!F4) -> 0 | G30: =-SUMIFS(Details!$BX$4:$BX$18,Details!$C$4:$C$18,Summary!G4) -> 0 | H30: =-SUMIFS(Details!$BX$4:$BX$18,Details!$C$4:$C$18,Summary!H4) -> 0 | I30: =-SUMIFS(Details!$BX$4:$BX$18,Details!$C$4:$C$18,Summary!I4) -> 0 | J30: =-SUMIFS(Details!$BX$4:$BX$18,Details!$C$4:$C$18,Summary!J4) -> 0 | K30: =-SUMIFS(Details!$BX$4:$BX$18,Details!$C$4:$C$18,Summary!K4) -> 0 | L30: =-SUMIFS(Details!$BX$4:$BX$18,Details!$C$4:$C$18,Summary!L4) -> 0 | M30: =-SUMIFS(Details!$BX$4:$BX$18,Details!$C$4:$C$18,Summary!M4) -> 0 | ... Q30: =-SUMIFS(Details!$BX$4:$BX$18,Details!$C$4:$C$18,Summary!Q4) -> 0 | R30: =SUM(D30:Q30) -> -345 | S30: =(Details!AK19-Details!AL19) -> -575 | T30: =R30+S30 -> -920
C31: Debit Notes (% to Purchase) | D31: =IFERROR((D30/D7),0) -> 0.00052219321 | E31: =IFERROR((E30/E7),0) -> -0.0006967955 | F31: =IFERROR((F30/F7),0) -> 0 | G31: =IFERROR((G30/G7),0) -> 0 | H31: =IFERROR((H30/H7),0) -> 0 | I31: =IFERROR((I30/I7),0) -> 0 | J31: =IFERROR((J30/J7),0) -> 0 | K31: =IFERROR((K30/K7),0) -> 0 | ... Q31: =IFERROR((Q30/Q7),0) -> 0 | R31: =(R30/(R7+R10)) -> -0.00018112699
C33: KPI's without Provisions | D33: =D4 -> 46113 | E33: =E4 -> 46143 | F33: =F4 -> 46174 | G33: =G4 -> 46204 | H33: =H4 -> 46235 | I33: =I4 -> 46266 | J33: =J4 -> 45931 | K33: =K4 -> 45962 | L33: 46296 | M33: 46327 | N33: =N4 -> 45992 | O33: =O4 -> 46023 | P33: =P4 -> 46054 | Q33: =Q4 -> 46082 | R33: =R4 -> FY 2026-27
C34: Sales without Provision | D34: =D6+D53 -> 268100 | E34: =E6+E53 -> 729921 | F34: =F6+F53 -> 1028032.6 | G34: =G6+G53 -> 0 | H34: =H6+H53 -> 0 | I34: =I6+I53 -> 0 | J34: =J6+J53 -> 0 | K34: =K6+K53 -> 0 | ... Q34: =Q6+Q53 -> 0 | R34: =SUM(D34:Q34) -> 2026053.6
C35: Purchases without Provision | D35: =D7+D10+D52 -> 274936 | E35: =E7+E10+E52 -> 660165 | F35: =F7+F10+F52 -> 969640 | G35: =G7+G10+G52 -> 0 | H35: =H7+H10+H52 -> 0 | I35: =I7+I10+I52 -> 0 | J35: =J7+J10+J52 -> 0 | K35: =K7+K10+K52 -> 0 | ... Q35: =Q7+Q10+Q52 -> 0 | R35: =SUM(D35:Q35) -> 1904741
C36: Contribution without Provision | D36: =D34-D35 -> -6836 | E36: =E34-E35 -> 69756 | F36: =F34-F35 -> 58392.6 | G36: =G34-G35 -> 0 | H36: =H34-H35 -> 0 | I36: =I34-I35 -> 0 | J36: =J34-J35 -> 0 | K36: =K34-K35 -> 0 | ... R36: =R34-R35 -> 121312.6
C37: Contribution (%) | D37: =D36/D34 -> -0.025497949 | E37: =E36/E34 -> 0.095566507 | F37: =F36/F34 -> 0.056800339 | G37: =G36/G34 -> #DIV/0! | H37: =H36/H34 -> #DIV/0! | I37: =I36/I34 -> #DIV/0! | J37: =J36/J34 -> #DIV/0! | K37: =K36/K34 -> #DIV/0! | ... R37: =R36/R34 -> 0.059876303
C39: Business Trends | D39: =D4 -> 46113 | E39: =E4 -> 46143 | F39: =F4 -> 46174 | G39: =G4 -> 46204 | H39: =H4 -> 46235 | I39: =I4 -> 46266 | J39: =J4 -> 45931 | K39: =K4 -> 45962 | L39: 46296 | M39: 46327 | N39: =N4 -> 45992 | O39: =O4 -> 46023 | P39: =P4 -> 46054 | Q39: =Q4 -> 46082 | R39: =R4 -> FY 2026-27
C40: Sales-Revenue (MoM) | D40: =IFERROR(((D6/C6)-1),0) -> 0 | E40: =IFERROR(((E6/D6)-1),0) -> 1.7225699 | F40: =IFERROR(((F6/E6)-1),0) -> 0.40841625 | G40: =IFERROR(((G6/F6)-1),0) -> -1 | H40: =IFERROR(((H6/G6)-1),0) -> 0 | I40: =IFERROR(((I6/H6)-1),0) -> 0 | J40: =IFERROR(((J6/I6)-1),0) -> 0 | K40: =IFERROR(((K6/J6)-1),0) -> 0 | ... M40: =IFERROR(((M6/L6)-1),0) -> 0 | N40: =IFERROR(((N6/K6)-1),0) -> 0 | O40: =IFERROR(((O6/N6)-1),0) -> 0 | P40: =IFERROR(((P6/O6)-1),0) -> 0 | Q40: =IFERROR(((Q6/P6)-1),0) -> 0 | R40: 0
C41: Sales-Volume (MoM) | D41: =IFERROR(((D5/C5)-1),0) -> 0 | E41: =IFERROR(((E5/D5)-1),0) -> 1.9123173 | F41: =IFERROR(((F5/E5)-1),0) -> 1.0234767 | G41: =IFERROR(((G5/F5)-1),0) -> -1 | H41: =IFERROR(((H5/G5)-1),0) -> 0 | I41: =IFERROR(((I5/H5)-1),0) -> 0 | J41: =IFERROR(((J5/I5)-1),0) -> 0 | K41: =IFERROR(((K5/J5)-1),0) -> 0 | ... M41: =IFERROR(((M5/L5)-1),0) -> 0 | N41: =IFERROR(((N5/K5)-1),0) -> 0 | O41: =IFERROR(((O5/N5)-1),0) -> 0 | P41: =IFERROR(((P5/O5)-1),0) -> 0 | Q41: =IFERROR(((Q5/P5)-1),0) -> 0 | R41: 0
C42: Sales-Transactions (MoM) | D42: =IFERROR(((D19/C19)-1),0) -> 0 | E42: =IFERROR(((E19/D19)-1),0) -> 2 | F42: =IFERROR(((F19/E19)-1),0) -> 2 | G42: =IFERROR(((G19/F19)-1),0) -> -1 | H42: =IFERROR(((#REF!/G19)-1),0) -> 0 | I42: =IFERROR(((I19/#REF!)-1),0) -> 0 | J42: =IFERROR(((J19/#REF!)-1),0) -> 0 | K42: =IFERROR(((K19/#REF!)-1),0) -> 0 | L42: =IFERROR(((L19/#REF!)-1),0) -> 0 | M42: =IFERROR(((M19/#REF!)-1),0) -> 0 | N42: =IFERROR(((N19/K19)-1),0) -> 0 | O42: =IFERROR(((O19/N19)-1),0) -> 0 | P42: =IFERROR(((P19/O19)-1),0) -> 0 | Q42: =IFERROR(((Q19/P19)-1),0) -> 0 | R42: 0
C44: Loss Making Transactions | D44: =D39 -> 46113 | E44: =E39 -> 46143 | F44: =F39 -> 46174 | G44: =G39 -> 46204 | H44: =H39 -> 46235 | I44: =I39 -> 46266 | J44: =J39 -> 45931 | K44: =K39 -> 45962 | L44: 46296 | M44: 46327 | N44: =N39 -> 45992 | O44: =O39 -> 46023 | P44: =P39 -> 46054 | Q44: =Q39 -> 46082 | R44: =R39 -> FY 2026-27
...

Sheet Details
B3: Raw Data -AFR | F3: Purchase Details | U3: Logistic Details of the transaction | AF3: Debit Notes to Suppliers | AM3: Sales Details | BD3: DN to Customer | BH3: Credit Notes from Customers | BM3: -0.025 | BV3: CN & DN Checks | CE3: Without Provisions | CK3: Margin Buckets | CN3: Financials with GST
B4: Quarter | C4: Month | D4: Date | E4: Shipment ID | F4: Supplier Name | G4: GST Reg No. | H4: Vendor Invoice No. | I4: Vendor Invoice Date | J4: P V No. | K4: P V Date | L4: State (Origin) | M4: Vehicle No. | N4: Material | O4: Qty (Kg) | P4: Price/Kg | Q4: Purchase Price | R4: Return Qty | S4: Net Qty | T4: Basic Customs Duty | U4: Transporter Name | V4: LR NO/BILL NO | W4: J V No. | X4: JV Date | Y4: Logistics cost | Z4: Debit note on logistic cost | AA4: Logistics Provision | AB4: Total Logistics Cost | AC4: Opeartional Cost | AD4: Cost/Kg. | AE4: Divertion/Internal | AF4: Debit Note No. | AG4: Debit Note Date. | AH4: Debit Note No. 2 | AI4: Debit Note Date. 2 | AJ4: Full Debit Note | AK4: Actual Debit Note | AL4: Provision for DN | AM4: Total Cost | AN4: Inv. Date | AO4: Inv. No. | AP4: Customer ID | AQ4: Buyer Name | AR4: Buyer GST Number | AS4: Location (Origin) | AT4: Location (Destination) | AU4: State (Destination) | AV4: E-way Bill No | AW4: Qty(Kg) | AX4: Rate/Kg | AY4: Amount | AZ4: Qty Check | BA4: Return Qty | BB4: Net Qty | BC4: Divertion/Internal | BD4: Return Type | BE4: Date : DN to Buyer | BF4: DN to Buyer | BG4: Amount | BH4: Credit Note No:1 | BI4: CN Date. No:1 | BJ4: Credit Note No:2 | BK4: CN Date. No:2 | BL4: Full Credit Notes | BM4: Actual Credit Note | BN4: Provision for CN | BO4: Net Revenue | BP4: Margin | BQ4: Reamrks - Margin | BR4: Remarks | BS4: LMI @ Inception | BT4: Remarks @ Inception | BU4: Margin (%) | BV4: Margin Bucket | BW4: Total CN(Inc.Provisions) | BX4: Total DN(Inc.Provisions) | BY4: Check | BZ4: Actaul CN | CA4: Actual DN | CB4: Check | CC4: Material-Short Form | CD4: Supplier Type | CE4: Month | CF4: Cost | CG4: Revenue | CH4: Week No: | CI4: Category (Material) | CJ4: Broad Category | CK4: POC Name | CL4: Gross Margin | CM4: Recykal Margin | CN4: Net Margin | CO4: Sales | CP4: Purchases | CQ4: Credit Note | CR4: Debit Note | CS4: Margin | CT4: Bill Branch | CU4: Inv Branch | CV4: Vendor PAN No | CW4: Customer PAN No
B5: ="Q" & IF(ROUNDUP(MONTH(D5)/3,0)-1=0,4,ROUNDUP(MONTH(D5)/3,0)-1) -> Q1 | C5: =TEXT(AN5,"mmm-yy") -> Apr-26 | D5: 46120 | E5: SH04260801 | F5: SRI PRASANNA TRADERS | G5: 37ANHPG0363J1Z1 | H5: 2 | I5: 46120 | J5: 26-27/PUR/000242 | K5: 46120 | L5: AD | M5: AP39WE3236 | N5: Pyrolysis Char - Briquettes | O5: 19160 | P5: 11.5 | Q5: =O5*P5 -> 220340 | R5: 0 | S5: =O5-R5 -> 19160 | T5: 0 | U5: 0 | V5: 0 | W5: 0 | X5: 0 | Y5: 0 | Z5: 0 | AA5: 0 | AB5: =Y5+AA5+Z5 -> 0 | AC5: 0 | AD5: 0 | AE5: 0 | AF5: 36/AFR/27VC00012 | AG5: 46128 | AH5: 0 | AI5: 0 | AJ5: 0 | AK5: -115 | AL5: 0 | AM5: =Q5+AB5+AL5+AK5+AJ5+T5+AE5 -> 220225 | AN5: 46120 | AO5: 36/AFR/27IN00001 | AP5: 832139000056764186 | AQ5: MRF LIMITED (36) | AR5: 36AAACM4154G1ZO | AS5: Tadpatri,Andhra Pradesh,515455 | AT5: Sadashivpet | AU5: Telangana | AW5: 19160 | AX5: 14 | AY5: =AW5*AX5 -> 268240 | AZ5: =AW5=O5 -> TRUE | BA5: 0 | BB5: =AW5-BA5 -> 19160 | BC5: 0 | BD5: Regular | BE5: 0 | BF5: 0 | BG5: 0 | BH5: 36/AFR/27CN00012 | BI5: 46128 | BJ5: 0 | BK5: 0 | BL5: 0 | BM5: -140 | BN5: 0 | BO5: =AY5+BL5+BM5+BN5+BC5+BG5 -> 268100 | BP5: =BO5-AM5 -> 47875 | BQ5: =IF(BP5>=0,"Positive Margin","Negative Margin") -> Positive Margin | BR5: DN & CN Issued | BS5: =AY5-Y5-Q5-AA5-T5+BC5 -> 47900 | BT5: =IF(BS5<0, "Negative Margin at Inception", "Positive Margin at Inception") -> Positive Margin at Inception | BU5: =IFERROR(BP5/BO5,"0") -> 0.17857143 | BV5: =IF(BU5<1%,"Less Than 1%",IF(BU5>2%,"More than 2%",IF(BU5>=1%,"1% - 2%"))) -> More than 2% | BW5: =BM5+BN5 -> -140 | BX5: =AL5+AK5 -> -115 | BY5: =BW5-BX5 -> -25 | BZ5: =BM5 -> -140 | CA5: =AK5 -> -115 | CB5: =BZ5-CA5 -> -25 | CC5: Marketplace Purchases (AFR) | CD5: 0 | CE5: =TEXT(AN5,"mmm-yy") -> Apr-26 | CF5: =AM5-AL5-AA5 -> 220225 | CG5: =BO5-BN5 -> 268100 | CH5: =INT((D5- IF(MONTH(D5) >= 4, DATE(YEAR(D5), 4, 1), DATE(YEAR(D5)-1, 4, 1))) / 7) + 1 -> 2 | CI5: AFR | CJ5: AFR | CK5: 0 | CL5: =AY5-Q5 -> 47900 | CM5: =CL5-Y5+Z5 -> 47900 | CN5: =BO5-AM5 -> 47875 | CO5: =AY5*118% -> 316523.2 | CP5: =-Q5*118% -> -260001.2 | CQ5: =-BZ5*118% -> 165.2 | CR5: =-CA5*118% -> 135.7 | CS5: =SUM(CO5:CR5) -> 56822.9 | CT5: Telangana - HO | CU5: Telangana - HO | CV5: =MID(G5,3,10) -> ANHPG0363J | CW5: =MID(AR5,3,10) -> AAACM4154G
B6: ="Q" & IF(ROUNDUP(MONTH(D6)/3,0)-1=0,4,ROUNDUP(MONTH(D6)/3,0)-1) -> Q1 | C6: =TEXT(AN6,"mmm-yy") -> May-26 | D6: 46151 | E6: SH05260901 | F6: SRI PRASANNA TRADERS | G6: 37ANHPG0363J1Z1 | H6: 11 | I6: 46151 | J6: 26-27/PUR/001929 | K6: 46151 | L6: AD | M6: TG29T7657 | N6: Pyrolysis Char - Briquettes | O6: 17950 | P6: 11.5 | Q6: =O6*P6 -> 206425 | R6: 0 | S6: =O6-R6 -> 17950 | T6: 0 | U6: 0 | V6: 0 | W6: 0 | X6: 0 | Y6: 0 | Z6: 0 | AA6: 0 | AB6: =Y6+AA6+Z6 -> 0 | AC6: 0 | AD6: 0 | AE6: 0 | AF6: 36/AFR/27VC00013 | AG6: 46168 | AH6: 0 | AI6: 0 | AJ6: 0 | AK6: -460 | AL6: 0 | AM6: =Q6+AB6+AL6+AK6+AJ6+T6+AE6 -> 205965 | AN6: 46151 | AO6: 36/AFR/27IN00002 | AP6: 832139000056764186 | AQ6: MRF LIMITED (36) | AR6: 36AAACM4154G1ZO | AS6: Proddatur Andhra Pradesh 516360 | AT6: Sadashivpet | AU6: Telangana | AW6: 17950 | AX6: 14 | AY6: =AW6*AX6 -> 251300 | AZ6: =AW6=O6 -> TRUE | BA6: 0 | BB6: =AW6-BA6 -> 17950 | BC6: 0 | BD6: Regular | BE6: 0 | BF6: 0 | BG6: 0 | BH6: 36/AFR/27CN00013 | BI6: 46168 | BJ6: 0 | BK6: 0 | BL6: 0 | BM6: -560 | BN6: 0 | BO6: =AY6+BL6+BM6+BN6+BC6+BG6 -> 250740 | BP6: =BO6-AM6 -> 44775 | BQ6: =IF(BP6>=0,"Positive Margin","Negative Margin") -> Positive Margin | BR6: DN & CN Issued | BS6: =AY6-Y6-Q6-AA6-T6+BC6 -> 44875 | BT6: =IF(BS6<0, "Negative Margin at Inception", "Positive Margin at Inception") -> Positive Margin at Inception | BU6: =IFERROR(BP6/BO6,"0") -> 0.17857143 | BV6: =IF(BU6<1%,"Less Than 1%",IF(BU6>2%,"More than 2%",IF(BU6>=1%,"1% - 2%"))) -> More than 2% | BW6: =BM6+BN6 -> -560 | BX6: =AL6+AK6 -> -460 | BY6: =BW6-BX6 -> -100 | BZ6: =BM6 -> -560 | CA6: =AK6 -> -460 | CB6: =BZ6-CA6 -> -100 | CC6: Marketplace Purchases (AFR) | CD6: 0 | CE6: =TEXT(AN6,"mmm-yy") -> May-26 | CF6: =AM6-AL6-AA6 -> 205965 | CG6: =BO6-BN6 -> 250740 | CH6: =INT((D6- IF(MONTH(D6) >= 4, DATE(YEAR(D6), 4, 1), DATE(YEAR(D6)-1, 4, 1))) / 7) + 1 -> 6 | CI6: AFR | CJ6: AFR | CK6: 0 | CL6: =AY6-Q6 -> 44875 | CM6: =CL6-Y6+Z6 -> 44875 | CN6: =BO6-AM6 -> 44775 | CO6: =AY6*118% -> 296534 | CP6: =-Q6*118% -> -243581.5 | CQ6: =-BZ6*118% -> 660.8 | CR6: =-CA6*118% -> 542.8 | CS6: =SUM(CO6:CR6) -> 54156.1 | CT6: Telangana - HO | CU6: Telangana - HO | CV6: =MID(G6,3,10) -> ANHPG0363J | CW6: =MID(AR6,3,10) -> AAACM4154G
B7: ="Q" & IF(ROUNDUP(MONTH(D7)/3,0)-1=0,4,ROUNDUP(MONTH(D7)/3,0)-1) -> Q1 | C7: =TEXT(AN7,"mmm-yy") -> May-26 | D7: 46155 | E7: SH05261303 | F7: SRI PRASANNA TRADERS | G7: 37ANHPG0363J1Z1 | H7: 13 | I7: 46155 | J7: 26-27/PUR/002090 | K7: 46155 | L7: AD | M7: AP39WL0468 | N7: Pyrolysis Char - Briquettes | O7: 23980 | P7: 12 | Q7: =O7*P7 -> 287760 | R7: 0 | S7: =O7-R7 -> 23980 | T7: 0 | U7: 0 | V7: 0 | W7: 0 | X7: 0 | Y7: 0 | Z7: 0 | AA7: 0 | AB7: =Y7+AA7+Z7 -> 0 | AC7: 0 | AD7: 0 | AE7: 0 | AF7: 0 | AG7: 0 | AH7: 0 | AI7: 0 | AJ7: 0 | AK7: 0 | AL7: 0 | AM7: =Q7+AB7+AL7+AK7+AJ7+T7+AE7 -> 287760 | AN7: 46155 | AO7: 36/AFR/27IN00003 | AP7: 832139000056764186 | AQ7: MRF LIMITED (36) | AR7: 36AAACM4154G1ZO | AS7: Tadipatri,Andhra Pradesh,515413 | AT7: Sadashivpet | AU7: Telangana | AW7: 23980 | AX7: 12.66 | AY7: =AW7*AX7 -> 303586.8 | AZ7: =AW7=O7 -> TRUE | BA7: 0 | BB7: =AW7-BA7 -> 23980 | BC7: 0 | BD7: Regular | BE7: 0 | BF7: 0 | BG7: 0 | BH7: 0 | BI7: 0 | BJ7: 0 | BK7: 0 | BL7: 0 | BM7: 0 | BN7: 0 | BO7: =AY7+BL7+BM7+BN7+BC7+BG7 -> 303586.8 | BP7: =BO7-AM7 -> 15826.8 | BQ7: =IF(BP7>=0,"Positive Margin","Negative Margin") -> Positive Margin | BR7: No DN | BS7: =AY7-Y7-Q7-AA7-T7+BC7 -> 15826.8 | BT7: =IF(BS7<0, "Negative Margin at Inception", "Positive Margin at Inception") -> Positive Margin at Inception | BU7: =IFERROR(BP7/BO7,"0") -> 0.052132701 | BV7: =IF(BU7<1%,"Less Than 1%",IF(BU7>2%,"More than 2%",IF(BU7>=1%,"1% - 2%"))) -> More than 2% | BW7: =BM7+BN7 -> 0 | BX7: =AL7+AK7 -> 0 | BY7: =BW7-BX7 -> 0 | BZ7: =BM7 -> 0 | CA7: =AK7 -> 0 | CB7: =BZ7-CA7 -> 0 | CC7: Marketplace Purchases (AFR) | CD7: 0 | CE7: =TEXT(AN7,"mmm-yy") -> May-26 | CF7: =AM7-AL7-AA7 -> 287760 | CG7: =BO7-BN7 -> 303586.8 | CH7: =INT((D7- IF(MONTH(D7) >= 4, DATE(YEAR(D7), 4, 1), DATE(YEAR(D7)-1, 4, 1))) / 7) + 1 -> 7 | CI7: AFR | CJ7: AFR | CK7: 0 | CL7: =AY7-Q7 -> 15826.8 | CM7: =CL7-Y7+Z7 -> 15826.8 | CN7: =BO7-AM7 -> 15826.8 | CO7: =AY7*118% -> 358232.42 | CP7: =-Q7*118% -> -339556.8 | CQ7: =-BZ7*118% -> 0 | CR7: =-CA7*118% -> 0 | CS7: =SUM(CO7:CR7) -> 18675.624 | CT7: Telangana - HO | CU7: Telangana - HO | CV7: =MID(G7,3,10) -> ANHPG0363J | CW7: =MID(AR7,3,10) -> AAACM4154G
B8: ="Q" & IF(ROUNDUP(MONTH(D8)/3,0)-1=0,4,ROUNDUP(MONTH(D8)/3,0)-1) -> Q1 | C8: =TEXT(AN8,"mmm-yy") -> May-26 | D8: 46168 | E8: SH05262501 | F8: SRI PRASANNA TRADERS | G8: 37ANHPG0363J1Z1 | H8: 19 | I8: 46168 | J8: 26-27/PUR/002617 | K8: 46168 | L8: AD | M8: AP39WR1641 | N8: Pyrolysis Char - Briquettes | O8: 13870 | P8: 12 | Q8: =O8*P8 -> 166440 | R8: 0 | S8: =O8-R8 -> 13870 | T8: 0 | U8: 0 | V8: 0 | W8: 0 | X8: 0 | Y8: 0 | Z8: 0 | AA8: 0 | AB8: =Y8+AA8+Z8 -> 0 | AC8: 0 | AD8: 0 | AE8: 0 | AF8: 0 | AG8: 0 | AH8: 0 | AI8: 0 | AJ8: 0 | AK8: 0 | AL8: 0 | AM8: =Q8+AB8+AL8+AK8+AJ8+T8+AE8 -> 166440 | AN8: 46168 | AO8: 36/AFR/27IN00004 | AP8: 832139000056764186 | AQ8: MRF LIMITED (36) | AR8: 36AAACM4154G1ZO | AS8: Proddatur Andhra Pradesh 516360 | AT8: Sadashivpet | AU8: Telangana | AW8: 13870 | AX8: 12.66 | AY8: =AW8*AX8 -> 175594.2 | AZ8: =AW8=O8 -> TRUE | BA8: 0 | BB8: =AW8-BA8 -> 13870 | BC8: 0 | BD8: Regular | BE8: 0 | BF8: 0 | BG8: 0 | BH8: 0 | BI8: 0 | BJ8: 0 | BK8: 0 | BL8: 0 | BM8: 0 | BN8: 0 | BO8: =AY8+BL8+BM8+BN8+BC8+BG8 -> 175594.2 | BP8: =BO8-AM8 -> 9154.2 | BQ8: =IF(BP8>=0,"Positive Margin","Negative Margin") -> Positive Margin | BR8: No DN | BS8: =AY8-Y8-Q8-AA8-T8+BC8 -> 9154.2 | BT8: =IF(BS8<0, "Negative Margin at Inception", "Positive Margin at Inception") -> Positive Margin at Inception | BU8: =IFERROR(BP8/BO8,"0") -> 0.052132701 | BV8: =IF(BU8<1%,"Less Than 1%",IF(BU8>2%,"More than 2%",IF(BU8>=1%,"1% - 2%"))) -> More than 2% | BW8: =BM8+BN8 -> 0 | BX8: =AL8+AK8 -> 0 | BY8: =BW8-BX8 -> 0 | BZ8: =BM8 -> 0 | CA8: =AK8 -> 0 | CB8: =BZ8-CA8 -> 0 | CC8: Marketplace Purchases (AFR) | CD8: 0 | CE8: =TEXT(AN8,"mmm-yy") -> May-26 | CF8: =AM8-AL8-AA8 -> 166440 | CG8: =BO8-BN8 -> 175594.2 | CH8: =INT((D8- IF(MONTH(D8) >= 4, DATE(YEAR(D8), 4, 1), DATE(YEAR(D8)-1, 4, 1))) / 7) + 1 -> 8 | CI8: AFR | CJ8: AFR | CK8: 0 | CL8: =AY8-Q8 -> 9154.2 | CM8: =CL8-Y8+Z8 -> 9154.2 | CN8: =BO8-AM8 -> 9154.2 | CO8: =AY8*118% -> 207201.16 | CP8: =-Q8*118% -> -196399.2 | CQ8: =-BZ8*118% -> 0 | CR8: =-CA8*118% -> 0 | CS8: =SUM(CO8:CR8) -> 10801.956 | CT8: Telangana - HO | CU8: Telangana - HO | CV8: =MID(G8,3,10) -> ANHPG0363J | CW8: =MID(AR8,3,10) -> AAACM4154G
B9: ="Q" & IF(ROUNDUP(MONTH(D9)/3,0)-1=0,4,ROUNDUP(MONTH(D9)/3,0)-1) -> Q1 | C9: =TEXT(AN9,"mmm-yy") -> Jun-26 | D9: 46174 | E9: SH05262704 | F9: SRI RAGHAVENDRA CORPORATION | G9: 37AGCPV7437N2ZK | H9: INV-26-800 | I9: 46174 | J9: 26-27/PUR/003034 | K9: 46174 | L9: AD | M9: AP27Y5049 | N9: Chilli Husk | O9: 11960 | P9: 3.4 | Q9: =O9*P9 -> 40664 | R9: 0 | S9: =O9-R9 -> 11960 | T9: 0 | U9: 0 | V9: 0 | W9: 0 | X9: 0 | Y9: 0 | Z9: 0 | AA9: 0 | AB9: =Y9+AA9+Z9 -> 0 | AC9: 0 | AD9: 0 | AE9: 0 | AF9: 0 | AG9: 0 | AH9: 0 | AI9: 0 | AJ9: 0 | AK9: 0 | AL9: 0 | AM9: =Q9+AB9+AL9+AK9+AJ9+T9+AE9 -> 40664 | AN9: 46174 | AO9: 36/AFR/27IN00005 | AP9: 832139000078794413 | AQ9: ULTRATECH CEMENT LIMITED | AR9: 37AAACL6442L1Z9 | AS9: Guntur,Andhra Pradesh,522005 | AT9: Vijayawada | AU9: Andhra Pradesh | AW9: 11960 | AX9: 3.7 | AY9: =AW9*AX9 -> 44252 | AZ9: =AW9=O9 -> TRUE | BA9: 0 | BB9: =AW9-BA9 -> 11960 | BC9: 0 | BD9: Regular | BE9: 0 | BF9: 0 | BG9: 0 | BH9: 0 | BI9: 0 | BJ9: 0 | BK9: 0 | BL9: 0 | BM9: 0 | BN9: 0 | BO9: =AY9+BL9+BM9+BN9+BC9+BG9 -> 44252 | BP9: =BO9-AM9 -> 3588 | BQ9: =IF(BP9>=0,"Positive Margin","Negative Margin") -> Positive Margin | BR9: No Provision | BS9: =AY9-Y9-Q9-AA9-T9+BC9 -> 3588 | BT9: =IF(BS9<0, "Negative Margin at Inception", "Positive Margin at Inception") -> Positive Margin at Inception | BU9: =IFERROR(BP9/BO9,"0") -> 0.081081081 | BV9: =IF(BU9<1%,"Less Than 1%",IF(BU9>2%,"More than 2%",IF(BU9>=1%,"1% - 2%"))) -> More than 2% | BW9: =BM9+BN9 -> 0 | BX9: =AL9+AK9 -> 0 | BY9: =BW9-BX9 -> 0 | BZ9: =BM9 -> 0 | CA9: =AK9 -> 0 | CB9: =BZ9-CA9 -> 0 | CC9: Marketplace Purchases (AFR) | CD9: 0 | CE9: =TEXT(AN9,"mmm-yy") -> Jun-26 | CF9: =AM9-AL9-AA9 -> 40664 | CG9: =BO9-BN9 -> 44252 | CH9: =INT((D9- IF(MONTH(D9) >= 4, DATE(YEAR(D9), 4, 1), DATE(YEAR(D9)-1, 4, 1))) / 7) + 1 -> 9 | CI9: AFR | CJ9: AFR | CK9: 0 | CL9: =AY9-Q9 -> 3588 | CM9: =CL9-Y9+Z9 -> 3588 | CN9: =BO9-AM9 -> 3588 | CO9: =AY9*118% -> 52217.36 | CP9: =-Q9*118% -> -47983.52 | CQ9: =-BZ9*118% -> 0 | CR9: =-CA9*118% -> 0 | CS9: =SUM(CO9:CR9) -> 4233.84 | CT9: Telangana - HO | CU9: Telangana - HO | CV9: =MID(G9,3,10) -> AGCPV7437N | CW9: =MID(AR9,3,10) -> AAACL6442L
B10: ="Q" & IF(ROUNDUP(MONTH(D10)/3,0)-1=0,4,ROUNDUP(MONTH(D10)/3,0)-1) -> Q1 | C10: =TEXT(AN10,"mmm-yy") -> Jun-26 | D10: 46176 | E10: SH06260301 | F10: SRI RAGHAVENDRA CORPORATION | G10: 37AGCPV7437N2ZK | H10: INV-26-802 | I10: 46176 | J10: 26-27/PUR/003224 | K10: 46176 | L10: AD | M10: TS12UD3174 | N10: Chilli Husk | O10: 12010 | P10: 3.4 | Q10: =O10*P10 -> 40834 | R10: 0 | S10: =O10-R10 -> 12010 | T10: 0 | U10: 0 | V10: 0 | W10: 0 | X10: 0 | Y10: 0 | Z10: 0 | AA10: 0 | AB10: =Y10+AA10+Z10 -> 0 | AC10: 0 | AD10: 0 | AE10: 0 | AF10: 0 | AG10: 0 | AH10: 0 | AI10: 0 | AJ10: 0 | AK10: 0 | AL10: 0 | AM10: =Q10+AB10+AL10+AK10+AJ10+T10+AE10 -> 40834 | AN10: 46176 | AO10: 36/AFR/27IN00006 | AP10: 832139000078794413 | AQ10: ULTRATECH CEMENT LIMITED | AR10: 37AAACL6442L1Z9 | AS10: Guntur Andhra Pradesh 522005 | AT10: Vijayawada | AU10: Andhra Pradesh | AW10: 12010 | AX10: 3.7 | AY10: =AW10*AX10 -> 44437 | AZ10: =AW10=O10 -> TRUE | BA10: 0 | BB10: =AW10-BA10 -> 12010 | BC10: 0 | BD10: Regular | BE10: 0 | BF10: 0 | BG10: 0 | BH10: 0 | BI10: 0 | BJ10: 0 | BK10: 0 | BL10: 0 | BM10: 0 | BN10: 0 | BO10: =AY10+BL10+BM10+BN10+BC10+BG10 -> 44437 | BP10: =BO10-AM10 -> 3603 | BQ10: =IF(BP10>=0,"Positive Margin","Negative Margin") -> Positive Margin | BR10: No Provision | BS10: =AY10-Y10-Q10-AA10-T10+BC10 -> 3603 | BT10: =IF(BS10<0, "Negative Margin at Inception", "Positive Margin at Inception") -> Positive Margin at Inception | BU10: =IFERROR(BP10/BO10,"0") -> 0.081081081 | BV10: =IF(BU10<1%,"Less Than 1%",IF(BU10>2%,"More than 2%",IF(BU10>=1%,"1% - 2%"))) -> More than 2% | BW10: =BM10+BN10 -> 0 | BX10: =AL10+AK10 -> 0 | BY10: =BW10-BX10 -> 0 | BZ10: =BM10 -> 0 | CA10: =AK10 -> 0 | CB10: =BZ10-CA10 -> 0 | CC10: Marketplace Purchases (AFR) | CD10: 0 | CE10: =TEXT(AN10,"mmm-yy") -> Jun-26 | CF10: =AM10-AL10-AA10 -> 40834 | CG10: =BO10-BN10 -> 44437 | CH10: =INT((D10- IF(MONTH(D10) >= 4, DATE(YEAR(D10), 4, 1), DATE(YEAR(D10)-1, 4, 1))) / 7) + 1 -> 10 | CI10: AFR | CJ10: AFR | CK10: 0 | CL10: =AY10-Q10 -> 3603 | CM10: =CL10-Y10+Z10 -> 3603 | CN10: =BO10-AM10 -> 3603 | CO10: =AY10*118% -> 52435.66 | CP10: =-Q10*118% -> -48184.12 | CQ10: =-BZ10*118% -> 0 | CR10: =-CA10*118% -> 0 | CS10: =SUM(CO10:CR10) -> 4251.54 | CT10: Telangana - HO | CU10: Telangana - HO | CV10: =MID(G10,3,10) -> AGCPV7437N | CW10: =MID(AR10,3,10) -> AAACL6442L
B11: ="Q" & IF(ROUNDUP(MONTH(D11)/3,0)-1=0,4,ROUNDUP(MONTH(D11)/3,0)-1) -> Q1 | C11: =TEXT(AN11,"mmm-yy") -> Jun-26 | D11: 46176 | E11: SH06260302 | F11: SRI RAGHAVENDRA CORPORATION | G11: 37AGCPV7437N2ZK | H11: INV-26-801 | I11: 46176 | J11: 26-27/PUR/003226 | K11: 46176 | L11: AD | M11: TG05U6911 | N11: Chilli Husk | O11: 12015 | P11: 3.4 | Q11: =O11*P11 -> 40851 | R11: 0 | S11: =O11-R11 -> 12015 | T11: 0 | U11: 0 | V11: 0 | W11: 0 | X11: 0 | Y11: 0 | Z11: 0 | AA11: 0 | AB11: =Y11+AA11+Z11 -> 0 | AC11: 0 | AD11: 0 | AE11: 0 | AF11: 0 | AG11: 0 | AH11: 0 | AI11: 0 | AJ11: 0 | AK11: 0 | AL11: 0 | AM11: =Q11+AB11+AL11+AK11+AJ11+T11+AE11 -> 40851 | AN11: 46176 | AO11: 36/AFR/27IN00007 | AP11: 832139000078794413 | AQ11: ULTRATECH CEMENT LIMITED | AR11: 37AAACL6442L1Z9 | AS11: Guntur,Andhra Pradesh,522005 | AT11: Vijayawada | AU11: Andhra Pradesh | AW11: 12015 | AX11: 3.7 | AY11: =AW11*AX11 -> 44455.5 | AZ11: =AW11=O11 -> TRUE | BA11: 0 | BB11: =AW11-BA11 -> 12015 | BC11: 0 | BD11: Regular | BE11: 0 | BF11: 0 | BG11: 0 | BH11: 0 | BI11: 0 | BJ11: 0 | BK11: 0 | BL11: 0 | BM11: 0 | BN11: 0 | BO11: =AY11+BL11+BM11+BN11+BC11+BG11 -> 44455.5 | BP11: =BO11-AM11 -> 3604.5 | BQ11: =IF(BP11>=0,"Positive Margin","Negative Margin") -> Positive Margin | BR11: No Provision | BS11: =AY11-Y11-Q11-AA11-T11+BC11 -> 3604.5 | BT11: =IF(BS11<0, "Negative Margin at Inception", "Positive Margin at Inception") -> Positive Margin at Inception | BU11: =IFERROR(BP11/BO11,"0") -> 0.081081081 | BV11: =IF(BU11<1%,"Less Than 1%",IF(BU11>2%,"More than 2%",IF(BU11>=1%,"1% - 2%"))) -> More than 2% | BW11: =BM11+BN11 -> 0 | BX11: =AL11+AK11 -> 0 | BY11: =BW11-BX11 -> 0 | BZ11: =BM11 -> 0 | CA11: =AK11 -> 0 | CB11: =BZ11-CA11 -> 0 | CC11: Marketplace Purchases (AFR) | CD11: 0 | CE11: =TEXT(AN11,"mmm-yy") -> Jun-26 | CF11: =AM11-AL11-AA11 -> 40851 | CG11: =BO11-BN11 -> 44455.5 | CH11: =INT((D11- IF(MONTH(D11) >= 4, DATE(YEAR(D11), 4, 1), DATE(YEAR(D11)-1, 4, 1))) / 7) + 1 -> 10 | CI11: AFR | CJ11: AFR | CK11: 0 | CL11: =AY11-Q11 -> 3604.5 | CM11: =CL11-Y11+Z11 -> 3604.5 | CN11: =BO11-AM11 -> 3604.5 | CO11: =AY11*118% -> 52457.49 | CP11: =-Q11*118% -> -48204.18 | CQ11: =-BZ11*118% -> 0 | CR11: =-CA11*118% -> 0 | CS11: =SUM(CO11:CR11) -> 4253.31 | CT11: Telangana - HO | CU11: Telangana - HO | CV11: =MID(G11,3,10) -> AGCPV7437N | CW11: =MID(AR11,3,10) -> AAACL6442L
B12: ="Q" & IF(ROUNDUP(MONTH(D12)/3,0)-1=0,4,ROUNDUP(MONTH(D12)/3,0)-1) -> Q1 | C12: =TEXT(AN12,"mmm-yy") -> Jun-26 | D12: 46177 | E12: SH06260402 | F12: SRI PRASANNA TRADERS | G12: 37ANHPG0363J1Z1 | H12: 25 | I12: 46177 | J12: 26-27/PUR/003277 | K12: 46177 | L12: AD | M12: AP02TH1557 | N12: Pyrolysis Char - Briquettes | O12: 10380 | P12: 12 | Q12: =O12*P12 -> 124560 | R12: 0 | S12: =O12-R12 -> 10380 | T12: 0 | U12: 0 | V12: 0 | W12: 0 | X12: 0 | Y12: 0 | Z12: 0 | AA12: 0 | AB12: =Y12+AA12+Z12 -> 0 | AC12: 0 | AD12: 0 | AE12: 0 | AF12: 0 | AG12: 0 | AH12: 0 | AI12: 0 | AJ12: 0 | AK12: 0 | AL12: 0 | AM12: =Q12+AB12+AL12+AK12+AJ12+T12+AE12 -> 124560 | AN12: 46177 | AO12: 36/AFR/27IN00008 | AP12: 832139000056764186 | AQ12: MRF LIMITED (36) | AR12: 36AAACM4154G1ZO | AS12: Proddatur Andhra Pradesh 516360 | AT12: Sadashivpet | AU12: Telangana | AW12: 10380 | AX12: 12.66 | AY12: =AW12*AX12 -> 131410.8 | AZ12: =AW12=O12 -> TRUE | BA12: 0 | BB12: =AW12-BA12 -> 10380 | BC12: 0 | BD12: Regular | BE12: 0 | BF12: 0 | BG12: 0 | BH12: 0 | BI12: 0 | BJ12: 0 | BK12: 0 | BL12: 0 | BM12: 0 | BN12: 0 | BO12: =AY12+BL12+BM12+BN12+BC12+BG12 -> 131410.8 | BP12: =BO12-AM12 -> 6850.8 | BQ12: =IF(BP12>=0,"Positive Margin","Negative Margin") -> Positive Margin | BR12: No Provision | BS12: =AY12-Y12-Q12-AA12-T12+BC12 -> 6850.8 | BT12: =IF(BS12<0, "Negative Margin at Inception", "Positive Margin at Inception") -> Positive Margin at Inception | BU12: =IFERROR(BP12/BO12,"0") -> 0.052132701 | BV12: =IF(BU12<1%,"Less Than 1%",IF(BU12>2%,"More than 2%",IF(BU12>=1%,"1% - 2%"))) -> More than 2% | BW12: =BM12+BN12 -> 0 | BX12: =AL12+AK12 -> 0 | BY12: =BW12-BX12 -> 0 | BZ12: =BM12 -> 0 | CA12: =AK12 -> 0 | CB12: =BZ12-CA12 -> 0 | CC12: Marketplace Purchases (AFR) | CD12: 0 | CE12: =TEXT(AN12,"mmm-yy") -> Jun-26 | CF12: =AM12-AL12-AA12 -> 124560 | CG12: =BO12-BN12 -> 131410.8 | CH12: =INT((D12- IF(MONTH(D12) >= 4, DATE(YEAR(D12), 4, 1), DATE(YEAR(D12)-1, 4, 1))) / 7) + 1 -> 10 | CI12: AFR | CJ12: AFR | CK12: 0 | CL12: =AY12-Q12 -> 6850.8 | CM12: =CL12-Y12+Z12 -> 6850.8 | CN12: =BO12-AM12 -> 6850.8 | CO12: =AY12*118% -> 155064.74 | CP12: =-Q12*118% -> -146980.8 | CQ12: =-BZ12*118% -> 0 | CR12: =-CA12*118% -> 0 | CS12: =SUM(CO12:CR12) -> 8083.944 | CT12: Telangana - HO | CU12: Telangana - HO | CV12: =MID(G12,3,10) -> ANHPG0363J | CW12: =MID(AR12,3,10) -> AAACM4154G
B13: ="Q" & IF(ROUNDUP(MONTH(D13)/3,0)-1=0,4,ROUNDUP(MONTH(D13)/3,0)-1) -> Q1 | C13: =TEXT(AN13,"mmm-yy") -> Jun-26 | D13: 46180 | E13: SH06260602 | F13: SRI PRASANNA TRADERS | G13: 37ANHPG0363J1Z1 | H13: 26 | I13: 46180 | J13: 26-27/PUR/003302 | K13: 46180 | L13: AD | M13: AP39UL9769 | N13: Pyrolysis Char - Briquettes | O13: 14380 | P13: 12 | Q13: =O13*P13 -> 172560 | R13: 0 | S13: =O13-R13 -> 14380 | T13: 0 | U13: 0 | V13: 0 | W13: 0 | X13: 0 | Y13: 0 | Z13: 0 | AA13: 0 | AB13: =Y13+AA13+Z13 -> 0 | AC13: 0 | AD13: 0 | AE13: 0 | AF13: 0 | AG13: 0 | AH13: 0 | AI13: 0 | AJ13: 0 | AK13: 0 | AL13: 0 | AM13: =Q13+AB13+AL13+AK13+AJ13+T13+AE13 -> 172560 | AN13: 46180 | AO13: 36/AFR/27IN00009 | AP13: 832139000056764186 | AQ13: MRF LIMITED (36) | AR13: 36AAACM4154G1ZO | AS13: Proddatur Andhra Pradesh 516360 | AT13: Sadashivpet | AU13: Telangana | AW13: 14380 | AX13: 12.66 | AY13: =AW13*AX13 -> 182050.8 | AZ13: =AW13=O13 -> TRUE | BA13: 0 | BB13: =AW13-BA13 -> 14380 | BC13: 0 | BD13: Regular | BE13: 0 | BF13: 0 | BG13: 0 | BH13: 0 | BI13: 0 | BJ13: 0 | BK13: 0 | BL13: 0 | BM13: 0 | BN13: 0 | BO13: =AY13+BL13+BM13+BN13+BC13+BG13 -> 182050.8 | BP13: =BO13-AM13 -> 9490.8 | BQ13: =IF(BP13>=0,"Positive Margin","Negative Margin") -> Positive Margin | BR13: No Provision | BS13: =AY13-Y13-Q13-AA13-T13+BC13 -> 9490.8 | BT13: =IF(BS13<0, "Negative Margin at Inception", "Positive Margin at Inception") -> Positive Margin at Inception | BU13: =IFERROR(BP13/BO13,"0") -> 0.052132701 | BV13: =IF(BU13<1%,"Less Than 1%",IF(BU13>2%,"More than 2%",IF(BU13>=1%,"1% - 2%"))) -> More than 2% | BW13: =BM13+BN13 -> 0 | BX13: =AL13+AK13 -> 0 | BY13: =BW13-BX13 -> 0 | BZ13: =BM13 -> 0 | CA13: =AK13 -> 0 | CB13: =BZ13-CA13 -> 0 | CC13: Marketplace Purchases (AFR) | CD13: 0 | CE13: =TEXT(AN13,"mmm-yy") -> Jun-26 | CF13: =AM13-AL13-AA13 -> 172560 | CG13: =BO13-BN13 -> 182050.8 | CH13: =INT((D13- IF(MONTH(D13) >= 4, DATE(YEAR(D13), 4, 1), DATE(YEAR(D13)-1, 4, 1))) / 7) + 1 -> 10 | CI13: AFR | CJ13: AFR | CK13: 0 | CL13: =AY13-Q13 -> 9490.8 | CM13: =CL13-Y13+Z13 -> 9490.8 | CN13: =BO13-AM13 -> 9490.8 | CO13: =AY13*118% -> 214819.94 | CP13: =-Q13*118% -> -203620.8 | CQ13: =-BZ13*118% -> 0 | CR13: =-CA13*118% -> 0 | CS13: =SUM(CO13:CR13) -> 11199.144 | CT13: Telangana - HO | CU13: Telangana - HO | CV13: =MID(G13,3,10) -> ANHPG0363J | CW13: =MID(AR13,3,10) -> AAACM4154G
B14: ="Q" & IF(ROUNDUP(MONTH(D14)/3,0)-1=0,4,ROUNDUP(MONTH(D14)/3,0)-1) -> Q1 | C14: =TEXT(AN14,"mmm-yy") -> Jun-26 | D14: 46181 | E14: SH06260701 | F14: SRI RAGHAVENDRA CORPORATION | G14: 37AGCPV7437N2ZK | H14: INV-26-803 | I14: 46181 | J14: 26-27/PUR/003308 | K14: 46181 | L14: AD | M14: TG04T7342 | N14: Chilli Husk | O14: 8815 | P14: 3.4 | Q14: =O14*P14 -> 29971 | R14: 0 | S14: =O14-R14 -> 8815 | T14: 0 | U14: 0 | V14: 0 | W14: 0 | X14: 0 | Y14: 0 | Z14: 0 | AA14: 0 | AB14: =Y14+AA14+Z14 -> 0 | AC14: 0 | AD14: 0 | AE14: 0 | AF14: 0 | AG14: 0 | AH14: 0 | AI14: 0 | AJ14: 0 | AK14: 0 | AL14: 0 | AM14: =Q14+AB14+AL14+AK14+AJ14+T14+AE14 -> 29971 | AN14: 46181 | AO14: 36/AFR/27IN00010 | AP14: 832139000078794413 | AQ14: ULTRATECH CEMENT LIMITED | AR14: 37AAACL6442L1Z9 | AS14: Guntur,Andhra Pradesh,522005 | AT14: Vijayawada | AU14: Andhra Pradesh | AW14: 8815 | AX14: 3.7 | AY14: =AW14*AX14 -> 32615.5 | AZ14: =AW14=O14 -> TRUE | BA14: 0 | BB14: =AW14-BA14 -> 8815 | BC14: 0 | BD14: Regular | BE14: 0 | BF14: 0 | BG14: 0 | BH14: 0 | BI14: 0 | BJ14: 0 | BK14: 0 | BL14: 0 | BM14: 0 | BN14: 0 | BO14: =AY14+BL14+BM14+BN14+BC14+BG14 -> 32615.5 | BP14: =BO14-AM14 -> 2644.5 | BQ14: =IF(BP14>=0,"Positive Margin","Negative Margin") -> Positive Margin | BR14: No Provision | BS14: =AY14-Y14-Q14-AA14-T14+BC14 -> 2644.5 | BT14: =IF(BS14<0, "Negative Margin at Inception", "Positive Margin at Inception") -> Positive Margin at Inception | BU14: =IFERROR(BP14/BO14,"0") -> 0.081081081 | BV14: =IF(BU14<1%,"Less Than 1%",IF(BU14>2%,"More than 2%",IF(BU14>=1%,"1% - 2%"))) -> More than 2% | BW14: =BM14+BN14 -> 0 | BX14: =AL14+AK14 -> 0 | BY14: =BW14-BX14 -> 0 | BZ14: =BM14 -> 0 | CA14: =AK14 -> 0 | CB14: =BZ14-CA14 -> 0 | CC14: Marketplace Purchases (AFR) | CD14: 0 | CE14: =TEXT(AN14,"mmm-yy") -> Jun-26 | CF14: =AM14-AL14-AA14 -> 29971 | CG14: =BO14-BN14 -> 32615.5 | CH14: =INT((D14- IF(MONTH(D14) >= 4, DATE(YEAR(D14), 4, 1), DATE(YEAR(D14)-1, 4, 1))) / 7) + 1 -> 10 | CI14: AFR | CJ14: AFR | CK14: 0 | CL14: =AY14-Q14 -> 2644.5 | CM14: =CL14-Y14+Z14 -> 2644.5 | CN14: =BO14-AM14 -> 2644.5 | CO14: =AY14*118% -> 38486.29 | CP14: =-Q14*118% -> -35365.78 | CQ14: =-BZ14*118% -> 0 | CR14: =-CA14*118% -> 0 | CS14: =SUM(CO14:CR14) -> 3120.51 | CT14: Telangana - HO | CU14: Telangana - HO | CV14: =MID(G14,3,10) -> AGCPV7437N | CW14: =MID(AR14,3,10) -> AAACL6442L
B15: ="Q" & IF(ROUNDUP(MONTH(D15)/3,0)-1=0,4,ROUNDUP(MONTH(D15)/3,0)-1) -> Q1 | C15: =TEXT(AN15,"mmm-yy") -> Jun-26 | D15: 46181 | E15: SH06260802 | F15: SRI PRASANNA TRADERS | G15: 37ANHPG0363J1Z1 | H15: 27 | I15: 46181 | J15: 26-27/PUR/003337 | K15: 46181 | L15: AD | M15: AP39UV4495 | N15: Pyrolysis Char - Briquettes | O15: 13000 | P15: 12 | Q15: =O15*P15 -> 156000 | R15: 0 | S15: =O15-R15 -> 13000 | T15: 0 | U15: 0 | V15: 0 | W15: 0 | X15: 0 | Y15: 0 | Z15: 0 | AA15: 0 | AB15: =Y15+AA15+Z15 -> 0 | AC15: 0 | AD15: 0 | AE15: 0 | AF15: 0 | AG15: 0 | AH15: 0 | AI15: 0 | AJ15: 0 | AK15: 0 | AL15: 0 | AM15: =Q15+AB15+AL15+AK15+AJ15+T15+AE15 -> 156000 | AN15: 46181 | AO15: 36/AFR/27IN00011 | AP15: 832139000056764186 | AQ15: MRF LIMITED (36) | AR15: 36AAACM4154G1ZO | AS15: Proddatur Andhra Pradesh 516360 | AT15: Sadashivpet | AU15: Telangana | AW15: 13000 | AX15: 12.66 | AY15: =AW15*AX15 -> 164580 | AZ15: =AW15=O15 -> TRUE | BA15: 0 | BB15: =AW15-BA15 -> 13000 | BC15: 0 | BD15: Regular | BE15: 0 | BF15: 0 | BG15: 0 | BH15: 0 | BI15: 0 | BJ15: 0 | BK15: 0 | BL15: 0 | BM15: 0 | BN15: 0 | BO15: =AY15+BL15+BM15+BN15+BC15+BG15 -> 164580 | BP15: =BO15-AM15 -> 8580 | BQ15: =IF(BP15>=0,"Positive Margin","Negative Margin") -> Positive Margin | BR15: No Provision | BS15: =AY15-Y15-Q15-AA15-T15+BC15 -> 8580 | BT15: =IF(BS15<0, "Negative Margin at Inception", "Positive Margin at Inception") -> Positive Margin at Inception | BU15: =IFERROR(BP15/BO15,"0") -> 0.052132701 | BV15: =IF(BU15<1%,"Less Than 1%",IF(BU15>2%,"More than 2%",IF(BU15>=1%,"1% - 2%"))) -> More than 2% | BW15: =BM15+BN15 -> 0 | BX15: =AL15+AK15 -> 0 | BY15: =BW15-BX15 -> 0 | BZ15: =BM15 -> 0 | CA15: =AK15 -> 0 | CB15: =BZ15-CA15 -> 0 | CC15: Marketplace Purchases (AFR) | CD15: 0 | CE15: =TEXT(AN15,"mmm-yy") -> Jun-26 | CF15: =AM15-AL15-AA15 -> 156000 | CG15: =BO15-BN15 -> 164580 | CH15: =INT((D15- IF(MONTH(D15) >= 4, DATE(YEAR(D15), 4, 1), DATE(YEAR(D15)-1, 4, 1))) / 7) + 1 -> 10 | CI15: AFR | CJ15: AFR | CK15: 0 | CL15: =AY15-Q15 -> 8580 | CM15: =CL15-Y15+Z15 -> 8580 | CN15: =BO15-AM15 -> 8580 | CO15: =AY15*118% -> 194204.4 | CP15: =-Q15*118% -> -184080 | CQ15: =-BZ15*118% -> 0 | CR15: =-CA15*118% -> 0 | CS15: =SUM(CO15:CR15) -> 10124.4 | CT15: Telangana - HO | CU15: Telangana - HO | CV15: =MID(G15,3,10) -> ANHPG0363J | CW15: =MID(AR15,3,10) -> AAACM4154G
B16: ="Q" & IF(ROUNDUP(MONTH(D16)/3,0)-1=0,4,ROUNDUP(MONTH(D16)/3,0)-1) -> Q1 | C16: =TEXT(AN16,"mmm-yy") -> Jun-26 | D16: 46186 | E16: SH06261301 | F16: SRI PRASANNA TRADERS | G16: 37ANHPG0363J1Z1 | H16: 32 | I16: 46186 | J16: 26-27/PUR/003646 | K16: 46186 | L16: AD | M16: AP39UN1375 | N16: Pyrolysis Char - Briquettes | O16: 15220 | P16: 12 | Q16: =O16*P16 -> 182640 | R16: 0 | S16: =O16-R16 -> 15220 | T16: 0 | U16: 0 | V16: 0 | W16: 0 | X16: 0 | Y16: 0 | Z16: 0 | AA16: 0 | AB16: =Y16+AA16+Z16 -> 0 | AC16: 0 | AD16: 0 | AE16: 0 | AF16: 0 | AG16: 0 | AH16: 0 | AI16: 0 | AJ16: 0 | AK16: 0 | AL16: 0 | AM16: =Q16+AB16+AL16+AK16+AJ16+T16+AE16 -> 182640 | AN16: 46186 | AO16: 36/AFR/27IN00012 | AP16: 832139000056764186 | AQ16: MRF LIMITED (36) | AR16: 36AAACM4154G1ZO | AS16: Proddatur,Andhra Pradesh,516360 | AT16: Sadashivpet | AU16: Telangana | AW16: 15220 | AX16: 12.66 | AY16: =AW16*AX16 -> 192685.2 | AZ16: =AW16=O16 -> TRUE | BA16: 0 | BB16: =AW16-BA16 -> 15220 | BC16: 0 | BD16: Regular | BE16: 0 | BF16: 0 | BG16: 0 | BH16: 0 | BI16: 0 | BJ16: 0 | BK16: 0 | BL16: 0 | BM16: 0 | BN16: 0 | BO16: =AY16+BL16+BM16+BN16+BC16+BG16 -> 192685.2 | BP16: =BO16-AM16 -> 10045.2 | BQ16: =IF(BP16>=0,"Positive Margin","Negative Margin") -> Positive Margin | BR16: No Provision | BS16: =AY16-Y16-Q16-AA16-T16+BC16 -> 10045.2 | BT16: =IF(BS16<0, "Negative Margin at Inception", "Positive Margin at Inception") -> Positive Margin at Inception | BU16: =IFERROR(BP16/BO16,"0") -> 0.052132701 | BV16: =IF(BU16<1%,"Less Than 1%",IF(BU16>2%,"More than 2%",IF(BU16>=1%,"1% - 2%"))) -> More than 2% | BW16: =BM16+BN16 -> 0 | BX16: =AL16+AK16 -> 0 | BY16: =BW16-BX16 -> 0 | BZ16: =BM16 -> 0 | CA16: =AK16 -> 0 | CB16: =BZ16-CA16 -> 0 | CC16: Marketplace Purchases (AFR) | CD16: 0 | CE16: =TEXT(AN16,"mmm-yy") -> Jun-26 | CF16: =AM16-AL16-AA16 -> 182640 | CG16: =BO16-BN16 -> 192685.2 | CH16: =INT((D16- IF(MONTH(D16) >= 4, DATE(YEAR(D16), 4, 1), DATE(YEAR(D16)-1, 4, 1))) / 7) + 1 -> 11 | CI16: AFR | CJ16: AFR | CK16: 0 | CL16: =AY16-Q16 -> 10045.2 | CM16: =CL16-Y16+Z16 -> 10045.2 | CN16: =BO16-AM16 -> 10045.2 | CO16: =AY16*118% -> 227368.54 | CP16: =-Q16*118% -> -215515.2 | CQ16: =-BZ16*118% -> 0 | CR16: =-CA16*118% -> 0 | CS16: =SUM(CO16:CR16) -> 11853.336 | CT16: Telangana - HO | CU16: Telangana - HO | CV16: =MID(G16,3,10) -> ANHPG0363J | CW16: =MID(AR16,3,10) -> AAACM4154G
B17: ="Q" & IF(ROUNDUP(MONTH(D17)/3,0)-1=0,4,ROUNDUP(MONTH(D17)/3,0)-1) -> Q1 | C17: =TEXT(AN17,"mmm-yy") -> Jun-26 | D17: 46191 | E17: SH06261606 | F17: SRI PRASANNA TRADERS | G17: 37ANHPG0363J1Z1 | H17: 36 | I17: 46191 | J17: 26-27/PUR/003921 | K17: 46191 | L17: AD | M17: AP39WH8039 | N17: Pyrolysis Char - Briquettes | O17: 15130 | P17: 12 | Q17: =O17*P17 -> 181560 | R17: 0 | S17: =O17-R17 -> 15130 | T17: 0 | U17: 0 | V17: 0 | W17: 0 | X17: 0 | Y17: 0 | Z17: 0 | AA17: 0 | AB17: =Y17+AA17+Z17 -> 0 | AC17: 0 | AD17: 0 | AE17: 0 | AF17: 0 | AG17: 0 | AH17: 0 | AI17: 0 | AJ17: 0 | AK17: 0 | AL17: 0 | AM17: =Q17+AB17+AL17+AK17+AJ17+T17+AE17 -> 181560 | AN17: 46191 | AO17: 36/AFR/27IN00013 | AP17: 832139000056764186 | AQ17: MRF LIMITED (36) | AR17: 36AAACM4154G1ZO | AS17: Proddatur Andhra Pradesh 516360 | AT17: Sadashivpet | AU17: Telangana | AW17: 15130 | AX17: 12.66 | AY17: =AW17*AX17 -> 191545.8 | AZ17: =AW17=O17 -> TRUE | BA17: 0 | BB17: =AW17-BA17 -> 15130 | BC17: 0 | BD17: Regular | BE17: 0 | BF17: 0 | BG17: 0 | BH17: 0 | BI17: 0 | BJ17: 0 | BK17: 0 | BL17: 0 | BM17: 0 | BN17: 0 | BO17: =AY17+BL17+BM17+BN17+BC17+BG17 -> 191545.8 | BP17: =BO17-AM17 -> 9985.8 | BQ17: =IF(BP17>=0,"Positive Margin","Negative Margin") -> Positive Margin | BR17: No Provision | BS17: =AY17-Y17-Q17-AA17-T17+BC17 -> 9985.8 | BT17: =IF(BS17<0, "Negative Margin at Inception", "Positive Margin at Inception") -> Positive Margin at Inception | BU17: =IFERROR(BP17/BO17,"0") -> 0.052132701 | BV17: =IF(BU17<1%,"Less Than 1%",IF(BU17>2%,"More than 2%",IF(BU17>=1%,"1% - 2%"))) -> More than 2% | BW17: =BM17+BN17 -> 0 | BX17: =AL17+AK17 -> 0 | BY17: =BW17-BX17 -> 0 | BZ17: =BM17 -> 0 | CA17: =AK17 -> 0 | CB17: =BZ17-CA17 -> 0 | CC17: Marketplace Purchases (AFR) | CD17: 0 | CE17: =TEXT(AN17,"mmm-yy") -> Jun-26 | CF17: =AM17-AL17-AA17 -> 181560 | CG17: =BO17-BN17 -> 191545.8 | CH17: =INT((D17- IF(MONTH(D17) >= 4, DATE(YEAR(D17), 4, 1), DATE(YEAR(D17)-1, 4, 1))) / 7) + 1 -> 12 | CI17: AFR | CJ17: AFR | CK17: 0 | CL17: =AY17-Q17 -> 9985.8 | CM17: =CL17-Y17+Z17 -> 9985.8 | CN17: =BO17-AM17 -> 9985.8 | CO17: =AY17*118% -> 226024.04 | CP17: =-Q17*118% -> -214240.8 | CQ17: =-BZ17*118% -> 0 | CR17: =-CA17*118% -> 0 | CS17: =SUM(CO17:CR17) -> 11783.244 | CT17: Telangana - HO | CU17: Telangana - HO | CV17: =MID(G17,3,10) -> ANHPG0363J | CW17: =MID(AR17,3,10) -> AAACM4154G
F19: Total | O19: =SUBTOTAL(9,O5:O18) -> 187870 | Q19: =SUBTOTAL(9,Q5:Q18) -> 1850605 | S19: =SUBTOTAL(9,S5:S18) -> 187870 | T19: =SUBTOTAL(9,T5:T18) -> 0 | Y19: =SUBTOTAL(9,Y5:Y18) -> 0 | Z19: =SUBTOTAL(9,Z5:Z18) -> 0 | AA19: =SUBTOTAL(9,AA5:AA18) -> 0 | AB19: =SUBTOTAL(9,AB5:AB18) -> 0 | AC19: =SUBTOTAL(9,AC5:AC18) -> 0 | AD19: =SUBTOTAL(1,AD5:AD18) -> 0 | AE19: =SUBTOTAL(9,AE5:AE18) -> 0 | AJ19: =SUBTOTAL(9,AJ5:AJ18) -> 0 | AK19: =SUBTOTAL(9,AK5:AK18) -> -575 | AL19: =SUBTOTAL(9,AL5:AL18) -> 0 | AM19: =SUBTOTAL(9,AM5:AM18) -> 1850030 | AW19: =SUBTOTAL(9,AW5:AW18) -> 187870 | AX19: =SUBTOTAL(101,AX5:AX18) -> 10.109231 | AY19: =SUBTOTAL(9,AY5:AY18) -> 2026753.6 | BA19: =SUBTOTAL(9,BA5:BA18) -> 0 | BB19: =SUBTOTAL(9,BB5:BB18) -> 187870 | BC19: =SUBTOTAL(9,BC5:BC18) -> 0 | BG19: =SUBTOTAL(9,BG5:BG18) -> 0 | BL19: =SUBTOTAL(9,BL5:BL18) -> 0 | BM19: =SUBTOTAL(9,BM5:BM18) -> -700 | BN19: =SUBTOTAL(9,BN5:BN18) -> 0 | BO19: =SUBTOTAL(9,BO5:BO18) -> 2026053.6 | BP19: =SUBTOTAL(9,BP5:BP18) -> 176023.6 | BS19: =SUBTOTAL(9,BS5:BS18) -> 176148.6 | BW19: =SUBTOTAL(9,BV1:BV18) -> 0 | BX19: =SUBTOTAL(9,BW1:BW18) -> -700 | BY19: =SUBTOTAL(9,BX1:BX18) -> -575 | BZ19: =SUBTOTAL(9,BY1:BY18) -> -125 | CA19: =SUBTOTAL(9,BZ1:BZ18) -> -700 | CB19: =SUBTOTAL(9,CA1:CA18) -> -575 | CF19: =SUBTOTAL(9,CE1:CE18) -> 0 | CG19: =SUBTOTAL(9,CF1:CF18) -> 1850030 | CL19: =SUBTOTAL(9,CK1:CK18) -> 0 | CM19: =SUBTOTAL(9,CL1:CL18) -> 176148.6 | CN19: =SUBTOTAL(9,CM1:CM18) -> 176148.6 | CO19: =SUBTOTAL(9,CN1:CN18) -> 176023.6 | CP19: =SUBTOTAL(9,CO1:CO18) -> 2391569.2 | CQ19: =SUBTOTAL(9,CP1:CP18) -> -2183713.9 | CR19: =SUBTOTAL(9,CQ1:CQ18) -> 826 | CS19: =SUBTOTAL(9,CR1:CR18) -> 678.5
N20: =O19-AW19 -> 0 | P20: =Q19+AK19+AJ19+AL19+T19+AE19 -> 1850030 | AA20: =AB19/AY19 -> 0 | BK20: =BK21/AY19 -> 0 | BN20: =BP19/BO19 -> 0.086880031 | BR20: =BS19/AY19 -> 0.0869117 | BX20: =BX19/BW19 -> #DIV/0! | CA20: =IFERROR(CA19/BZ19,0) -> 5.6 | CD20: With GST | CE20: =CF19*118% -> 0 | CF20: =CG19*118% -> 2183035.4
AC21: =+AL19+AK19 -> -575
B23: Quarter | C23: Month | D23: Date | E23: Shipment ID | F23: Supplier Name | G23: GST Reg No. | H23: Vendor Invoice No. | I23: Vendor Invoice Date | J23: P V No. | K23: P V Date | L23: State (Origin) | M23: Vehicle No. | N23: Material | O23: Qty (Kg) | P23: Price/Kg | Q23: Purchase Price | R23: Return Qty | S23: Net Qty | T23: Basic Customs Duty | U23: Transporter Name | V23: LR NO/BILL NO | W23: J V No. | X23: JV Date | Y23: Logistics cost | Z23: Debit note on logistic cost | AA23: Logistics Provision | AB23: Total Logistics Cost | AC23: Opeartional Cost | AD23: Cost/Kg. | AE23: Divertion/Internal | AF23: Debit Note No. | AG23: Debit Note Date. | AH23: Debit Note No. 2 | AI23: Debit Note Date. 2 | AJ23: Full Debit Note | AK23: Actual Debit Note | AL23: Provision for DN | AM23: Total Cost | AN23: Inv. Date | AO23: Inv. No. | AP23: Customer ID | AQ23: Buyer Name | AR23: Buyer GST Number | AS23: Location (Origin) | AT23: Location (Destination) | AU23: State (Destination) | AV23: E-way Bill No | AW23: Qty(Kg) | AX23: Rate/Kg | AY23: Amount | AZ23: Qty Check | BA23: Return Qty | BB23: Net Qty | BC23: Divertion/Internal | BD23: Return Type | BE23: Date : DN to Buyer | BF23: DN to Buyer | BG23: Amount | BH23: Credit Note No:1 | BI23: CN Date. No:1 | BJ23: Credit Note No:2 | BK23: CN Date. No:2 | BL23: Full Credit Notes | BM23: Actual Credit Note | BN23: Provision for CN | BO23: Net Revenue | BP23: Margin | BQ23: Reamrks - Margin | BR23: Remarks | BS23: LMI @ Inception | BT23: Remarks @ Inception | BU23: Margin (%) | BV23: Margin Bucket | BW23: Total CN(Inc.Provisions) | BX23: Total DN(Inc.Provisions) | BY23: Check | BZ23: Actaul CN | CA23: Actual DN | CB23: Check | CC23: Material-Short Form | CD23: Supplier Type | CE23: Month | CF23: Cost | CG23: Revenue | CH23: Week No: | CI23: Category (Material) | CJ23: Broad Category | CK23: POC Name | CL23: Gross Margin | CM23: Recykal Margin | CN23: Net Margin | CO23: Sales | CP23: Purchases | CQ23: Credit Note | CR23: Debit Note | CS23: Margin | CT23: Bill Branch | CU23: Inv Branch | CV23: Vendor PAN No | CW23: Customer PAN No
