Workbook

Sheet Summary
D2: =TEXT(D4, "mmm-yy") -> Apr-26 | E2: =TEXT(E4, "mmm-yy") -> May-26 | F2: =TEXT(F4, "mmm-yy") -> Jun-26 | G2: =TEXT(G4, "mmm-yy") -> Jul-26 | H2: =TEXT(H4, "mmm-yy") -> Aug-26 | I2: =TEXT(I4, "mmm-yy") -> Sep-26 | J2: =TEXT(J4, "mmm-yy") -> Oct-26 | K2: =TEXT(K4, "mmm-yy") -> Nov-26 | ... O2: =TEXT(O4, "mmm-yy") -> Mar-27
D3: 30 | E3: 31 | F3: 21 | G3: 0 | H3: 0 | I3: 0 | J3: 0 | K3: 0 | L3: 0 | M3: 0 | N3: 0 | O3: 0 | P3: =SUM(D3:O3) -> 82
C4: Marketplace (Plastic) | D4: 46113 | E4: 46143 | F4: 46174 | G4: 46204 | H4: 46235 | I4: 46266 | J4: 46296 | K4: 46327 | L4: 46357 | M4: 46388 | N4: 46419 | O4: 46447 | P4: FY 2026-27
C5: Quantity (MT) | D5: 36.25 | E5: =SUMIFS(Details!$BB$4:$BB$8,Details!$C$4:$C$8,Summary!E$4)/1000 -> 0 | F5: =SUMIFS(Details!$BB$4:$BB$8,Details!$C$4:$C$8,Summary!F$4)/1000 -> 0 | G5: =SUMIFS(Details!$BB$4:$BB$8,Details!$C$4:$C$8,Summary!G$4)/1000 -> 0 | H5: =SUMIFS(Details!$BB$4:$BB$8,Details!$C$4:$C$8,Summary!H$4)/1000 -> 0 | I5: =SUMIFS(Details!$BB$4:$BB$8,Details!$C$4:$C$8,Summary!I$4)/1000 -> 0 | J5: =SUMIFS(Details!$BB$4:$BB$8,Details!$C$4:$C$8,Summary!J$4)/1000 -> 0 | K5: =SUMIFS(Details!$BB$4:$BB$8,Details!$C$4:$C$8,Summary!K$4)/1000 -> 0 | L5: =SUMIFS(Details!$BB$4:$BB$8,Details!$C$4:$C$8,Summary!L$4)/1000 -> 0 | ... O5: =SUMIFS(Details!$BB$4:$BB$8,Details!$C$4:$C$8,Summary!O$4)/1000 -> 0 | P5: =SUM(D5:O5) -> 36.25 | Q5: =Details!BB9/1000 -> 36.25 | R5: =P5-Q5 -> 0
C6: Net Revenue | D6: 2167276.3 | E6: =SUMIFS(Details!$BL$4:$BL$8,Details!$C$4:$C$8,Summary!E$4) -> 0 | F6: =SUMIFS(Details!$BL$4:$BL$8,Details!$C$4:$C$8,Summary!F$4) -> 0 | G6: =SUMIFS(Details!$BL$4:$BL$8,Details!$C$4:$C$8,Summary!G$4) -> 0 | H6: =SUMIFS(Details!$BL$4:$BL$8,Details!$C$4:$C$8,Summary!H$4) -> 0 | I6: =SUMIFS(Details!$BL$4:$BL$8,Details!$C$4:$C$8,Summary!I$4) -> 0 | J6: =SUMIFS(Details!$BL$4:$BL$8,Details!$C$4:$C$8,Summary!J$4) -> 0 | K6: =SUMIFS(Details!$BL$4:$BL$8,Details!$C$4:$C$8,Summary!K$4) -> 0 | L6: =SUMIFS(Details!$BL$4:$BL$8,Details!$C$4:$C$8,Summary!L$4) -> 0 | ... O6: =SUMIFS(Details!$BL$4:$BL$8,Details!$C$4:$C$8,Summary!O$4) -> 0 | P6: =SUM(D6:O6) -> 2167276.3 | Q6: =Details!BL9 -> 2185035 | R6: =P6-Q6+P75 -> -17758.688
C7: Purchases | D7: 2130617.5 | E7: =SUMIFS(Details!$AM$4:$AM$8,Details!$C$4:$C$8,Summary!E$4)-SUMIFS(Details!$AB$4:$AB$8,Details!$C$4:$C$8,Summary!E$4) -> 0 | F7: =SUMIFS(Details!$AM$4:$AM$8,Details!$C$4:$C$8,Summary!F$4)-SUMIFS(Details!$AB$4:$AB$8,Details!$C$4:$C$8,Summary!F$4) -> 0 | G7: =SUMIFS(Details!$AM$4:$AM$8,Details!$C$4:$C$8,Summary!G$4)-SUMIFS(Details!$AB$4:$AB$8,Details!$C$4:$C$8,Summary!G$4) -> 0 | H7: =SUMIFS(Details!$AM$4:$AM$8,Details!$C$4:$C$8,Summary!H$4)-SUMIFS(Details!$AB$4:$AB$8,Details!$C$4:$C$8,Summary!H$4) -> 0 | I7: =SUMIFS(Details!$AM$4:$AM$8,Details!$C$4:$C$8,Summary!I$4)-SUMIFS(Details!$AB$4:$AB$8,Details!$C$4:$C$8,Summary!I$4) -> 0 | J7: =SUMIFS(Details!$AM$4:$AM$8,Details!$C$4:$C$8,Summary!J$4)-SUMIFS(Details!$AB$4:$AB$8,Details!$C$4:$C$8,Summary!J$4) -> 0 | K7: =SUMIFS(Details!$AM$4:$AM$8,Details!$C$4:$C$8,Summary!K$4)-SUMIFS(Details!$AB$4:$AB$8,Details!$C$4:$C$8,Summary!K$4) -> 0 | L7: =SUMIFS(Details!$AM$4:$AM$8,Details!$C$4:$C$8,Summary!L$4)-SUMIFS(Details!$AB$4:$AB$8,Details!$C$4:$C$8,Summary!L$4) -> 0 | ... O7: =SUMIFS(Details!$AM$4:$AM$8,Details!$C$4:$C$8,Summary!O$4)-SUMIFS(Details!$AB$4:$AB$8,Details!$C$4:$C$8,Summary!O$4) -> 0 | P7: =SUM(D7:O7) -> 2130617.5 | Q7: =Details!P10 -> 2147861 | R7: =P7-Q7 -> -17243.55
C8: Gross Margin | D8: =D6-D7 -> 36658.837 | E8: =E6-E7 -> 0 | F8: =F6-F7 -> 0 | G8: =G6-G7 -> 0 | H8: =H6-H7 -> 0 | I8: =I6-I7 -> 0 | J8: =J6-J7 -> 0 | K8: =K6-K7 -> 0 | ... O8: =O6-O7 -> 0 | P8: =SUM(D8:O8) -> 36658.837
C9: Gross Margin (%) | D9: =IFERROR((D8/D6),0) -> 0.016914704 | E9: =IFERROR((E8/E6),0) -> 0 | F9: =IFERROR((F8/F6),0) -> 0 | G9: =IFERROR((G8/G6),0) -> 0 | H9: =IFERROR((H8/H6),0) -> 0 | I9: =IFERROR((I8/I6),0) -> 0 | J9: =IFERROR((J8/J6),0) -> 0 | K9: =IFERROR((K8/K6),0) -> 0 | ... P9: =IFERROR((P8/P6),0) -> 0.016914704
C10: Transportation Charges | D10: 0 | E10: =SUMIFS(Details!$AB$4:$AB$8,Details!$C$4:$C$8,Summary!E$4) -> 0 | F10: =SUMIFS(Details!$AB$4:$AB$8,Details!$C$4:$C$8,Summary!F$4) -> 0 | G10: =SUMIFS(Details!$AB$4:$AB$8,Details!$C$4:$C$8,Summary!G$4) -> 0 | H10: =SUMIFS(Details!$AB$4:$AB$8,Details!$C$4:$C$8,Summary!H$4) -> 0 | I10: =SUMIFS(Details!$AB$4:$AB$8,Details!$C$4:$C$8,Summary!I$4) -> 0 | J10: =SUMIFS(Details!$AB$4:$AB$8,Details!$C$4:$C$8,Summary!J$4) -> 0 | K10: =SUMIFS(Details!$AB$4:$AB$8,Details!$C$4:$C$8,Summary!K$4) -> 0 | L10: =SUMIFS(Details!$AB$4:$AB$8,Details!$C$4:$C$8,Summary!L$4) -> 0 | ... O10: =SUMIFS(Details!$AB$4:$AB$8,Details!$C$4:$C$8,Summary!O$4) -> 0 | P10: =SUM(D10:O10) -> 0 | Q10: =Details!AB9 -> 0 | R10: =P10-Q10 -> 0
C11: Operational Cost | D11: =SUMIFS(Details!$AC$4:$AC$8,Details!$C$4:$C$8,Summary!D$4) -> 0 | E11: =SUMIFS(Details!$AC$4:$AC$8,Details!$C$4:$C$8,Summary!E$4) -> 0 | F11: =SUMIFS(Details!$AC$4:$AC$8,Details!$C$4:$C$8,Summary!F$4) -> 0 | G11: =SUMIFS(Details!$AC$4:$AC$8,Details!$C$4:$C$8,Summary!G$4) -> 0 | H11: =SUMIFS(Details!$AC$4:$AC$8,Details!$C$4:$C$8,Summary!H$4) -> 0 | I11: =SUMIFS(Details!$AC$4:$AC$8,Details!$C$4:$C$8,Summary!I$4) -> 0 | J11: =SUMIFS(Details!$AC$4:$AC$8,Details!$C$4:$C$8,Summary!J$4) -> 0 | K11: =SUMIFS(Details!$AC$4:$AC$8,Details!$C$4:$C$8,Summary!K$4) -> 0 | ... O11: =SUMIFS(Details!$AC$4:$AC$8,Details!$C$4:$C$8,Summary!O$4) -> 0 | P11: =SUM(D11:O11) -> 0
C12: Net Margin | D12: =D6-D7-D10-D11 -> 36658.837 | E12: =E6-E7-E10-E11 -> 0 | F12: =F6-F7-F10-F11 -> 0 | G12: =G6-G7-G10-G11 -> 0 | H12: =H6-H7-H10-H11 -> 0 | I12: =I6-I7-I10-I11 -> 0 | J12: =J6-J7-J10-J11 -> 0 | K12: =K6-K7-K10-K11 -> 0 | ... O12: =O6-O7-O10-O11 -> 0 | P12: =SUM(D12:O12) -> 36658.837
C13: Net Margin (%) | D13: =IFERROR((D12/D6),0) -> 0.016914704 | E13: =IFERROR((E12/E6),0) -> 0 | F13: =IFERROR((F12/F6),0) -> 0 | G13: =IFERROR((G12/G6),0) -> 0 | H13: =IFERROR((H12/H6),0) -> 0 | I13: =IFERROR((I12/I6),0) -> 0 | J13: =IFERROR((J12/J6),0) -> 0 | K13: =IFERROR((K12/K6),0) -> 0 | ... P13: =IFERROR((P12/P6),0) -> 0.016914704
C14: Other Income | D14: =SUMIFS(Details!$BL$13:$BL$17,Details!$C$13:$C$17,Summary!D$4) -> 1363676 | E14: =SUMIFS(Details!$BL$13:$BL$17,Details!$C$13:$C$17,Summary!E$4) -> 0 | F14: =SUMIFS(Details!$BL$13:$BL$17,Details!$C$13:$C$17,Summary!F$4) -> 0 | G14: =SUMIFS(Details!$BL$13:$BL$17,Details!$C$13:$C$17,Summary!G$4) -> 0 | H14: =SUMIFS(Details!$BL$13:$BL$17,Details!$C$13:$C$17,Summary!H$4) -> 0 | I14: =SUMIFS(Details!$BL$13:$BL$17,Details!$C$13:$C$17,Summary!I$4) -> 0 | J14: =SUMIFS(Details!$BL$13:$BL$17,Details!$C$13:$C$17,Summary!J$4) -> 0 | K14: =SUMIFS(Details!$BL$13:$BL$17,Details!$C$13:$C$17,Summary!K$4) -> 0 | ... O14: =SUMIFS(Details!$BL$13:$BL$17,Details!$C$13:$C$17,Summary!O$4) -> 0 | P14: =SUM(D14:O14) -> 1363676
C15: Transport Charges (%) | D15: =IFERROR((D10/D6),0) -> 0 | E15: =IFERROR((E10/E6),0) -> 0 | F15: =IFERROR((F10/F6),0) -> 0 | G15: =IFERROR((G10/G6),0) -> 0 | H15: =IFERROR((H10/H6),0) -> 0 | I15: =IFERROR((I10/I6),0) -> 0 | J15: =IFERROR((J10/J6),0) -> 0 | K15: =IFERROR((K10/K6),0) -> 0 | ... P15: =IFERROR((P10/P6),0) -> 0
C16: Revenue Per Kg | D16: =IFERROR(D6/(D5*1000),0) -> 59.786933 | E16: =IFERROR(E6/(E5*1000),0) -> 0 | F16: =IFERROR(F6/(F5*1000),0) -> 0 | G16: =IFERROR(G6/(G5*1000),0) -> 0 | H16: =IFERROR(H6/(H5*1000),0) -> 0 | I16: =IFERROR(I6/(I5*1000),0) -> 0 | J16: =IFERROR(J6/(J5*1000),0) -> 0 | K16: =IFERROR(K6/(K5*1000),0) -> 0 | ... O16: =IFERROR(O6/(O5*1000),0) -> 0 | P16: =+P6/(P5*1000) -> 59.786933
C17: Purchase Cost Per Kg | D17: =IFERROR(D7/(D5*1000),0) -> 58.775654 | E17: =IFERROR(E7/(E5*1000),0) -> 0 | F17: =IFERROR(F7/(F5*1000),0) -> 0 | G17: =IFERROR(G7/(G5*1000),0) -> 0 | H17: =IFERROR(H7/(H5*1000),0) -> 0 | I17: =IFERROR(I7/(I5*1000),0) -> 0 | J17: =IFERROR(J7/(J5*1000),0) -> 0 | K17: =IFERROR(K7/(K5*1000),0) -> 0 | ... O17: =IFERROR(O7/(O5*1000),0) -> 0 | P17: =+P7/(P5*1000) -> 58.775654
C18: Transportation Charges Per Kg | D18: =D10/(D5*1000) -> 0 | E18: =E10/(E5*1000) -> #DIV/0! | F18: =F10/(F5*1000) -> #DIV/0! | G18: =G10/(G5*1000) -> #DIV/0! | H18: =H10/(H5*1000) -> #DIV/0! | I18: =I10/(I5*1000) -> #DIV/0! | J18: =J10/(J5*1000) -> #DIV/0! | K18: =K10/(K5*1000) -> #DIV/0! | ... P18: =P10/(P5*1000) -> 0
C19: No. of Transactions | D19: {=IFERROR(ROWS(_xlfn.UNIQUE(_xlfn._xlws.FILTER(Details!$AO$5:$AO$8, (Details!$C$5:$C$8)=Summary!D$2))),0)} -> 3 | E19: {=IFERROR(ROWS(_xlfn.UNIQUE(_xlfn._xlws.FILTER(Details!$AO$5:$AO$8, (Details!$C$5:$C$8)=Summary!E$2))),0)} -> 0 | F19: {=IFERROR(ROWS(_xlfn.UNIQUE(_xlfn._xlws.FILTER(Details!$AO$5:$AO$8, (Details!$C$5:$C$8)=Summary!F$2))),0)} -> 0 | G19: {=IFERROR(ROWS(_xlfn.UNIQUE(_xlfn._xlws.FILTER(Details!$AO$5:$AO$8, (Details!$C$5:$C$8)=Summary!G$2))),0)} -> 0 | H19: {=IFERROR(ROWS(_xlfn.UNIQUE(_xlfn._xlws.FILTER(Details!$AO$5:$AO$8, (Details!$C$5:$C$8)=Summary!H$2))),0)} -> 0 | I19: {=IFERROR(ROWS(_xlfn.UNIQUE(_xlfn._xlws.FILTER(Details!$AO$5:$AO$8, (Details!$C$5:$C$8)=Summary!I$2))),0)} -> 0 | J19: {=IFERROR(ROWS(_xlfn.UNIQUE(_xlfn._xlws.FILTER(Details!$AO$5:$AO$8, (Details!$C$5:$C$8)=Summary!J$2))),0)} -> 0 | K19: {=IFERROR(ROWS(_xlfn.UNIQUE(_xlfn._xlws.FILTER(Details!$AO$5:$AO$8, (Details!$C$5:$C$8)=Summary!K$2))),0)} -> 0 | ... O19: {=IFERROR(ROWS(_xlfn.UNIQUE(_xlfn._xlws.FILTER(Details!$AO$5:$AO$8, (Details!$C$5:$C$8)=Summary!O$2))),0)} -> 0 | P19: =SUM(D19:O19) -> 3
C20: No. of Sellers (Aggregators) | D20: {=IFERROR(ROWS(_xlfn.UNIQUE(_xlfn._xlws.FILTER(MID(Details!$G$5:$G$8,3,10), (Details!$C$5:$C$8)=Summary!D$2))),0)-1} -> 2 | E20: {=IFERROR(ROWS(_xlfn.UNIQUE(_xlfn._xlws.FILTER(MID(Details!$G$5:$G$8,3,10), (Details!$C$5:$C$8)=Summary!E$2))),0)} -> 0 | F20: {=IFERROR(ROWS(_xlfn.UNIQUE(_xlfn._xlws.FILTER(MID(Details!$G$5:$G$8,3,10), (Details!$C$5:$C$8)=Summary!F$2))),0)} -> 0 | G20: {=IFERROR(ROWS(_xlfn.UNIQUE(_xlfn._xlws.FILTER(MID(Details!$G$5:$G$8,3,10), (Details!$C$5:$C$8)=Summary!G$2))),0)} -> 0 | H20: {=IFERROR(ROWS(_xlfn.UNIQUE(_xlfn._xlws.FILTER(MID(Details!$G$5:$G$8,3,10), (Details!$C$5:$C$8)=Summary!H$2))),0)} -> 0 | I20: {=IFERROR(ROWS(_xlfn.UNIQUE(_xlfn._xlws.FILTER(MID(Details!$G$5:$G$8,3,10), (Details!$C$5:$C$8)=Summary!I$2))),0)} -> 0 | J20: {=IFERROR(ROWS(_xlfn.UNIQUE(_xlfn._xlws.FILTER(MID(Details!$G$5:$G$8,3,10), (Details!$C$5:$C$8)=Summary!J$2))),0)} -> 0 | K20: {=IFERROR(ROWS(_xlfn.UNIQUE(_xlfn._xlws.FILTER(MID(Details!$G$5:$G$8,3,10), (Details!$C$5:$C$8)=Summary!K$2))),0)} -> 0 | L20: {=IFERROR(ROWS(_xlfn.UNIQUE(_xlfn._xlws.FILTER(MID(Details!$G$5:$G$8,3,10), (Details!$C$5:$C$8)=Summary!L$2))),0)} -> 0 | ... O20: {=IFERROR(ROWS(_xlfn.UNIQUE(_xlfn._xlws.FILTER(MID(Details!$G$5:$G$8,3,10), (Details!$C$5:$C$8)=Summary!O$2))),0)} -> 0 | P20: ='Supplier Metrics'!E2-1 -> 2
C21: No. of Buyers (Recyclers) | D21: {=IFERROR(ROWS(_xlfn.UNIQUE(_xlfn._xlws.FILTER(MID(Details!$AR$5:$AR$8,3,10), (Details!$C$5:$C$8)=Summary!D$2))),0)-1} -> 2 | E21: {=IFERROR(ROWS(_xlfn.UNIQUE(_xlfn._xlws.FILTER(MID(Details!$AR$5:$AR$8,3,10), (Details!$C$5:$C$8)=Summary!E$2))),0)} -> 0 | F21: {=IFERROR(ROWS(_xlfn.UNIQUE(_xlfn._xlws.FILTER(MID(Details!$AR$5:$AR$8,3,10), (Details!$C$5:$C$8)=Summary!F$2))),0)} -> 0 | G21: {=IFERROR(ROWS(_xlfn.UNIQUE(_xlfn._xlws.FILTER(MID(Details!$AR$5:$AR$8,3,10), (Details!$C$5:$C$8)=Summary!G$2))),0)} -> 0 | H21: {=IFERROR(ROWS(_xlfn.UNIQUE(_xlfn._xlws.FILTER(MID(Details!$AR$5:$AR$8,3,10), (Details!$C$5:$C$8)=Summary!H$2))),0)} -> 0 | I21: {=IFERROR(ROWS(_xlfn.UNIQUE(_xlfn._xlws.FILTER(MID(Details!$AR$5:$AR$8,3,10), (Details!$C$5:$C$8)=Summary!I$2))),0)} -> 0 | J21: {=IFERROR(ROWS(_xlfn.UNIQUE(_xlfn._xlws.FILTER(MID(Details!$AR$5:$AR$8,3,10), (Details!$C$5:$C$8)=Summary!J$2))),0)} -> 0 | K21: {=IFERROR(ROWS(_xlfn.UNIQUE(_xlfn._xlws.FILTER(MID(Details!$AR$5:$AR$8,3,10), (Details!$C$5:$C$8)=Summary!K$2))),0)} -> 0 | L21: {=IFERROR(ROWS(_xlfn.UNIQUE(_xlfn._xlws.FILTER(MID(Details!$AR$5:$AR$8,3,10), (Details!$C$5:$C$8)=Summary!L$2))),0)} -> 0 | ... O21: {=IFERROR(ROWS(_xlfn.UNIQUE(_xlfn._xlws.FILTER(MID(Details!$AR$5:$AR$8,3,10), (Details!$C$5:$C$8)=Summary!O$2))),0)} -> 0 | P21: ='Buyer Metrics'!B3-1 -> 2
C22: Full Rejection | D22: {=IFERROR(ROWS(_xlfn.UNIQUE(_xlfn._xlws.FILTER(Details!$E$5:$E$8,(Details!$C$5:$C$8=Summary!D$2)*(Details!$BO$5:$BO$8=Summary!$C$22)))),0)} -> 0 | E22: {=IFERROR(ROWS(_xlfn.UNIQUE(_xlfn._xlws.FILTER(Details!$E$5:$E$8,(Details!$C$5:$C$8=Summary!E$2)*(Details!$BO$5:$BO$8=Summary!$C$22)))),0)} -> 0 | F22: {=IFERROR(ROWS(_xlfn.UNIQUE(_xlfn._xlws.FILTER(Details!$E$5:$E$8,(Details!$C$5:$C$8=Summary!F$2)*(Details!$BO$5:$BO$8=Summary!$C$22)))),0)} -> 0 | G22: {=IFERROR(ROWS(_xlfn.UNIQUE(_xlfn._xlws.FILTER(Details!$E$5:$E$8,(Details!$C$5:$C$8=Summary!G$2)*(Details!$BO$5:$BO$8=Summary!$C$22)))),0)} -> 0 | H22: {=IFERROR(ROWS(_xlfn.UNIQUE(_xlfn._xlws.FILTER(Details!$E$5:$E$8,(Details!$C$5:$C$8=Summary!H$2)*(Details!$BO$5:$BO$8=Summary!$C$22)))),0)} -> 0 | I22: {=IFERROR(ROWS(_xlfn.UNIQUE(_xlfn._xlws.FILTER(Details!$E$5:$E$8,(Details!$C$5:$C$8=Summary!I$2)*(Details!$BO$5:$BO$8=Summary!$C$22)))),0)} -> 0 | J22: {=IFERROR(ROWS(_xlfn.UNIQUE(_xlfn._xlws.FILTER(Details!$E$5:$E$8,(Details!$C$5:$C$8=Summary!J$2)*(Details!$BO$5:$BO$8=Summary!$C$22)))),0)} -> 0 | K22: {=IFERROR(ROWS(_xlfn.UNIQUE(_xlfn._xlws.FILTER(Details!$E$5:$E$8,(Details!$C$5:$C$8=Summary!K$2)*(Details!$BO$5:$BO$8=Summary!$C$22)))),0)} -> 0 | ... O22: {=IFERROR(ROWS(_xlfn.UNIQUE(_xlfn._xlws.FILTER(Details!$E$5:$E$8,(Details!$C$5:$C$8=Summary!O$2)*(Details!$BO$5:$BO$8=Summary!$C$22)))),0)} -> 0 | P22: =SUM(D22:O22) -> 0
C23: Receivable | D23: 72181241 | E23: 60130029 | F23: 54302522 | G23: 0 | H23: 0 | I23: 0 | J23: 0 | K23: 0 | L23: 0 | M23: 0 | N23: 0 | O23: 0 | P23: =F23 -> 54302522
C24: DSO (Days) | D24: =IFERROR(((D23/(D6*1.18))*D3),0) -> 846.7385 | E24: =IFERROR(((E23/(E6*1.18))*E3),0) -> 0 | F24: =IFERROR(((F23/(F6*1.18))*F3),0) -> 0 | G24: =IFERROR(((G23/(G6*1.18))*G3),0) -> 0 | H24: =IFERROR(((H23/(H6*1.18))*H3),0) -> 0 | I24: =IFERROR(((I23/(I6*1.18))*I3),0) -> 0 | J24: =IFERROR(((J23/(J6*1.18))*J3),0) -> 0 | K24: =IFERROR(((K23/(K6*1.18))*K3),0) -> 0 | ... O24: =IFERROR(((O23/(O6*1.18))*O3),0) -> 0 | P24: =IFERROR(((P23)/(P6*1.18)*P3),0) -> 1741.1555
C25: Payable | D25: 23789534 | E25: 21485726 | F25: 19968208 | G25: 0 | H25: 0 | I25: 0 | J25: 0 | K25: 0 | L25: 0 | M25: 0 | N25: 0 | O25: 0 | P25: =F25 -> 19968208
C26: DPO (Days) | D26: =IFERROR(((D25/(D7*1.18))*D3),0) -> 283.87013 | E26: =IFERROR(((E25/(E7*1.18))*E3),0) -> 0 | F26: =IFERROR(((F25/(F7*1.18))*F3),0) -> 0 | G26: =IFERROR(((G25/(G7*1.18))*G3),0) -> 0 | H26: =IFERROR(((H25/(H7*1.18))*H3),0) -> 0 | I26: =IFERROR(((I25/(I7*1.18))*I3),0) -> 0 | J26: =IFERROR(((J25/(J7*1.18))*J3),0) -> 0 | K26: =IFERROR(((K25/(K7*1.18))*K3),0) -> 0 | ... P26: =IFERROR(((P25/(P7*1.18))*P3),0) -> 651.27658
C27: Working Capital Days | D27: =D24-D26 -> 562.86837 | E27: =E24-E26 -> 0 | F27: =F24-F26 -> 0 | G27: =G24-G26 -> 0 | H27: =H24-H26 -> 0 | I27: =I24-I26 -> 0 | J27: =J24-J26 -> 0 | K27: =K24-K26 -> 0 | ... P27: =P24-P26 -> 1089.8789
C28: Credit Notes (Value - Incl. Prov) | D28: 55571.188 | E28: =-SUMIFS(Details!$BT$4:$BT$8,Details!$C$4:$C$8,Summary!E4) -> 0 | F28: =-SUMIFS(Details!$BT$4:$BT$8,Details!$C$4:$C$8,Summary!F4) -> 0 | G28: =-SUMIFS(Details!$BT$4:$BT$8,Details!$C$4:$C$8,Summary!G4) -> 0 | H28: =-SUMIFS(Details!$BT$4:$BT$8,Details!$C$4:$C$8,Summary!H4) -> 0 | I28: =-SUMIFS(Details!$BT$4:$BT$8,Details!$C$4:$C$8,Summary!I4) -> 0 | J28: =-SUMIFS(Details!$BT$4:$BT$8,Details!$C$4:$C$8,Summary!J4) -> 0 | K28: =-SUMIFS(Details!$BT$4:$BT$8,Details!$C$4:$C$8,Summary!K4) -> 0 | L28: =-SUMIFS(Details!$BT$4:$BT$8,Details!$C$4:$C$8,Summary!L4) -> 0 | ... O28: =-SUMIFS(Details!$BT$4:$BT$8,Details!$C$4:$C$8,Summary!O4) -> 0 | P28: =SUM(D28:O28) -> 55571.188 | Q28: =(-Details!BJ9-Details!BK9) -> 37812.5 | R28: =P28-Q28 -> 17758.688
C29: Credit Notes (% to Revenue) | D29: =IFERROR((D28/D6),0) -> 0.025641026 | E29: =IFERROR((E28/E6),0) -> 0 | F29: =IFERROR((F28/F6),0) -> 0 | G29: =IFERROR((G28/G6),0) -> 0 | H29: =IFERROR((H28/H6),0) -> 0 | I29: =IFERROR((I28/I6),0) -> 0 | J29: =IFERROR((J28/J6),0) -> 0 | K29: =IFERROR((K28/K6),0) -> 0 | ... O29: =IFERROR((O28/O6),0) -> 0 | P29: =+P28/P6 -> 0.025641026
C30: Debit Notes (Value - Incl. Prov) | D30: 50677.025 | E30: =-SUMIFS(Details!$BU$4:$BU$8,Details!$C$4:$C$8,Summary!E4) -> 0 | F30: =-SUMIFS(Details!$BU$4:$BU$8,Details!$C$4:$C$8,Summary!F4) -> 0 | G30: =-SUMIFS(Details!$BU$4:$BU$8,Details!$C$4:$C$8,Summary!G4) -> 0 | H30: =-SUMIFS(Details!$BU$4:$BU$8,Details!$C$4:$C$8,Summary!H4) -> 0 | I30: =-SUMIFS(Details!$BU$4:$BU$8,Details!$C$4:$C$8,Summary!I4) -> 0 | J30: =-SUMIFS(Details!$BU$4:$BU$8,Details!$C$4:$C$8,Summary!J4) -> 0 | K30: =-SUMIFS(Details!$BU$4:$BU$8,Details!$C$4:$C$8,Summary!K4) -> 0 | L30: =-SUMIFS(Details!$BU$4:$BU$8,Details!$C$4:$C$8,Summary!L4) -> 0 | ... O30: =-SUMIFS(Details!$BU$4:$BU$8,Details!$C$4:$C$8,Summary!O4) -> 0 | P30: =SUM(D30:O30) -> 50677.025 | Q30: =(-Details!AK9-Details!AL9) -> 33433.475 | R30: =P30-Q30 -> 17243.55
C31: Debit Notes (% to Purchase) | D31: =IFERROR((D30/D7),0) -> 0.023785135 | E31: =IFERROR((E30/E7),0) -> 0 | F31: =IFERROR((F30/F7),0) -> 0 | G31: =IFERROR((G30/G7),0) -> 0 | H31: =IFERROR((H30/H7),0) -> 0 | I31: =IFERROR((I30/I7),0) -> 0 | J31: =IFERROR((J30/J7),0) -> 0 | K31: =IFERROR((K30/K7),0) -> 0 | ... O31: =IFERROR((O30/O7),0) -> 0 | P31: =(P30/(P7+P10)) -> 0.023785135
C33: KPI's without Provisions | D33: =D4 -> 46113 | E33: =E4 -> 46143 | F33: =F4 -> 46174 | G33: =G4 -> 46204 | H33: =H4 -> 46235 | I33: =I4 -> 46266 | J33: =J4 -> 46296 | K33: =K4 -> 46327 | ... P33: =P4 -> FY 2026-27
C34: Sales without Provision | D34: =D6+D53 -> 2205088.8 | E34: =E6+E53 -> 0 | F34: =F6+F53 -> 0 | G34: =G6+G53 -> 0 | H34: =H6+H53 -> 0 | I34: =I6+I53 -> 0 | J34: =J6+J53 -> 0 | K34: =K6+K53 -> 0 | ... O34: =O6+O53 -> 0 | P34: =SUM(D34:O34) -> 2205088.8
C35: Purchases without Provision | D35: =D7+D10+D52 -> 2153085.1 | E35: =E7+E10+E52 -> 0 | F35: =F7+F10+F52 -> 0 | G35: =G7+G10+G52 -> 0 | H35: =H7+H10+H52 -> 0 | I35: =I7+I10+I52 -> 0 | J35: =J7+J10+J52 -> 0 | K35: =K7+K10+K52 -> 0 | ... O35: =O7+O10+O52 -> 0 | P35: =SUM(D35:O35) -> 2153085.1
C36: Contribution without Provision | D36: =D34-D35 -> 52003.712 | E36: =E34-E35 -> 0 | F36: =F34-F35 -> 0 | G36: =G34-G35 -> 0 | H36: =H34-H35 -> 0 | I36: =I34-I35 -> 0 | J36: =J34-J35 -> 0 | K36: =K34-K35 -> 0 | ... P36: =P34-P35 -> 52003.712
C37: Contribution (%) | D37: =D36/D34 -> 0.0235835 | E37: =E36/E34 -> #DIV/0! | F37: =F36/F34 -> #DIV/0! | G37: =G36/G34 -> #DIV/0! | H37: =H36/H34 -> #DIV/0! | I37: =I36/I34 -> #DIV/0! | J37: =J36/J34 -> #DIV/0! | K37: =K36/K34 -> #DIV/0! | ... P37: =P36/P34 -> 0.0235835
C39: Business Trends | D39: =D4 -> 46113 | E39: =E4 -> 46143 | F39: =F4 -> 46174 | G39: =G4 -> 46204 | H39: =H4 -> 46235 | I39: =I4 -> 46266 | J39: =J4 -> 46296 | K39: =K4 -> 46327 | ... P39: =P4 -> FY 2026-27
C40: Sales-Revenue (MoM) | D40: =IFERROR(((D6/C6)-1),0) -> 0 | E40: =IFERROR(((E6/D6)-1),0) -> -1 | F40: =IFERROR(((F6/E6)-1),0) -> 0 | G40: =IFERROR(((G6/F6)-1),0) -> 0 | H40: =IFERROR(((H6/G6)-1),0) -> 0 | I40: =IFERROR(((I6/H6)-1),0) -> 0 | J40: =IFERROR(((J6/I6)-1),0) -> 0 | K40: =IFERROR(((K6/J6)-1),0) -> 0 | ... O40: =IFERROR(((O6/N6)-1),0) -> 0 | P40: 0
C41: Sales-Volume (MoM) | D41: =IFERROR(((D5/C5)-1),0) -> 0 | E41: =IFERROR(((E5/D5)-1),0) -> -1 | F41: =IFERROR(((F5/E5)-1),0) -> 0 | G41: =IFERROR(((G5/F5)-1),0) -> 0 | H41: =IFERROR(((H5/G5)-1),0) -> 0 | I41: =IFERROR(((I5/H5)-1),0) -> 0 | J41: =IFERROR(((J5/I5)-1),0) -> 0 | K41: =IFERROR(((K5/J5)-1),0) -> 0 | ... O41: =IFERROR(((O5/N5)-1),0) -> 0 | P41: 0
C42: Sales-Transactions (MoM) | D42: =IFERROR(((D19/C19)-1),0) -> 0 | E42: =IFERROR(((E19/D19)-1),0) -> -1 | F42: =IFERROR(((F19/E19)-1),0) -> 0 | G42: =IFERROR(((G19/F19)-1),0) -> 0 | H42: =IFERROR(((#REF!/G19)-1),0) -> 0 | I42: =IFERROR(((I19/#REF!)-1),0) -> 0 | J42: =IFERROR(((J19/I19)-1),0) -> 0 | K42: =IFERROR(((K19/J19)-1),0) -> 0 | L42: =IFERROR(((L19/K19)-1),0) -> 0 | M42: =IFERROR(((M19/L19)-1),0) -> 0 | N42: =IFERROR(((N19/M19)-1),0) -> 0 | O42: =IFERROR(((O19/N19)-1),0) -> 0 | P42: 0
C44: Loss Making Transactions | D44: =D39 -> 46113 | E44: =E39 -> 46143 | F44: =F39 -> 46174 | G44: =G39 -> 46204 | H44: =H39 -> 46235 | I44: =I39 -> 46266 | J44: =J39 -> 46296 | K44: =K39 -> 46327 | ... P44: =P39 -> FY 2026-27
...

Sheet Details
B3: Raw Data -Plastic | F3: Purchase Details | U3: Logistic Details of the transaction | AF3: Debit Notes to Suppliers | AM3: Sales Details | BD3: DN to Customer | BE3: Credit Notes from Customers | BJ3: -0.025 | BS3: CN & DN Checks | CB3: Without Provisions | CH3: Margin Buckets | CK3: Financials with GST
B4: Quarter | C4: Month | D4: Date | E4: Shipment ID | F4: Supplier Name | G4: GST Reg No. | H4: Vendor Invoice No. | I4: Vendor Invoice Date | J4: P V No. | K4: P V Date | L4: State (Origin) | M4: Vehicle No. | N4: Material | O4: Qty (Kg) | P4: Price/Kg | Q4: Purchase Price | R4: Return Qty | S4: Net Qty | T4: Basic Customs Duty | U4: Transporter Name | V4: LR NO/BILL NO | W4: J V No. | X4: JV Date | Y4: Logistics cost | Z4: Debit note on logistic cost | AA4: Logistics Provision | AB4: Total Logistics Cost | AC4: Operational Cost | AD4: Cost/Kg. | AE4: Divertion/Internal | AF4: Debit Note No. | AG4: Debit Note Date. | AH4: Debit Note No. 2 | AI4: Debit Note Date. 2 | AJ4: Full Debit Note | AK4: Actual Debit Note | AL4: Provision for DN | AM4: Total Cost | AN4: Inv. Date | AO4: Inv. No. | AP4: Customer ID | AQ4: Buyer Name | AR4: Buyer GST Number | AS4: Location (Origin) | AT4: Location (Destination) | AU4: State (Destination) | AV4: E-WayBill Number | AW4: Qty(Kg) | AX4: Rate/Kg | AY4: Amount | AZ4: Qty Check | BA4: Return Qty | BB4: Net Qty | BC4: Divertion/Internal | BD4: Return Type | BE4: Credit Note No:1 | BF4: CN Date. No:1 | BG4: Credit Note No:2 | BH4: CN Date. No:2 | BI4: Full Credit Notes | BJ4: Actual Credit Note | BK4: Provision for CN | BL4: Net Revenue | BM4: Margin | BN4: Reamrks - Margin | BO4: Remarks | BP4: LMI @ Inception | BQ4: Remarks @ Inception | BR4: Margin (%) | BS4: Margin Bucket | BT4: Total CN(Inc.Provisions) | BU4: Total DN(Inc.Provisions) | BV4: Check | BW4: Actaul CN | BX4: Actual DN | BY4: Check | BZ4: Material-Short Form | CA4: Supplier Type | CB4: Month | CC4: Cost | CD4: Revenue | CE4: Week No: | CF4: Category (Material) | CG4: Broad Category | CH4: POC Name | CI4: Gross Margin | CJ4: Recykal Margin | CK4: Net Margin | CL4: Sales | CM4: Purchases | CN4: Credit Note | CO4: Debit Note | CP4: Margin | CQ4: Bill Branch | CR4: Inv Branch | CS4: Vendor PAN No | CT4: Customer PAN No | CU4: GST TDS Applicability | CV4: Cash Discount(Provision) | CW4: Cash Discount | CX4: Cash Discount. No | CY4: CD Date
B5: ="Q" & IF(ROUNDUP(MONTH(D5)/3,0)-1=0,4,ROUNDUP(MONTH(D5)/3,0)-1) -> Q1 | C5: =TEXT(AN5,"mmm-yy") -> Apr-26 | D5: 46114 | E5: SH04260306 | F5: BHAGIRATHI POLYMER PRIVATE LIMITED | G5: 09AALCB0491L1ZA | H5: BPPL/26-27/1 | I5: 46114 | J5: 26-27/PUR/000001 | K5: 46115 | L5: UP | M5: UP15JT8380 | N5: PET - Hot Washed White Flakes, Grade 2 | O5: 10845 | P5: 63.6 | Q5: =O5*P5 -> 689742 | R5: 0 | S5: =O5-R5 -> 10845 | T5: 0 | U5: 0 | V5: 0 | W5: 0 | X5: 0 | Y5: 0 | Z5: 0 | AA5: 0 | AB5: =Y5+AA5+Z5 -> 0 | AC5: 0 | AD5: =IFERROR((Q5+AB5)/S5,0) -> 63.6 | AE5: 0 | AF5: 0 | AG5: 0 | AH5: 0 | AI5: 0 | AJ5: 0 | AK5: 0 | AL5: 0 | AM5: =Q5+AB5+AL5+AK5+AJ5+T5+AE5 -> 689742 | AN5: 46115 | AO5: 36/PET/27IN00002 | AP5: 832139000005565947 | AQ5: Silver Ecotex LLP | AR5: 09AEJFS8446P1ZY | AS5: Meerut,Uttar Pradesh,250002 | AT5: Shamali | AU5: Uttar Pradesh | AW5: 10845 | AX5: 65.5 | AY5: =AW5*AX5 -> 710347.5 | AZ5: =AW5=O5 -> TRUE | BA5: 0 | BB5: =AW5-BA5 -> 10845 | BC5: 0 | BD5: Regular | BE5: 0 | BF5: 0 | BG5: 0 | BH5: 0 | BI5: 0 | BJ5: 0 | BK5: 0 | BL5: =AY5+BI5+BJ5+BK5+BC5 -> 710347.5 | BM5: =BL5-AM5 -> 20605.5 | BN5: =IF(BM5>=0,"Positive Margin","Negative Margin") -> Positive Margin | BO5: NO DN | BP5: =AY5-Y5-Q5-AA5-T5+BC5 -> 20605.5 | BQ5: =IF(BP5<0, "Negative Margin at Inception", "Positive Margin at Inception") -> Positive Margin at Inception | BR5: =IFERROR(BM5/BL5,"0") -> 0.029007634 | BS5: =IF(BR5<1%,"Less Than 1%",IF(BR5>2%,"More than 2%",IF(BR5>=1%,"1% - 2%"))) -> More than 2% | BT5: =BJ5+BK5 -> 0 | BU5: =AL5+AK5 -> 0 | BV5: =BT5-BU5 -> 0 | BW5: =BJ5 -> 0 | BX5: =AK5 -> 0 | BY5: =BW5-BX5 -> 0 | BZ5: Marketplace (Plastic Waste) | CA5: 0 | CB5: =TEXT(AN5,"mmm-yy") -> Apr-26 | CC5: =AM5-AL5-AA5 -> 689742 | CD5: =BL5-BK5 -> 710347.5 | CE5: =INT((D5- IF(MONTH(D5) >= 4, DATE(YEAR(D5), 4, 1), DATE(YEAR(D5)-1, 4, 1))) / 7) + 1 -> 1 | CF5: Plastic | CG5: Plastic | CH5: =_xlfn.XLOOKUP(AR5,receivables!B:B,receivables!D:D) -> Neelesh Dixit | CI5: =AY5-Q5 -> 20605.5 | CJ5: =CI5-Y5+Z5 -> 20605.5 | CK5: =BL5-AM5 -> 20605.5 | CL5: =AY5*118% -> 838210.05 | CM5: =-Q5*118% -> -813895.56 | CN5: =-BW5*118% -> 0 | CO5: =-BX5*118% -> 0 | CP5: =SUM(CL5:CO5) -> 24314.49 | CQ5: Telangana - HO | CR5: Telangana - HO | CS5: =MID(G5,3,10) -> AALCB0491L | CT5: =MID(AR5,3,10) -> AEJFS8446P | CU5: 0 | CV5: 0 | CW5: 0 | CX5: 0 | CY5: 0
B6: ="Q" & IF(ROUNDUP(MONTH(D6)/3,0)-1=0,4,ROUNDUP(MONTH(D6)/3,0)-1) -> Q1 | C6: =TEXT(AN6,"mmm-yy") -> Apr-26 | D6: 46116 | E6: SH04261004 | F6: MK POLYPET INDIA PRIVATE LIMITED | G6: 29AAQCM8215Q1ZG | H6: MPI/26-27/6 | I6: 46116 | J6: 26-27/PUR/000396 | K6: 46122 | L6: KA | M6: KA569215 | N6: WASTE PLASTIC-PP | O6: 16490 | P6: 54.5 | Q6: =O6*P6 -> 898705 | R6: 0 | S6: =O6-R6 -> 16490 | T6: 0 | U6: 0 | V6: 0 | W6: 0 | X6: 0 | Y6: 0 | Z6: 0 | AA6: 0 | AB6: =Y6+AA6+Z6 -> 0 | AC6: 0 | AD6: =IFERROR((Q6+AB6)/S6,0) -> 54.5 | AE6: 0 | AF6: 36/PET/27VC00009 | AG6: 46129 | AH6: 0 | AI6: 0 | AJ6: 0 | AK6: -10965.85 | AL6: =(BK6*P6/AX6)+AB6/O6*(BK6/AX6) -> -22467.625 | AM6: =Q6+AB6+AL6+AK6+AJ6+T6+AE6 -> 865271.53 | AN6: 46122 | AO6: 36/PET/27IN00003 | AP6: 832139000000121856 | AQ6: J B ECOTEX LIMITED | AR6: 24AAFCJ3332A1Z9 | AS6: Kallur Karnataka 585330 | AT6: Surat | AU6: Gujarat | AV6: 182397339124 | AW6: 16490 | AX6: 55.5 | AY6: =AW6*AX6 -> 915195 | AZ6: =AW6=O6 -> TRUE | BA6: 0 | BB6: =AW6-BA6 -> 16490 | BC6: 0 | BD6: Regular | BE6: 0 | BF6: 0 | BG6: 0 | BH6: 0 | BI6: 0 | BJ6: 0 | BK6: =AY6*$BJ$3 -> -22879.875 | BL6: =AY6+BI6+BJ6+BK6+BC6 -> 892315.12 | BM6: =BL6-AM6 -> 27043.6 | BN6: =IF(BM6>=0,"Positive Margin","Negative Margin") -> Positive Margin | BO6: DN & CN Provision | BP6: =AY6-Y6-Q6-AA6-T6+BC6 -> 16490 | BQ6: =IF(BP6<0, "Negative Margin at Inception", "Positive Margin at Inception") -> Positive Margin at Inception | BR6: =IFERROR(BM6/BL6,"0") -> 0.03030723 | BS6: =IF(BR6<1%,"Less Than 1%",IF(BR6>2%,"More than 2%",IF(BR6>=1%,"1% - 2%"))) -> More than 2% | BT6: =BJ6+BK6 -> -22879.875 | BU6: =AL6+AK6 -> -33433.475 | BV6: =BT6-BU6 -> 10553.6 | BW6: =BJ6 -> 0 | BX6: =AK6 -> -10965.85 | BY6: =BW6-BX6 -> 10965.85 | BZ6: Marketplace (Plastic Waste) | CA6: 0 | CB6: =TEXT(AN6,"mmm-yy") -> Apr-26 | CC6: =AM6-AL6-AA6 -> 887739.15 | CD6: =BL6-BK6 -> 915195 | CE6: =INT((D6- IF(MONTH(D6) >= 4, DATE(YEAR(D6), 4, 1), DATE(YEAR(D6)-1, 4, 1))) / 7) + 1 -> 1 | CF6: Plastic | CG6: Plastic | CH6: =_xlfn.XLOOKUP(AR6,receivables!B:B,receivables!D:D) -> Neelesh Dixit | CI6: =AY6-Q6 -> 16490 | CJ6: =CI6-Y6+Z6 -> 16490 | CK6: =BL6-AM6 -> 27043.6 | CL6: =AY6*118% -> 1079930.1 | CM6: =-Q6*118% -> -1060471.9 | CN6: =-BW6*118% -> 0 | CO6: =-BX6*118% -> 12939.703 | CP6: =SUM(CL6:CO6) -> 32397.903 | CQ6: Telangana - HO | CR6: Telangana - HO | CS6: =MID(G6,3,10) -> AAQCM8215Q | CT6: =MID(AR6,3,10) -> AAFCJ3332A | CU6: 0 | CV6: 0 | CW6: 0 | CX6: 0 | CY6: 0
B7: ="Q" & IF(ROUNDUP(MONTH(D7)/3,0)-1=0,4,ROUNDUP(MONTH(D7)/3,0)-1) -> Q1 | C7: =TEXT(AN7,"mmm-yy") -> Apr-26 | D7: 46135 | E7: SH04262304 | F7: HITARTH ENTERPRISES | G7: 23AAPFH5775E1Z6 | H7: HE/26-27/10 | I7: 46135 | J7: 26-27/PUR/001402 | K7: 46136 | L7: MP | M7: UP24T8069 | N7: Hot washed PET flakes | O7: 8915 | P7: 66.5 | Q7: =O7*P7 -> 592847.5 | R7: 0 | S7: =O7-R7 -> 8915 | T7: 0 | U7: 0 | V7: 0 | W7: 0 | X7: 0 | Y7: 0 | Z7: 0 | AA7: 0 | AB7: =Y7+AA7+Z7 -> 0 | AC7: 0 | AD7: =IFERROR((Q7+AB7)/S7,0) -> 66.5 | AE7: 0 | AF7: 0 | AG7: 0 | AH7: 0 | AI7: 0 | AJ7: 0 | AK7: 0 | AL7: 0 | AM7: =Q7+AB7+AL7+AK7+AJ7+T7+AE7 -> 592847.5 | AN7: 46136 | AO7: 36/PET/27IN00004 | AP7: 832139000000024349 | AQ7: BLUEOCEAN ECOTECH LIMITED | AR7: 23AAICB1747Q1ZC | AS7: Pratap Pura, Madhya Pradesh 472246 | AT7: Bhopal | AU7: Madhya Pradesh | AV7: 0 | AW7: 8915 | AX7: 67 | AY7: =AW7*AX7 -> 597305 | AZ7: =AW7=O7 -> TRUE | BA7: 0 | BB7: =AW7-BA7 -> 8915 | BC7: 0 | BD7: Regular | BE7: 0 | BF7: 0 | BG7: 0 | BH7: 0 | BI7: 0 | BJ7: 0 | BK7: =AY7*$BJ$3 -> -14932.625 | BL7: =AY7+BI7+BJ7+BK7+BC7 -> 582372.38 | BM7: =BL7-AM7 -> -10475.125 | BN7: =IF(BM7>=0,"Positive Margin","Negative Margin") -> Negative Margin | BO7: Excess Qty DN | BP7: =AY7-Y7-Q7-AA7-T7+BC7 -> 4457.5 | BQ7: =IF(BP7<0, "Negative Margin at Inception", "Positive Margin at Inception") -> Positive Margin at Inception | BR7: =IFERROR(BM7/BL7,"0") -> -0.017986988 | BS7: =IF(BR7<1%,"Less Than 1%",IF(BR7>2%,"More than 2%",IF(BR7>=1%,"1% - 2%"))) -> Less Than 1% | BT7: =BJ7+BK7 -> -14932.625 | BU7: =AL7+AK7 -> 0 | BV7: =BT7-BU7 -> -14932.625 | BW7: =BJ7 -> 0 | BX7: =AK7 -> 0 | BY7: =BW7-BX7 -> 0 | BZ7: Marketplace (Plastic Waste) | CA7: 0 | CB7: =TEXT(AN7,"mmm-yy") -> Apr-26 | CC7: =AM7-AL7-AA7 -> 592847.5 | CD7: =BL7-BK7 -> 597305 | CE7: =INT((D7- IF(MONTH(D7) >= 4, DATE(YEAR(D7), 4, 1), DATE(YEAR(D7)-1, 4, 1))) / 7) + 1 -> 4 | CF7: Plastic | CG7: Plastic | CH7: =_xlfn.XLOOKUP(AR7,receivables!B:B,receivables!D:D) -> Neelesh Dixit | CI7: =AY7-Q7 -> 4457.5 | CJ7: =CI7-Y7+Z7 -> 4457.5 | CK7: =BL7-AM7 -> -10475.125 | CL7: =AY7*118% -> 704819.9 | CM7: =-Q7*118% -> -699560.05 | CN7: =-BW7*118% -> 0 | CO7: =-BX7*118% -> 0 | CP7: =SUM(CL7:CO7) -> 5259.85 | CQ7: Telangana - HO | CR7: Telangana - HO | CS7: =MID(G7,3,10) -> AAPFH5775E | CT7: =MID(AR7,3,10) -> AAICB1747Q | CU7: 0 | CV7: 0 | CW7: 0 | CX7: 0 | CY7: 0
F9: Total | O9: =SUBTOTAL(9,O5:O8) -> 36250 | Q9: =SUBTOTAL(9,Q5:Q8) -> 2181294.5 | S9: =SUBTOTAL(9,S5:S8) -> 36250 | T9: =SUBTOTAL(9,T5:T8) -> 0 | Y9: =SUBTOTAL(9,Y5:Y8) -> 0 | Z9: =SUBTOTAL(9,Z5:Z8) -> 0 | AA9: =SUBTOTAL(9,AA5:AA8) -> 0 | AB9: =SUBTOTAL(9,AB5:AB8) -> 0 | AC9: =SUBTOTAL(9,AC5:AC8) -> 0 | AD9: =SUBTOTAL(1,AD5:AD8) -> 61.533333 | AE9: =SUBTOTAL(9,AE5:AE8) -> 0 | AJ9: =SUBTOTAL(9,AJ5:AJ8) -> 0 | AK9: =SUBTOTAL(9,AK5:AK8) -> -10965.85 | AL9: =SUBTOTAL(9,AL5:AL8) -> -22467.625 | AM9: =SUBTOTAL(9,AM5:AM8) -> 2147861 | AW9: =SUBTOTAL(9,AW5:AW8) -> 36250 | AX9: =SUBTOTAL(101,AX5:AX8) -> 62.666667 | AY9: =SUBTOTAL(9,AY5:AY8) -> 2222847.5 | BA9: =SUBTOTAL(9,BA5:BA8) -> 0 | BB9: =SUBTOTAL(9,BB5:BB8) -> 36250 | BC9: =SUBTOTAL(9,BC5:BC8) -> 0 | BI9: =SUBTOTAL(9,BI5:BI8) -> 0 | BJ9: =SUBTOTAL(9,BJ5:BJ8) -> 0 | BK9: =SUBTOTAL(9,BK5:BK8) -> -37812.5 | BL9: =SUBTOTAL(9,BL5:BL8) -> 2185035 | BM9: =SUBTOTAL(9,BM5:BM8) -> 37173.975 | BP9: =SUBTOTAL(9,BP5:BP8) -> 41553 | BT9: =SUBTOTAL(9,BT5:BT8) -> -37812.5 | BU9: =SUBTOTAL(9,BU5:BU8) -> -33433.475 | BV9: =SUBTOTAL(9,BV5:BV8) -> -4379.025 | BW9: =SUBTOTAL(9,BW5:BW8) -> 0 | BX9: =SUBTOTAL(9,BX5:BX8) -> -10965.85 | BY9: =SUBTOTAL(9,BY5:BY8) -> 10965.85 | CC9: =SUBTOTAL(9,CC5:CC8) -> 2170328.6 | CD9: =SUBTOTAL(9,CD5:CD8) -> 2222847.5 | CI9: =SUBTOTAL(9,CI5:CI8) -> 41553 | CJ9: =SUBTOTAL(9,CJ5:CJ8) -> 41553 | CK9: =SUBTOTAL(9,CK5:CK8) -> 37173.975 | CL9: =SUBTOTAL(9,CL5:CL8) -> 2622960 | CM9: =SUBTOTAL(9,CM5:CM8) -> -2573927.5 | CN9: =SUBTOTAL(9,CN5:CN8) -> 0 | CO9: =SUBTOTAL(9,CO5:CO8) -> 12939.703 | CP9: =SUBTOTAL(9,CP5:CP8) -> 61972.243
N10: =O9-AW9+'Recon Items'!R31 -> 0 | P10: =Q9+AK9+AJ9+AL9+T9+AE9 -> 2147861 | Q10: =Q9*18% -> 392633.01 | R10: =Q10*25% -> 98158.253 | AA10: =AB9/AY9 -> 0 | AC10: =+AL9+AK9 -> -33433.475 | AI10: Total DN in FY 2025-26 | AJ10: =AK9+AJ9+AE9 -> -10965.85 | AM10: =AM9*18% -> 386614.98 | BE10: Total CN in FY 2025-26 | BF10: =BI9+BJ9+BC9+BJ18 -> 0 | BH10: =BF10/AY9 -> 0 | BK10: =BM9/BL9 -> 0.017012988 | BO10: =BP9/AY9 -> 0.01869359 | BU10: =BU9/BT9 -> 0.88419107 | BX10: =IFERROR(BX9/BW9,0) -> 0 | CA10: With GST | CB10: =CC9*118% -> 2560987.8 | CC10: =CD9*118% -> 2622960
AI11: Total DN of FY 2024-25 | AJ11: =-'Last year''s'!F30 -> -718187.35 | BE11: Total CN of FY 2024-25 | BF11: =-'Last year''s'!L30 -> -729139.49
B12: Quarter | C12: Month | D12: Date | E12: Shipment ID | F12: Supplier Name | G12: GST Reg No. | H12: Vendor Invoice No. | I12: Vendor Invoice Date | J12: P V No. | K12: P V Date | L12: State (Origin) | M12: Vehicle No. | N12: Material | O12: Qty (Kg) | P12: Price/Kg | Q12: Purchase Price | R12: Return Qty | S12: Net Qty | T12: Basic Customs Duty | U12: Transporter Name | V12: LR NO/BILL NO | W12: J V No. | X12: JV Date | Y12: Logistics cost | Z12: Debit note on logistic cost | AA12: Logistics Provision | AB12: Total Logistics Cost | AC12: Operational Cost | AD12: Cost/Kg. | AE12: Divertion/Internal | AF12: Debit Note No. | AG12: Debit Note Date. | AH12: Debit Note No. 2 | AI12: Debit Note Date. 2 | AJ12: Full Debit Note | AK12: Actual Debit Note | AL12: Provision for DN | AM12: Total Cost | AN12: Inv. Date | AO12: Inv. No. | AP12: Customer ID | AQ12: Buyer Name | AR12: Buyer GST Number | AS12: Location (Origin) | AT12: Location (Destination) | AU12: State (Destination) | AV12: E-WayBill Number | AW12: Qty(Kg) | AX12: Rate/Kg | AY12: Amount | AZ12: Qty Check | BA12: Return Qty | BB12: Net Qty | BC12: Divertion/Internal | BD12: Return Type | BE12: Credit Note No:1 | BF12: CN Date. No:1 | BG12: Credit Note No:2 | BH12: CN Date. No:2 | BI12: Full Credit Notes | BJ12: Actual Credit Note | BK12: Provision for CN | BL12: Net Revenue | BM12: Margin | BN12: Reamrks - Margin | BO12: Remarks | BP12: LMI @ Inception | BQ12: Remarks @ Inception | BR12: Margin (%) | BS12: Margin Bucket | BT12: Total CN(Inc.Provisions) | BU12: Total DN(Inc.Provisions) | BV12: Check | BW12: Actaul CN | BX12: Actual DN | BY12: Check | BZ12: Material-Short Form | CA12: Supplier Type | CB12: Month | CC12: Cost | CD12: Revenue | CE12: Week No: | CF12: Category (Material) | CG12: Broad Category | CH12: POC Name | CI12: Gross Margin | CJ12: Recykal Margin | CK12: Net Margin | CL12: Sales | CM12: Purchases | CN12: Credit Note | CO12: Debit Note | CP12: Margin | CQ12: Bill Branch | CR12: Inv Branch | CS12: Vendor PAN No | CT12: Customer PAN No | CU12: GST TDS Applicability | CV12: Cash Discount(Provision) | CW12: Cash Discount | CX12: Cash Discount. No | CY12: CD Date
B13: Q2 | C13: =TEXT(AN13,"mmm-yy") -> Apr-26 | D13: =AN13 -> 46122 | E13: 0 | F13: 0 | G13: 0 | H13: 0 | I13: 0 | J13: 0 | K13: 0 | L13: 0 | M13: 0 | N13: 0 | O13: 0 | P13: 0 | Q13: =O13*P13 -> 0 | R13: 0 | S13: =O13-R13 -> 0 | T13: 0 | U13: 0 | V13: 0 | W13: 0 | X13: 0 | Y13: 0 | Z13: 0 | AA13: 0 | AB13: =Y13+AA13+Z13 -> 0 | AC13: 0 | AD13: =IFERROR((Q13+AB13)/S13,0) -> 0 | AE13: 0 | AF13: 0 | AG13: 0 | AH13: 0 | AI13: 0 | AJ13: 0 | AK13: 0 | AL13: 0 | AM13: =Q13+AB13+AL13+AK13+AJ13+T13+AE13 -> 0 | AN13: 46122 | AO13: 36/PET/27DN00001 | AP13: 832139000000027397 | AQ13: Sri Chakra Poly Plast India Private Limited | AR13: 36AAOCS6150Q1ZJ | AT13: Kandi | AU13: Telangana | AV13: 0 | AW13: 1 | AX13: 303019 | AY13: =AW13*AX13 -> 303019 | AZ13: =AW13=O13 -> FALSE | BA13: 0 | BB13: =AW13-BA13 -> 1 | BC13: 0 | BD13: Regular | BE13: 36/PET/27CN00010 | BF13: 46167 | BG13: 0 | BH13: 0 | BI13: -303019 | BJ13: 0 | BK13: 0 | BL13: =AY13+BI13+BJ13+BK13+BC13 -> 0 | BM13: =BL13-AM13 -> 0 | BN13: =IF(BM13>=0,"Positive Margin","Negative Margin") -> Positive Margin | BO13: Finance Up Charges | BP13: =AY13-Y13-Q13-AA13-T13+BC13 -> 303019 | BQ13: =IF(BP13<0, "Negative Margin at Inception", "Positive Margin at Inception") -> Positive Margin at Inception | BR13: =IFERROR(BM13/BL13,"0") -> 0 | BS13: =IF(BR13<1%,"Less Than 1%",IF(BR13>2%,"More than 2%",IF(BR13>=1%,"1% - 2%"))) -> More than 2% | BT13: =BJ13+BK13 -> 0 | BU13: =AL13+AK13 -> 0 | BV13: =BT13-BU13 -> 0 | BW13: =BJ13 -> 0 | BX13: =AK13 -> 0 | BY13: =BW13-BX13 -> 0 | BZ13: Marketplace (Plastic Waste) | CA13: 0 | CB13: =TEXT(AN13,"mmm-yy") -> Apr-26 | CC13: =AM13-AL13-AA13 -> 0 | CD13: =BL13-BK13 -> 0 | CE13: =INT((D13- IF(MONTH(D13) >= 4, DATE(YEAR(D13), 4, 1), DATE(YEAR(D13)-1, 4, 1))) / 7) + 1 -> 2 | CF13: Plastic | CG13: Plastic | CH13: =_xlfn.XLOOKUP(AR13,receivables!B:B,receivables!D:D) -> #N/A | CI13: =AY13-Q13 -> 303019 | CJ13: =CI13-Y13+Z13 -> 303019 | CK13: =BL13-AM13 -> 0 | CL13: =AY13*118% -> 357562.42 | CM13: =-Q13*118% -> 0 | CN13: =-BW13*118% -> 0 | CO13: =-BX13*118% -> 0 | CP13: =SUM(CL13:CO13) -> 357562.42 | CQ13: Telangana - HO | CR13: Telangana - HO | CS13: =MID(G13,3,10) | CT13: =MID(AR13,3,10) -> AAOCS6150Q | CU13: 0 | CV13: 0 | CW13: 0 | CX13: 0 | CY13: 0
B14: Q2 | C14: =TEXT(AN14,"mmm-yy") -> Apr-26 | D14: =AN14 -> 46125 | E14: 0 | F14: 0 | G14: 0 | H14: 0 | I14: 0 | J14: 0 | K14: 0 | L14: 0 | M14: 0 | N14: 0 | O14: 0 | P14: 0 | Q14: =O14*P14 -> 0 | R14: 0 | S14: =O14-R14 -> 0 | T14: 0 | U14: 0 | V14: 0 | W14: 0 | X14: 0 | Y14: 0 | Z14: 0 | AA14: 0 | AB14: =Y14+AA14+Z14 -> 0 | AC14: 0 | AD14: =IFERROR((Q14+AB14)/S14,0) -> 0 | AE14: 0 | AF14: 0 | AG14: 0 | AH14: 0 | AI14: 0 | AJ14: 0 | AK14: 0 | AL14: 0 | AM14: =Q14+AB14+AL14+AK14+AJ14+T14+AE14 -> 0 | AN14: 46125 | AO14: 36/PET/27DN00002 | AP14: 832139000000022933 | AQ14: Apex International | AR14: 05AAQFA3937J1Z7 | AT14: KASHIPUR | AU14: Uttarakhand | AV14: 0 | AW14: 1 | AX14: 608652.03 | AY14: =AW14*AX14 -> 608652.03 | AZ14: =AW14=O14 -> FALSE | BA14: 0 | BB14: =AW14-BA14 -> 1 | BC14: 0 | BD14: Regular | BE14: 0 | BF14: 0 | BG14: 0 | BH14: 0 | BI14: 0 | BJ14: 0 | BK14: 0 | BL14: =AY14+BI14+BJ14+BK14+BC14 -> 608652.03 | BM14: =BL14-AM14 -> 608652.03 | BN14: =IF(BM14>=0,"Positive Margin","Negative Margin") -> Positive Margin | BO14: Finance Up Charges | BP14: =AY14-Y14-Q14-AA14-T14+BC14 -> 608652.03 | BQ14: =IF(BP14<0, "Negative Margin at Inception", "Positive Margin at Inception") -> Positive Margin at Inception | BR14: =IFERROR(BM14/BL14,"0") -> 1 | BS14: =IF(BR14<1%,"Less Than 1%",IF(BR14>2%,"More than 2%",IF(BR14>=1%,"1% - 2%"))) -> More than 2% | BT14: =BJ14+BK14 -> 0 | BU14: =AL14+AK14 -> 0 | BV14: =BT14-BU14 -> 0 | BW14: =BJ14 -> 0 | BX14: =AK14 -> 0 | BY14: =BW14-BX14 -> 0 | BZ14: Marketplace (Plastic Waste) | CA14: 0 | CB14: =TEXT(AN14,"mmm-yy") -> Apr-26 | CC14: =AM14-AL14-AA14 -> 0 | CD14: =BL14-BK14 -> 608652.03 | CE14: =INT((D14- IF(MONTH(D14) >= 4, DATE(YEAR(D14), 4, 1), DATE(YEAR(D14)-1, 4, 1))) / 7) + 1 -> 2 | CF14: Plastic | CG14: Plastic | CH14: =_xlfn.XLOOKUP(AR14,receivables!B:B,receivables!D:D) -> #N/A | CI14: =AY14-Q14 -> 608652.03 | CJ14: =CI14-Y14+Z14 -> 608652.03 | CK14: =BL14-AM14 -> 608652.03 | CL14: =AY14*118% -> 718209.4 | CM14: =-Q14*118% -> 0 | CN14: =-BW14*118% -> 0 | CO14: =-BX14*118% -> 0 | CP14: =SUM(CL14:CO14) -> 718209.4 | CQ14: Telangana - HO | CR14: Telangana - HO | CS14: =MID(G14,3,10) | CT14: =MID(AR14,3,10) -> AAQFA3937J | CU14: 0 | CV14: 0 | CW14: 0 | CX14: 0 | CY14: 0
B15: Q2 | C15: =TEXT(AN15,"mmm-yy") -> Apr-26 | D15: =AN15 -> 46125 | E15: 0 | F15: 0 | G15: 0 | H15: 0 | I15: 0 | J15: 0 | K15: 0 | L15: 0 | M15: 0 | N15: 0 | O15: 0 | P15: 0 | Q15: =O15*P15 -> 0 | R15: 0 | S15: =O15-R15 -> 0 | T15: 0 | U15: 0 | V15: 0 | W15: 0 | X15: 0 | Y15: 0 | Z15: 0 | AA15: 0 | AB15: =Y15+AA15+Z15 -> 0 | AC15: 0 | AD15: =IFERROR((Q15+AB15)/S15,0) -> 0 | AE15: 0 | AF15: 0 | AG15: 0 | AH15: 0 | AI15: 0 | AJ15: 0 | AK15: 0 | AL15: 0 | AM15: =Q15+AB15+AL15+AK15+AJ15+T15+AE15 -> 0 | AN15: 46125 | AO15: 36/PET/27DN00003 | AP15: 832139000007459042 | AQ15: JAINARAIN FABTECH LIMITED | AR15: 09AADCJ2313B1Z6 | AT15: Meerut | AU15: Uttar Pradesh | AV15: 0 | AW15: 1 | AX15: 755024 | AY15: =AW15*AX15 -> 755024 | AZ15: =AW15=O15 -> FALSE | BA15: 0 | BB15: =AW15-BA15 -> 1 | BC15: 0 | BD15: Regular | BE15: 0 | BF15: 0 | BG15: 0 | BH15: 0 | BI15: 0 | BJ15: 0 | BK15: 0 | BL15: =AY15+BI15+BJ15+BK15+BC15 -> 755024 | BM15: =BL15-AM15 -> 755024 | BN15: =IF(BM15>=0,"Positive Margin","Negative Margin") -> Positive Margin | BO15: Finance Up Charges | BP15: =AY15-Y15-Q15-AA15-T15+BC15 -> 755024 | BQ15: =IF(BP15<0, "Negative Margin at Inception", "Positive Margin at Inception") -> Positive Margin at Inception | BR15: =IFERROR(BM15/BL15,"0") -> 1 | BS15: =IF(BR15<1%,"Less Than 1%",IF(BR15>2%,"More than 2%",IF(BR15>=1%,"1% - 2%"))) -> More than 2% | BT15: =BJ15+BK15 -> 0 | BU15: =AL15+AK15 -> 0 | BV15: =BT15-BU15 -> 0 | BW15: =BJ15 -> 0 | BX15: =AK15 -> 0 | BY15: =BW15-BX15 -> 0 | BZ15: Marketplace (Plastic Waste) | CA15: 0 | CB15: =TEXT(AN15,"mmm-yy") -> Apr-26 | CC15: =AM15-AL15-AA15 -> 0 | CD15: =BL15-BK15 -> 755024 | CE15: =INT((D15- IF(MONTH(D15) >= 4, DATE(YEAR(D15), 4, 1), DATE(YEAR(D15)-1, 4, 1))) / 7) + 1 -> 2 | CF15: Plastic | CG15: Plastic | CH15: =_xlfn.XLOOKUP(AR15,receivables!B:B,receivables!D:D) -> #N/A | CI15: =AY15-Q15 -> 755024 | CJ15: =CI15-Y15+Z15 -> 755024 | CK15: =BL15-AM15 -> 755024 | CL15: =AY15*118% -> 890928.32 | CM15: =-Q15*118% -> 0 | CN15: =-BW15*118% -> 0 | CO15: =-BX15*118% -> 0 | CP15: =SUM(CL15:CO15) -> 890928.32 | CQ15: Telangana - HO | CR15: Telangana - HO | CS15: =MID(G15,3,10) | CT15: =MID(AR15,3,10) -> AADCJ2313B | CU15: 0 | CV15: 0 | CW15: 0 | CX15: 0 | CY15: 0
B16: Q2 | C16: =TEXT(AN16,"mmm-yy") -> Apr-26 | D16: =AN16 -> 46132 | E16: 0 | F16: 0 | G16: 0 | H16: 0 | I16: 0 | J16: 0 | K16: 0 | L16: 0 | M16: 0 | N16: 0 | O16: 0 | P16: 0 | Q16: =O16*P16 -> 0 | R16: 0 | S16: =O16-R16 -> 0 | T16: 0 | U16: 0 | V16: 0 | W16: 0 | X16: 0 | Y16: 0 | Z16: 0 | AA16: 0 | AB16: =Y16+AA16+Z16 -> 0 | AC16: 0 | AD16: =IFERROR((Q16+AB16)/S16,0) -> 0 | AE16: 0 | AF16: 0 | AG16: 0 | AH16: 0 | AI16: 0 | AJ16: 0 | AK16: 0 | AL16: 0 | AM16: =Q16+AB16+AL16+AK16+AJ16+T16+AE16 -> 0 | AN16: 46132 | AO16: 36/PET/27DN00004 | AP16: 832139000058476217 | AQ16: NATIONAL FIBRES PRIVATE LIMITED | AR16: 26AAICN2675D1ZG | AT16: Silvassa | AU16: Dadra and Nagar Haveli and Daman and Diu | AV16: 0 | AW16: 1 | AX16: 395165.28 | AY16: =AW16*AX16 -> 395165.28 | AZ16: =AW16=O16 -> FALSE | BA16: 0 | BB16: =AW16-BA16 -> 1 | BC16: 0 | BD16: Regular | BE16: 36/PET/27CN00011 | BF16: 46168 | BG16: 0 | BH16: 0 | BI16: -395165.28 | BJ16: 0 | BK16: 0 | BL16: =AY16+BI16+BJ16+BK16+BC16 -> 0 | BM16: =BL16-AM16 -> 0 | BN16: =IF(BM16>=0,"Positive Margin","Negative Margin") -> Positive Margin | BO16: Finance Up Charges | BP16: =AY16-Y16-Q16-AA16-T16+BC16 -> 395165.28 | BQ16: =IF(BP16<0, "Negative Margin at Inception", "Positive Margin at Inception") -> Positive Margin at Inception | BR16: =IFERROR(BM16/BL16,"0") -> 0 | BS16: =IF(BR16<1%,"Less Than 1%",IF(BR16>2%,"More than 2%",IF(BR16>=1%,"1% - 2%"))) -> More than 2% | BT16: =BJ16+BK16 -> 0 | BU16: =AL16+AK16 -> 0 | BV16: =BT16-BU16 -> 0 | BW16: =BJ16 -> 0 | BX16: =AK16 -> 0 | BY16: =BW16-BX16 -> 0 | BZ16: Marketplace (Plastic Waste) | CA16: 0 | CB16: =TEXT(AN16,"mmm-yy") -> Apr-26 | CC16: =AM16-AL16-AA16 -> 0 | CD16: =BL16-BK16 -> 0 | CE16: =INT((D16- IF(MONTH(D16) >= 4, DATE(YEAR(D16), 4, 1), DATE(YEAR(D16)-1, 4, 1))) / 7) + 1 -> 3 | CF16: Plastic | CG16: Plastic | CH16: =_xlfn.XLOOKUP(AR16,receivables!B:B,receivables!D:D) -> #N/A | CI16: =AY16-Q16 -> 395165.28 | CJ16: =CI16-Y16+Z16 -> 395165.28 | CK16: =BL16-AM16 -> 0 | CL16: =AY16*118% -> 466295.03 | CM16: =-Q16*118% -> 0 | CN16: =-BW16*118% -> 0 | CO16: =-BX16*118% -> 0 | CP16: =SUM(CL16:CO16) -> 466295.03 | CQ16: Telangana - HO | CR16: Telangana - HO | CS16: =MID(G16,3,10) | CT16: =MID(AR16,3,10) -> AAICN2675D | CU16: 0 | CV16: 0 | CW16: 0 | CX16: 0 | CY16: 0
F18: Total | O18: =SUBTOTAL(9,O13:O17) -> 0 | Q18: =SUBTOTAL(9,Q13:Q17) -> 0 | R18: =SUBTOTAL(9,R13:R17) -> 0 | S18: =SUBTOTAL(9,S13:S17) -> 0 | T18: =SUBTOTAL(9,T13:T17) -> 0 | Y18: =SUBTOTAL(9,Y13:Y17) -> 0 | Z18: =SUBTOTAL(9,Z13:Z17) -> 0 | AA18: =SUBTOTAL(9,AA13:AA17) -> 0 | AB18: =SUBTOTAL(9,AB13:AB17) -> 0 | AC18: =SUBTOTAL(9,AC13:AC17) -> 0 | AD18: =SUBTOTAL(9,AD13:AD17) -> 0 | AE18: =SUBTOTAL(9,AE13:AE17) -> 0 | AF18: =SUBTOTAL(9,AF13:AF17) -> 0 | AG18: =SUBTOTAL(9,AG13:AG17) -> 0 | AJ18: =SUBTOTAL(9,AJ13:AJ17) -> 0 | AK18: =SUBTOTAL(9,AK13:AK17) -> 0 | AL18: =SUBTOTAL(9,AL13:AL17) -> 0 | AM18: =SUBTOTAL(9,AM13:AM17) -> 0 | AW18: =SUBTOTAL(9,AW13:AW17) -> 4 | AY18: =SUBTOTAL(9,AY13:AY17) -> 2061860.3 | BA18: =SUBTOTAL(9,BA13:BA17) -> 0 | BB18: =SUBTOTAL(9,BB13:BB17) -> 4 | BC18: =SUBTOTAL(9,BC13:BC17) -> 0 | BI18: =SUBTOTAL(9,BI13:BI17) -> -698184.28 | BJ18: =SUBTOTAL(9,BJ13:BJ17) -> 0 | BK18: =SUBTOTAL(9,BK13:BK17) -> 0 | BL18: =SUBTOTAL(9,BL13:BL17) -> 1363676 | BM18: =SUBTOTAL(9,BM13:BM17) -> 1363676 | BP18: =SUBTOTAL(9,BP13:BP17) -> 2061860.3 | BT18: =SUBTOTAL(9,BT13:BT17) -> 0 | BU18: =SUBTOTAL(9,BU13:BU17) -> 0 | BV18: =SUBTOTAL(9,BV13:BV17) -> 0 | BW18: =SUBTOTAL(9,BW13:BW17) -> 0 | BX18: =SUBTOTAL(9,BX13:BX17) -> 0 | BY18: =SUBTOTAL(9,BY13:BY17) -> 0 | CC18: =SUBTOTAL(9,CC13:CC17) -> 0 | CD18: =SUBTOTAL(9,CD13:CD17) -> 1363676 | CI18: =SUBTOTAL(9,CI13:CI17) -> 2061860.3 | CJ18: =SUBTOTAL(9,CJ13:CJ17) -> 2061860.3 | CK18: =SUBTOTAL(9,CK13:CK17) -> 1363676 | CL18: =SUBTOTAL(9,CL13:CL17) -> 2432995.2 | CM18: =SUBTOTAL(9,CM13:CM17) -> 0 | CN18: =SUBTOTAL(9,CN13:CN17) -> 0 | CO18: =SUBTOTAL(9,CO13:CO17) -> 0 | CP18: =SUBTOTAL(9,CP13:CP17) -> 2432995.2
N20: Particulars | O20: Amount | AA20: Particulars | AC20: Amount | AX20: Particulars | AY20: Amount
N21: Net Purchase as per report | O21: =Q9+AJ9+AK9+AE9+Q18+AK18 -> 2170328.6 | AA21: Net Logistic Cost as per report | AC21: =Y9+Z9 -> 0 | AX21: Net Sales As per report | AY21: =+AY9+BI9+BJ9+BC9+AY18+BJ18+BI18+BC18 -> 3586523.5
N22: As per ZOHO | O22: 1778946.3 | P22: 46194 | AA22: As per ZOHO | AC22: 0 | AD22: =P22 -> 46194 | AX22: As per ZOHO | AY22: 3173162 | AZ22: =P22 -> 46194
N23: Variance | O23: =O22-O21 -> -391382.33 | AA23: Variance | AC23: =-(AC22-AC21) -> 0 | AX23: Variance | AY23: =AY21-AY22 -> 413361.58
N24: Provision for DN to Vendors(Fy 2024-25) | O24: ='Last year''s'!F3 -> 309308 | AA24: Fy 2024-25 Logistic Provision Reversal | AC24: 0 | AX24: CN Provision in Zoho FY 25-26 | AY24: ='Last year''s'!L3 -> 315777.91
N25: JV for last year Bills | O25: 0 | AA25: FY 2025-26 Logistics | AC25: 0 | AX25: FY 2025-26 Credit notes | AY25: =-'Last year''s'!L30 -> -729139.49
N26: Debit note FY 25-26 | O26: ='Last year''s'!F30 -> 718187.35 | AA26: Provision for Logistics (Fy 2025-26) | AC26: 0 | AX26: Provision for CN from Customers(Fy 2025-26) | AY26: 0
N27: Paper | O27: =-'Recon Items'!C46 -> 0 | AA27: Paper | AC27: =-'Recon Items'!K56 -> 0 | AX27: Paper | AY27: ='Recon Items'!G46 -> 0
N28: Reconciliation | O28: ='Recon Items'!G18-'Recon Items'!C18-'Recon Items'!N18+'Recon Items'!C43 -> 17497.02 | AA28: Reconciliation | AC28: ='Recon Items'!K42 -> 0 | AX28: Reconciliation | AY28: =-'Recon Items'!C29+'Recon Items'!G29+'Recon Items'!R24+'Recon Items'!H43 -> 0
N29: Variance | O29: =O23+O26-O28-O25-O24-O27 -> 1.1641532e-10 | AA29: Variance | AC29: =SUM(AC23:AC28) -> 0 | AX29: Final Variance | AY29: =AY23+AY25+AY28+AY24-AY26-AY27 -> 5.8207661e-11
BG42: =SUM(BG36:BG41) -> 0
BG43: =BG35-BG42 -> 0
AK49: =AK50-AK51 -> 0

Sheet Recon Items
J3: Qty Reco | M3: FY 2025-26 bills considered ths year | Q3: FY 2025-26
B4: Bills in report not in P&L | C4: Amount | F4: Bills in P&L not in report | G4: Amount | H4: Qty | J4: Qty Check | K4: =Details!AD22 -> 46194 | M4: Bills in report not in P&L | N4: Amount | O4: Qty | Q4: DN to Customer | R4: Amount
M5: SH022606031 | N5: 11011.02 | O5: 1
J6: As Per Report | K6: =-Details!AW9 -> -36250 | M6: SH012627021 | N6: 4536 | O6: 70
J7: As per Zoho(till last month) | K7: 36351 | M7: SH012621039 | N7: 1950 | O7: 30
J8: As per Zoho (current month) | K8: 0
J9: Reco | K9: =R31+I42 -> 0
J10: Variance | K10: =SUM(K6:K9)-H18-O18 -> 0
J14: BCD not in Report | K14: Amount
B18: G.Total | C18: =SUM(C5:C17) -> 0 | F18: G.Total | G18: =SUBTOTAL(9,G5:G17) -> 0 | H18: =SUBTOTAL(9,H5:H17) -> 0 | K18: =SUM(K15:K17) -> 0 | M18: G.Total | N18: =-SUM(N5:N17) -> -17497.02 | O18: =SUM(O5:O17) -> 101
B21: Sales in report not in P&L | C21: Amount | F21: Sales in P&L not in report | G21: Amount | H21: Qty | J21: Bils in Report & P&L , Sale yet to be done
Q24: G.Total | R24: =SUM(R5:R23) -> 0
Q25: Offline orders & Divertions
Q26: SO Number | R26: Qty
B29: G.Total | C29: =SUM(C22:C28) -> 0 | F29: G.Total | G29: =SUBTOTAL(9,G22:G28) -> 0 | H29: 0 | J29: G.Total
B31: DRS | Q31: G.Total | R31: =SUM(R27:R30) -> 0
B32: Bills | C32: Amount | D32: DN | F32: Invoices | G32: Amount | H32: CN | I32: Qty | J32: Logistic Bill | K32: Amount
B42: G.Total | C42: =SUM(C33:C41) -> 0 | D42: =SUM(D33:D41) -> 0 | F42: G.Total | G42: =SUBTOTAL(9,G33:G41) -> 0 | H42: =SUBTOTAL(9,H33:H41) -> 0 | I42: =SUBTOTAL(9,I33:I41) -> 0 | J42: G.Total | K42: =SUBTOTAL(9,K33:K41) -> 0
C43: =C42-D42 -> 0 | H43: =G42+H42 -> 0
B46: Paper | C46: =C56-D56 -> 0 | G46: =G56-H56 -> 0
B47: Bills | C47: Amount | D47: DN | F47: Invoices | G47: Amount | H47: CN | I47: Qty | J47: Logistic Bill | K47: Amount
B56: G.Total | C56: =SUM(C48:C55) -> 0 | D56: =SUM(D48:D55) -> 0 | F56: G.Total | G56: =SUBTOTAL(9,G48:G55) -> 0 | H56: =SUBTOTAL(9,H48:H55) -> 0 | I56: =SUBTOTAL(9,I48:I55) -> 0 | J56: G.Total | K56: =SUBTOTAL(9,K48:K55) -> 0
AB696: -568957
AB701: =-AB697+AB698-AB699 -> 0

Sheet Supplier Metrics
D1: =D2-Summary!Q7 -> 0
D2: =SUBTOTAL(9,D4:D25) -> 2147861 | E2: =COUNTA(_xlfn.ANCHORARRAY(E4)) -> 3
B3: Supplier Name | C3: GST Reg No. | D3: Purchases | E3: Count Supplier Name
B4: =_xlfn.XLOOKUP(C4,Details!$G$5:$G$8,Details!$F$5:$F$8) -> BHAGIRATHI POLYMER PRIVATE LIMITED | C4: {=_xlfn.UNIQUE(_xlfn._TRO_TRAILING(Details!G5:G8))} -> 09AALCB0491L1ZA | D4: =SUMIFS(Details!$AM$5:$AM$8,Details!$G$5:$G$8,'Supplier Metrics'!C4)-SUMIFS(Details!$AB$5:$AB$8,Details!$G$5:$G$8,'Supplier Metrics'!C4) -> 689742 | E4: {=_xlfn.UNIQUE(MID(_xlfn._TRO_TRAILING(Details!G5:G8),3,10))} -> AALCB0491L
B5: =_xlfn.XLOOKUP(C5,Details!$G$5:$G$8,Details!$F$5:$F$8) -> MK POLYPET INDIA PRIVATE LIMITED | C5: 29AAQCM8215Q1ZG | D5: =SUMIFS(Details!$AM$5:$AM$8,Details!$G$5:$G$8,'Supplier Metrics'!C5)-SUMIFS(Details!$AB$5:$AB$8,Details!$G$5:$G$8,'Supplier Metrics'!C5) -> 865271.53 | E5: AAQCM8215Q
B6: =_xlfn.XLOOKUP(C6,Details!$G$5:$G$8,Details!$F$5:$F$8) -> HITARTH ENTERPRISES | C6: 23AAPFH5775E1Z6 | D6: =SUMIFS(Details!$AM$5:$AM$8,Details!$G$5:$G$8,'Supplier Metrics'!C6)-SUMIFS(Details!$AB$5:$AB$8,Details!$G$5:$G$8,'Supplier Metrics'!C6) -> 592847.5 | E6: AAPFH5775E
B7: =_xlfn.XLOOKUP(C7,Details!$G$5:$G$8,Details!$F$5:$F$8) -> 0 | D7: =SUMIFS(Details!$AM$5:$AM$8,Details!$G$5:$G$8,'Supplier Metrics'!C7)-SUMIFS(Details!$AB$5:$AB$8,Details!$G$5:$G$8,'Supplier Metrics'!C7) -> 0

Sheet Buyer Metrics
F2: =F3-Summary!P6-Details!BL18 -> -1345917.3 | G2: =G3-Summary!P12-Summary!P75-Details!BM18 -> -1363160.9 | H2: =H3-Summary!P13 -> 9.8284264e-05 | I2: =I3-Details!BW9 -> 0 | K2: =K3-Summary!P19 -> 0 | S2: Revenue | AD2: Qty
B3: =COUNTA(_xlfn.ANCHORARRAY(B5)) -> 3 | C3: =COUNTA(_xlfn.ANCHORARRAY(C5)) -> 3 | E3: =SUM(E$5:E5) -> 10845 | F3: =SUM(F$5:F83) -> 2185035 | G3: =SUM(G$5:G83) -> 37173.975 | H3: =G3/F3 -> 0.017012988 | I3: =SUM(I$5:I83) -> 0 | J3: =I3/F3 -> 0 | K3: =SUM(K$5:K83) -> 3 | L3: =SUBTOTAL(1,L5:L83) -> 728345 | M3: =F3/E3 -> 201.47856 | N3: =SUM(N$5:N83) -> 0 | S3: =SUBTOTAL(9,S5:S5) -> 0 | T3: =SUBTOTAL(9,T5:T5) -> 0 | U3: =SUBTOTAL(9,U5:U5) -> 0 | V3: =SUBTOTAL(9,V5:V5) -> 0 | W3: =SUBTOTAL(9,W5:W5) -> 0 | X3: =SUBTOTAL(9,X5:X5) -> 0 | Y3: =SUBTOTAL(9,Y5:Y5) -> 0 | Z3: =SUBTOTAL(9,Z5:Z5) -> 0 | ... AB3: =SUBTOTAL(9,AB5:AB5) -> 0 | AD3: =SUBTOTAL(9,AD5:AD5) -> 0 | AE3: =SUBTOTAL(9,AE5:AE5) -> 0 | AF3: =SUBTOTAL(9,AF5:AF5) -> 0 | AG3: =SUBTOTAL(9,AG5:AG5) -> 0 | AH3: =SUBTOTAL(9,AH5:AH5) -> 0 | AI3: =SUBTOTAL(9,AI5:AI5) -> 0 | AJ3: =SUBTOTAL(9,AJ5:AJ5) -> 0 | AK3: =SUBTOTAL(9,AK5:AK5) -> 0 | ... AM3: =SUBTOTAL(9,AM5:AM5) -> 0
B4: Count Recyclers | C4: Customer ID | D4: Customer Name | E4: Qty | F4: Revenue | G4: Margin | H4: Margin(% | I4: Debit Notes | J4: DN to Sale(%) | K4: No of transactions | L4: Avg Tran Value | M4: Avg.Price/kg | N4: Receivables | Q4: Count Recyclers | R4: Name | S4: Apr-25 | T4: May-25 | U4: Jun-25 | V4: Jul-25 | W4: Aug-25 | X4: Sep-25 | Y4: Oct-25 | Z4: Nov-25 | AA4: Dec-25 | AB4: Jan-26 | AD4: Apr-25 | AE4: May-25 | AF4: Jun-25 | AG4: Jul-25 | AH4: Aug-25 | AI4: Sep-25 | AJ4: Oct-25 | AK4: Nov-25 | AL4: Dec-25 | AM4: Jan-26
B5: {=_xlfn.UNIQUE(MID(_xlfn._TRO_TRAILING(Details!AR5:AR8),3,10))} -> AEJFS8446P | C5: {=_xlfn.UNIQUE(_xlfn._TRO_TRAILING(Details!AR5:AR8))} -> 09AEJFS8446P1ZY | D5: =(_xlfn.XLOOKUP(C5,Details!$AR$5:$AR$8,Details!$AQ$5:$AQ$8)) -> Silver Ecotex LLP | E5: =SUMIFS(Details!BB:BB,Details!AR:AR,'Buyer Metrics'!$C5) -> 10845 | F5: =SUMIFS(Details!BL:BL,Details!AR:AR,'Buyer Metrics'!$C5) -> 710347.5 | G5: =SUMIFS(Details!BM:BM,Details!AR:AR,'Buyer Metrics'!$C5) -> 20605.5 | H5: =G5/F5 -> 0.029007634 | I5: =SUMIFS(Details!BW:BW,Details!AR:AR,'Buyer Metrics'!C5) -> 0 | J5: =-(I5/F5) -> 0 | K5: {=COUNTA(_xlfn.UNIQUE(_xlfn._xlws.FILTER(Details!AO5:AO8,Details!AR5:AR8='Buyer Metrics'!$C5)))} -> 1 | L5: =F5/K5 -> 710347.5 | M5: =F5/E5 -> 65.5 | N5: =IFERROR(_xlfn.XLOOKUP(C5,receivables!#REF!,receivables!#REF!),0) -> 0 | Q5: {=_xlfn.UNIQUE(Details!CT5:CT8)} -> AEJFS8446P | R5: =_xlfn.XLOOKUP(Q5,Details!CT:CT,Details!AQ:AQ) -> Silver Ecotex LLP | S5: =SUMIFS(Details!$BL:$BL,Details!$CT:$CT,'Buyer Metrics'!$Q5,Details!$C:$C,'Buyer Metrics'!S$4) -> 0 | T5: =SUMIFS(Details!$BL:$BL,Details!$CT:$CT,'Buyer Metrics'!$Q5,Details!$C:$C,'Buyer Metrics'!T$4) -> 0 | U5: =SUMIFS(Details!$BL:$BL,Details!$CT:$CT,'Buyer Metrics'!$Q5,Details!$C:$C,'Buyer Metrics'!U$4) -> 0 | V5: =SUMIFS(Details!$BL:$BL,Details!$CT:$CT,'Buyer Metrics'!$Q5,Details!$C:$C,'Buyer Metrics'!V$4) -> 0 | W5: =SUMIFS(Details!$BL:$BL,Details!$CT:$CT,'Buyer Metrics'!$Q5,Details!$C:$C,'Buyer Metrics'!W$4) -> 0 | X5: =SUMIFS(Details!$BL:$BL,Details!$CT:$CT,'Buyer Metrics'!$Q5,Details!$C:$C,'Buyer Metrics'!X$4) -> 0 | Y5: =SUMIFS(Details!$BL:$BL,Details!$CT:$CT,'Buyer Metrics'!$Q5,Details!$C:$C,'Buyer Metrics'!Y$4) -> 0 | Z5: =SUMIFS(Details!$BL:$BL,Details!$CT:$CT,'Buyer Metrics'!$Q5,Details!$C:$C,'Buyer Metrics'!Z$4) -> 0 | ... AB5: =SUMIFS(Details!$BL:$BL,Details!$CT:$CT,'Buyer Metrics'!$Q5,Details!$C:$C,'Buyer Metrics'!AB$4) -> 0 | AD5: =SUMIFS(Details!$BB:$BB,Details!$CT:$CT,'Buyer Metrics'!$Q5,Details!$C:$C,'Buyer Metrics'!AD$4) -> 0 | AE5: =SUMIFS(Details!$BB:$BB,Details!$CT:$CT,'Buyer Metrics'!$Q5,Details!$C:$C,'Buyer Metrics'!AE$4) -> 0 | AF5: =SUMIFS(Details!$BB:$BB,Details!$CT:$CT,'Buyer Metrics'!$Q5,Details!$C:$C,'Buyer Metrics'!AF$4) -> 0 | AG5: =SUMIFS(Details!$BB:$BB,Details!$CT:$CT,'Buyer Metrics'!$Q5,Details!$C:$C,'Buyer Metrics'!AG$4) -> 0 | AH5: =SUMIFS(Details!$BB:$BB,Details!$CT:$CT,'Buyer Metrics'!$Q5,Details!$C:$C,'Buyer Metrics'!AH$4) -> 0 | AI5: =SUMIFS(Details!$BB:$BB,Details!$CT:$CT,'Buyer Metrics'!$Q5,Details!$C:$C,'Buyer Metrics'!AI$4) -> 0 | AJ5: =SUMIFS(Details!$BB:$BB,Details!$CT:$CT,'Buyer Metrics'!$Q5,Details!$C:$C,'Buyer Metrics'!AJ$4) -> 0 | AK5: =SUMIFS(Details!$BB:$BB,Details!$CT:$CT,'Buyer Metrics'!$Q5,Details!$C:$C,'Buyer Metrics'!AK$4) -> 0 | ... AM5: =SUMIFS(Details!$BB:$BB,Details!$CT:$CT,'Buyer Metrics'!$Q5,Details!$C:$C,'Buyer Metrics'!AM$4) -> 0
B6: AAFCJ3332A | C6: 24AAFCJ3332A1Z9 | D6: =(_xlfn.XLOOKUP(C6,Details!$AR$5:$AR$8,Details!$AQ$5:$AQ$8)) -> J B ECOTEX LIMITED | E6: =SUMIFS(Details!BB:BB,Details!AR:AR,'Buyer Metrics'!$C6) -> 16490 | F6: =SUMIFS(Details!BL:BL,Details!AR:AR,'Buyer Metrics'!$C6) -> 892315.12 | G6: =SUMIFS(Details!BM:BM,Details!AR:AR,'Buyer Metrics'!$C6) -> 27043.6 | H6: =G6/F6 -> 0.03030723 | I6: =SUMIFS(Details!BW:BW,Details!AR:AR,'Buyer Metrics'!C6) -> 0 | J6: =-(I6/F6) -> 0 | K6: {=COUNTA(_xlfn.UNIQUE(_xlfn._xlws.FILTER(Details!AO6:AO9,Details!AR6:AR9='Buyer Metrics'!$C6)))} -> 1 | L6: =F6/K6 -> 892315.12 | M6: =F6/E6 -> 54.1125 | N6: =IFERROR(_xlfn.XLOOKUP(C6,receivables!#REF!,receivables!#REF!),0) -> 0 | Q6: AAFCJ3332A
B7: AAICB1747Q | C7: 23AAICB1747Q1ZC | D7: =(_xlfn.XLOOKUP(C7,Details!$AR$5:$AR$8,Details!$AQ$5:$AQ$8)) -> BLUEOCEAN ECOTECH LIMITED | E7: =SUMIFS(Details!BB:BB,Details!AR:AR,'Buyer Metrics'!$C7) -> 8915 | F7: =SUMIFS(Details!BL:BL,Details!AR:AR,'Buyer Metrics'!$C7) -> 582372.38 | G7: =SUMIFS(Details!BM:BM,Details!AR:AR,'Buyer Metrics'!$C7) -> -10475.125 | H7: =G7/F7 -> -0.017986988 | I7: =SUMIFS(Details!BW:BW,Details!AR:AR,'Buyer Metrics'!C7) -> 0 | J7: =-(I7/F7) -> 0 | K7: {=COUNTA(_xlfn.UNIQUE(_xlfn._xlws.FILTER(Details!AO7:AO10,Details!AR7:AR10='Buyer Metrics'!$C7)))} -> 1 | L7: =F7/K7 -> 582372.38 | M7: =F7/E7 -> 65.325 | N7: =IFERROR(_xlfn.XLOOKUP(C7,receivables!#REF!,receivables!#REF!),0) -> 0 | Q7: AAICB1747Q
Q8: 0

Sheet Material Metrics
B2: Material | C2: Category A | D2: Category B
B3: {=_xlfn.UNIQUE(_xlfn._TRO_TRAILING(Details!N5:N8))} -> PET - Hot Washed White Flakes, Grade 2 | C3: PET
B4: WASTE PLASTIC-PP
B5: Hot washed PET flakes
C41: HDPE
C42: HDPE

Sheet receivables
D1: =Details!P22 -> 46194 | E1: =SUBTOTAL(9,E3:E136) -> #N/A | R1: =SUBTOTAL(9,R3:R1000) -> 1.1283315e+08 | S1: =SUBTOTAL(9,S3:S1000) -> 1.5939088e+08 | AA1: =SUBTOTAL(9,AA3:AA150) -> 776632.63 | AB1: =R1-AA1 -> 1.1205652e+08 | AE1: Legacy | AF1: =R1-AA1-SUM(AF3:AF16)-AF18 -> 54302522 | AO1: =SUM(AO3:AO480) -> 19968208
B2: Customer ID | C2: Buyer Name | D2: POC Name | E2: Recivables | H2: POC Name | I2: Buyer Name | K2: date | L2: status | M2: entity | N2: age | O2: due_date | P2: transaction_number | Q2: customer_name | R2: balance | S2: amount | T2: payment_terms | U2: gst_no | V2: credit_limit | W2: unused_credits_receivable_amount | X2: contact.CF.Vertical Name | Y2: Check | Z2: Customer Name | AA2: Unused | AE2: Customer Name | AF2: Current O/s | AH2: date | AI2: status | AJ2: entity | AK2: age | AL2: due_date | AM2: transaction_number | AN2: vendor_name | AO2: balance | AP2: amount | AQ2: gst_no | AR2: vendor.CF.Vertical Name | AS2: vendor.CF.MSME Category
B3: {=_xlfn.UNIQUE(_xlfn._TRO_TRAILING(Details!AR5:AR8))} -> 09AEJFS8446P1ZY | C3: =_xlfn.XLOOKUP(B3,Details!AR:AR,Details!AQ:AQ) -> Silver Ecotex LLP | D3: Neelesh Dixit | E3: =_xlfn.XLOOKUP(C3,I:I,H:H) -> Neelesh Dixit | H3: Neelesh Dixit | I3: M/S KASHI VISHWANATH TEXTILE MILL PRIVATE LIMITED | K3: 44801 | L3: overdue | M3: invoice | N3: 1375 | O3: 2022-09-15 | P3: 23/MPPET/INV2883 | Q3: VANSH POLYPACK LLP | R3: 866675.04 | S3: 1073444.2 | T3: Net 15 (Days) | U3: 09AARFV5599C1ZE | V3: 0.01 | W3: 0 | X3: Marketplace (Plastic Waste) | Y3: Marketplace (Plastic Waste) | Z3: {=_xlfn.UNIQUE(Q3:Q766)} -> VANSH POLYPACK LLP | AA3: =_xlfn.XLOOKUP(Z3,Q:Q,W:W) -> 0 | AE3: VANSH POLYPACK LLP | AF3: =SUMIFS(R:R,Q:Q,AE3) -> 27995932 | AH3: 2022-03-31 | AI3: overdue | AJ3: bill | AK3: 1540 | AL3: 2022-04-03 | AM3: 15294 | AN3: NEW SHALIMAR ROADWAYS | AO3: 7140 | AP3: 51000 | AQ3: 23AAIFN0748A2ZR | AR3: Marketplace (Plastic Waste) | AS3: Small
B4: 24AAFCJ3332A1Z9 | C4: =_xlfn.XLOOKUP(B4,Details!AR:AR,Details!AQ:AQ) -> J B ECOTEX LIMITED | D4: Neelesh Dixit | E4: =_xlfn.XLOOKUP(C4,I:I,H:H) -> Ramesh G | H4: Neelesh Dixit | I4: NIRMAL FIBRES PRIVATE LIMITED | K4: 44803 | L4: overdue | M4: invoice | N4: 1372 | O4: 2022-09-18 | P4: 23/MPPET/INV2909 | Q4: VANSH POLYPACK LLP | R4: 451970.68 | S4: 472619.5 | T4: Net 15 (Days) | U4: 09AARFV5599C1ZE | V4: 0.01 | W4: 0 | X4: Marketplace (Plastic Waste) | Y4: Marketplace (Plastic Waste) | Z4: INDIA POLYMERS | AA4: =_xlfn.XLOOKUP(Z4,Q:Q,W:W) -> 0 | AE4: INDIA POLYMERS | AF4: =SUMIFS(R:R,Q:Q,AE4) -> 26666038 | AH4: 2022-03-31 | AI4: overdue | AJ4: bill | AK4: 1542 | AL4: 2022-04-01 | AM4: 692302 | AN4: VRL Logistics Ltd | AO4: 1800 | AP4: 97000 | AQ4: 29AABCV3609C1ZJ | AR4: Marketplace (Plastic Waste) | AS4: Not Registered
